Workbook

Sheet Roster
A1: For public domain. No rights reserved. Generated on Sep 06, 2026.
A2: Howell Tournament
A3: Pairs | C3: 7
A4: Tables | C4: 4
A5: Rounds | C5: 7
A6: Boards per round | C6: 3
A7: Total Boards to play | C7: 21
A9: Pairs | D9: MP | E9: IMP
A10: 1 | B10: Name 30 | C10: Name 79 | D10: =SUMIF('By Board'!D3:D86,"="&A10,'By Board'!Q3:Q86)/36+SUMIF('By Board'!E3:E86,"="&A10,'By Board'!R3:R86)/36 | E10: =SUMIF('By Board'!D3:D86,"="&A10,'By Board'!M3:M86)+SUMIF('By Board'!E3:E86,"="&A10,'By Board'!N3:N86)
A11: 2 | B11: Name 63 | C11: Name 33 | D11: =SUMIF('By Board'!D3:D86,"="&A11,'By Board'!Q3:Q86)/36+SUMIF('By Board'!E3:E86,"="&A11,'By Board'!R3:R86)/36 | E11: =SUMIF('By Board'!D3:D86,"="&A11,'By Board'!M3:M86)+SUMIF('By Board'!E3:E86,"="&A11,'By Board'!N3:N86)
A12: 3 | B12: Name 25 | C12: Name 26 | D12: =SUMIF('By Board'!D3:D86,"="&A12,'By Board'!Q3:Q86)/36+SUMIF('By Board'!E3:E86,"="&A12,'By Board'!R3:R86)/36 | E12: =SUMIF('By Board'!D3:D86,"="&A12,'By Board'!M3:M86)+SUMIF('By Board'!E3:E86,"="&A12,'By Board'!N3:N86)
A13: 4 | B13: Name 17 | C13: Name 60 | D13: =SUMIF('By Board'!D3:D86,"="&A13,'By Board'!Q3:Q86)/36+SUMIF('By Board'!E3:E86,"="&A13,'By Board'!R3:R86)/36 | E13: =SUMIF('By Board'!D3:D86,"="&A13,'By Board'!M3:M86)+SUMIF('By Board'!E3:E86,"="&A13,'By Board'!N3:N86)
A14: 5 | B14: Name 77 | C14: Name 15 | D14: =SUMIF('By Board'!D3:D86,"="&A14,'By Board'!Q3:Q86)/36+SUMIF('By Board'!E3:E86,"="&A14,'By Board'!R3:R86)/36 | E14: =SUMIF('By Board'!D3:D86,"="&A14,'By Board'!M3:M86)+SUMIF('By Board'!E3:E86,"="&A14,'By Board'!N3:N86)
A15: 6 | B15: Name 64 | C15: Name 80 | D15: =SUMIF('By Board'!D3:D86,"="&A15,'By Board'!Q3:Q86)/36+SUMIF('By Board'!E3:E86,"="&A15,'By Board'!R3:R86)/36 | E15: =SUMIF('By Board'!D3:D86,"="&A15,'By Board'!M3:M86)+SUMIF('By Board'!E3:E86,"="&A15,'By Board'!N3:N86)
A16: 7 | B16: Name 77 | C16: Name 14 | D16: =SUMIF('By Board'!D3:D86,"="&A16,'By Board'!Q3:Q86)/36+SUMIF('By Board'!E3:E86,"="&A16,'By Board'!R3:R86)/36 | E16: =SUMIF('By Board'!D3:D86,"="&A16,'By Board'!M3:M86)+SUMIF('By Board'!E3:E86,"="&A16,'By Board'!N3:N86)
D17: =AVERAGE(D10:D16) | E17: =SUM(E10:E16)

Sheet By Board
I1: Result | K1: Score | M1: IMP | O1: MP % | Q1: MP Pts | S1: Net | U1: MP Calculation | Y1: IMP Calculation
A2: Board | B2: Round | C2: Table | D2: NS | E2: EW | F2: Vul | G2: Contract | H2: By | I2: Made | J2: Down | K2: NS | L2: EW | M2: NS | N2: EW | O2: NS | P2: EW | Q2: NS | R2: EW | S2: NS | T2: EW | U2: NS MP Scores | W2: EW MP Scores | Y2: NS IMP Pair-wise | AA2: EW IMP Pair-wise
A3: 1 | B3: ='By Round'!A3 | C3: ='By Round'!B3 | D3: ='By Round'!C3 | E3: ='By Round'!D3 | F3: =IF(ISBLANK('By Round'!F3),"",'By Round'!F3) | G3: =IF(ISBLANK('By Round'!G3),"",'By Round'!G3) | H3: =IF(ISBLANK('By Round'!H3),"",'By Round'!H3) | I3: =IF(ISBLANK('By Round'!I3),"",'By Round'!I3) | J3: =IF(ISBLANK('By Round'!J3),"",'By Round'!J3) | K3: =IF(ISBLANK('By Round'!K3),"",'By Round'!K3) | L3: =IF(ISBLANK('By Round'!L3),"",'By Round'!L3) | M3: =IF(ISBLANK('By Round'!M3),"",'By Round'!M3) | ... X3: =IF(ISBLANK('By Round'!X3),"",'By Round'!X3)
B4: ='By Round'!A63 | C4: ='By Round'!B69 | D4: ='By Round'!C69 | E4: ='By Round'!D69 | F4: =IF(ISBLANK('By Round'!F69),"",'By Round'!F69) | G4: =IF(ISBLANK('By Round'!G69),"",'By Round'!G69) | H4: =IF(ISBLANK('By Round'!H69),"",'By Round'!H69) | I4: =IF(ISBLANK('By Round'!I69),"",'By Round'!I69) | J4: =IF(ISBLANK('By Round'!J69),"",'By Round'!J69) | K4: =IF(ISBLANK('By Round'!K69),"",'By Round'!K69) | L4: =IF(ISBLANK('By Round'!L69),"",'By Round'!L69) | M4: =AVERAGE(Y4:Z4) | N4: =AVERAGE(AA4:AB4) | O4: =IF(COUNT(U4:V4)>0,Q4/COUNT(U4:V4),0.5) | P4: =IF(COUNT(W4:X4)>0,R4/COUNT(W4:X4),0.5) | Q4: =SUM(U4:V4) | R4: =SUM(W4:X4) | S4: =IF(ISNUMBER(K4),K4,IF(ISNUMBER(L4),-L4,"")) | T4: =IF(ISNUMBER(L4),L4,IF(ISNUMBER(K4),-K4,"")) | U4: =IF(ISNUMBER(S4),IF(ISNUMBER(S5),IF(S4>S5,1.0,IF(S4=S5,0.5,0.0)),0.5),0.5) | V4: =IF(ISNUMBER(S4),IF(ISNUMBER(S6),IF(S4>S6,1.0,IF(S4=S6,0.5,0.0)),0.5),0.5) | W4: =IF(ISNUMBER(T4),IF(ISNUMBER(T5),IF(T4>T5,1.0,IF(T4=T5,0.5,0.0)),0.5),0.5) | X4: =IF(ISNUMBER(T4),IF(ISNUMBER(T6),IF(T4>T6,1.0,IF(T4=T6,0.5,0.0)),0.5),0.5) | Y4: =IF(AND(ISNUMBER(S4),ISNUMBER(S5)),VLOOKUP(ABS(S4-S5),'IMP Table'!$A$2:$C$26,3)*SIGN(S4-S5),0) | Z4: =IF(AND(ISNUMBER(S4),ISNUMBER(S6)),VLOOKUP(ABS(S4-S6),'IMP Table'!$A$2:$C$26,3)*SIGN(S4-S6),0) | AA4: =IF(AND(ISNUMBER(T4),ISNUMBER(T5)),VLOOKUP(ABS(T4-T5),'IMP Table'!$A$2:$C$26,3)*SIGN(T4-T5),0) | AB4: =IF(AND(ISNUMBER(T4),ISNUMBER(T6)),VLOOKUP(ABS(T4-T6),'IMP Table'!$A$2:$C$26,3)*SIGN(T4-T6),0)
B5: ='By Round'!A39 | C5: ='By Round'!B48 | D5: ='By Round'!C48 | E5: ='By Round'!D48 | F5: =IF(ISBLANK('By Round'!F48),"",'By Round'!F48) | G5: =IF(ISBLANK('By Round'!G48),"",'By Round'!G48) | H5: =IF(ISBLANK('By Round'!H48),"",'By Round'!H48) | I5: =IF(ISBLANK('By Round'!I48),"",'By Round'!I48) | J5: =IF(ISBLANK('By Round'!J48),"",'By Round'!J48) | K5: =IF(ISBLANK('By Round'!K48),"",'By Round'!K48) | L5: =IF(ISBLANK('By Round'!L48),"",'By Round'!L48) | M5: =AVERAGE(Y5:Z5) | N5: =AVERAGE(AA5:AB5) | O5: =IF(COUNT(U5:V5)>0,Q5/COUNT(U5:V5),0.5) | P5: =IF(COUNT(W5:X5)>0,R5/COUNT(W5:X5),0.5) | Q5: =SUM(U5:V5) | R5: =SUM(W5:X5) | S5: =IF(ISNUMBER(K5),K5,IF(ISNUMBER(L5),-L5,"")) | T5: =IF(ISNUMBER(L5),L5,IF(ISNUMBER(K5),-K5,"")) | U5: =IF(ISNUMBER(S5),IF(ISNUMBER(S4),IF(S5>S4,1.0,IF(S5=S4,0.5,0.0)),0.5),0.5) | V5: =IF(ISNUMBER(S5),IF(ISNUMBER(S6),IF(S5>S6,1.0,IF(S5=S6,0.5,0.0)),0.5),0.5) | W5: =IF(ISNUMBER(T5),IF(ISNUMBER(T4),IF(T5>T4,1.0,IF(T5=T4,0.5,0.0)),0.5),0.5) | X5: =IF(ISNUMBER(T5),IF(ISNUMBER(T6),IF(T5>T6,1.0,IF(T5=T6,0.5,0.0)),0.5),0.5) | Y5: =IF(AND(ISNUMBER(S5),ISNUMBER(S4)),VLOOKUP(ABS(S5-S4),'IMP Table'!$A$2:$C$26,3)*SIGN(S5-S4),0) | Z5: =IF(AND(ISNUMBER(S5),ISNUMBER(S6)),VLOOKUP(ABS(S5-S6),'IMP Table'!$A$2:$C$26,3)*SIGN(S5-S6),0) | AA5: =IF(AND(ISNUMBER(T5),ISNUMBER(T4)),VLOOKUP(ABS(T5-T4),'IMP Table'!$A$2:$C$26,3)*SIGN(T5-T4),0) | AB5: =IF(AND(ISNUMBER(T5),ISNUMBER(T6)),VLOOKUP(ABS(T5-T6),'IMP Table'!$A$2:$C$26,3)*SIGN(T5-T6),0)
B6: ='By Round'!A75 | C6: ='By Round'!B78 | D6: ='By Round'!C78 | E6: ='By Round'!D78 | F6: =IF(ISBLANK('By Round'!F78),"",'By Round'!F78) | G6: =IF(ISBLANK('By Round'!G78),"",'By Round'!G78) | H6: =IF(ISBLANK('By Round'!H78),"",'By Round'!H78) | I6: =IF(ISBLANK('By Round'!I78),"",'By Round'!I78) | J6: =IF(ISBLANK('By Round'!J78),"",'By Round'!J78) | K6: =IF(ISBLANK('By Round'!K78),"",'By Round'!K78) | L6: =IF(ISBLANK('By Round'!L78),"",'By Round'!L78) | M6: =AVERAGE(Y6:Z6) | N6: =AVERAGE(AA6:AB6) | O6: =IF(COUNT(U6:V6)>0,Q6/COUNT(U6:V6),0.5) | P6: =IF(COUNT(W6:X6)>0,R6/COUNT(W6:X6),0.5) | Q6: =SUM(U6:V6) | R6: =SUM(W6:X6) | S6: =IF(ISNUMBER(K6),K6,IF(ISNUMBER(L6),-L6,"")) | T6: =IF(ISNUMBER(L6),L6,IF(ISNUMBER(K6),-K6,"")) | U6: =IF(ISNUMBER(S6),IF(ISNUMBER(S4),IF(S6>S4,1.0,IF(S6=S4,0.5,0.0)),0.5),0.5) | V6: =IF(ISNUMBER(S6),IF(ISNUMBER(S5),IF(S6>S5,1.0,IF(S6=S5,0.5,0.0)),0.5),0.5) | W6: =IF(ISNUMBER(T6),IF(ISNUMBER(T4),IF(T6>T4,1.0,IF(T6=T4,0.5,0.0)),0.5),0.5) | X6: =IF(ISNUMBER(T6),IF(ISNUMBER(T5),IF(T6>T5,1.0,IF(T6=T5,0.5,0.0)),0.5),0.5) | Y6: =IF(AND(ISNUMBER(S6),ISNUMBER(S4)),VLOOKUP(ABS(S6-S4),'IMP Table'!$A$2:$C$26,3)*SIGN(S6-S4),0) | Z6: =IF(AND(ISNUMBER(S6),ISNUMBER(S5)),VLOOKUP(ABS(S6-S5),'IMP Table'!$A$2:$C$26,3)*SIGN(S6-S5),0) | AA6: =IF(AND(ISNUMBER(T6),ISNUMBER(T4)),VLOOKUP(ABS(T6-T4),'IMP Table'!$A$2:$C$26,3)*SIGN(T6-T4),0) | AB6: =IF(AND(ISNUMBER(T6),ISNUMBER(T5)),VLOOKUP(ABS(T6-T5),'IMP Table'!$A$2:$C$26,3)*SIGN(T6-T5),0)
A7: 2 | B7: ='By Round'!A3 | C7: ='By Round'!B3 | D7: ='By Round'!C3 | E7: ='By Round'!D3 | F7: =IF(ISBLANK('By Round'!F4),"",'By Round'!F4) | G7: =IF(ISBLANK('By Round'!G4),"",'By Round'!G4) | H7: =IF(ISBLANK('By Round'!H4),"",'By Round'!H4) | I7: =IF(ISBLANK('By Round'!I4),"",'By Round'!I4) | J7: =IF(ISBLANK('By Round'!J4),"",'By Round'!J4) | K7: =IF(ISBLANK('By Round'!K4),"",'By Round'!K4) | L7: =IF(ISBLANK('By Round'!L4),"",'By Round'!L4) | M7: =IF(ISBLANK('By Round'!M4),"",'By Round'!M4) | ... X7: =IF(ISBLANK('By Round'!X4),"",'By Round'!X4)
B8: ='By Round'!A63 | C8: ='By Round'!B69 | D8: ='By Round'!C69 | E8: ='By Round'!D69 | F8: =IF(ISBLANK('By Round'!F70),"",'By Round'!F70) | G8: =IF(ISBLANK('By Round'!G70),"",'By Round'!G70) | H8: =IF(ISBLANK('By Round'!H70),"",'By Round'!H70) | I8: =IF(ISBLANK('By Round'!I70),"",'By Round'!I70) | J8: =IF(ISBLANK('By Round'!J70),"",'By Round'!J70) | K8: =IF(ISBLANK('By Round'!K70),"",'By Round'!K70) | L8: =IF(ISBLANK('By Round'!L70),"",'By Round'!L70) | M8: =AVERAGE(Y8:Z8) | N8: =AVERAGE(AA8:AB8) | O8: =IF(COUNT(U8:V8)>0,Q8/COUNT(U8:V8),0.5) | P8: =IF(COUNT(W8:X8)>0,R8/COUNT(W8:X8),0.5) | Q8: =SUM(U8:V8) | R8: =SUM(W8:X8) | S8: =IF(ISNUMBER(K8),K8,IF(ISNUMBER(L8),-L8,"")) | T8: =IF(ISNUMBER(L8),L8,IF(ISNUMBER(K8),-K8,"")) | U8: =IF(ISNUMBER(S8),IF(ISNUMBER(S9),IF(S8>S9,1.0,IF(S8=S9,0.5,0.0)),0.5),0.5) | V8: =IF(ISNUMBER(S8),IF(ISNUMBER(S10),IF(S8>S10,1.0,IF(S8=S10,0.5,0.0)),0.5),0.5) | W8: =IF(ISNUMBER(T8),IF(ISNUMBER(T9),IF(T8>T9,1.0,IF(T8=T9,0.5,0.0)),0.5),0.5) | X8: =IF(ISNUMBER(T8),IF(ISNUMBER(T10),IF(T8>T10,1.0,IF(T8=T10,0.5,0.0)),0.5),0.5) | Y8: =IF(AND(ISNUMBER(S8),ISNUMBER(S9)),VLOOKUP(ABS(S8-S9),'IMP Table'!$A$2:$C$26,3)*SIGN(S8-S9),0) | Z8: =IF(AND(ISNUMBER(S8),ISNUMBER(S10)),VLOOKUP(ABS(S8-S10),'IMP Table'!$A$2:$C$26,3)*SIGN(S8-S10),0) | AA8: =IF(AND(ISNUMBER(T8),ISNUMBER(T9)),VLOOKUP(ABS(T8-T9),'IMP Table'!$A$2:$C$26,3)*SIGN(T8-T9),0) | AB8: =IF(AND(ISNUMBER(T8),ISNUMBER(T10)),VLOOKUP(ABS(T8-T10),'IMP Table'!$A$2:$C$26,3)*SIGN(T8-T10),0)
B9: ='By Round'!A39 | C9: ='By Round'!B48 | D9: ='By Round'!C48 | E9: ='By Round'!D48 | F9: =IF(ISBLANK('By Round'!F49),"",'By Round'!F49) | G9: =IF(ISBLANK('By Round'!G49),"",'By Round'!G49) | H9: =IF(ISBLANK('By Round'!H49),"",'By Round'!H49) | I9: =IF(ISBLANK('By Round'!I49),"",'By Round'!I49) | J9: =IF(ISBLANK('By Round'!J49),"",'By Round'!J49) | K9: =IF(ISBLANK('By Round'!K49),"",'By Round'!K49) | L9: =IF(ISBLANK('By Round'!L49),"",'By Round'!L49) | M9: =AVERAGE(Y9:Z9) | N9: =AVERAGE(AA9:AB9) | O9: =IF(COUNT(U9:V9)>0,Q9/COUNT(U9:V9),0.5) | P9: =IF(COUNT(W9:X9)>0,R9/COUNT(W9:X9),0.5) | Q9: =SUM(U9:V9) | R9: =SUM(W9:X9) | S9: =IF(ISNUMBER(K9),K9,IF(ISNUMBER(L9),-L9,"")) | T9: =IF(ISNUMBER(L9),L9,IF(ISNUMBER(K9),-K9,"")) | U9: =IF(ISNUMBER(S9),IF(ISNUMBER(S8),IF(S9>S8,1.0,IF(S9=S8,0.5,0.0)),0.5),0.5) | V9: =IF(ISNUMBER(S9),IF(ISNUMBER(S10),IF(S9>S10,1.0,IF(S9=S10,0.5,0.0)),0.5),0.5) | W9: =IF(ISNUMBER(T9),IF(ISNUMBER(T8),IF(T9>T8,1.0,IF(T9=T8,0.5,0.0)),0.5),0.5) | X9: =IF(ISNUMBER(T9),IF(ISNUMBER(T10),IF(T9>T10,1.0,IF(T9=T10,0.5,0.0)),0.5),0.5) | Y9: =IF(AND(ISNUMBER(S9),ISNUMBER(S8)),VLOOKUP(ABS(S9-S8),'IMP Table'!$A$2:$C$26,3)*SIGN(S9-S8),0) | Z9: =IF(AND(ISNUMBER(S9),ISNUMBER(S10)),VLOOKUP(ABS(S9-S10),'IMP Table'!$A$2:$C$26,3)*SIGN(S9-S10),0) | AA9: =IF(AND(ISNUMBER(T9),ISNUMBER(T8)),VLOOKUP(ABS(T9-T8),'IMP Table'!$A$2:$C$26,3)*SIGN(T9-T8),0) | AB9: =IF(AND(ISNUMBER(T9),ISNUMBER(T10)),VLOOKUP(ABS(T9-T10),'IMP Table'!$A$2:$C$26,3)*SIGN(T9-T10),0)
B10: ='By Round'!A75 | C10: ='By Round'!B78 | D10: ='By Round'!C78 | E10: ='By Round'!D78 | F10: =IF(ISBLANK('By Round'!F79),"",'By Round'!F79) | G10: =IF(ISBLANK('By Round'!G79),"",'By Round'!G79) | H10: =IF(ISBLANK('By Round'!H79),"",'By Round'!H79) | I10: =IF(ISBLANK('By Round'!I79),"",'By Round'!I79) | J10: =IF(ISBLANK('By Round'!J79),"",'By Round'!J79) | K10: =IF(ISBLANK('By Round'!K79),"",'By Round'!K79) | L10: =IF(ISBLANK('By Round'!L79),"",'By Round'!L79) | M10: =AVERAGE(Y10:Z10) | N10: =AVERAGE(AA10:AB10) | O10: =IF(COUNT(U10:V10)>0,Q10/COUNT(U10:V10),0.5) | P10: =IF(COUNT(W10:X10)>0,R10/COUNT(W10:X10),0.5) | Q10: =SUM(U10:V10) | R10: =SUM(W10:X10) | S10: =IF(ISNUMBER(K10),K10,IF(ISNUMBER(L10),-L10,"")) | T10: =IF(ISNUMBER(L10),L10,IF(ISNUMBER(K10),-K10,"")) | U10: =IF(ISNUMBER(S10),IF(ISNUMBER(S8),IF(S10>S8,1.0,IF(S10=S8,0.5,0.0)),0.5),0.5) | V10: =IF(ISNUMBER(S10),IF(ISNUMBER(S9),IF(S10>S9,1.0,IF(S10=S9,0.5,0.0)),0.5),0.5) | W10: =IF(ISNUMBER(T10),IF(ISNUMBER(T8),IF(T10>T8,1.0,IF(T10=T8,0.5,0.0)),0.5),0.5) | X10: =IF(ISNUMBER(T10),IF(ISNUMBER(T9),IF(T10>T9,1.0,IF(T10=T9,0.5,0.0)),0.5),0.5) | Y10: =IF(AND(ISNUMBER(S10),ISNUMBER(S8)),VLOOKUP(ABS(S10-S8),'IMP Table'!$A$2:$C$26,3)*SIGN(S10-S8),0) | Z10: =IF(AND(ISNUMBER(S10),ISNUMBER(S9)),VLOOKUP(ABS(S10-S9),'IMP Table'!$A$2:$C$26,3)*SIGN(S10-S9),0) | AA10: =IF(AND(ISNUMBER(T10),ISNUMBER(T8)),VLOOKUP(ABS(T10-T8),'IMP Table'!$A$2:$C$26,3)*SIGN(T10-T8),0) | AB10: =IF(AND(ISNUMBER(T10),ISNUMBER(T9)),VLOOKUP(ABS(T10-T9),'IMP Table'!$A$2:$C$26,3)*SIGN(T10-T9),0)
A11: 3 | B11: ='By Round'!A3 | C11: ='By Round'!B3 | D11: ='By Round'!C3 | E11: ='By Round'!D3 | F11: =IF(ISBLANK('By Round'!F5),"",'By Round'!F5) | G11: =IF(ISBLANK('By Round'!G5),"",'By Round'!G5) | H11: =IF(ISBLANK('By Round'!H5),"",'By Round'!H5) | I11: =IF(ISBLANK('By Round'!I5),"",'By Round'!I5) | J11: =IF(ISBLANK('By Round'!J5),"",'By Round'!J5) | K11: =IF(ISBLANK('By Round'!K5),"",'By Round'!K5) | L11: =IF(ISBLANK('By Round'!L5),"",'By Round'!L5) | M11: =IF(ISBLANK('By Round'!M5),"",'By Round'!M5) | ... X11: =IF(ISBLANK('By Round'!X5),"",'By Round'!X5)
B12: ='By Round'!A63 | C12: ='By Round'!B69 | D12: ='By Round'!C69 | E12: ='By Round'!D69 | F12: =IF(ISBLANK('By Round'!F71),"",'By Round'!F71) | G12: =IF(ISBLANK('By Round'!G71),"",'By Round'!G71) | H12: =IF(ISBLANK('By Round'!H71),"",'By Round'!H71) | I12: =IF(ISBLANK('By Round'!I71),"",'By Round'!I71) | J12: =IF(ISBLANK('By Round'!J71),"",'By Round'!J71) | K12: =IF(ISBLANK('By Round'!K71),"",'By Round'!K71) | L12: =IF(ISBLANK('By Round'!L71),"",'By Round'!L71) | M12: =AVERAGE(Y12:Z12) | N12: =AVERAGE(AA12:AB12) | O12: =IF(COUNT(U12:V12)>0,Q12/COUNT(U12:V12),0.5) | P12: =IF(COUNT(W12:X12)>0,R12/COUNT(W12:X12),0.5) | Q12: =SUM(U12:V12) | R12: =SUM(W12:X12) | S12: =IF(ISNUMBER(K12),K12,IF(ISNUMBER(L12),-L12,"")) | T12: =IF(ISNUMBER(L12),L12,IF(ISNUMBER(K12),-K12,"")) | U12: =IF(ISNUMBER(S12),IF(ISNUMBER(S13),IF(S12>S13,1.0,IF(S12=S13,0.5,0.0)),0.5),0.5) | V12: =IF(ISNUMBER(S12),IF(ISNUMBER(S14),IF(S12>S14,1.0,IF(S12=S14,0.5,0.0)),0.5),0.5) | W12: =IF(ISNUMBER(T12),IF(ISNUMBER(T13),IF(T12>T13,1.0,IF(T12=T13,0.5,0.0)),0.5),0.5) | X12: =IF(ISNUMBER(T12),IF(ISNUMBER(T14),IF(T12>T14,1.0,IF(T12=T14,0.5,0.0)),0.5),0.5) | Y12: =IF(AND(ISNUMBER(S12),ISNUMBER(S13)),VLOOKUP(ABS(S12-S13),'IMP Table'!$A$2:$C$26,3)*SIGN(S12-S13),0) | Z12: =IF(AND(ISNUMBER(S12),ISNUMBER(S14)),VLOOKUP(ABS(S12-S14),'IMP Table'!$A$2:$C$26,3)*SIGN(S12-S14),0) | AA12: =IF(AND(ISNUMBER(T12),ISNUMBER(T13)),VLOOKUP(ABS(T12-T13),'IMP Table'!$A$2:$C$26,3)*SIGN(T12-T13),0) | AB12: =IF(AND(ISNUMBER(T12),ISNUMBER(T14)),VLOOKUP(ABS(T12-T14),'IMP Table'!$A$2:$C$26,3)*SIGN(T12-T14),0)
B13: ='By Round'!A39 | C13: ='By Round'!B48 | D13: ='By Round'!C48 | E13: ='By Round'!D48 | F13: =IF(ISBLANK('By Round'!F50),"",'By Round'!F50) | G13: =IF(ISBLANK('By Round'!G50),"",'By Round'!G50) | H13: =IF(ISBLANK('By Round'!H50),"",'By Round'!H50) | I13: =IF(ISBLANK('By Round'!I50),"",'By Round'!I50) | J13: =IF(ISBLANK('By Round'!J50),"",'By Round'!J50) | K13: =IF(ISBLANK('By Round'!K50),"",'By Round'!K50) | L13: =IF(ISBLANK('By Round'!L50),"",'By Round'!L50) | M13: =AVERAGE(Y13:Z13) | N13: =AVERAGE(AA13:AB13) | O13: =IF(COUNT(U13:V13)>0,Q13/COUNT(U13:V13),0.5) | P13: =IF(COUNT(W13:X13)>0,R13/COUNT(W13:X13),0.5) | Q13: =SUM(U13:V13) | R13: =SUM(W13:X13) | S13: =IF(ISNUMBER(K13),K13,IF(ISNUMBER(L13),-L13,"")) | T13: =IF(ISNUMBER(L13),L13,IF(ISNUMBER(K13),-K13,"")) | U13: =IF(ISNUMBER(S13),IF(ISNUMBER(S12),IF(S13>S12,1.0,IF(S13=S12,0.5,0.0)),0.5),0.5) | V13: =IF(ISNUMBER(S13),IF(ISNUMBER(S14),IF(S13>S14,1.0,IF(S13=S14,0.5,0.0)),0.5),0.5) | W13: =IF(ISNUMBER(T13),IF(ISNUMBER(T12),IF(T13>T12,1.0,IF(T13=T12,0.5,0.0)),0.5),0.5) | X13: =IF(ISNUMBER(T13),IF(ISNUMBER(T14),IF(T13>T14,1.0,IF(T13=T14,0.5,0.0)),0.5),0.5) | Y13: =IF(AND(ISNUMBER(S13),ISNUMBER(S12)),VLOOKUP(ABS(S13-S12),'IMP Table'!$A$2:$C$26,3)*SIGN(S13-S12),0) | Z13: =IF(AND(ISNUMBER(S13),ISNUMBER(S14)),VLOOKUP(ABS(S13-S14),'IMP Table'!$A$2:$C$26,3)*SIGN(S13-S14),0) | AA13: =IF(AND(ISNUMBER(T13),ISNUMBER(T12)),VLOOKUP(ABS(T13-T12),'IMP Table'!$A$2:$C$26,3)*SIGN(T13-T12),0) | AB13: =IF(AND(ISNUMBER(T13),ISNUMBER(T14)),VLOOKUP(ABS(T13-T14),'IMP Table'!$A$2:$C$26,3)*SIGN(T13-T14),0)
B14: ='By Round'!A75 | C14: ='By Round'!B78 | D14: ='By Round'!C78 | E14: ='By Round'!D78 | F14: =IF(ISBLANK('By Round'!F80),"",'By Round'!F80) | G14: =IF(ISBLANK('By Round'!G80),"",'By Round'!G80) | H14: =IF(ISBLANK('By Round'!H80),"",'By Round'!H80) | I14: =IF(ISBLANK('By Round'!I80),"",'By Round'!I80) | J14: =IF(ISBLANK('By Round'!J80),"",'By Round'!J80) | K14: =IF(ISBLANK('By Round'!K80),"",'By Round'!K80) | L14: =IF(ISBLANK('By Round'!L80),"",'By Round'!L80) | M14: =AVERAGE(Y14:Z14) | N14: =AVERAGE(AA14:AB14) | O14: =IF(COUNT(U14:V14)>0,Q14/COUNT(U14:V14),0.5) | P14: =IF(COUNT(W14:X14)>0,R14/COUNT(W14:X14),0.5) | Q14: =SUM(U14:V14) | R14: =SUM(W14:X14) | S14: =IF(ISNUMBER(K14),K14,IF(ISNUMBER(L14),-L14,"")) | T14: =IF(ISNUMBER(L14),L14,IF(ISNUMBER(K14),-K14,"")) | U14: =IF(ISNUMBER(S14),IF(ISNUMBER(S12),IF(S14>S12,1.0,IF(S14=S12,0.5,0.0)),0.5),0.5) | V14: =IF(ISNUMBER(S14),IF(ISNUMBER(S13),IF(S14>S13,1.0,IF(S14=S13,0.5,0.0)),0.5),0.5) | W14: =IF(ISNUMBER(T14),IF(ISNUMBER(T12),IF(T14>T12,1.0,IF(T14=T12,0.5,0.0)),0.5),0.5) | X14: =IF(ISNUMBER(T14),IF(ISNUMBER(T13),IF(T14>T13,1.0,IF(T14=T13,0.5,0.0)),0.5),0.5) | Y14: =IF(AND(ISNUMBER(S14),ISNUMBER(S12)),VLOOKUP(ABS(S14-S12),'IMP Table'!$A$2:$C$26,3)*SIGN(S14-S12),0) | Z14: =IF(AND(ISNUMBER(S14),ISNUMBER(S13)),VLOOKUP(ABS(S14-S13),'IMP Table'!$A$2:$C$26,3)*SIGN(S14-S13),0) | AA14: =IF(AND(ISNUMBER(T14),ISNUMBER(T12)),VLOOKUP(ABS(T14-T12),'IMP Table'!$A$2:$C$26,3)*SIGN(T14-T12),0) | AB14: =IF(AND(ISNUMBER(T14),ISNUMBER(T13)),VLOOKUP(ABS(T14-T13),'IMP Table'!$A$2:$C$26,3)*SIGN(T14-T13),0)
A15: 4 | B15: ='By Round'!A15 | C15: ='By Round'!B15 | D15: ='By Round'!C15 | E15: ='By Round'!D15 | F15: =IF(ISBLANK('By Round'!F15),"",'By Round'!F15) | G15: =IF(ISBLANK('By Round'!G15),"",'By Round'!G15) | H15: =IF(ISBLANK('By Round'!H15),"",'By Round'!H15) | I15: =IF(ISBLANK('By Round'!I15),"",'By Round'!I15) | J15: =IF(ISBLANK('By Round'!J15),"",'By Round'!J15) | K15: =IF(ISBLANK('By Round'!K15),"",'By Round'!K15) | L15: =IF(ISBLANK('By Round'!L15),"",'By Round'!L15) | M15: =IF(ISBLANK('By Round'!M15),"",'By Round'!M15) | ... X15: =IF(ISBLANK('By Round'!X15),"",'By Round'!X15)
B16: ='By Round'!A75 | C16: ='By Round'!B81 | D16: ='By Round'!C81 | E16: ='By Round'!D81 | F16: =IF(ISBLANK('By Round'!F81),"",'By Round'!F81) | G16: =IF(ISBLANK('By Round'!G81),"",'By Round'!G81) | H16: =IF(ISBLANK('By Round'!H81),"",'By Round'!H81) | I16: =IF(ISBLANK('By Round'!I81),"",'By Round'!I81) | J16: =IF(ISBLANK('By Round'!J81),"",'By Round'!J81) | K16: =IF(ISBLANK('By Round'!K81),"",'By Round'!K81) | L16: =IF(ISBLANK('By Round'!L81),"",'By Round'!L81) | M16: =AVERAGE(Y16:Z16) | N16: =AVERAGE(AA16:AB16) | O16: =IF(COUNT(U16:V16)>0,Q16/COUNT(U16:V16),0.5) | P16: =IF(COUNT(W16:X16)>0,R16/COUNT(W16:X16),0.5) | Q16: =SUM(U16:V16) | R16: =SUM(W16:X16) | S16: =IF(ISNUMBER(K16),K16,IF(ISNUMBER(L16),-L16,"")) | T16: =IF(ISNUMBER(L16),L16,IF(ISNUMBER(K16),-K16,"")) | U16: =IF(ISNUMBER(S16),IF(ISNUMBER(S17),IF(S16>S17,1.0,IF(S16=S17,0.5,0.0)),0.5),0.5) | V16: =IF(ISNUMBER(S16),IF(ISNUMBER(S18),IF(S16>S18,1.0,IF(S16=S18,0.5,0.0)),0.5),0.5) | W16: =IF(ISNUMBER(T16),IF(ISNUMBER(T17),IF(T16>T17,1.0,IF(T16=T17,0.5,0.0)),0.5),0.5) | X16: =IF(ISNUMBER(T16),IF(ISNUMBER(T18),IF(T16>T18,1.0,IF(T16=T18,0.5,0.0)),0.5),0.5) | Y16: =IF(AND(ISNUMBER(S16),ISNUMBER(S17)),VLOOKUP(ABS(S16-S17),'IMP Table'!$A$2:$C$26,3)*SIGN(S16-S17),0) | Z16: =IF(AND(ISNUMBER(S16),ISNUMBER(S18)),VLOOKUP(ABS(S16-S18),'IMP Table'!$A$2:$C$26,3)*SIGN(S16-S18),0) | AA16: =IF(AND(ISNUMBER(T16),ISNUMBER(T17)),VLOOKUP(ABS(T16-T17),'IMP Table'!$A$2:$C$26,3)*SIGN(T16-T17),0) | AB16: =IF(AND(ISNUMBER(T16),ISNUMBER(T18)),VLOOKUP(ABS(T16-T18),'IMP Table'!$A$2:$C$26,3)*SIGN(T16-T18),0)
B17: ='By Round'!A51 | C17: ='By Round'!B60 | D17: ='By Round'!C60 | E17: ='By Round'!D60 | F17: =IF(ISBLANK('By Round'!F60),"",'By Round'!F60) | G17: =IF(ISBLANK('By Round'!G60),"",'By Round'!G60) | H17: =IF(ISBLANK('By Round'!H60),"",'By Round'!H60) | I17: =IF(ISBLANK('By Round'!I60),"",'By Round'!I60) | J17: =IF(ISBLANK('By Round'!J60),"",'By Round'!J60) | K17: =IF(ISBLANK('By Round'!K60),"",'By Round'!K60) | L17: =IF(ISBLANK('By Round'!L60),"",'By Round'!L60) | M17: =AVERAGE(Y17:Z17) | N17: =AVERAGE(AA17:AB17) | O17: =IF(COUNT(U17:V17)>0,Q17/COUNT(U17:V17),0.5) | P17: =IF(COUNT(W17:X17)>0,R17/COUNT(W17:X17),0.5) | Q17: =SUM(U17:V17) | R17: =SUM(W17:X17) | S17: =IF(ISNUMBER(K17),K17,IF(ISNUMBER(L17),-L17,"")) | T17: =IF(ISNUMBER(L17),L17,IF(ISNUMBER(K17),-K17,"")) | U17: =IF(ISNUMBER(S17),IF(ISNUMBER(S16),IF(S17>S16,1.0,IF(S17=S16,0.5,0.0)),0.5),0.5) | V17: =IF(ISNUMBER(S17),IF(ISNUMBER(S18),IF(S17>S18,1.0,IF(S17=S18,0.5,0.0)),0.5),0.5) | W17: =IF(ISNUMBER(T17),IF(ISNUMBER(T16),IF(T17>T16,1.0,IF(T17=T16,0.5,0.0)),0.5),0.5) | X17: =IF(ISNUMBER(T17),IF(ISNUMBER(T18),IF(T17>T18,1.0,IF(T17=T18,0.5,0.0)),0.5),0.5) | Y17: =IF(AND(ISNUMBER(S17),ISNUMBER(S16)),VLOOKUP(ABS(S17-S16),'IMP Table'!$A$2:$C$26,3)*SIGN(S17-S16),0) | Z17: =IF(AND(ISNUMBER(S17),ISNUMBER(S18)),VLOOKUP(ABS(S17-S18),'IMP Table'!$A$2:$C$26,3)*SIGN(S17-S18),0) | AA17: =IF(AND(ISNUMBER(T17),ISNUMBER(T16)),VLOOKUP(ABS(T17-T16),'IMP Table'!$A$2:$C$26,3)*SIGN(T17-T16),0) | AB17: =IF(AND(ISNUMBER(T17),ISNUMBER(T18)),VLOOKUP(ABS(T17-T18),'IMP Table'!$A$2:$C$26,3)*SIGN(T17-T18),0)
B18: ='By Round'!A3 | C18: ='By Round'!B6 | D18: ='By Round'!C6 | E18: ='By Round'!D6 | F18: =IF(ISBLANK('By Round'!F6),"",'By Round'!F6) | G18: =IF(ISBLANK('By Round'!G6),"",'By Round'!G6) | H18: =IF(ISBLANK('By Round'!H6),"",'By Round'!H6) | I18: =IF(ISBLANK('By Round'!I6),"",'By Round'!I6) | J18: =IF(ISBLANK('By Round'!J6),"",'By Round'!J6) | K18: =IF(ISBLANK('By Round'!K6),"",'By Round'!K6) | L18: =IF(ISBLANK('By Round'!L6),"",'By Round'!L6) | M18: =AVERAGE(Y18:Z18) | N18: =AVERAGE(AA18:AB18) | O18: =IF(COUNT(U18:V18)>0,Q18/COUNT(U18:V18),0.5) | P18: =IF(COUNT(W18:X18)>0,R18/COUNT(W18:X18),0.5) | Q18: =SUM(U18:V18) | R18: =SUM(W18:X18) | S18: =IF(ISNUMBER(K18),K18,IF(ISNUMBER(L18),-L18,"")) | T18: =IF(ISNUMBER(L18),L18,IF(ISNUMBER(K18),-K18,"")) | U18: =IF(ISNUMBER(S18),IF(ISNUMBER(S16),IF(S18>S16,1.0,IF(S18=S16,0.5,0.0)),0.5),0.5) | V18: =IF(ISNUMBER(S18),IF(ISNUMBER(S17),IF(S18>S17,1.0,IF(S18=S17,0.5,0.0)),0.5),0.5) | W18: =IF(ISNUMBER(T18),IF(ISNUMBER(T16),IF(T18>T16,1.0,IF(T18=T16,0.5,0.0)),0.5),0.5) | X18: =IF(ISNUMBER(T18),IF(ISNUMBER(T17),IF(T18>T17,1.0,IF(T18=T17,0.5,0.0)),0.5),0.5) | Y18: =IF(AND(ISNUMBER(S18),ISNUMBER(S16)),VLOOKUP(ABS(S18-S16),'IMP Table'!$A$2:$C$26,3)*SIGN(S18-S16),0) | Z18: =IF(AND(ISNUMBER(S18),ISNUMBER(S17)),VLOOKUP(ABS(S18-S17),'IMP Table'!$A$2:$C$26,3)*SIGN(S18-S17),0) | AA18: =IF(AND(ISNUMBER(T18),ISNUMBER(T16)),VLOOKUP(ABS(T18-T16),'IMP Table'!$A$2:$C$26,3)*SIGN(T18-T16),0) | AB18: =IF(AND(ISNUMBER(T18),ISNUMBER(T17)),VLOOKUP(ABS(T18-T17),'IMP Table'!$A$2:$C$26,3)*SIGN(T18-T17),0)
A19: 5 | B19: ='By Round'!A15 | C19: ='By Round'!B15 | D19: ='By Round'!C15 | E19: ='By Round'!D15 | F19: =IF(ISBLANK('By Round'!F16),"",'By Round'!F16) | G19: =IF(ISBLANK('By Round'!G16),"",'By Round'!G16) | H19: =IF(ISBLANK('By Round'!H16),"",'By Round'!H16) | I19: =IF(ISBLANK('By Round'!I16),"",'By Round'!I16) | J19: =IF(ISBLANK('By Round'!J16),"",'By Round'!J16) | K19: =IF(ISBLANK('By Round'!K16),"",'By Round'!K16) | L19: =IF(ISBLANK('By Round'!L16),"",'By Round'!L16) | M19: =IF(ISBLANK('By Round'!M16),"",'By Round'!M16) | ... X19: =IF(ISBLANK('By Round'!X16),"",'By Round'!X16)
B20: ='By Round'!A75 | C20: ='By Round'!B81 | D20: ='By Round'!C81 | E20: ='By Round'!D81 | F20: =IF(ISBLANK('By Round'!F82),"",'By Round'!F82) | G20: =IF(ISBLANK('By Round'!G82),"",'By Round'!G82) | H20: =IF(ISBLANK('By Round'!H82),"",'By Round'!H82) | I20: =IF(ISBLANK('By Round'!I82),"",'By Round'!I82) | J20: =IF(ISBLANK('By Round'!J82),"",'By Round'!J82) | K20: =IF(ISBLANK('By Round'!K82),"",'By Round'!K82) | L20: =IF(ISBLANK('By Round'!L82),"",'By Round'!L82) | M20: =AVERAGE(Y20:Z20) | N20: =AVERAGE(AA20:AB20) | O20: =IF(COUNT(U20:V20)>0,Q20/COUNT(U20:V20),0.5) | P20: =IF(COUNT(W20:X20)>0,R20/COUNT(W20:X20),0.5) | Q20: =SUM(U20:V20) | R20: =SUM(W20:X20) | S20: =IF(ISNUMBER(K20),K20,IF(ISNUMBER(L20),-L20,"")) | T20: =IF(ISNUMBER(L20),L20,IF(ISNUMBER(K20),-K20,"")) | U20: =IF(ISNUMBER(S20),IF(ISNUMBER(S21),IF(S20>S21,1.0,IF(S20=S21,0.5,0.0)),0.5),0.5) | V20: =IF(ISNUMBER(S20),IF(ISNUMBER(S22),IF(S20>S22,1.0,IF(S20=S22,0.5,0.0)),0.5),0.5) | W20: =IF(ISNUMBER(T20),IF(ISNUMBER(T21),IF(T20>T21,1.0,IF(T20=T21,0.5,0.0)),0.5),0.5) | X20: =IF(ISNUMBER(T20),IF(ISNUMBER(T22),IF(T20>T22,1.0,IF(T20=T22,0.5,0.0)),0.5),0.5) | Y20: =IF(AND(ISNUMBER(S20),ISNUMBER(S21)),VLOOKUP(ABS(S20-S21),'IMP Table'!$A$2:$C$26,3)*SIGN(S20-S21),0) | Z20: =IF(AND(ISNUMBER(S20),ISNUMBER(S22)),VLOOKUP(ABS(S20-S22),'IMP Table'!$A$2:$C$26,3)*SIGN(S20-S22),0) | AA20: =IF(AND(ISNUMBER(T20),ISNUMBER(T21)),VLOOKUP(ABS(T20-T21),'IMP Table'!$A$2:$C$26,3)*SIGN(T20-T21),0) | AB20: =IF(AND(ISNUMBER(T20),ISNUMBER(T22)),VLOOKUP(ABS(T20-T22),'IMP Table'!$A$2:$C$26,3)*SIGN(T20-T22),0)
B21: ='By Round'!A51 | C21: ='By Round'!B60 | D21: ='By Round'!C60 | E21: ='By Round'!D60 | F21: =IF(ISBLANK('By Round'!F61),"",'By Round'!F61) | G21: =IF(ISBLANK('By Round'!G61),"",'By Round'!G61) | H21: =IF(ISBLANK('By Round'!H61),"",'By Round'!H61) | I21: =IF(ISBLANK('By Round'!I61),"",'By Round'!I61) | J21: =IF(ISBLANK('By Round'!J61),"",'By Round'!J61) | K21: =IF(ISBLANK('By Round'!K61),"",'By Round'!K61) | L21: =IF(ISBLANK('By Round'!L61),"",'By Round'!L61) | M21: =AVERAGE(Y21:Z21) | N21: =AVERAGE(AA21:AB21) | O21: =IF(COUNT(U21:V21)>0,Q21/COUNT(U21:V21),0.5) | P21: =IF(COUNT(W21:X21)>0,R21/COUNT(W21:X21),0.5) | Q21: =SUM(U21:V21) | R21: =SUM(W21:X21) | S21: =IF(ISNUMBER(K21),K21,IF(ISNUMBER(L21),-L21,"")) | T21: =IF(ISNUMBER(L21),L21,IF(ISNUMBER(K21),-K21,"")) | U21: =IF(ISNUMBER(S21),IF(ISNUMBER(S20),IF(S21>S20,1.0,IF(S21=S20,0.5,0.0)),0.5),0.5) | V21: =IF(ISNUMBER(S21),IF(ISNUMBER(S22),IF(S21>S22,1.0,IF(S21=S22,0.5,0.0)),0.5),0.5) | W21: =IF(ISNUMBER(T21),IF(ISNUMBER(T20),IF(T21>T20,1.0,IF(T21=T20,0.5,0.0)),0.5),0.5) | X21: =IF(ISNUMBER(T21),IF(ISNUMBER(T22),IF(T21>T22,1.0,IF(T21=T22,0.5,0.0)),0.5),0.5) | Y21: =IF(AND(ISNUMBER(S21),ISNUMBER(S20)),VLOOKUP(ABS(S21-S20),'IMP Table'!$A$2:$C$26,3)*SIGN(S21-S20),0) | Z21: =IF(AND(ISNUMBER(S21),ISNUMBER(S22)),VLOOKUP(ABS(S21-S22),'IMP Table'!$A$2:$C$26,3)*SIGN(S21-S22),0) | AA21: =IF(AND(ISNUMBER(T21),ISNUMBER(T20)),VLOOKUP(ABS(T21-T20),'IMP Table'!$A$2:$C$26,3)*SIGN(T21-T20),0) | AB21: =IF(AND(ISNUMBER(T21),ISNUMBER(T22)),VLOOKUP(ABS(T21-T22),'IMP Table'!$A$2:$C$26,3)*SIGN(T21-T22),0)
B22: ='By Round'!A3 | C22: ='By Round'!B6 | D22: ='By Round'!C6 | E22: ='By Round'!D6 | F22: =IF(ISBLANK('By Round'!F7),"",'By Round'!F7) | G22: =IF(ISBLANK('By Round'!G7),"",'By Round'!G7) | H22: =IF(ISBLANK('By Round'!H7),"",'By Round'!H7) | I22: =IF(ISBLANK('By Round'!I7),"",'By Round'!I7) | J22: =IF(ISBLANK('By Round'!J7),"",'By Round'!J7) | K22: =IF(ISBLANK('By Round'!K7),"",'By Round'!K7) | L22: =IF(ISBLANK('By Round'!L7),"",'By Round'!L7) | M22: =AVERAGE(Y22:Z22) | N22: =AVERAGE(AA22:AB22) | O22: =IF(COUNT(U22:V22)>0,Q22/COUNT(U22:V22),0.5) | P22: =IF(COUNT(W22:X22)>0,R22/COUNT(W22:X22),0.5) | Q22: =SUM(U22:V22) | R22: =SUM(W22:X22) | S22: =IF(ISNUMBER(K22),K22,IF(ISNUMBER(L22),-L22,"")) | T22: =IF(ISNUMBER(L22),L22,IF(ISNUMBER(K22),-K22,"")) | U22: =IF(ISNUMBER(S22),IF(ISNUMBER(S20),IF(S22>S20,1.0,IF(S22=S20,0.5,0.0)),0.5),0.5) | V22: =IF(ISNUMBER(S22),IF(ISNUMBER(S21),IF(S22>S21,1.0,IF(S22=S21,0.5,0.0)),0.5),0.5) | W22: =IF(ISNUMBER(T22),IF(ISNUMBER(T20),IF(T22>T20,1.0,IF(T22=T20,0.5,0.0)),0.5),0.5) | X22: =IF(ISNUMBER(T22),IF(ISNUMBER(T21),IF(T22>T21,1.0,IF(T22=T21,0.5,0.0)),0.5),0.5) | Y22: =IF(AND(ISNUMBER(S22),ISNUMBER(S20)),VLOOKUP(ABS(S22-S20),'IMP Table'!$A$2:$C$26,3)*SIGN(S22-S20),0) | Z22: =IF(AND(ISNUMBER(S22),ISNUMBER(S21)),VLOOKUP(ABS(S22-S21),'IMP Table'!$A$2:$C$26,3)*SIGN(S22-S21),0) | AA22: =IF(AND(ISNUMBER(T22),ISNUMBER(T20)),VLOOKUP(ABS(T22-T20),'IMP Table'!$A$2:$C$26,3)*SIGN(T22-T20),0) | AB22: =IF(AND(ISNUMBER(T22),ISNUMBER(T21)),VLOOKUP(ABS(T22-T21),'IMP Table'!$A$2:$C$26,3)*SIGN(T22-T21),0)
A23: 6 | B23: ='By Round'!A15 | C23: ='By Round'!B15 | D23: ='By Round'!C15 | E23: ='By Round'!D15 | F23: =IF(ISBLANK('By Round'!F17),"",'By Round'!F17) | G23: =IF(ISBLANK('By Round'!G17),"",'By Round'!G17) | H23: =IF(ISBLANK('By Round'!H17),"",'By Round'!H17) | I23: =IF(ISBLANK('By Round'!I17),"",'By Round'!I17) | J23: =IF(ISBLANK('By Round'!J17),"",'By Round'!J17) | K23: =IF(ISBLANK('By Round'!K17),"",'By Round'!K17) | L23: =IF(ISBLANK('By Round'!L17),"",'By Round'!L17) | M23: =IF(ISBLANK('By Round'!M17),"",'By Round'!M17) | ... X23: =IF(ISBLANK('By Round'!X17),"",'By Round'!X17)
B24: ='By Round'!A75 | C24: ='By Round'!B81 | D24: ='By Round'!C81 | E24: ='By Round'!D81 | F24: =IF(ISBLANK('By Round'!F83),"",'By Round'!F83) | G24: =IF(ISBLANK('By Round'!G83),"",'By Round'!G83) | H24: =IF(ISBLANK('By Round'!H83),"",'By Round'!H83) | I24: =IF(ISBLANK('By Round'!I83),"",'By Round'!I83) | J24: =IF(ISBLANK('By Round'!J83),"",'By Round'!J83) | K24: =IF(ISBLANK('By Round'!K83),"",'By Round'!K83) | L24: =IF(ISBLANK('By Round'!L83),"",'By Round'!L83) | M24: =AVERAGE(Y24:Z24) | N24: =AVERAGE(AA24:AB24) | O24: =IF(COUNT(U24:V24)>0,Q24/COUNT(U24:V24),0.5) | P24: =IF(COUNT(W24:X24)>0,R24/COUNT(W24:X24),0.5) | Q24: =SUM(U24:V24) | R24: =SUM(W24:X24) | S24: =IF(ISNUMBER(K24),K24,IF(ISNUMBER(L24),-L24,"")) | T24: =IF(ISNUMBER(L24),L24,IF(ISNUMBER(K24),-K24,"")) | U24: =IF(ISNUMBER(S24),IF(ISNUMBER(S25),IF(S24>S25,1.0,IF(S24=S25,0.5,0.0)),0.5),0.5) | V24: =IF(ISNUMBER(S24),IF(ISNUMBER(S26),IF(S24>S26,1.0,IF(S24=S26,0.5,0.0)),0.5),0.5) | W24: =IF(ISNUMBER(T24),IF(ISNUMBER(T25),IF(T24>T25,1.0,IF(T24=T25,0.5,0.0)),0.5),0.5) | X24: =IF(ISNUMBER(T24),IF(ISNUMBER(T26),IF(T24>T26,1.0,IF(T24=T26,0.5,0.0)),0.5),0.5) | Y24: =IF(AND(ISNUMBER(S24),ISNUMBER(S25)),VLOOKUP(ABS(S24-S25),'IMP Table'!$A$2:$C$26,3)*SIGN(S24-S25),0) | Z24: =IF(AND(ISNUMBER(S24),ISNUMBER(S26)),VLOOKUP(ABS(S24-S26),'IMP Table'!$A$2:$C$26,3)*SIGN(S24-S26),0) | AA24: =IF(AND(ISNUMBER(T24),ISNUMBER(T25)),VLOOKUP(ABS(T24-T25),'IMP Table'!$A$2:$C$26,3)*SIGN(T24-T25),0) | AB24: =IF(AND(ISNUMBER(T24),ISNUMBER(T26)),VLOOKUP(ABS(T24-T26),'IMP Table'!$A$2:$C$26,3)*SIGN(T24-T26),0)
B25: ='By Round'!A51 | C25: ='By Round'!B60 | D25: ='By Round'!C60 | E25: ='By Round'!D60 | F25: =IF(ISBLANK('By Round'!F62),"",'By Round'!F62) | G25: =IF(ISBLANK('By Round'!G62),"",'By Round'!G62) | H25: =IF(ISBLANK('By Round'!H62),"",'By Round'!H62) | I25: =IF(ISBLANK('By Round'!I62),"",'By Round'!I62) | J25: =IF(ISBLANK('By Round'!J62),"",'By Round'!J62) | K25: =IF(ISBLANK('By Round'!K62),"",'By Round'!K62) | L25: =IF(ISBLANK('By Round'!L62),"",'By Round'!L62) | M25: =AVERAGE(Y25:Z25) | N25: =AVERAGE(AA25:AB25) | O25: =IF(COUNT(U25:V25)>0,Q25/COUNT(U25:V25),0.5) | P25: =IF(COUNT(W25:X25)>0,R25/COUNT(W25:X25),0.5) | Q25: =SUM(U25:V25) | R25: =SUM(W25:X25) | S25: =IF(ISNUMBER(K25),K25,IF(ISNUMBER(L25),-L25,"")) | T25: =IF(ISNUMBER(L25),L25,IF(ISNUMBER(K25),-K25,"")) | U25: =IF(ISNUMBER(S25),IF(ISNUMBER(S24),IF(S25>S24,1.0,IF(S25=S24,0.5,0.0)),0.5),0.5) | V25: =IF(ISNUMBER(S25),IF(ISNUMBER(S26),IF(S25>S26,1.0,IF(S25=S26,0.5,0.0)),0.5),0.5) | W25: =IF(ISNUMBER(T25),IF(ISNUMBER(T24),IF(T25>T24,1.0,IF(T25=T24,0.5,0.0)),0.5),0.5) | X25: =IF(ISNUMBER(T25),IF(ISNUMBER(T26),IF(T25>T26,1.0,IF(T25=T26,0.5,0.0)),0.5),0.5) | Y25: =IF(AND(ISNUMBER(S25),ISNUMBER(S24)),VLOOKUP(ABS(S25-S24),'IMP Table'!$A$2:$C$26,3)*SIGN(S25-S24),0) | Z25: =IF(AND(ISNUMBER(S25),ISNUMBER(S26)),VLOOKUP(ABS(S25-S26),'IMP Table'!$A$2:$C$26,3)*SIGN(S25-S26),0) | AA25: =IF(AND(ISNUMBER(T25),ISNUMBER(T24)),VLOOKUP(ABS(T25-T24),'IMP Table'!$A$2:$C$26,3)*SIGN(T25-T24),0) | AB25: =IF(AND(ISNUMBER(T25),ISNUMBER(T26)),VLOOKUP(ABS(T25-T26),'IMP Table'!$A$2:$C$26,3)*SIGN(T25-T26),0)
B26: ='By Round'!A3 | C26: ='By Round'!B6 | D26: ='By Round'!C6 | E26: ='By Round'!D6 | F26: =IF(ISBLANK('By Round'!F8),"",'By Round'!F8) | G26: =IF(ISBLANK('By Round'!G8),"",'By Round'!G8) | H26: =IF(ISBLANK('By Round'!H8),"",'By Round'!H8) | I26: =IF(ISBLANK('By Round'!I8),"",'By Round'!I8) | J26: =IF(ISBLANK('By Round'!J8),"",'By Round'!J8) | K26: =IF(ISBLANK('By Round'!K8),"",'By Round'!K8) | L26: =IF(ISBLANK('By Round'!L8),"",'By Round'!L8) | M26: =AVERAGE(Y26:Z26) | N26: =AVERAGE(AA26:AB26) | O26: =IF(COUNT(U26:V26)>0,Q26/COUNT(U26:V26),0.5) | P26: =IF(COUNT(W26:X26)>0,R26/COUNT(W26:X26),0.5) | Q26: =SUM(U26:V26) | R26: =SUM(W26:X26) | S26: =IF(ISNUMBER(K26),K26,IF(ISNUMBER(L26),-L26,"")) | T26: =IF(ISNUMBER(L26),L26,IF(ISNUMBER(K26),-K26,"")) | U26: =IF(ISNUMBER(S26),IF(ISNUMBER(S24),IF(S26>S24,1.0,IF(S26=S24,0.5,0.0)),0.5),0.5) | V26: =IF(ISNUMBER(S26),IF(ISNUMBER(S25),IF(S26>S25,1.0,IF(S26=S25,0.5,0.0)),0.5),0.5) | W26: =IF(ISNUMBER(T26),IF(ISNUMBER(T24),IF(T26>T24,1.0,IF(T26=T24,0.5,0.0)),0.5),0.5) | X26: =IF(ISNUMBER(T26),IF(ISNUMBER(T25),IF(T26>T25,1.0,IF(T26=T25,0.5,0.0)),0.5),0.5) | Y26: =IF(AND(ISNUMBER(S26),ISNUMBER(S24)),VLOOKUP(ABS(S26-S24),'IMP Table'!$A$2:$C$26,3)*SIGN(S26-S24),0) | Z26: =IF(AND(ISNUMBER(S26),ISNUMBER(S25)),VLOOKUP(ABS(S26-S25),'IMP Table'!$A$2:$C$26,3)*SIGN(S26-S25),0) | AA26: =IF(AND(ISNUMBER(T26),ISNUMBER(T24)),VLOOKUP(ABS(T26-T24),'IMP Table'!$A$2:$C$26,3)*SIGN(T26-T24),0) | AB26: =IF(AND(ISNUMBER(T26),ISNUMBER(T25)),VLOOKUP(ABS(T26-T25),'IMP Table'!$A$2:$C$26,3)*SIGN(T26-T25),0)
A27: 7 | B27: ='By Round'!A27 | C27: ='By Round'!B27 | D27: ='By Round'!C27 | E27: ='By Round'!D27 | F27: =IF(ISBLANK('By Round'!F27),"",'By Round'!F27) | G27: =IF(ISBLANK('By Round'!G27),"",'By Round'!G27) | H27: =IF(ISBLANK('By Round'!H27),"",'By Round'!H27) | I27: =IF(ISBLANK('By Round'!I27),"",'By Round'!I27) | J27: =IF(ISBLANK('By Round'!J27),"",'By Round'!J27) | K27: =IF(ISBLANK('By Round'!K27),"",'By Round'!K27) | L27: =IF(ISBLANK('By Round'!L27),"",'By Round'!L27) | M27: =IF(ISBLANK('By Round'!M27),"",'By Round'!M27) | ... X27: =IF(ISBLANK('By Round'!X27),"",'By Round'!X27)
B28: ='By Round'!A3 | C28: ='By Round'!B9 | D28: ='By Round'!C9 | E28: ='By Round'!D9 | F28: =IF(ISBLANK('By Round'!F9),"",'By Round'!F9) | G28: =IF(ISBLANK('By Round'!G9),"",'By Round'!G9) | H28: =IF(ISBLANK('By Round'!H9),"",'By Round'!H9) | I28: =IF(ISBLANK('By Round'!I9),"",'By Round'!I9) | J28: =IF(ISBLANK('By Round'!J9),"",'By Round'!J9) | K28: =IF(ISBLANK('By Round'!K9),"",'By Round'!K9) | L28: =IF(ISBLANK('By Round'!L9),"",'By Round'!L9) | M28: =AVERAGE(Y28:Z28) | N28: =AVERAGE(AA28:AB28) | O28: =IF(COUNT(U28:V28)>0,Q28/COUNT(U28:V28),0.5) | P28: =IF(COUNT(W28:X28)>0,R28/COUNT(W28:X28),0.5) | Q28: =SUM(U28:V28) | R28: =SUM(W28:X28) | S28: =IF(ISNUMBER(K28),K28,IF(ISNUMBER(L28),-L28,"")) | T28: =IF(ISNUMBER(L28),L28,IF(ISNUMBER(K28),-K28,"")) | U28: =IF(ISNUMBER(S28),IF(ISNUMBER(S29),IF(S28>S29,1.0,IF(S28=S29,0.5,0.0)),0.5),0.5) | V28: =IF(ISNUMBER(S28),IF(ISNUMBER(S30),IF(S28>S30,1.0,IF(S28=S30,0.5,0.0)),0.5),0.5) | W28: =IF(ISNUMBER(T28),IF(ISNUMBER(T29),IF(T28>T29,1.0,IF(T28=T29,0.5,0.0)),0.5),0.5) | X28: =IF(ISNUMBER(T28),IF(ISNUMBER(T30),IF(T28>T30,1.0,IF(T28=T30,0.5,0.0)),0.5),0.5) | Y28: =IF(AND(ISNUMBER(S28),ISNUMBER(S29)),VLOOKUP(ABS(S28-S29),'IMP Table'!$A$2:$C$26,3)*SIGN(S28-S29),0) | Z28: =IF(AND(ISNUMBER(S28),ISNUMBER(S30)),VLOOKUP(ABS(S28-S30),'IMP Table'!$A$2:$C$26,3)*SIGN(S28-S30),0) | AA28: =IF(AND(ISNUMBER(T28),ISNUMBER(T29)),VLOOKUP(ABS(T28-T29),'IMP Table'!$A$2:$C$26,3)*SIGN(T28-T29),0) | AB28: =IF(AND(ISNUMBER(T28),ISNUMBER(T30)),VLOOKUP(ABS(T28-T30),'IMP Table'!$A$2:$C$26,3)*SIGN(T28-T30),0)
B29: ='By Round'!A63 | C29: ='By Round'!B72 | D29: ='By Round'!C72 | E29: ='By Round'!D72 | F29: =IF(ISBLANK('By Round'!F72),"",'By Round'!F72) | G29: =IF(ISBLANK('By Round'!G72),"",'By Round'!G72) | H29: =IF(ISBLANK('By Round'!H72),"",'By Round'!H72) | I29: =IF(ISBLANK('By Round'!I72),"",'By Round'!I72) | J29: =IF(ISBLANK('By Round'!J72),"",'By Round'!J72) | K29: =IF(ISBLANK('By Round'!K72),"",'By Round'!K72) | L29: =IF(ISBLANK('By Round'!L72),"",'By Round'!L72) | M29: =AVERAGE(Y29:Z29) | N29: =AVERAGE(AA29:AB29) | O29: =IF(COUNT(U29:V29)>0,Q29/COUNT(U29:V29),0.5) | P29: =IF(COUNT(W29:X29)>0,R29/COUNT(W29:X29),0.5) | Q29: =SUM(U29:V29) | R29: =SUM(W29:X29) | S29: =IF(ISNUMBER(K29),K29,IF(ISNUMBER(L29),-L29,"")) | T29: =IF(ISNUMBER(L29),L29,IF(ISNUMBER(K29),-K29,"")) | U29: =IF(ISNUMBER(S29),IF(ISNUMBER(S28),IF(S29>S28,1.0,IF(S29=S28,0.5,0.0)),0.5),0.5) | V29: =IF(ISNUMBER(S29),IF(ISNUMBER(S30),IF(S29>S30,1.0,IF(S29=S30,0.5,0.0)),0.5),0.5) | W29: =IF(ISNUMBER(T29),IF(ISNUMBER(T28),IF(T29>T28,1.0,IF(T29=T28,0.5,0.0)),0.5),0.5) | X29: =IF(ISNUMBER(T29),IF(ISNUMBER(T30),IF(T29>T30,1.0,IF(T29=T30,0.5,0.0)),0.5),0.5) | Y29: =IF(AND(ISNUMBER(S29),ISNUMBER(S28)),VLOOKUP(ABS(S29-S28),'IMP Table'!$A$2:$C$26,3)*SIGN(S29-S28),0) | Z29: =IF(AND(ISNUMBER(S29),ISNUMBER(S30)),VLOOKUP(ABS(S29-S30),'IMP Table'!$A$2:$C$26,3)*SIGN(S29-S30),0) | AA29: =IF(AND(ISNUMBER(T29),ISNUMBER(T28)),VLOOKUP(ABS(T29-T28),'IMP Table'!$A$2:$C$26,3)*SIGN(T29-T28),0) | AB29: =IF(AND(ISNUMBER(T29),ISNUMBER(T30)),VLOOKUP(ABS(T29-T30),'IMP Table'!$A$2:$C$26,3)*SIGN(T29-T30),0)
B30: ='By Round'!A15 | C30: ='By Round'!B18 | D30: ='By Round'!C18 | E30: ='By Round'!D18 | F30: =IF(ISBLANK('By Round'!F18),"",'By Round'!F18) | G30: =IF(ISBLANK('By Round'!G18),"",'By Round'!G18) | H30: =IF(ISBLANK('By Round'!H18),"",'By Round'!H18) | I30: =IF(ISBLANK('By Round'!I18),"",'By Round'!I18) | J30: =IF(ISBLANK('By Round'!J18),"",'By Round'!J18) | K30: =IF(ISBLANK('By Round'!K18),"",'By Round'!K18) | L30: =IF(ISBLANK('By Round'!L18),"",'By Round'!L18) | M30: =AVERAGE(Y30:Z30) | N30: =AVERAGE(AA30:AB30) | O30: =IF(COUNT(U30:V30)>0,Q30/COUNT(U30:V30),0.5) | P30: =IF(COUNT(W30:X30)>0,R30/COUNT(W30:X30),0.5) | Q30: =SUM(U30:V30) | R30: =SUM(W30:X30) | S30: =IF(ISNUMBER(K30),K30,IF(ISNUMBER(L30),-L30,"")) | T30: =IF(ISNUMBER(L30),L30,IF(ISNUMBER(K30),-K30,"")) | U30: =IF(ISNUMBER(S30),IF(ISNUMBER(S28),IF(S30>S28,1.0,IF(S30=S28,0.5,0.0)),0.5),0.5) | V30: =IF(ISNUMBER(S30),IF(ISNUMBER(S29),IF(S30>S29,1.0,IF(S30=S29,0.5,0.0)),0.5),0.5) | W30: =IF(ISNUMBER(T30),IF(ISNUMBER(T28),IF(T30>T28,1.0,IF(T30=T28,0.5,0.0)),0.5),0.5) | X30: =IF(ISNUMBER(T30),IF(ISNUMBER(T29),IF(T30>T29,1.0,IF(T30=T29,0.5,0.0)),0.5),0.5) | Y30: =IF(AND(ISNUMBER(S30),ISNUMBER(S28)),VLOOKUP(ABS(S30-S28),'IMP Table'!$A$2:$C$26,3)*SIGN(S30-S28),0) | Z30: =IF(AND(ISNUMBER(S30),ISNUMBER(S29)),VLOOKUP(ABS(S30-S29),'IMP Table'!$A$2:$C$26,3)*SIGN(S30-S29),0) | AA30: =IF(AND(ISNUMBER(T30),ISNUMBER(T28)),VLOOKUP(ABS(T30-T28),'IMP Table'!$A$2:$C$26,3)*SIGN(T30-T28),0) | AB30: =IF(AND(ISNUMBER(T30),ISNUMBER(T29)),VLOOKUP(ABS(T30-T29),'IMP Table'!$A$2:$C$26,3)*SIGN(T30-T29),0)
A31: 8 | B31: ='By Round'!A27 | C31: ='By Round'!B27 | D31: ='By Round'!C27 | E31: ='By Round'!D27 | F31: =IF(ISBLANK('By Round'!F28),"",'By Round'!F28) | G31: =IF(ISBLANK('By Round'!G28),"",'By Round'!G28) | H31: =IF(ISBLANK('By Round'!H28),"",'By Round'!H28) | I31: =IF(ISBLANK('By Round'!I28),"",'By Round'!I28) | J31: =IF(ISBLANK('By Round'!J28),"",'By Round'!J28) | K31: =IF(ISBLANK('By Round'!K28),"",'By Round'!K28) | L31: =IF(ISBLANK('By Round'!L28),"",'By Round'!L28) | M31: =IF(ISBLANK('By Round'!M28),"",'By Round'!M28) | ... X31: =IF(ISBLANK('By Round'!X28),"",'By Round'!X28)
B32: ='By Round'!A3 | C32: ='By Round'!B9 | D32: ='By Round'!C9 | E32: ='By Round'!D9 | F32: =IF(ISBLANK('By Round'!F10),"",'By Round'!F10) | G32: =IF(ISBLANK('By Round'!G10),"",'By Round'!G10) | H32: =IF(ISBLANK('By Round'!H10),"",'By Round'!H10) | I32: =IF(ISBLANK('By Round'!I10),"",'By Round'!I10) | J32: =IF(ISBLANK('By Round'!J10),"",'By Round'!J10) | K32: =IF(ISBLANK('By Round'!K10),"",'By Round'!K10) | L32: =IF(ISBLANK('By Round'!L10),"",'By Round'!L10) | M32: =AVERAGE(Y32:Z32) | N32: =AVERAGE(AA32:AB32) | O32: =IF(COUNT(U32:V32)>0,Q32/COUNT(U32:V32),0.5) | P32: =IF(COUNT(W32:X32)>0,R32/COUNT(W32:X32),0.5) | Q32: =SUM(U32:V32) | R32: =SUM(W32:X32) | S32: =IF(ISNUMBER(K32),K32,IF(ISNUMBER(L32),-L32,"")) | T32: =IF(ISNUMBER(L32),L32,IF(ISNUMBER(K32),-K32,"")) | U32: =IF(ISNUMBER(S32),IF(ISNUMBER(S33),IF(S32>S33,1.0,IF(S32=S33,0.5,0.0)),0.5),0.5) | V32: =IF(ISNUMBER(S32),IF(ISNUMBER(S34),IF(S32>S34,1.0,IF(S32=S34,0.5,0.0)),0.5),0.5) | W32: =IF(ISNUMBER(T32),IF(ISNUMBER(T33),IF(T32>T33,1.0,IF(T32=T33,0.5,0.0)),0.5),0.5) | X32: =IF(ISNUMBER(T32),IF(ISNUMBER(T34),IF(T32>T34,1.0,IF(T32=T34,0.5,0.0)),0.5),0.5) | Y32: =IF(AND(ISNUMBER(S32),ISNUMBER(S33)),VLOOKUP(ABS(S32-S33),'IMP Table'!$A$2:$C$26,3)*SIGN(S32-S33),0) | Z32: =IF(AND(ISNUMBER(S32),ISNUMBER(S34)),VLOOKUP(ABS(S32-S34),'IMP Table'!$A$2:$C$26,3)*SIGN(S32-S34),0) | AA32: =IF(AND(ISNUMBER(T32),ISNUMBER(T33)),VLOOKUP(ABS(T32-T33),'IMP Table'!$A$2:$C$26,3)*SIGN(T32-T33),0) | AB32: =IF(AND(ISNUMBER(T32),ISNUMBER(T34)),VLOOKUP(ABS(T32-T34),'IMP Table'!$A$2:$C$26,3)*SIGN(T32-T34),0)
B33: ='By Round'!A63 | C33: ='By Round'!B72 | D33: ='By Round'!C72 | E33: ='By Round'!D72 | F33: =IF(ISBLANK('By Round'!F73),"",'By Round'!F73) | G33: =IF(ISBLANK('By Round'!G73),"",'By Round'!G73) | H33: =IF(ISBLANK('By Round'!H73),"",'By Round'!H73) | I33: =IF(ISBLANK('By Round'!I73),"",'By Round'!I73) | J33: =IF(ISBLANK('By Round'!J73),"",'By Round'!J73) | K33: =IF(ISBLANK('By Round'!K73),"",'By Round'!K73) | L33: =IF(ISBLANK('By Round'!L73),"",'By Round'!L73) | M33: =AVERAGE(Y33:Z33) | N33: =AVERAGE(AA33:AB33) | O33: =IF(COUNT(U33:V33)>0,Q33/COUNT(U33:V33),0.5) | P33: =IF(COUNT(W33:X33)>0,R33/COUNT(W33:X33),0.5) | Q33: =SUM(U33:V33) | R33: =SUM(W33:X33) | S33: =IF(ISNUMBER(K33),K33,IF(ISNUMBER(L33),-L33,"")) | T33: =IF(ISNUMBER(L33),L33,IF(ISNUMBER(K33),-K33,"")) | U33: =IF(ISNUMBER(S33),IF(ISNUMBER(S32),IF(S33>S32,1.0,IF(S33=S32,0.5,0.0)),0.5),0.5) | V33: =IF(ISNUMBER(S33),IF(ISNUMBER(S34),IF(S33>S34,1.0,IF(S33=S34,0.5,0.0)),0.5),0.5) | W33: =IF(ISNUMBER(T33),IF(ISNUMBER(T32),IF(T33>T32,1.0,IF(T33=T32,0.5,0.0)),0.5),0.5) | X33: =IF(ISNUMBER(T33),IF(ISNUMBER(T34),IF(T33>T34,1.0,IF(T33=T34,0.5,0.0)),0.5),0.5) | Y33: =IF(AND(ISNUMBER(S33),ISNUMBER(S32)),VLOOKUP(ABS(S33-S32),'IMP Table'!$A$2:$C$26,3)*SIGN(S33-S32),0) | Z33: =IF(AND(ISNUMBER(S33),ISNUMBER(S34)),VLOOKUP(ABS(S33-S34),'IMP Table'!$A$2:$C$26,3)*SIGN(S33-S34),0) | AA33: =IF(AND(ISNUMBER(T33),ISNUMBER(T32)),VLOOKUP(ABS(T33-T32),'IMP Table'!$A$2:$C$26,3)*SIGN(T33-T32),0) | AB33: =IF(AND(ISNUMBER(T33),ISNUMBER(T34)),VLOOKUP(ABS(T33-T34),'IMP Table'!$A$2:$C$26,3)*SIGN(T33-T34),0)
B34: ='By Round'!A15 | C34: ='By Round'!B18 | D34: ='By Round'!C18 | E34: ='By Round'!D18 | F34: =IF(ISBLANK('By Round'!F19),"",'By Round'!F19) | G34: =IF(ISBLANK('By Round'!G19),"",'By Round'!G19) | H34: =IF(ISBLANK('By Round'!H19),"",'By Round'!H19) | I34: =IF(ISBLANK('By Round'!I19),"",'By Round'!I19) | J34: =IF(ISBLANK('By Round'!J19),"",'By Round'!J19) | K34: =IF(ISBLANK('By Round'!K19),"",'By Round'!K19) | L34: =IF(ISBLANK('By Round'!L19),"",'By Round'!L19) | M34: =AVERAGE(Y34:Z34) | N34: =AVERAGE(AA34:AB34) | O34: =IF(COUNT(U34:V34)>0,Q34/COUNT(U34:V34),0.5) | P34: =IF(COUNT(W34:X34)>0,R34/COUNT(W34:X34),0.5) | Q34: =SUM(U34:V34) | R34: =SUM(W34:X34) | S34: =IF(ISNUMBER(K34),K34,IF(ISNUMBER(L34),-L34,"")) | T34: =IF(ISNUMBER(L34),L34,IF(ISNUMBER(K34),-K34,"")) | U34: =IF(ISNUMBER(S34),IF(ISNUMBER(S32),IF(S34>S32,1.0,IF(S34=S32,0.5,0.0)),0.5),0.5) | V34: =IF(ISNUMBER(S34),IF(ISNUMBER(S33),IF(S34>S33,1.0,IF(S34=S33,0.5,0.0)),0.5),0.5) | W34: =IF(ISNUMBER(T34),IF(ISNUMBER(T32),IF(T34>T32,1.0,IF(T34=T32,0.5,0.0)),0.5),0.5) | X34: =IF(ISNUMBER(T34),IF(ISNUMBER(T33),IF(T34>T33,1.0,IF(T34=T33,0.5,0.0)),0.5),0.5) | Y34: =IF(AND(ISNUMBER(S34),ISNUMBER(S32)),VLOOKUP(ABS(S34-S32),'IMP Table'!$A$2:$C$26,3)*SIGN(S34-S32),0) | Z34: =IF(AND(ISNUMBER(S34),ISNUMBER(S33)),VLOOKUP(ABS(S34-S33),'IMP Table'!$A$2:$C$26,3)*SIGN(S34-S33),0) | AA34: =IF(AND(ISNUMBER(T34),ISNUMBER(T32)),VLOOKUP(ABS(T34-T32),'IMP Table'!$A$2:$C$26,3)*SIGN(T34-T32),0) | AB34: =IF(AND(ISNUMBER(T34),ISNUMBER(T33)),VLOOKUP(ABS(T34-T33),'IMP Table'!$A$2:$C$26,3)*SIGN(T34-T33),0)
A35: 9 | B35: ='By Round'!A27 | C35: ='By Round'!B27 | D35: ='By Round'!C27 | E35: ='By Round'!D27 | F35: =IF(ISBLANK('By Round'!F29),"",'By Round'!F29) | G35: =IF(ISBLANK('By Round'!G29),"",'By Round'!G29) | H35: =IF(ISBLANK('By Round'!H29),"",'By Round'!H29) | I35: =IF(ISBLANK('By Round'!I29),"",'By Round'!I29) | J35: =IF(ISBLANK('By Round'!J29),"",'By Round'!J29) | K35: =IF(ISBLANK('By Round'!K29),"",'By Round'!K29) | L35: =IF(ISBLANK('By Round'!L29),"",'By Round'!L29) | M35: =IF(ISBLANK('By Round'!M29),"",'By Round'!M29) | ... X35: =IF(ISBLANK('By Round'!X29),"",'By Round'!X29)
B36: ='By Round'!A3 | C36: ='By Round'!B9 | D36: ='By Round'!C9 | E36: ='By Round'!D9 | F36: =IF(ISBLANK('By Round'!F11),"",'By Round'!F11) | G36: =IF(ISBLANK('By Round'!G11),"",'By Round'!G11) | H36: =IF(ISBLANK('By Round'!H11),"",'By Round'!H11) | I36: =IF(ISBLANK('By Round'!I11),"",'By Round'!I11) | J36: =IF(ISBLANK('By Round'!J11),"",'By Round'!J11) | K36: =IF(ISBLANK('By Round'!K11),"",'By Round'!K11) | L36: =IF(ISBLANK('By Round'!L11),"",'By Round'!L11) | M36: =AVERAGE(Y36:Z36) | N36: =AVERAGE(AA36:AB36) | O36: =IF(COUNT(U36:V36)>0,Q36/COUNT(U36:V36),0.5) | P36: =IF(COUNT(W36:X36)>0,R36/COUNT(W36:X36),0.5) | Q36: =SUM(U36:V36) | R36: =SUM(W36:X36) | S36: =IF(ISNUMBER(K36),K36,IF(ISNUMBER(L36),-L36,"")) | T36: =IF(ISNUMBER(L36),L36,IF(ISNUMBER(K36),-K36,"")) | U36: =IF(ISNUMBER(S36),IF(ISNUMBER(S37),IF(S36>S37,1.0,IF(S36=S37,0.5,0.0)),0.5),0.5) | V36: =IF(ISNUMBER(S36),IF(ISNUMBER(S38),IF(S36>S38,1.0,IF(S36=S38,0.5,0.0)),0.5),0.5) | W36: =IF(ISNUMBER(T36),IF(ISNUMBER(T37),IF(T36>T37,1.0,IF(T36=T37,0.5,0.0)),0.5),0.5) | X36: =IF(ISNUMBER(T36),IF(ISNUMBER(T38),IF(T36>T38,1.0,IF(T36=T38,0.5,0.0)),0.5),0.5) | Y36: =IF(AND(ISNUMBER(S36),ISNUMBER(S37)),VLOOKUP(ABS(S36-S37),'IMP Table'!$A$2:$C$26,3)*SIGN(S36-S37),0) | Z36: =IF(AND(ISNUMBER(S36),ISNUMBER(S38)),VLOOKUP(ABS(S36-S38),'IMP Table'!$A$2:$C$26,3)*SIGN(S36-S38),0) | AA36: =IF(AND(ISNUMBER(T36),ISNUMBER(T37)),VLOOKUP(ABS(T36-T37),'IMP Table'!$A$2:$C$26,3)*SIGN(T36-T37),0) | AB36: =IF(AND(ISNUMBER(T36),ISNUMBER(T38)),VLOOKUP(ABS(T36-T38),'IMP Table'!$A$2:$C$26,3)*SIGN(T36-T38),0)
B37: ='By Round'!A63 | C37: ='By Round'!B72 | D37: ='By Round'!C72 | E37: ='By Round'!D72 | F37: =IF(ISBLANK('By Round'!F74),"",'By Round'!F74) | G37: =IF(ISBLANK('By Round'!G74),"",'By Round'!G74) | H37: =IF(ISBLANK('By Round'!H74),"",'By Round'!H74) | I37: =IF(ISBLANK('By Round'!I74),"",'By Round'!I74) | J37: =IF(ISBLANK('By Round'!J74),"",'By Round'!J74) | K37: =IF(ISBLANK('By Round'!K74),"",'By Round'!K74) | L37: =IF(ISBLANK('By Round'!L74),"",'By Round'!L74) | M37: =AVERAGE(Y37:Z37) | N37: =AVERAGE(AA37:AB37) | O37: =IF(COUNT(U37:V37)>0,Q37/COUNT(U37:V37),0.5) | P37: =IF(COUNT(W37:X37)>0,R37/COUNT(W37:X37),0.5) | Q37: =SUM(U37:V37) | R37: =SUM(W37:X37) | S37: =IF(ISNUMBER(K37),K37,IF(ISNUMBER(L37),-L37,"")) | T37: =IF(ISNUMBER(L37),L37,IF(ISNUMBER(K37),-K37,"")) | U37: =IF(ISNUMBER(S37),IF(ISNUMBER(S36),IF(S37>S36,1.0,IF(S37=S36,0.5,0.0)),0.5),0.5) | V37: =IF(ISNUMBER(S37),IF(ISNUMBER(S38),IF(S37>S38,1.0,IF(S37=S38,0.5,0.0)),0.5),0.5) | W37: =IF(ISNUMBER(T37),IF(ISNUMBER(T36),IF(T37>T36,1.0,IF(T37=T36,0.5,0.0)),0.5),0.5) | X37: =IF(ISNUMBER(T37),IF(ISNUMBER(T38),IF(T37>T38,1.0,IF(T37=T38,0.5,0.0)),0.5),0.5) | Y37: =IF(AND(ISNUMBER(S37),ISNUMBER(S36)),VLOOKUP(ABS(S37-S36),'IMP Table'!$A$2:$C$26,3)*SIGN(S37-S36),0) | Z37: =IF(AND(ISNUMBER(S37),ISNUMBER(S38)),VLOOKUP(ABS(S37-S38),'IMP Table'!$A$2:$C$26,3)*SIGN(S37-S38),0) | AA37: =IF(AND(ISNUMBER(T37),ISNUMBER(T36)),VLOOKUP(ABS(T37-T36),'IMP Table'!$A$2:$C$26,3)*SIGN(T37-T36),0) | AB37: =IF(AND(ISNUMBER(T37),ISNUMBER(T38)),VLOOKUP(ABS(T37-T38),'IMP Table'!$A$2:$C$26,3)*SIGN(T37-T38),0)
B38: ='By Round'!A15 | C38: ='By Round'!B18 | D38: ='By Round'!C18 | E38: ='By Round'!D18 | F38: =IF(ISBLANK('By Round'!F20),"",'By Round'!F20) | G38: =IF(ISBLANK('By Round'!G20),"",'By Round'!G20) | H38: =IF(ISBLANK('By Round'!H20),"",'By Round'!H20) | I38: =IF(ISBLANK('By Round'!I20),"",'By Round'!I20) | J38: =IF(ISBLANK('By Round'!J20),"",'By Round'!J20) | K38: =IF(ISBLANK('By Round'!K20),"",'By Round'!K20) | L38: =IF(ISBLANK('By Round'!L20),"",'By Round'!L20) | M38: =AVERAGE(Y38:Z38) | N38: =AVERAGE(AA38:AB38) | O38: =IF(COUNT(U38:V38)>0,Q38/COUNT(U38:V38),0.5) | P38: =IF(COUNT(W38:X38)>0,R38/COUNT(W38:X38),0.5) | Q38: =SUM(U38:V38) | R38: =SUM(W38:X38) | S38: =IF(ISNUMBER(K38),K38,IF(ISNUMBER(L38),-L38,"")) | T38: =IF(ISNUMBER(L38),L38,IF(ISNUMBER(K38),-K38,"")) | U38: =IF(ISNUMBER(S38),IF(ISNUMBER(S36),IF(S38>S36,1.0,IF(S38=S36,0.5,0.0)),0.5),0.5) | V38: =IF(ISNUMBER(S38),IF(ISNUMBER(S37),IF(S38>S37,1.0,IF(S38=S37,0.5,0.0)),0.5),0.5) | W38: =IF(ISNUMBER(T38),IF(ISNUMBER(T36),IF(T38>T36,1.0,IF(T38=T36,0.5,0.0)),0.5),0.5) | X38: =IF(ISNUMBER(T38),IF(ISNUMBER(T37),IF(T38>T37,1.0,IF(T38=T37,0.5,0.0)),0.5),0.5) | Y38: =IF(AND(ISNUMBER(S38),ISNUMBER(S36)),VLOOKUP(ABS(S38-S36),'IMP Table'!$A$2:$C$26,3)*SIGN(S38-S36),0) | Z38: =IF(AND(ISNUMBER(S38),ISNUMBER(S37)),VLOOKUP(ABS(S38-S37),'IMP Table'!$A$2:$C$26,3)*SIGN(S38-S37),0) | AA38: =IF(AND(ISNUMBER(T38),ISNUMBER(T36)),VLOOKUP(ABS(T38-T36),'IMP Table'!$A$2:$C$26,3)*SIGN(T38-T36),0) | AB38: =IF(AND(ISNUMBER(T38),ISNUMBER(T37)),VLOOKUP(ABS(T38-T37),'IMP Table'!$A$2:$C$26,3)*SIGN(T38-T37),0)
A39: 10 | B39: ='By Round'!A39 | C39: ='By Round'!B39 | D39: ='By Round'!C39 | E39: ='By Round'!D39 | F39: =IF(ISBLANK('By Round'!F39),"",'By Round'!F39) | G39: =IF(ISBLANK('By Round'!G39),"",'By Round'!G39) | H39: =IF(ISBLANK('By Round'!H39),"",'By Round'!H39) | I39: =IF(ISBLANK('By Round'!I39),"",'By Round'!I39) | J39: =IF(ISBLANK('By Round'!J39),"",'By Round'!J39) | K39: =IF(ISBLANK('By Round'!K39),"",'By Round'!K39) | L39: =IF(ISBLANK('By Round'!L39),"",'By Round'!L39) | M39: =IF(ISBLANK('By Round'!M39),"",'By Round'!M39) | ... X39: =IF(ISBLANK('By Round'!X39),"",'By Round'!X39)
B40: ='By Round'!A27 | C40: ='By Round'!B30 | D40: ='By Round'!C30 | E40: ='By Round'!D30 | F40: =IF(ISBLANK('By Round'!F30),"",'By Round'!F30) | G40: =IF(ISBLANK('By Round'!G30),"",'By Round'!G30) | H40: =IF(ISBLANK('By Round'!H30),"",'By Round'!H30) | I40: =IF(ISBLANK('By Round'!I30),"",'By Round'!I30) | J40: =IF(ISBLANK('By Round'!J30),"",'By Round'!J30) | K40: =IF(ISBLANK('By Round'!K30),"",'By Round'!K30) | L40: =IF(ISBLANK('By Round'!L30),"",'By Round'!L30) | M40: =AVERAGE(Y40:Z40) | N40: =AVERAGE(AA40:AB40) | O40: =IF(COUNT(U40:V40)>0,Q40/COUNT(U40:V40),0.5) | P40: =IF(COUNT(W40:X40)>0,R40/COUNT(W40:X40),0.5) | Q40: =SUM(U40:V40) | R40: =SUM(W40:X40) | S40: =IF(ISNUMBER(K40),K40,IF(ISNUMBER(L40),-L40,"")) | T40: =IF(ISNUMBER(L40),L40,IF(ISNUMBER(K40),-K40,"")) | U40: =IF(ISNUMBER(S40),IF(ISNUMBER(S41),IF(S40>S41,1.0,IF(S40=S41,0.5,0.0)),0.5),0.5) | V40: =IF(ISNUMBER(S40),IF(ISNUMBER(S42),IF(S40>S42,1.0,IF(S40=S42,0.5,0.0)),0.5),0.5) | W40: =IF(ISNUMBER(T40),IF(ISNUMBER(T41),IF(T40>T41,1.0,IF(T40=T41,0.5,0.0)),0.5),0.5) | X40: =IF(ISNUMBER(T40),IF(ISNUMBER(T42),IF(T40>T42,1.0,IF(T40=T42,0.5,0.0)),0.5),0.5) | Y40: =IF(AND(ISNUMBER(S40),ISNUMBER(S41)),VLOOKUP(ABS(S40-S41),'IMP Table'!$A$2:$C$26,3)*SIGN(S40-S41),0) | Z40: =IF(AND(ISNUMBER(S40),ISNUMBER(S42)),VLOOKUP(ABS(S40-S42),'IMP Table'!$A$2:$C$26,3)*SIGN(S40-S42),0) | AA40: =IF(AND(ISNUMBER(T40),ISNUMBER(T41)),VLOOKUP(ABS(T40-T41),'IMP Table'!$A$2:$C$26,3)*SIGN(T40-T41),0) | AB40: =IF(AND(ISNUMBER(T40),ISNUMBER(T42)),VLOOKUP(ABS(T40-T42),'IMP Table'!$A$2:$C$26,3)*SIGN(T40-T42),0)
...

Sheet By Round
I1: Result | K1: Score
A2: Round | B2: Table | C2: NS | D2: EW | E2: Board | F2: Vul | G2: Contract | H2: By | I2: Made | J2: Down | K2: NS | L2: EW
A3: 1 | B3: 1 | C3: Sit-Out | D3: 1 | E3: 1 | F3: None
E4: 2 | F4: NS
E5: 3 | F5: EW
B6: 2 | C6: 6 | D6: 5 | E6: 4 | F6: Both
E7: 5 | F7: NS
E8: 6 | F8: EW
B9: 3 | C9: 4 | D9: 2 | E9: 7 | F9: Both
E10: 8 | F10: None
E11: 9 | F11: EW
B12: 4 | C12: 7 | D12: 3 | E12: 13 | F12: Both
E13: 14 | F13: None
E14: 15 | F14: NS
A15: 2 | B15: 1 | C15: Sit-Out | D15: 2 | E15: 4 | F15: Both
E16: 5 | F16: NS
E17: 6 | F17: EW
B18: 2 | C18: 7 | D18: 6 | E18: 7 | F18: Both
E19: 8 | F19: None
E20: 9 | F20: EW
B21: 3 | C21: 5 | D21: 3 | E21: 10 | F21: Both
E22: 11 | F22: None
E23: 12 | F23: NS
B24: 4 | C24: 1 | D24: 4 | E24: 16 | F24: EW
E25: 17 | F25: None
E26: 18 | F26: NS
A27: 3 | B27: 1 | C27: Sit-Out | D27: 3 | E27: 7 | F27: Both
E28: 8 | F28: None
E29: 9 | F29: EW
B30: 2 | C30: 1 | D30: 7 | E30: 10 | F30: Both
E31: 11 | F31: None
E32: 12 | F32: NS
B33: 3 | C33: 6 | D33: 4 | E33: 13 | F33: Both
E34: 14 | F34: None
E35: 15 | F35: NS
B36: 4 | C36: 2 | D36: 5 | E36: 19 | F36: EW
E37: 20 | F37: Both
E38: 21 | F38: NS
A39: 4 | B39: 1 | C39: Sit-Out | D39: 4 | E39: 10 | F39: Both
E40: 11 | F40: None
...

Sheet IMP Table
A1: From | B1: To | C1: IMP
A2: 0 | B2: 10 | C2: 0
A3: 20 | B3: 40 | C3: 1
A4: 50 | B4: 80 | C4: 2
A5: 90 | B5: 120 | C5: 3
A6: 130 | B6: 160 | C6: 4
A7: 170 | B7: 210 | C7: 5
A8: 220 | B8: 260 | C8: 6
A9: 270 | B9: 310 | C9: 7
A10: 320 | B10: 360 | C10: 8
A11: 370 | B11: 420 | C11: 9
A12: 430 | B12: 490 | C12: 10
A13: 500 | B13: 590 | C13: 11
... A26: 4000 | B26: 10000 | C26: 24

Sheet Scoring Table
C1: Not Vulnerable | F1: Vulnerable | K1: Not Vulnerable | N1: Vulnerable
A2: Contract | B2: Made | D2: X | E2: XX | G2: X | H2: XX | J2: Down by | L2: X | M2: XX | O2: X | P2: XX
A3: 1 D/C | B3: 1 | C3: 70 | D3: 140 | E3: 230 | F3: 70 | G3: 140 | H3: 230 | J3: -1 | K3: -50 | L3: -100 | M3: =L3*2 | N3: -100 | O3: -200 | P3: =O3*2
B4: 2 | C4: 90 | D4: 240 | E4: 430 | F4: 90 | G4: 340 | H4: 630 | J4: -2 | K4: =K3-50 | L4: =L3-200 | M4: =L4*2 | N4: =N3-100 | O4: =O3-300 | P4: =O4*2
B5: 3 | C5: 110 | D5: 340 | E5: 630 | F5: 110 | G5: 540 | H5: 1030 | J5: -3 | K5: =K4-50 | L5: =L4-200 | M5: =L5*2 | N5: =N4-100 | O5: =O4-300 | P5: =O5*2
B6: 4 | C6: 130 | D6: 440 | E6: 830 | F6: 130 | G6: 740 | H6: 1430 | J6: -4 | K6: =K5-50 | L6: =L5-300 | M6: =L6*2 | N6: =N5-100 | O6: =O5-300 | P6: =O6*2
B7: 5 | C7: 150 | D7: 540 | E7: 1030 | F7: 150 | G7: 940 | H7: 1830 | J7: -5 | K7: =K6-50 | L7: =L6-300 | M7: =L7*2 | N7: =N6-100 | O7: =O6-300 | P7: =O7*2
B8: 6 | C8: 170 | D8: 640 | E8: 1230 | F8: 170 | G8: 1140 | H8: 2230 | J8: -6 | K8: =K7-50 | L8: =L7-300 | M8: =L8*2 | N8: =N7-100 | O8: =O7-300 | P8: =O8*2
B9: 7 | C9: 190 | D9: 740 | E9: 1430 | F9: 190 | G9: 1340 | H9: 2630 | J9: -7 | K9: =K8-50 | L9: =L8-300 | M9: =L9*2 | N9: =N8-100 | O9: =O8-300 | P9: =O9*2
A10: 1 H/S | B10: 1 | C10: 80 | D10: 160 | E10: 520 | F10: 80 | G10: 160 | H10: 720 | J10: -8 | K10: =K9-50 | L10: =L9-300 | M10: =L10*2 | N10: =N9-100 | O10: =O9-300 | P10: =O10*2
B11: 2 | C11: 110 | D11: 260 | E11: 720 | F11: 110 | G11: 360 | H11: 1120 | J11: -9 | K11: =K10-50 | L11: =L10-300 | M11: =L11*2 | N11: =N10-100 | O11: =O10-300 | P11: =O11*2
B12: 3 | C12: 140 | D12: 360 | E12: 920 | F12: 140 | G12: 560 | H12: 1520 | J12: -10 | K12: =K11-50 | L12: =L11-300 | M12: =L12*2 | N12: =N11-100 | O12: =O11-300 | P12: =O12*2
B13: 4 | C13: 170 | D13: 460 | E13: 1120 | F13: 170 | G13: 760 | H13: 1920 | J13: -11 | K13: =K12-50 | L13: =L12-300 | M13: =L13*2 | N13: =N12-100 | O13: =O12-300 | P13: =O13*2
B14: 5 | C14: 200 | D14: 560 | E14: 1320 | F14: 200 | G14: 960 | H14: 2320 | J14: -12 | K14: =K13-50 | L14: =L13-300 | M14: =L14*2 | N14: =N13-100 | O14: =O13-300 | P14: =O14*2
B15: 6 | C15: 230 | D15: 660 | E15: 1520 | F15: 230 | G15: 1160 | H15: 2720 | J15: -13 | K15: =K14-50 | L15: =L14-300 | M15: =L15*2 | N15: =N14-100 | O15: =O14-300 | P15: =O15*2
B16: 7 | C16: 260 | D16: 760 | E16: 1720 | F16: 260 | G16: 1360 | H16: 3120
A17: 1 NT | B17: 1 | C17: 90 | D17: 180 | E17: 560 | F17: 90 | G17: 180 | H17: 760
B18: 2 | C18: 120 | D18: 280 | E18: 760 | F18: 120 | G18: 380 | H18: 1160
B19: 3 | C19: 150 | D19: 380 | E19: 960 | F19: 150 | G19: 580 | H19: 1560
B20: 4 | C20: 180 | D20: 480 | E20: 1160 | F20: 180 | G20: 780 | H20: 1960
B21: 5 | C21: 210 | D21: 580 | E21: 1360 | F21: 210 | G21: 980 | H21: 2360
B22: 6 | C22: 240 | D22: 680 | E22: 1560 | F22: 240 | G22: 1180 | H22: 2760
B23: 7 | C23: 270 | D23: 780 | E23: 1760 | F23: 270 | G23: 1380 | H23: 3160
A24: 2 D/C | B24: 2 | C24: 90 | D24: 180 | E24: 560 | F24: 90 | G24: 180 | H24: 760
B25: 3 | C25: 110 | D25: 280 | E25: 760 | F25: 110 | G25: 380 | H25: 1160
B26: 4 | C26: 130 | D26: 380 | E26: 960 | F26: 130 | G26: 580 | H26: 1560
B27: 5 | C27: 150 | D27: 480 | E27: 1160 | F27: 150 | G27: 780 | H27: 1960
B28: 6 | C28: 170 | D28: 580 | E28: 1360 | F28: 170 | G28: 980 | H28: 2360
B29: 7 | C29: 190 | D29: 680 | E29: 1560 | F29: 190 | G29: 1180 | H29: 2760
A30: 2 H/S | B30: 2 | C30: 110 | D30: 470 | E30: 640 | F30: 110 | G30: 670 | H30: 840
B31: 3 | C31: 140 | D31: 570 | E31: 840 | F31: 140 | G31: 870 | H31: 1240
B32: 4 | C32: 170 | D32: 670 | E32: 1040 | F32: 170 | G32: 1070 | H32: 1640
B33: 5 | C33: 200 | D33: 770 | E33: 1240 | F33: 200 | G33: 1270 | H33: 2040
B34: 6 | C34: 230 | D34: 870 | E34: 1440 | F34: 230 | G34: 1470 | H34: 2440
B35: 7 | C35: 260 | D35: 970 | E35: 1640 | F35: 260 | G35: 1670 | H35: 2840
A36: 2 NT | B36: 2 | C36: 120 | D36: 490 | E36: 680 | F36: 120 | G36: 690 | H36: 880
B37: 3 | C37: 150 | D37: 590 | E37: 880 | F37: 150 | G37: 890 | H37: 1280
B38: 4 | C38: 180 | D38: 690 | E38: 1080 | F38: 180 | G38: 1090 | H38: 1680
B39: 5 | C39: 210 | D39: 790 | E39: 1280 | F39: 210 | G39: 1290 | H39: 2080
B40: 6 | C40: 240 | D40: 890 | E40: 1480 | F40: 240 | G40: 1490 | H40: 2480
...
