Workbook

Sheet Roster
A1: For public domain. No rights reserved. Generated on Mar 08, 2026.
A2: Howell Tournament
A3: Pairs | C3: 14
A4: Tables | C4: 7
A5: Rounds | C5: 13
A6: Boards per round | C6: 2
A7: Total Boards to play | C7: 26
A9: Pairs | D9: MP | E9: IMP
A10: 1 | B10: Name 62 | C10: Name 52 | D10: =SUMIF('By Board'!$D$3:$D$184,"=1",'By Board'!$O$3:$O$184)/26+SUMIF('By Board'!$E$3:$E$184,"=1",'By Board'!$P$3:$P$184)/26 | E10: =SUMIF('By Board'!$D$3:$D$184,"=1",'By Board'!$M$3:$M$184)+SUMIF('By Board'!$E$3:$E$184,"=1",'By Board'!$N$3:$N$184)
A11: 2 | B11: Name 44 | C11: Name 62 | D11: =SUMIF('By Board'!$D$3:$D$184,"=2",'By Board'!$O$3:$O$184)/26+SUMIF('By Board'!$E$3:$E$184,"=2",'By Board'!$P$3:$P$184)/26 | E11: =SUMIF('By Board'!$D$3:$D$184,"=2",'By Board'!$M$3:$M$184)+SUMIF('By Board'!$E$3:$E$184,"=2",'By Board'!$N$3:$N$184)
A12: 3 | B12: Name 12 | C12: Name 19 | D12: =SUMIF('By Board'!$D$3:$D$184,"=3",'By Board'!$O$3:$O$184)/26+SUMIF('By Board'!$E$3:$E$184,"=3",'By Board'!$P$3:$P$184)/26 | E12: =SUMIF('By Board'!$D$3:$D$184,"=3",'By Board'!$M$3:$M$184)+SUMIF('By Board'!$E$3:$E$184,"=3",'By Board'!$N$3:$N$184)
A13: 4 | B13: Name 75 | C13: Name 34 | D13: =SUMIF('By Board'!$D$3:$D$184,"=4",'By Board'!$O$3:$O$184)/26+SUMIF('By Board'!$E$3:$E$184,"=4",'By Board'!$P$3:$P$184)/26 | E13: =SUMIF('By Board'!$D$3:$D$184,"=4",'By Board'!$M$3:$M$184)+SUMIF('By Board'!$E$3:$E$184,"=4",'By Board'!$N$3:$N$184)
A14: 5 | B14: Name 50 | C14: Name 22 | D14: =SUMIF('By Board'!$D$3:$D$184,"=5",'By Board'!$O$3:$O$184)/26+SUMIF('By Board'!$E$3:$E$184,"=5",'By Board'!$P$3:$P$184)/26 | E14: =SUMIF('By Board'!$D$3:$D$184,"=5",'By Board'!$M$3:$M$184)+SUMIF('By Board'!$E$3:$E$184,"=5",'By Board'!$N$3:$N$184)
A15: 6 | B15: Name 42 | C15: Name 20 | D15: =SUMIF('By Board'!$D$3:$D$184,"=6",'By Board'!$O$3:$O$184)/26+SUMIF('By Board'!$E$3:$E$184,"=6",'By Board'!$P$3:$P$184)/26 | E15: =SUMIF('By Board'!$D$3:$D$184,"=6",'By Board'!$M$3:$M$184)+SUMIF('By Board'!$E$3:$E$184,"=6",'By Board'!$N$3:$N$184)
A16: 7 | B16: Name 90 | C16: Name 41 | D16: =SUMIF('By Board'!$D$3:$D$184,"=7",'By Board'!$O$3:$O$184)/26+SUMIF('By Board'!$E$3:$E$184,"=7",'By Board'!$P$3:$P$184)/26 | E16: =SUMIF('By Board'!$D$3:$D$184,"=7",'By Board'!$M$3:$M$184)+SUMIF('By Board'!$E$3:$E$184,"=7",'By Board'!$N$3:$N$184)
A17: 8 | B17: Name 26 | C17: Name 70 | D17: =SUMIF('By Board'!$D$3:$D$184,"=8",'By Board'!$O$3:$O$184)/26+SUMIF('By Board'!$E$3:$E$184,"=8",'By Board'!$P$3:$P$184)/26 | E17: =SUMIF('By Board'!$D$3:$D$184,"=8",'By Board'!$M$3:$M$184)+SUMIF('By Board'!$E$3:$E$184,"=8",'By Board'!$N$3:$N$184)
A18: 9 | B18: Name 30 | C18: Name 56 | D18: =SUMIF('By Board'!$D$3:$D$184,"=9",'By Board'!$O$3:$O$184)/26+SUMIF('By Board'!$E$3:$E$184,"=9",'By Board'!$P$3:$P$184)/26 | E18: =SUMIF('By Board'!$D$3:$D$184,"=9",'By Board'!$M$3:$M$184)+SUMIF('By Board'!$E$3:$E$184,"=9",'By Board'!$N$3:$N$184)
A19: 10 | B19: Name 26 | C19: Name 34 | D19: =SUMIF('By Board'!$D$3:$D$184,"=10",'By Board'!$O$3:$O$184)/26+SUMIF('By Board'!$E$3:$E$184,"=10",'By Board'!$P$3:$P$184)/26 | E19: =SUMIF('By Board'!$D$3:$D$184,"=10",'By Board'!$M$3:$M$184)+SUMIF('By Board'!$E$3:$E$184,"=10",'By Board'!$N$3:$N$184)
A20: 11 | B20: Name 59 | C20: Name 82 | D20: =SUMIF('By Board'!$D$3:$D$184,"=11",'By Board'!$O$3:$O$184)/26+SUMIF('By Board'!$E$3:$E$184,"=11",'By Board'!$P$3:$P$184)/26 | E20: =SUMIF('By Board'!$D$3:$D$184,"=11",'By Board'!$M$3:$M$184)+SUMIF('By Board'!$E$3:$E$184,"=11",'By Board'!$N$3:$N$184)
A21: 12 | B21: Name 82 | C21: Name 69 | D21: =SUMIF('By Board'!$D$3:$D$184,"=12",'By Board'!$O$3:$O$184)/26+SUMIF('By Board'!$E$3:$E$184,"=12",'By Board'!$P$3:$P$184)/26 | E21: =SUMIF('By Board'!$D$3:$D$184,"=12",'By Board'!$M$3:$M$184)+SUMIF('By Board'!$E$3:$E$184,"=12",'By Board'!$N$3:$N$184)
A22: 13 | B22: Name 30 | C22: Name 51 | D22: =SUMIF('By Board'!$D$3:$D$184,"=13",'By Board'!$O$3:$O$184)/26+SUMIF('By Board'!$E$3:$E$184,"=13",'By Board'!$P$3:$P$184)/26 | E22: =SUMIF('By Board'!$D$3:$D$184,"=13",'By Board'!$M$3:$M$184)+SUMIF('By Board'!$E$3:$E$184,"=13",'By Board'!$N$3:$N$184)
A23: 14 | B23: Name 53 | C23: Name 27 | D23: =SUMIF('By Board'!$D$3:$D$184,"=14",'By Board'!$O$3:$O$184)/26+0/26 | E23: =SUMIF('By Board'!$D$3:$D$184,"=14",'By Board'!$M$3:$M$184)+0
D24: =AVERAGE(D10:D23) | E24: =SUM(E10:E23)

Sheet By Board
I1: Result | K1: Score | M1: IMP | O1: MP % | Q1: MP Pts | S1: Net | U1: MP Calculation | AG1: IMP Calculation
A2: Board | B2: Round | C2: Table | D2: NS | E2: EW | F2: Vul | G2: Contract | H2: By | I2: Made | J2: Down | K2: NS | L2: EW | M2: NS | N2: EW | O2: NS | P2: EW | Q2: NS | R2: EW | S2: NS | T2: EW | U2: NS MP Scores | AA2: EW MP Scores | AG2: NS IMP Pair-wise | AM2: EW IMP Pair-wise
A3: 1 | B3: ='By Round'!A157 | C3: ='By Round'!B159 | D3: ='By Round'!C159 | E3: ='By Round'!D159 | F3: =IF(ISBLANK('By Round'!F159),"",'By Round'!F159) | G3: =IF(ISBLANK('By Round'!G159),"",'By Round'!G159) | H3: =IF(ISBLANK('By Round'!H159),"",'By Round'!H159) | I3: =IF(ISBLANK('By Round'!I159),"",'By Round'!I159) | J3: =IF(ISBLANK('By Round'!J159),"",'By Round'!J159) | K3: =IF(ISBLANK('By Round'!K159),"",'By Round'!K159) | L3: =IF(ISBLANK('By Round'!L159),"",'By Round'!L159) | M3: =AVERAGE(AG3:AL3) | N3: =AVERAGE(AM3:AR3) | O3: =IF(COUNT(U3:Z3)>0,Q3/COUNT(U3:Z3),0.5) | P3: =IF(COUNT(AA3:AF3)>0,R3/COUNT(AA3:AF3),0.5) | Q3: =SUM(U3:Z3) | R3: =SUM(AA3:AF3) | S3: =IF(ISNUMBER(K3),K3,IF(ISNUMBER(L3),-L3,"")) | T3: =IF(ISNUMBER(L3),L3,IF(ISNUMBER(K3),-K3,"")) | U3: =IF(ISNUMBER(S3),IF(ISNUMBER(S4),IF(S3>S4,1.0,IF(S3=S4,0.5,0.0)),""),"") | V3: =IF(ISNUMBER(S3),IF(ISNUMBER(S5),IF(S3>S5,1.0,IF(S3=S5,0.5,0.0)),""),"") | W3: =IF(ISNUMBER(S3),IF(ISNUMBER(S6),IF(S3>S6,1.0,IF(S3=S6,0.5,0.0)),""),"") | X3: =IF(ISNUMBER(S3),IF(ISNUMBER(S7),IF(S3>S7,1.0,IF(S3=S7,0.5,0.0)),""),"") | Y3: =IF(ISNUMBER(S3),IF(ISNUMBER(S8),IF(S3>S8,1.0,IF(S3=S8,0.5,0.0)),""),"") | Z3: =IF(ISNUMBER(S3),IF(ISNUMBER(S9),IF(S3>S9,1.0,IF(S3=S9,0.5,0.0)),""),"") | AA3: =IF(ISNUMBER(T3),IF(ISNUMBER(T4),IF(T3>T4,1.0,IF(T3=T4,0.5,0.0)),""),"") | AB3: =IF(ISNUMBER(T3),IF(ISNUMBER(T5),IF(T3>T5,1.0,IF(T3=T5,0.5,0.0)),""),"") | AC3: =IF(ISNUMBER(T3),IF(ISNUMBER(T6),IF(T3>T6,1.0,IF(T3=T6,0.5,0.0)),""),"") | AD3: =IF(ISNUMBER(T3),IF(ISNUMBER(T7),IF(T3>T7,1.0,IF(T3=T7,0.5,0.0)),""),"") | AE3: =IF(ISNUMBER(T3),IF(ISNUMBER(T8),IF(T3>T8,1.0,IF(T3=T8,0.5,0.0)),""),"") | AF3: =IF(ISNUMBER(T3),IF(ISNUMBER(T9),IF(T3>T9,1.0,IF(T3=T9,0.5,0.0)),""),"") | AG3: =IF(AND(ISNUMBER(S3),ISNUMBER(S4)),VLOOKUP(ABS(S3-S4),'IMP Table'!$A$2:$C$26,3)*SIGN(S3-S4),0) | AH3: =IF(AND(ISNUMBER(S3),ISNUMBER(S5)),VLOOKUP(ABS(S3-S5),'IMP Table'!$A$2:$C$26,3)*SIGN(S3-S5),0) | AI3: =IF(AND(ISNUMBER(S3),ISNUMBER(S6)),VLOOKUP(ABS(S3-S6),'IMP Table'!$A$2:$C$26,3)*SIGN(S3-S6),0) | AJ3: =IF(AND(ISNUMBER(S3),ISNUMBER(S7)),VLOOKUP(ABS(S3-S7),'IMP Table'!$A$2:$C$26,3)*SIGN(S3-S7),0) | AK3: =IF(AND(ISNUMBER(S3),ISNUMBER(S8)),VLOOKUP(ABS(S3-S8),'IMP Table'!$A$2:$C$26,3)*SIGN(S3-S8),0) | AL3: =IF(AND(ISNUMBER(S3),ISNUMBER(S9)),VLOOKUP(ABS(S3-S9),'IMP Table'!$A$2:$C$26,3)*SIGN(S3-S9),0) | AM3: =IF(AND(ISNUMBER(T3),ISNUMBER(T4)),VLOOKUP(ABS(T3-T4),'IMP Table'!$A$2:$C$26,3)*SIGN(T3-T4),0) | AN3: =IF(AND(ISNUMBER(T3),ISNUMBER(T5)),VLOOKUP(ABS(T3-T5),'IMP Table'!$A$2:$C$26,3)*SIGN(T3-T5),0) | AO3: =IF(AND(ISNUMBER(T3),ISNUMBER(T6)),VLOOKUP(ABS(T3-T6),'IMP Table'!$A$2:$C$26,3)*SIGN(T3-T6),0) | AP3: =IF(AND(ISNUMBER(T3),ISNUMBER(T7)),VLOOKUP(ABS(T3-T7),'IMP Table'!$A$2:$C$26,3)*SIGN(T3-T7),0) | AQ3: =IF(AND(ISNUMBER(T3),ISNUMBER(T8)),VLOOKUP(ABS(T3-T8),'IMP Table'!$A$2:$C$26,3)*SIGN(T3-T8),0) | AR3: =IF(AND(ISNUMBER(T3),ISNUMBER(T9)),VLOOKUP(ABS(T3-T9),'IMP Table'!$A$2:$C$26,3)*SIGN(T3-T9),0)
B4: ='By Round'!A129 | C4: ='By Round'!B135 | D4: ='By Round'!C135 | E4: ='By Round'!D135 | F4: =IF(ISBLANK('By Round'!F135),"",'By Round'!F135) | G4: =IF(ISBLANK('By Round'!G135),"",'By Round'!G135) | H4: =IF(ISBLANK('By Round'!H135),"",'By Round'!H135) | I4: =IF(ISBLANK('By Round'!I135),"",'By Round'!I135) | J4: =IF(ISBLANK('By Round'!J135),"",'By Round'!J135) | K4: =IF(ISBLANK('By Round'!K135),"",'By Round'!K135) | L4: =IF(ISBLANK('By Round'!L135),"",'By Round'!L135) | M4: =AVERAGE(AG4:AL4) | N4: =AVERAGE(AM4:AR4) | O4: =IF(COUNT(U4:Z4)>0,Q4/COUNT(U4:Z4),0.5) | P4: =IF(COUNT(AA4:AF4)>0,R4/COUNT(AA4:AF4),0.5) | Q4: =SUM(U4:Z4) | R4: =SUM(AA4:AF4) | S4: =IF(ISNUMBER(K4),K4,IF(ISNUMBER(L4),-L4,"")) | T4: =IF(ISNUMBER(L4),L4,IF(ISNUMBER(K4),-K4,"")) | U4: =IF(ISNUMBER(S4),IF(ISNUMBER(S3),IF(S4>S3,1.0,IF(S4=S3,0.5,0.0)),""),"") | V4: =IF(ISNUMBER(S4),IF(ISNUMBER(S5),IF(S4>S5,1.0,IF(S4=S5,0.5,0.0)),""),"") | W4: =IF(ISNUMBER(S4),IF(ISNUMBER(S6),IF(S4>S6,1.0,IF(S4=S6,0.5,0.0)),""),"") | X4: =IF(ISNUMBER(S4),IF(ISNUMBER(S7),IF(S4>S7,1.0,IF(S4=S7,0.5,0.0)),""),"") | Y4: =IF(ISNUMBER(S4),IF(ISNUMBER(S8),IF(S4>S8,1.0,IF(S4=S8,0.5,0.0)),""),"") | Z4: =IF(ISNUMBER(S4),IF(ISNUMBER(S9),IF(S4>S9,1.0,IF(S4=S9,0.5,0.0)),""),"") | AA4: =IF(ISNUMBER(T4),IF(ISNUMBER(T3),IF(T4>T3,1.0,IF(T4=T3,0.5,0.0)),""),"") | AB4: =IF(ISNUMBER(T4),IF(ISNUMBER(T5),IF(T4>T5,1.0,IF(T4=T5,0.5,0.0)),""),"") | AC4: =IF(ISNUMBER(T4),IF(ISNUMBER(T6),IF(T4>T6,1.0,IF(T4=T6,0.5,0.0)),""),"") | AD4: =IF(ISNUMBER(T4),IF(ISNUMBER(T7),IF(T4>T7,1.0,IF(T4=T7,0.5,0.0)),""),"") | AE4: =IF(ISNUMBER(T4),IF(ISNUMBER(T8),IF(T4>T8,1.0,IF(T4=T8,0.5,0.0)),""),"") | AF4: =IF(ISNUMBER(T4),IF(ISNUMBER(T9),IF(T4>T9,1.0,IF(T4=T9,0.5,0.0)),""),"") | AG4: =IF(AND(ISNUMBER(S4),ISNUMBER(S3)),VLOOKUP(ABS(S4-S3),'IMP Table'!$A$2:$C$26,3)*SIGN(S4-S3),0) | AH4: =IF(AND(ISNUMBER(S4),ISNUMBER(S5)),VLOOKUP(ABS(S4-S5),'IMP Table'!$A$2:$C$26,3)*SIGN(S4-S5),0) | AI4: =IF(AND(ISNUMBER(S4),ISNUMBER(S6)),VLOOKUP(ABS(S4-S6),'IMP Table'!$A$2:$C$26,3)*SIGN(S4-S6),0) | AJ4: =IF(AND(ISNUMBER(S4),ISNUMBER(S7)),VLOOKUP(ABS(S4-S7),'IMP Table'!$A$2:$C$26,3)*SIGN(S4-S7),0) | AK4: =IF(AND(ISNUMBER(S4),ISNUMBER(S8)),VLOOKUP(ABS(S4-S8),'IMP Table'!$A$2:$C$26,3)*SIGN(S4-S8),0) | AL4: =IF(AND(ISNUMBER(S4),ISNUMBER(S9)),VLOOKUP(ABS(S4-S9),'IMP Table'!$A$2:$C$26,3)*SIGN(S4-S9),0) | AM4: =IF(AND(ISNUMBER(T4),ISNUMBER(T3)),VLOOKUP(ABS(T4-T3),'IMP Table'!$A$2:$C$26,3)*SIGN(T4-T3),0) | AN4: =IF(AND(ISNUMBER(T4),ISNUMBER(T5)),VLOOKUP(ABS(T4-T5),'IMP Table'!$A$2:$C$26,3)*SIGN(T4-T5),0) | AO4: =IF(AND(ISNUMBER(T4),ISNUMBER(T6)),VLOOKUP(ABS(T4-T6),'IMP Table'!$A$2:$C$26,3)*SIGN(T4-T6),0) | AP4: =IF(AND(ISNUMBER(T4),ISNUMBER(T7)),VLOOKUP(ABS(T4-T7),'IMP Table'!$A$2:$C$26,3)*SIGN(T4-T7),0) | AQ4: =IF(AND(ISNUMBER(T4),ISNUMBER(T8)),VLOOKUP(ABS(T4-T8),'IMP Table'!$A$2:$C$26,3)*SIGN(T4-T8),0) | AR4: =IF(AND(ISNUMBER(T4),ISNUMBER(T9)),VLOOKUP(ABS(T4-T9),'IMP Table'!$A$2:$C$26,3)*SIGN(T4-T9),0)
B5: ='By Round'!A31 | C5: ='By Round'!B43 | D5: ='By Round'!C43 | E5: ='By Round'!D43 | F5: =IF(ISBLANK('By Round'!F43),"",'By Round'!F43) | G5: =IF(ISBLANK('By Round'!G43),"",'By Round'!G43) | H5: =IF(ISBLANK('By Round'!H43),"",'By Round'!H43) | I5: =IF(ISBLANK('By Round'!I43),"",'By Round'!I43) | J5: =IF(ISBLANK('By Round'!J43),"",'By Round'!J43) | K5: =IF(ISBLANK('By Round'!K43),"",'By Round'!K43) | L5: =IF(ISBLANK('By Round'!L43),"",'By Round'!L43) | M5: =AVERAGE(AG5:AL5) | N5: =AVERAGE(AM5:AR5) | O5: =IF(COUNT(U5:Z5)>0,Q5/COUNT(U5:Z5),0.5) | P5: =IF(COUNT(AA5:AF5)>0,R5/COUNT(AA5:AF5),0.5) | Q5: =SUM(U5:Z5) | R5: =SUM(AA5:AF5) | S5: =IF(ISNUMBER(K5),K5,IF(ISNUMBER(L5),-L5,"")) | T5: =IF(ISNUMBER(L5),L5,IF(ISNUMBER(K5),-K5,"")) | U5: =IF(ISNUMBER(S5),IF(ISNUMBER(S3),IF(S5>S3,1.0,IF(S5=S3,0.5,0.0)),""),"") | V5: =IF(ISNUMBER(S5),IF(ISNUMBER(S4),IF(S5>S4,1.0,IF(S5=S4,0.5,0.0)),""),"") | W5: =IF(ISNUMBER(S5),IF(ISNUMBER(S6),IF(S5>S6,1.0,IF(S5=S6,0.5,0.0)),""),"") | X5: =IF(ISNUMBER(S5),IF(ISNUMBER(S7),IF(S5>S7,1.0,IF(S5=S7,0.5,0.0)),""),"") | Y5: =IF(ISNUMBER(S5),IF(ISNUMBER(S8),IF(S5>S8,1.0,IF(S5=S8,0.5,0.0)),""),"") | Z5: =IF(ISNUMBER(S5),IF(ISNUMBER(S9),IF(S5>S9,1.0,IF(S5=S9,0.5,0.0)),""),"") | AA5: =IF(ISNUMBER(T5),IF(ISNUMBER(T3),IF(T5>T3,1.0,IF(T5=T3,0.5,0.0)),""),"") | AB5: =IF(ISNUMBER(T5),IF(ISNUMBER(T4),IF(T5>T4,1.0,IF(T5=T4,0.5,0.0)),""),"") | AC5: =IF(ISNUMBER(T5),IF(ISNUMBER(T6),IF(T5>T6,1.0,IF(T5=T6,0.5,0.0)),""),"") | AD5: =IF(ISNUMBER(T5),IF(ISNUMBER(T7),IF(T5>T7,1.0,IF(T5=T7,0.5,0.0)),""),"") | AE5: =IF(ISNUMBER(T5),IF(ISNUMBER(T8),IF(T5>T8,1.0,IF(T5=T8,0.5,0.0)),""),"") | AF5: =IF(ISNUMBER(T5),IF(ISNUMBER(T9),IF(T5>T9,1.0,IF(T5=T9,0.5,0.0)),""),"") | AG5: =IF(AND(ISNUMBER(S5),ISNUMBER(S3)),VLOOKUP(ABS(S5-S3),'IMP Table'!$A$2:$C$26,3)*SIGN(S5-S3),0) | AH5: =IF(AND(ISNUMBER(S5),ISNUMBER(S4)),VLOOKUP(ABS(S5-S4),'IMP Table'!$A$2:$C$26,3)*SIGN(S5-S4),0) | AI5: =IF(AND(ISNUMBER(S5),ISNUMBER(S6)),VLOOKUP(ABS(S5-S6),'IMP Table'!$A$2:$C$26,3)*SIGN(S5-S6),0) | AJ5: =IF(AND(ISNUMBER(S5),ISNUMBER(S7)),VLOOKUP(ABS(S5-S7),'IMP Table'!$A$2:$C$26,3)*SIGN(S5-S7),0) | AK5: =IF(AND(ISNUMBER(S5),ISNUMBER(S8)),VLOOKUP(ABS(S5-S8),'IMP Table'!$A$2:$C$26,3)*SIGN(S5-S8),0) | AL5: =IF(AND(ISNUMBER(S5),ISNUMBER(S9)),VLOOKUP(ABS(S5-S9),'IMP Table'!$A$2:$C$26,3)*SIGN(S5-S9),0) | AM5: =IF(AND(ISNUMBER(T5),ISNUMBER(T3)),VLOOKUP(ABS(T5-T3),'IMP Table'!$A$2:$C$26,3)*SIGN(T5-T3),0) | AN5: =IF(AND(ISNUMBER(T5),ISNUMBER(T4)),VLOOKUP(ABS(T5-T4),'IMP Table'!$A$2:$C$26,3)*SIGN(T5-T4),0) | AO5: =IF(AND(ISNUMBER(T5),ISNUMBER(T6)),VLOOKUP(ABS(T5-T6),'IMP Table'!$A$2:$C$26,3)*SIGN(T5-T6),0) | AP5: =IF(AND(ISNUMBER(T5),ISNUMBER(T7)),VLOOKUP(ABS(T5-T7),'IMP Table'!$A$2:$C$26,3)*SIGN(T5-T7),0) | AQ5: =IF(AND(ISNUMBER(T5),ISNUMBER(T8)),VLOOKUP(ABS(T5-T8),'IMP Table'!$A$2:$C$26,3)*SIGN(T5-T8),0) | AR5: =IF(AND(ISNUMBER(T5),ISNUMBER(T9)),VLOOKUP(ABS(T5-T9),'IMP Table'!$A$2:$C$26,3)*SIGN(T5-T9),0)
B6: ='By Round'!A59 | C6: ='By Round'!B67 | D6: ='By Round'!C67 | E6: ='By Round'!D67 | F6: =IF(ISBLANK('By Round'!F67),"",'By Round'!F67) | G6: =IF(ISBLANK('By Round'!G67),"",'By Round'!G67) | H6: =IF(ISBLANK('By Round'!H67),"",'By Round'!H67) | I6: =IF(ISBLANK('By Round'!I67),"",'By Round'!I67) | J6: =IF(ISBLANK('By Round'!J67),"",'By Round'!J67) | K6: =IF(ISBLANK('By Round'!K67),"",'By Round'!K67) | L6: =IF(ISBLANK('By Round'!L67),"",'By Round'!L67) | M6: =AVERAGE(AG6:AL6) | N6: =AVERAGE(AM6:AR6) | O6: =IF(COUNT(U6:Z6)>0,Q6/COUNT(U6:Z6),0.5) | P6: =IF(COUNT(AA6:AF6)>0,R6/COUNT(AA6:AF6),0.5) | Q6: =SUM(U6:Z6) | R6: =SUM(AA6:AF6) | S6: =IF(ISNUMBER(K6),K6,IF(ISNUMBER(L6),-L6,"")) | T6: =IF(ISNUMBER(L6),L6,IF(ISNUMBER(K6),-K6,"")) | U6: =IF(ISNUMBER(S6),IF(ISNUMBER(S3),IF(S6>S3,1.0,IF(S6=S3,0.5,0.0)),""),"") | V6: =IF(ISNUMBER(S6),IF(ISNUMBER(S4),IF(S6>S4,1.0,IF(S6=S4,0.5,0.0)),""),"") | W6: =IF(ISNUMBER(S6),IF(ISNUMBER(S5),IF(S6>S5,1.0,IF(S6=S5,0.5,0.0)),""),"") | X6: =IF(ISNUMBER(S6),IF(ISNUMBER(S7),IF(S6>S7,1.0,IF(S6=S7,0.5,0.0)),""),"") | Y6: =IF(ISNUMBER(S6),IF(ISNUMBER(S8),IF(S6>S8,1.0,IF(S6=S8,0.5,0.0)),""),"") | Z6: =IF(ISNUMBER(S6),IF(ISNUMBER(S9),IF(S6>S9,1.0,IF(S6=S9,0.5,0.0)),""),"") | AA6: =IF(ISNUMBER(T6),IF(ISNUMBER(T3),IF(T6>T3,1.0,IF(T6=T3,0.5,0.0)),""),"") | AB6: =IF(ISNUMBER(T6),IF(ISNUMBER(T4),IF(T6>T4,1.0,IF(T6=T4,0.5,0.0)),""),"") | AC6: =IF(ISNUMBER(T6),IF(ISNUMBER(T5),IF(T6>T5,1.0,IF(T6=T5,0.5,0.0)),""),"") | AD6: =IF(ISNUMBER(T6),IF(ISNUMBER(T7),IF(T6>T7,1.0,IF(T6=T7,0.5,0.0)),""),"") | AE6: =IF(ISNUMBER(T6),IF(ISNUMBER(T8),IF(T6>T8,1.0,IF(T6=T8,0.5,0.0)),""),"") | AF6: =IF(ISNUMBER(T6),IF(ISNUMBER(T9),IF(T6>T9,1.0,IF(T6=T9,0.5,0.0)),""),"") | AG6: =IF(AND(ISNUMBER(S6),ISNUMBER(S3)),VLOOKUP(ABS(S6-S3),'IMP Table'!$A$2:$C$26,3)*SIGN(S6-S3),0) | AH6: =IF(AND(ISNUMBER(S6),ISNUMBER(S4)),VLOOKUP(ABS(S6-S4),'IMP Table'!$A$2:$C$26,3)*SIGN(S6-S4),0) | AI6: =IF(AND(ISNUMBER(S6),ISNUMBER(S5)),VLOOKUP(ABS(S6-S5),'IMP Table'!$A$2:$C$26,3)*SIGN(S6-S5),0) | AJ6: =IF(AND(ISNUMBER(S6),ISNUMBER(S7)),VLOOKUP(ABS(S6-S7),'IMP Table'!$A$2:$C$26,3)*SIGN(S6-S7),0) | AK6: =IF(AND(ISNUMBER(S6),ISNUMBER(S8)),VLOOKUP(ABS(S6-S8),'IMP Table'!$A$2:$C$26,3)*SIGN(S6-S8),0) | AL6: =IF(AND(ISNUMBER(S6),ISNUMBER(S9)),VLOOKUP(ABS(S6-S9),'IMP Table'!$A$2:$C$26,3)*SIGN(S6-S9),0) | AM6: =IF(AND(ISNUMBER(T6),ISNUMBER(T3)),VLOOKUP(ABS(T6-T3),'IMP Table'!$A$2:$C$26,3)*SIGN(T6-T3),0) | AN6: =IF(AND(ISNUMBER(T6),ISNUMBER(T4)),VLOOKUP(ABS(T6-T4),'IMP Table'!$A$2:$C$26,3)*SIGN(T6-T4),0) | AO6: =IF(AND(ISNUMBER(T6),ISNUMBER(T5)),VLOOKUP(ABS(T6-T5),'IMP Table'!$A$2:$C$26,3)*SIGN(T6-T5),0) | AP6: =IF(AND(ISNUMBER(T6),ISNUMBER(T7)),VLOOKUP(ABS(T6-T7),'IMP Table'!$A$2:$C$26,3)*SIGN(T6-T7),0) | AQ6: =IF(AND(ISNUMBER(T6),ISNUMBER(T8)),VLOOKUP(ABS(T6-T8),'IMP Table'!$A$2:$C$26,3)*SIGN(T6-T8),0) | AR6: =IF(AND(ISNUMBER(T6),ISNUMBER(T9)),VLOOKUP(ABS(T6-T9),'IMP Table'!$A$2:$C$26,3)*SIGN(T6-T9),0)
B7: ='By Round'!A45 | C7: ='By Round'!B55 | D7: ='By Round'!C55 | E7: ='By Round'!D55 | F7: =IF(ISBLANK('By Round'!F55),"",'By Round'!F55) | G7: =IF(ISBLANK('By Round'!G55),"",'By Round'!G55) | H7: =IF(ISBLANK('By Round'!H55),"",'By Round'!H55) | I7: =IF(ISBLANK('By Round'!I55),"",'By Round'!I55) | J7: =IF(ISBLANK('By Round'!J55),"",'By Round'!J55) | K7: =IF(ISBLANK('By Round'!K55),"",'By Round'!K55) | L7: =IF(ISBLANK('By Round'!L55),"",'By Round'!L55) | M7: =AVERAGE(AG7:AL7) | N7: =AVERAGE(AM7:AR7) | O7: =IF(COUNT(U7:Z7)>0,Q7/COUNT(U7:Z7),0.5) | P7: =IF(COUNT(AA7:AF7)>0,R7/COUNT(AA7:AF7),0.5) | Q7: =SUM(U7:Z7) | R7: =SUM(AA7:AF7) | S7: =IF(ISNUMBER(K7),K7,IF(ISNUMBER(L7),-L7,"")) | T7: =IF(ISNUMBER(L7),L7,IF(ISNUMBER(K7),-K7,"")) | U7: =IF(ISNUMBER(S7),IF(ISNUMBER(S3),IF(S7>S3,1.0,IF(S7=S3,0.5,0.0)),""),"") | V7: =IF(ISNUMBER(S7),IF(ISNUMBER(S4),IF(S7>S4,1.0,IF(S7=S4,0.5,0.0)),""),"") | W7: =IF(ISNUMBER(S7),IF(ISNUMBER(S5),IF(S7>S5,1.0,IF(S7=S5,0.5,0.0)),""),"") | X7: =IF(ISNUMBER(S7),IF(ISNUMBER(S6),IF(S7>S6,1.0,IF(S7=S6,0.5,0.0)),""),"") | Y7: =IF(ISNUMBER(S7),IF(ISNUMBER(S8),IF(S7>S8,1.0,IF(S7=S8,0.5,0.0)),""),"") | Z7: =IF(ISNUMBER(S7),IF(ISNUMBER(S9),IF(S7>S9,1.0,IF(S7=S9,0.5,0.0)),""),"") | AA7: =IF(ISNUMBER(T7),IF(ISNUMBER(T3),IF(T7>T3,1.0,IF(T7=T3,0.5,0.0)),""),"") | AB7: =IF(ISNUMBER(T7),IF(ISNUMBER(T4),IF(T7>T4,1.0,IF(T7=T4,0.5,0.0)),""),"") | AC7: =IF(ISNUMBER(T7),IF(ISNUMBER(T5),IF(T7>T5,1.0,IF(T7=T5,0.5,0.0)),""),"") | AD7: =IF(ISNUMBER(T7),IF(ISNUMBER(T6),IF(T7>T6,1.0,IF(T7=T6,0.5,0.0)),""),"") | AE7: =IF(ISNUMBER(T7),IF(ISNUMBER(T8),IF(T7>T8,1.0,IF(T7=T8,0.5,0.0)),""),"") | AF7: =IF(ISNUMBER(T7),IF(ISNUMBER(T9),IF(T7>T9,1.0,IF(T7=T9,0.5,0.0)),""),"") | AG7: =IF(AND(ISNUMBER(S7),ISNUMBER(S3)),VLOOKUP(ABS(S7-S3),'IMP Table'!$A$2:$C$26,3)*SIGN(S7-S3),0) | AH7: =IF(AND(ISNUMBER(S7),ISNUMBER(S4)),VLOOKUP(ABS(S7-S4),'IMP Table'!$A$2:$C$26,3)*SIGN(S7-S4),0) | AI7: =IF(AND(ISNUMBER(S7),ISNUMBER(S5)),VLOOKUP(ABS(S7-S5),'IMP Table'!$A$2:$C$26,3)*SIGN(S7-S5),0) | AJ7: =IF(AND(ISNUMBER(S7),ISNUMBER(S6)),VLOOKUP(ABS(S7-S6),'IMP Table'!$A$2:$C$26,3)*SIGN(S7-S6),0) | AK7: =IF(AND(ISNUMBER(S7),ISNUMBER(S8)),VLOOKUP(ABS(S7-S8),'IMP Table'!$A$2:$C$26,3)*SIGN(S7-S8),0) | AL7: =IF(AND(ISNUMBER(S7),ISNUMBER(S9)),VLOOKUP(ABS(S7-S9),'IMP Table'!$A$2:$C$26,3)*SIGN(S7-S9),0) | AM7: =IF(AND(ISNUMBER(T7),ISNUMBER(T3)),VLOOKUP(ABS(T7-T3),'IMP Table'!$A$2:$C$26,3)*SIGN(T7-T3),0) | AN7: =IF(AND(ISNUMBER(T7),ISNUMBER(T4)),VLOOKUP(ABS(T7-T4),'IMP Table'!$A$2:$C$26,3)*SIGN(T7-T4),0) | AO7: =IF(AND(ISNUMBER(T7),ISNUMBER(T5)),VLOOKUP(ABS(T7-T5),'IMP Table'!$A$2:$C$26,3)*SIGN(T7-T5),0) | AP7: =IF(AND(ISNUMBER(T7),ISNUMBER(T6)),VLOOKUP(ABS(T7-T6),'IMP Table'!$A$2:$C$26,3)*SIGN(T7-T6),0) | AQ7: =IF(AND(ISNUMBER(T7),ISNUMBER(T8)),VLOOKUP(ABS(T7-T8),'IMP Table'!$A$2:$C$26,3)*SIGN(T7-T8),0) | AR7: =IF(AND(ISNUMBER(T7),ISNUMBER(T9)),VLOOKUP(ABS(T7-T9),'IMP Table'!$A$2:$C$26,3)*SIGN(T7-T9),0)
B8: ='By Round'!A143 | C8: ='By Round'!B147 | D8: ='By Round'!C147 | E8: ='By Round'!D147 | F8: =IF(ISBLANK('By Round'!F147),"",'By Round'!F147) | G8: =IF(ISBLANK('By Round'!G147),"",'By Round'!G147) | H8: =IF(ISBLANK('By Round'!H147),"",'By Round'!H147) | I8: =IF(ISBLANK('By Round'!I147),"",'By Round'!I147) | J8: =IF(ISBLANK('By Round'!J147),"",'By Round'!J147) | K8: =IF(ISBLANK('By Round'!K147),"",'By Round'!K147) | L8: =IF(ISBLANK('By Round'!L147),"",'By Round'!L147) | M8: =AVERAGE(AG8:AL8) | N8: =AVERAGE(AM8:AR8) | O8: =IF(COUNT(U8:Z8)>0,Q8/COUNT(U8:Z8),0.5) | P8: =IF(COUNT(AA8:AF8)>0,R8/COUNT(AA8:AF8),0.5) | Q8: =SUM(U8:Z8) | R8: =SUM(AA8:AF8) | S8: =IF(ISNUMBER(K8),K8,IF(ISNUMBER(L8),-L8,"")) | T8: =IF(ISNUMBER(L8),L8,IF(ISNUMBER(K8),-K8,"")) | U8: =IF(ISNUMBER(S8),IF(ISNUMBER(S3),IF(S8>S3,1.0,IF(S8=S3,0.5,0.0)),""),"") | V8: =IF(ISNUMBER(S8),IF(ISNUMBER(S4),IF(S8>S4,1.0,IF(S8=S4,0.5,0.0)),""),"") | W8: =IF(ISNUMBER(S8),IF(ISNUMBER(S5),IF(S8>S5,1.0,IF(S8=S5,0.5,0.0)),""),"") | X8: =IF(ISNUMBER(S8),IF(ISNUMBER(S6),IF(S8>S6,1.0,IF(S8=S6,0.5,0.0)),""),"") | Y8: =IF(ISNUMBER(S8),IF(ISNUMBER(S7),IF(S8>S7,1.0,IF(S8=S7,0.5,0.0)),""),"") | Z8: =IF(ISNUMBER(S8),IF(ISNUMBER(S9),IF(S8>S9,1.0,IF(S8=S9,0.5,0.0)),""),"") | AA8: =IF(ISNUMBER(T8),IF(ISNUMBER(T3),IF(T8>T3,1.0,IF(T8=T3,0.5,0.0)),""),"") | AB8: =IF(ISNUMBER(T8),IF(ISNUMBER(T4),IF(T8>T4,1.0,IF(T8=T4,0.5,0.0)),""),"") | AC8: =IF(ISNUMBER(T8),IF(ISNUMBER(T5),IF(T8>T5,1.0,IF(T8=T5,0.5,0.0)),""),"") | AD8: =IF(ISNUMBER(T8),IF(ISNUMBER(T6),IF(T8>T6,1.0,IF(T8=T6,0.5,0.0)),""),"") | AE8: =IF(ISNUMBER(T8),IF(ISNUMBER(T7),IF(T8>T7,1.0,IF(T8=T7,0.5,0.0)),""),"") | AF8: =IF(ISNUMBER(T8),IF(ISNUMBER(T9),IF(T8>T9,1.0,IF(T8=T9,0.5,0.0)),""),"") | AG8: =IF(AND(ISNUMBER(S8),ISNUMBER(S3)),VLOOKUP(ABS(S8-S3),'IMP Table'!$A$2:$C$26,3)*SIGN(S8-S3),0) | AH8: =IF(AND(ISNUMBER(S8),ISNUMBER(S4)),VLOOKUP(ABS(S8-S4),'IMP Table'!$A$2:$C$26,3)*SIGN(S8-S4),0) | AI8: =IF(AND(ISNUMBER(S8),ISNUMBER(S5)),VLOOKUP(ABS(S8-S5),'IMP Table'!$A$2:$C$26,3)*SIGN(S8-S5),0) | AJ8: =IF(AND(ISNUMBER(S8),ISNUMBER(S6)),VLOOKUP(ABS(S8-S6),'IMP Table'!$A$2:$C$26,3)*SIGN(S8-S6),0) | AK8: =IF(AND(ISNUMBER(S8),ISNUMBER(S7)),VLOOKUP(ABS(S8-S7),'IMP Table'!$A$2:$C$26,3)*SIGN(S8-S7),0) | AL8: =IF(AND(ISNUMBER(S8),ISNUMBER(S9)),VLOOKUP(ABS(S8-S9),'IMP Table'!$A$2:$C$26,3)*SIGN(S8-S9),0) | AM8: =IF(AND(ISNUMBER(T8),ISNUMBER(T3)),VLOOKUP(ABS(T8-T3),'IMP Table'!$A$2:$C$26,3)*SIGN(T8-T3),0) | AN8: =IF(AND(ISNUMBER(T8),ISNUMBER(T4)),VLOOKUP(ABS(T8-T4),'IMP Table'!$A$2:$C$26,3)*SIGN(T8-T4),0) | AO8: =IF(AND(ISNUMBER(T8),ISNUMBER(T5)),VLOOKUP(ABS(T8-T5),'IMP Table'!$A$2:$C$26,3)*SIGN(T8-T5),0) | AP8: =IF(AND(ISNUMBER(T8),ISNUMBER(T6)),VLOOKUP(ABS(T8-T6),'IMP Table'!$A$2:$C$26,3)*SIGN(T8-T6),0) | AQ8: =IF(AND(ISNUMBER(T8),ISNUMBER(T7)),VLOOKUP(ABS(T8-T7),'IMP Table'!$A$2:$C$26,3)*SIGN(T8-T7),0) | AR8: =IF(AND(ISNUMBER(T8),ISNUMBER(T9)),VLOOKUP(ABS(T8-T9),'IMP Table'!$A$2:$C$26,3)*SIGN(T8-T9),0)
B9: ='By Round'!A3 | C9: ='By Round'!B3 | D9: ='By Round'!C3 | E9: ='By Round'!D3 | F9: =IF(ISBLANK('By Round'!F3),"",'By Round'!F3) | G9: =IF(ISBLANK('By Round'!G3),"",'By Round'!G3) | H9: =IF(ISBLANK('By Round'!H3),"",'By Round'!H3) | I9: =IF(ISBLANK('By Round'!I3),"",'By Round'!I3) | J9: =IF(ISBLANK('By Round'!J3),"",'By Round'!J3) | K9: =IF(ISBLANK('By Round'!K3),"",'By Round'!K3) | L9: =IF(ISBLANK('By Round'!L3),"",'By Round'!L3) | M9: =AVERAGE(AG9:AL9) | N9: =AVERAGE(AM9:AR9) | O9: =IF(COUNT(U9:Z9)>0,Q9/COUNT(U9:Z9),0.5) | P9: =IF(COUNT(AA9:AF9)>0,R9/COUNT(AA9:AF9),0.5) | Q9: =SUM(U9:Z9) | R9: =SUM(AA9:AF9) | S9: =IF(ISNUMBER(K9),K9,IF(ISNUMBER(L9),-L9,"")) | T9: =IF(ISNUMBER(L9),L9,IF(ISNUMBER(K9),-K9,"")) | U9: =IF(ISNUMBER(S9),IF(ISNUMBER(S3),IF(S9>S3,1.0,IF(S9=S3,0.5,0.0)),""),"") | V9: =IF(ISNUMBER(S9),IF(ISNUMBER(S4),IF(S9>S4,1.0,IF(S9=S4,0.5,0.0)),""),"") | W9: =IF(ISNUMBER(S9),IF(ISNUMBER(S5),IF(S9>S5,1.0,IF(S9=S5,0.5,0.0)),""),"") | X9: =IF(ISNUMBER(S9),IF(ISNUMBER(S6),IF(S9>S6,1.0,IF(S9=S6,0.5,0.0)),""),"") | Y9: =IF(ISNUMBER(S9),IF(ISNUMBER(S7),IF(S9>S7,1.0,IF(S9=S7,0.5,0.0)),""),"") | Z9: =IF(ISNUMBER(S9),IF(ISNUMBER(S8),IF(S9>S8,1.0,IF(S9=S8,0.5,0.0)),""),"") | AA9: =IF(ISNUMBER(T9),IF(ISNUMBER(T3),IF(T9>T3,1.0,IF(T9=T3,0.5,0.0)),""),"") | AB9: =IF(ISNUMBER(T9),IF(ISNUMBER(T4),IF(T9>T4,1.0,IF(T9=T4,0.5,0.0)),""),"") | AC9: =IF(ISNUMBER(T9),IF(ISNUMBER(T5),IF(T9>T5,1.0,IF(T9=T5,0.5,0.0)),""),"") | AD9: =IF(ISNUMBER(T9),IF(ISNUMBER(T6),IF(T9>T6,1.0,IF(T9=T6,0.5,0.0)),""),"") | AE9: =IF(ISNUMBER(T9),IF(ISNUMBER(T7),IF(T9>T7,1.0,IF(T9=T7,0.5,0.0)),""),"") | AF9: =IF(ISNUMBER(T9),IF(ISNUMBER(T8),IF(T9>T8,1.0,IF(T9=T8,0.5,0.0)),""),"") | AG9: =IF(AND(ISNUMBER(S9),ISNUMBER(S3)),VLOOKUP(ABS(S9-S3),'IMP Table'!$A$2:$C$26,3)*SIGN(S9-S3),0) | AH9: =IF(AND(ISNUMBER(S9),ISNUMBER(S4)),VLOOKUP(ABS(S9-S4),'IMP Table'!$A$2:$C$26,3)*SIGN(S9-S4),0) | AI9: =IF(AND(ISNUMBER(S9),ISNUMBER(S5)),VLOOKUP(ABS(S9-S5),'IMP Table'!$A$2:$C$26,3)*SIGN(S9-S5),0) | AJ9: =IF(AND(ISNUMBER(S9),ISNUMBER(S6)),VLOOKUP(ABS(S9-S6),'IMP Table'!$A$2:$C$26,3)*SIGN(S9-S6),0) | AK9: =IF(AND(ISNUMBER(S9),ISNUMBER(S7)),VLOOKUP(ABS(S9-S7),'IMP Table'!$A$2:$C$26,3)*SIGN(S9-S7),0) | AL9: =IF(AND(ISNUMBER(S9),ISNUMBER(S8)),VLOOKUP(ABS(S9-S8),'IMP Table'!$A$2:$C$26,3)*SIGN(S9-S8),0) | AM9: =IF(AND(ISNUMBER(T9),ISNUMBER(T3)),VLOOKUP(ABS(T9-T3),'IMP Table'!$A$2:$C$26,3)*SIGN(T9-T3),0) | AN9: =IF(AND(ISNUMBER(T9),ISNUMBER(T4)),VLOOKUP(ABS(T9-T4),'IMP Table'!$A$2:$C$26,3)*SIGN(T9-T4),0) | AO9: =IF(AND(ISNUMBER(T9),ISNUMBER(T5)),VLOOKUP(ABS(T9-T5),'IMP Table'!$A$2:$C$26,3)*SIGN(T9-T5),0) | AP9: =IF(AND(ISNUMBER(T9),ISNUMBER(T6)),VLOOKUP(ABS(T9-T6),'IMP Table'!$A$2:$C$26,3)*SIGN(T9-T6),0) | AQ9: =IF(AND(ISNUMBER(T9),ISNUMBER(T7)),VLOOKUP(ABS(T9-T7),'IMP Table'!$A$2:$C$26,3)*SIGN(T9-T7),0) | AR9: =IF(AND(ISNUMBER(T9),ISNUMBER(T8)),VLOOKUP(ABS(T9-T8),'IMP Table'!$A$2:$C$26,3)*SIGN(T9-T8),0)
A10: 2 | B10: ='By Round'!A157 | C10: ='By Round'!B159 | D10: ='By Round'!C159 | E10: ='By Round'!D159 | F10: =IF(ISBLANK('By Round'!F160),"",'By Round'!F160) | G10: =IF(ISBLANK('By Round'!G160),"",'By Round'!G160) | H10: =IF(ISBLANK('By Round'!H160),"",'By Round'!H160) | I10: =IF(ISBLANK('By Round'!I160),"",'By Round'!I160) | J10: =IF(ISBLANK('By Round'!J160),"",'By Round'!J160) | K10: =IF(ISBLANK('By Round'!K160),"",'By Round'!K160) | L10: =IF(ISBLANK('By Round'!L160),"",'By Round'!L160) | M10: =AVERAGE(AG10:AL10) | N10: =AVERAGE(AM10:AR10) | O10: =IF(COUNT(U10:Z10)>0,Q10/COUNT(U10:Z10),0.5) | P10: =IF(COUNT(AA10:AF10)>0,R10/COUNT(AA10:AF10),0.5) | Q10: =SUM(U10:Z10) | R10: =SUM(AA10:AF10) | S10: =IF(ISNUMBER(K10),K10,IF(ISNUMBER(L10),-L10,"")) | T10: =IF(ISNUMBER(L10),L10,IF(ISNUMBER(K10),-K10,"")) | U10: =IF(ISNUMBER(S10),IF(ISNUMBER(S11),IF(S10>S11,1.0,IF(S10=S11,0.5,0.0)),""),"") | V10: =IF(ISNUMBER(S10),IF(ISNUMBER(S12),IF(S10>S12,1.0,IF(S10=S12,0.5,0.0)),""),"") | W10: =IF(ISNUMBER(S10),IF(ISNUMBER(S13),IF(S10>S13,1.0,IF(S10=S13,0.5,0.0)),""),"") | X10: =IF(ISNUMBER(S10),IF(ISNUMBER(S14),IF(S10>S14,1.0,IF(S10=S14,0.5,0.0)),""),"") | Y10: =IF(ISNUMBER(S10),IF(ISNUMBER(S15),IF(S10>S15,1.0,IF(S10=S15,0.5,0.0)),""),"") | Z10: =IF(ISNUMBER(S10),IF(ISNUMBER(S16),IF(S10>S16,1.0,IF(S10=S16,0.5,0.0)),""),"") | AA10: =IF(ISNUMBER(T10),IF(ISNUMBER(T11),IF(T10>T11,1.0,IF(T10=T11,0.5,0.0)),""),"") | AB10: =IF(ISNUMBER(T10),IF(ISNUMBER(T12),IF(T10>T12,1.0,IF(T10=T12,0.5,0.0)),""),"") | AC10: =IF(ISNUMBER(T10),IF(ISNUMBER(T13),IF(T10>T13,1.0,IF(T10=T13,0.5,0.0)),""),"") | AD10: =IF(ISNUMBER(T10),IF(ISNUMBER(T14),IF(T10>T14,1.0,IF(T10=T14,0.5,0.0)),""),"") | AE10: =IF(ISNUMBER(T10),IF(ISNUMBER(T15),IF(T10>T15,1.0,IF(T10=T15,0.5,0.0)),""),"") | AF10: =IF(ISNUMBER(T10),IF(ISNUMBER(T16),IF(T10>T16,1.0,IF(T10=T16,0.5,0.0)),""),"") | AG10: =IF(AND(ISNUMBER(S10),ISNUMBER(S11)),VLOOKUP(ABS(S10-S11),'IMP Table'!$A$2:$C$26,3)*SIGN(S10-S11),0) | AH10: =IF(AND(ISNUMBER(S10),ISNUMBER(S12)),VLOOKUP(ABS(S10-S12),'IMP Table'!$A$2:$C$26,3)*SIGN(S10-S12),0) | AI10: =IF(AND(ISNUMBER(S10),ISNUMBER(S13)),VLOOKUP(ABS(S10-S13),'IMP Table'!$A$2:$C$26,3)*SIGN(S10-S13),0) | AJ10: =IF(AND(ISNUMBER(S10),ISNUMBER(S14)),VLOOKUP(ABS(S10-S14),'IMP Table'!$A$2:$C$26,3)*SIGN(S10-S14),0) | AK10: =IF(AND(ISNUMBER(S10),ISNUMBER(S15)),VLOOKUP(ABS(S10-S15),'IMP Table'!$A$2:$C$26,3)*SIGN(S10-S15),0) | AL10: =IF(AND(ISNUMBER(S10),ISNUMBER(S16)),VLOOKUP(ABS(S10-S16),'IMP Table'!$A$2:$C$26,3)*SIGN(S10-S16),0) | AM10: =IF(AND(ISNUMBER(T10),ISNUMBER(T11)),VLOOKUP(ABS(T10-T11),'IMP Table'!$A$2:$C$26,3)*SIGN(T10-T11),0) | AN10: =IF(AND(ISNUMBER(T10),ISNUMBER(T12)),VLOOKUP(ABS(T10-T12),'IMP Table'!$A$2:$C$26,3)*SIGN(T10-T12),0) | AO10: =IF(AND(ISNUMBER(T10),ISNUMBER(T13)),VLOOKUP(ABS(T10-T13),'IMP Table'!$A$2:$C$26,3)*SIGN(T10-T13),0) | AP10: =IF(AND(ISNUMBER(T10),ISNUMBER(T14)),VLOOKUP(ABS(T10-T14),'IMP Table'!$A$2:$C$26,3)*SIGN(T10-T14),0) | AQ10: =IF(AND(ISNUMBER(T10),ISNUMBER(T15)),VLOOKUP(ABS(T10-T15),'IMP Table'!$A$2:$C$26,3)*SIGN(T10-T15),0) | AR10: =IF(AND(ISNUMBER(T10),ISNUMBER(T16)),VLOOKUP(ABS(T10-T16),'IMP Table'!$A$2:$C$26,3)*SIGN(T10-T16),0)
B11: ='By Round'!A129 | C11: ='By Round'!B135 | D11: ='By Round'!C135 | E11: ='By Round'!D135 | F11: =IF(ISBLANK('By Round'!F136),"",'By Round'!F136) | G11: =IF(ISBLANK('By Round'!G136),"",'By Round'!G136) | H11: =IF(ISBLANK('By Round'!H136),"",'By Round'!H136) | I11: =IF(ISBLANK('By Round'!I136),"",'By Round'!I136) | J11: =IF(ISBLANK('By Round'!J136),"",'By Round'!J136) | K11: =IF(ISBLANK('By Round'!K136),"",'By Round'!K136) | L11: =IF(ISBLANK('By Round'!L136),"",'By Round'!L136) | M11: =AVERAGE(AG11:AL11) | N11: =AVERAGE(AM11:AR11) | O11: =IF(COUNT(U11:Z11)>0,Q11/COUNT(U11:Z11),0.5) | P11: =IF(COUNT(AA11:AF11)>0,R11/COUNT(AA11:AF11),0.5) | Q11: =SUM(U11:Z11) | R11: =SUM(AA11:AF11) | S11: =IF(ISNUMBER(K11),K11,IF(ISNUMBER(L11),-L11,"")) | T11: =IF(ISNUMBER(L11),L11,IF(ISNUMBER(K11),-K11,"")) | U11: =IF(ISNUMBER(S11),IF(ISNUMBER(S10),IF(S11>S10,1.0,IF(S11=S10,0.5,0.0)),""),"") | V11: =IF(ISNUMBER(S11),IF(ISNUMBER(S12),IF(S11>S12,1.0,IF(S11=S12,0.5,0.0)),""),"") | W11: =IF(ISNUMBER(S11),IF(ISNUMBER(S13),IF(S11>S13,1.0,IF(S11=S13,0.5,0.0)),""),"") | X11: =IF(ISNUMBER(S11),IF(ISNUMBER(S14),IF(S11>S14,1.0,IF(S11=S14,0.5,0.0)),""),"") | Y11: =IF(ISNUMBER(S11),IF(ISNUMBER(S15),IF(S11>S15,1.0,IF(S11=S15,0.5,0.0)),""),"") | Z11: =IF(ISNUMBER(S11),IF(ISNUMBER(S16),IF(S11>S16,1.0,IF(S11=S16,0.5,0.0)),""),"") | AA11: =IF(ISNUMBER(T11),IF(ISNUMBER(T10),IF(T11>T10,1.0,IF(T11=T10,0.5,0.0)),""),"") | AB11: =IF(ISNUMBER(T11),IF(ISNUMBER(T12),IF(T11>T12,1.0,IF(T11=T12,0.5,0.0)),""),"") | AC11: =IF(ISNUMBER(T11),IF(ISNUMBER(T13),IF(T11>T13,1.0,IF(T11=T13,0.5,0.0)),""),"") | AD11: =IF(ISNUMBER(T11),IF(ISNUMBER(T14),IF(T11>T14,1.0,IF(T11=T14,0.5,0.0)),""),"") | AE11: =IF(ISNUMBER(T11),IF(ISNUMBER(T15),IF(T11>T15,1.0,IF(T11=T15,0.5,0.0)),""),"") | AF11: =IF(ISNUMBER(T11),IF(ISNUMBER(T16),IF(T11>T16,1.0,IF(T11=T16,0.5,0.0)),""),"") | AG11: =IF(AND(ISNUMBER(S11),ISNUMBER(S10)),VLOOKUP(ABS(S11-S10),'IMP Table'!$A$2:$C$26,3)*SIGN(S11-S10),0) | AH11: =IF(AND(ISNUMBER(S11),ISNUMBER(S12)),VLOOKUP(ABS(S11-S12),'IMP Table'!$A$2:$C$26,3)*SIGN(S11-S12),0) | AI11: =IF(AND(ISNUMBER(S11),ISNUMBER(S13)),VLOOKUP(ABS(S11-S13),'IMP Table'!$A$2:$C$26,3)*SIGN(S11-S13),0) | AJ11: =IF(AND(ISNUMBER(S11),ISNUMBER(S14)),VLOOKUP(ABS(S11-S14),'IMP Table'!$A$2:$C$26,3)*SIGN(S11-S14),0) | AK11: =IF(AND(ISNUMBER(S11),ISNUMBER(S15)),VLOOKUP(ABS(S11-S15),'IMP Table'!$A$2:$C$26,3)*SIGN(S11-S15),0) | AL11: =IF(AND(ISNUMBER(S11),ISNUMBER(S16)),VLOOKUP(ABS(S11-S16),'IMP Table'!$A$2:$C$26,3)*SIGN(S11-S16),0) | AM11: =IF(AND(ISNUMBER(T11),ISNUMBER(T10)),VLOOKUP(ABS(T11-T10),'IMP Table'!$A$2:$C$26,3)*SIGN(T11-T10),0) | AN11: =IF(AND(ISNUMBER(T11),ISNUMBER(T12)),VLOOKUP(ABS(T11-T12),'IMP Table'!$A$2:$C$26,3)*SIGN(T11-T12),0) | AO11: =IF(AND(ISNUMBER(T11),ISNUMBER(T13)),VLOOKUP(ABS(T11-T13),'IMP Table'!$A$2:$C$26,3)*SIGN(T11-T13),0) | AP11: =IF(AND(ISNUMBER(T11),ISNUMBER(T14)),VLOOKUP(ABS(T11-T14),'IMP Table'!$A$2:$C$26,3)*SIGN(T11-T14),0) | AQ11: =IF(AND(ISNUMBER(T11),ISNUMBER(T15)),VLOOKUP(ABS(T11-T15),'IMP Table'!$A$2:$C$26,3)*SIGN(T11-T15),0) | AR11: =IF(AND(ISNUMBER(T11),ISNUMBER(T16)),VLOOKUP(ABS(T11-T16),'IMP Table'!$A$2:$C$26,3)*SIGN(T11-T16),0)
B12: ='By Round'!A31 | C12: ='By Round'!B43 | D12: ='By Round'!C43 | E12: ='By Round'!D43 | F12: =IF(ISBLANK('By Round'!F44),"",'By Round'!F44) | G12: =IF(ISBLANK('By Round'!G44),"",'By Round'!G44) | H12: =IF(ISBLANK('By Round'!H44),"",'By Round'!H44) | I12: =IF(ISBLANK('By Round'!I44),"",'By Round'!I44) | J12: =IF(ISBLANK('By Round'!J44),"",'By Round'!J44) | K12: =IF(ISBLANK('By Round'!K44),"",'By Round'!K44) | L12: =IF(ISBLANK('By Round'!L44),"",'By Round'!L44) | M12: =AVERAGE(AG12:AL12) | N12: =AVERAGE(AM12:AR12) | O12: =IF(COUNT(U12:Z12)>0,Q12/COUNT(U12:Z12),0.5) | P12: =IF(COUNT(AA12:AF12)>0,R12/COUNT(AA12:AF12),0.5) | Q12: =SUM(U12:Z12) | R12: =SUM(AA12:AF12) | S12: =IF(ISNUMBER(K12),K12,IF(ISNUMBER(L12),-L12,"")) | T12: =IF(ISNUMBER(L12),L12,IF(ISNUMBER(K12),-K12,"")) | U12: =IF(ISNUMBER(S12),IF(ISNUMBER(S10),IF(S12>S10,1.0,IF(S12=S10,0.5,0.0)),""),"") | V12: =IF(ISNUMBER(S12),IF(ISNUMBER(S11),IF(S12>S11,1.0,IF(S12=S11,0.5,0.0)),""),"") | W12: =IF(ISNUMBER(S12),IF(ISNUMBER(S13),IF(S12>S13,1.0,IF(S12=S13,0.5,0.0)),""),"") | X12: =IF(ISNUMBER(S12),IF(ISNUMBER(S14),IF(S12>S14,1.0,IF(S12=S14,0.5,0.0)),""),"") | Y12: =IF(ISNUMBER(S12),IF(ISNUMBER(S15),IF(S12>S15,1.0,IF(S12=S15,0.5,0.0)),""),"") | Z12: =IF(ISNUMBER(S12),IF(ISNUMBER(S16),IF(S12>S16,1.0,IF(S12=S16,0.5,0.0)),""),"") | AA12: =IF(ISNUMBER(T12),IF(ISNUMBER(T10),IF(T12>T10,1.0,IF(T12=T10,0.5,0.0)),""),"") | AB12: =IF(ISNUMBER(T12),IF(ISNUMBER(T11),IF(T12>T11,1.0,IF(T12=T11,0.5,0.0)),""),"") | AC12: =IF(ISNUMBER(T12),IF(ISNUMBER(T13),IF(T12>T13,1.0,IF(T12=T13,0.5,0.0)),""),"") | AD12: =IF(ISNUMBER(T12),IF(ISNUMBER(T14),IF(T12>T14,1.0,IF(T12=T14,0.5,0.0)),""),"") | AE12: =IF(ISNUMBER(T12),IF(ISNUMBER(T15),IF(T12>T15,1.0,IF(T12=T15,0.5,0.0)),""),"") | AF12: =IF(ISNUMBER(T12),IF(ISNUMBER(T16),IF(T12>T16,1.0,IF(T12=T16,0.5,0.0)),""),"") | AG12: =IF(AND(ISNUMBER(S12),ISNUMBER(S10)),VLOOKUP(ABS(S12-S10),'IMP Table'!$A$2:$C$26,3)*SIGN(S12-S10),0) | AH12: =IF(AND(ISNUMBER(S12),ISNUMBER(S11)),VLOOKUP(ABS(S12-S11),'IMP Table'!$A$2:$C$26,3)*SIGN(S12-S11),0) | AI12: =IF(AND(ISNUMBER(S12),ISNUMBER(S13)),VLOOKUP(ABS(S12-S13),'IMP Table'!$A$2:$C$26,3)*SIGN(S12-S13),0) | AJ12: =IF(AND(ISNUMBER(S12),ISNUMBER(S14)),VLOOKUP(ABS(S12-S14),'IMP Table'!$A$2:$C$26,3)*SIGN(S12-S14),0) | AK12: =IF(AND(ISNUMBER(S12),ISNUMBER(S15)),VLOOKUP(ABS(S12-S15),'IMP Table'!$A$2:$C$26,3)*SIGN(S12-S15),0) | AL12: =IF(AND(ISNUMBER(S12),ISNUMBER(S16)),VLOOKUP(ABS(S12-S16),'IMP Table'!$A$2:$C$26,3)*SIGN(S12-S16),0) | AM12: =IF(AND(ISNUMBER(T12),ISNUMBER(T10)),VLOOKUP(ABS(T12-T10),'IMP Table'!$A$2:$C$26,3)*SIGN(T12-T10),0) | AN12: =IF(AND(ISNUMBER(T12),ISNUMBER(T11)),VLOOKUP(ABS(T12-T11),'IMP Table'!$A$2:$C$26,3)*SIGN(T12-T11),0) | AO12: =IF(AND(ISNUMBER(T12),ISNUMBER(T13)),VLOOKUP(ABS(T12-T13),'IMP Table'!$A$2:$C$26,3)*SIGN(T12-T13),0) | AP12: =IF(AND(ISNUMBER(T12),ISNUMBER(T14)),VLOOKUP(ABS(T12-T14),'IMP Table'!$A$2:$C$26,3)*SIGN(T12-T14),0) | AQ12: =IF(AND(ISNUMBER(T12),ISNUMBER(T15)),VLOOKUP(ABS(T12-T15),'IMP Table'!$A$2:$C$26,3)*SIGN(T12-T15),0) | AR12: =IF(AND(ISNUMBER(T12),ISNUMBER(T16)),VLOOKUP(ABS(T12-T16),'IMP Table'!$A$2:$C$26,3)*SIGN(T12-T16),0)
B13: ='By Round'!A59 | C13: ='By Round'!B67 | D13: ='By Round'!C67 | E13: ='By Round'!D67 | F13: =IF(ISBLANK('By Round'!F68),"",'By Round'!F68) | G13: =IF(ISBLANK('By Round'!G68),"",'By Round'!G68) | H13: =IF(ISBLANK('By Round'!H68),"",'By Round'!H68) | I13: =IF(ISBLANK('By Round'!I68),"",'By Round'!I68) | J13: =IF(ISBLANK('By Round'!J68),"",'By Round'!J68) | K13: =IF(ISBLANK('By Round'!K68),"",'By Round'!K68) | L13: =IF(ISBLANK('By Round'!L68),"",'By Round'!L68) | M13: =AVERAGE(AG13:AL13) | N13: =AVERAGE(AM13:AR13) | O13: =IF(COUNT(U13:Z13)>0,Q13/COUNT(U13:Z13),0.5) | P13: =IF(COUNT(AA13:AF13)>0,R13/COUNT(AA13:AF13),0.5) | Q13: =SUM(U13:Z13) | R13: =SUM(AA13:AF13) | S13: =IF(ISNUMBER(K13),K13,IF(ISNUMBER(L13),-L13,"")) | T13: =IF(ISNUMBER(L13),L13,IF(ISNUMBER(K13),-K13,"")) | U13: =IF(ISNUMBER(S13),IF(ISNUMBER(S10),IF(S13>S10,1.0,IF(S13=S10,0.5,0.0)),""),"") | V13: =IF(ISNUMBER(S13),IF(ISNUMBER(S11),IF(S13>S11,1.0,IF(S13=S11,0.5,0.0)),""),"") | W13: =IF(ISNUMBER(S13),IF(ISNUMBER(S12),IF(S13>S12,1.0,IF(S13=S12,0.5,0.0)),""),"") | X13: =IF(ISNUMBER(S13),IF(ISNUMBER(S14),IF(S13>S14,1.0,IF(S13=S14,0.5,0.0)),""),"") | Y13: =IF(ISNUMBER(S13),IF(ISNUMBER(S15),IF(S13>S15,1.0,IF(S13=S15,0.5,0.0)),""),"") | Z13: =IF(ISNUMBER(S13),IF(ISNUMBER(S16),IF(S13>S16,1.0,IF(S13=S16,0.5,0.0)),""),"") | AA13: =IF(ISNUMBER(T13),IF(ISNUMBER(T10),IF(T13>T10,1.0,IF(T13=T10,0.5,0.0)),""),"") | AB13: =IF(ISNUMBER(T13),IF(ISNUMBER(T11),IF(T13>T11,1.0,IF(T13=T11,0.5,0.0)),""),"") | AC13: =IF(ISNUMBER(T13),IF(ISNUMBER(T12),IF(T13>T12,1.0,IF(T13=T12,0.5,0.0)),""),"") | AD13: =IF(ISNUMBER(T13),IF(ISNUMBER(T14),IF(T13>T14,1.0,IF(T13=T14,0.5,0.0)),""),"") | AE13: =IF(ISNUMBER(T13),IF(ISNUMBER(T15),IF(T13>T15,1.0,IF(T13=T15,0.5,0.0)),""),"") | AF13: =IF(ISNUMBER(T13),IF(ISNUMBER(T16),IF(T13>T16,1.0,IF(T13=T16,0.5,0.0)),""),"") | AG13: =IF(AND(ISNUMBER(S13),ISNUMBER(S10)),VLOOKUP(ABS(S13-S10),'IMP Table'!$A$2:$C$26,3)*SIGN(S13-S10),0) | AH13: =IF(AND(ISNUMBER(S13),ISNUMBER(S11)),VLOOKUP(ABS(S13-S11),'IMP Table'!$A$2:$C$26,3)*SIGN(S13-S11),0) | AI13: =IF(AND(ISNUMBER(S13),ISNUMBER(S12)),VLOOKUP(ABS(S13-S12),'IMP Table'!$A$2:$C$26,3)*SIGN(S13-S12),0) | AJ13: =IF(AND(ISNUMBER(S13),ISNUMBER(S14)),VLOOKUP(ABS(S13-S14),'IMP Table'!$A$2:$C$26,3)*SIGN(S13-S14),0) | AK13: =IF(AND(ISNUMBER(S13),ISNUMBER(S15)),VLOOKUP(ABS(S13-S15),'IMP Table'!$A$2:$C$26,3)*SIGN(S13-S15),0) | AL13: =IF(AND(ISNUMBER(S13),ISNUMBER(S16)),VLOOKUP(ABS(S13-S16),'IMP Table'!$A$2:$C$26,3)*SIGN(S13-S16),0) | AM13: =IF(AND(ISNUMBER(T13),ISNUMBER(T10)),VLOOKUP(ABS(T13-T10),'IMP Table'!$A$2:$C$26,3)*SIGN(T13-T10),0) | AN13: =IF(AND(ISNUMBER(T13),ISNUMBER(T11)),VLOOKUP(ABS(T13-T11),'IMP Table'!$A$2:$C$26,3)*SIGN(T13-T11),0) | AO13: =IF(AND(ISNUMBER(T13),ISNUMBER(T12)),VLOOKUP(ABS(T13-T12),'IMP Table'!$A$2:$C$26,3)*SIGN(T13-T12),0) | AP13: =IF(AND(ISNUMBER(T13),ISNUMBER(T14)),VLOOKUP(ABS(T13-T14),'IMP Table'!$A$2:$C$26,3)*SIGN(T13-T14),0) | AQ13: =IF(AND(ISNUMBER(T13),ISNUMBER(T15)),VLOOKUP(ABS(T13-T15),'IMP Table'!$A$2:$C$26,3)*SIGN(T13-T15),0) | AR13: =IF(AND(ISNUMBER(T13),ISNUMBER(T16)),VLOOKUP(ABS(T13-T16),'IMP Table'!$A$2:$C$26,3)*SIGN(T13-T16),0)
B14: ='By Round'!A45 | C14: ='By Round'!B55 | D14: ='By Round'!C55 | E14: ='By Round'!D55 | F14: =IF(ISBLANK('By Round'!F56),"",'By Round'!F56) | G14: =IF(ISBLANK('By Round'!G56),"",'By Round'!G56) | H14: =IF(ISBLANK('By Round'!H56),"",'By Round'!H56) | I14: =IF(ISBLANK('By Round'!I56),"",'By Round'!I56) | J14: =IF(ISBLANK('By Round'!J56),"",'By Round'!J56) | K14: =IF(ISBLANK('By Round'!K56),"",'By Round'!K56) | L14: =IF(ISBLANK('By Round'!L56),"",'By Round'!L56) | M14: =AVERAGE(AG14:AL14) | N14: =AVERAGE(AM14:AR14) | O14: =IF(COUNT(U14:Z14)>0,Q14/COUNT(U14:Z14),0.5) | P14: =IF(COUNT(AA14:AF14)>0,R14/COUNT(AA14:AF14),0.5) | Q14: =SUM(U14:Z14) | R14: =SUM(AA14:AF14) | S14: =IF(ISNUMBER(K14),K14,IF(ISNUMBER(L14),-L14,"")) | T14: =IF(ISNUMBER(L14),L14,IF(ISNUMBER(K14),-K14,"")) | U14: =IF(ISNUMBER(S14),IF(ISNUMBER(S10),IF(S14>S10,1.0,IF(S14=S10,0.5,0.0)),""),"") | V14: =IF(ISNUMBER(S14),IF(ISNUMBER(S11),IF(S14>S11,1.0,IF(S14=S11,0.5,0.0)),""),"") | W14: =IF(ISNUMBER(S14),IF(ISNUMBER(S12),IF(S14>S12,1.0,IF(S14=S12,0.5,0.0)),""),"") | X14: =IF(ISNUMBER(S14),IF(ISNUMBER(S13),IF(S14>S13,1.0,IF(S14=S13,0.5,0.0)),""),"") | Y14: =IF(ISNUMBER(S14),IF(ISNUMBER(S15),IF(S14>S15,1.0,IF(S14=S15,0.5,0.0)),""),"") | Z14: =IF(ISNUMBER(S14),IF(ISNUMBER(S16),IF(S14>S16,1.0,IF(S14=S16,0.5,0.0)),""),"") | AA14: =IF(ISNUMBER(T14),IF(ISNUMBER(T10),IF(T14>T10,1.0,IF(T14=T10,0.5,0.0)),""),"") | AB14: =IF(ISNUMBER(T14),IF(ISNUMBER(T11),IF(T14>T11,1.0,IF(T14=T11,0.5,0.0)),""),"") | AC14: =IF(ISNUMBER(T14),IF(ISNUMBER(T12),IF(T14>T12,1.0,IF(T14=T12,0.5,0.0)),""),"") | AD14: =IF(ISNUMBER(T14),IF(ISNUMBER(T13),IF(T14>T13,1.0,IF(T14=T13,0.5,0.0)),""),"") | AE14: =IF(ISNUMBER(T14),IF(ISNUMBER(T15),IF(T14>T15,1.0,IF(T14=T15,0.5,0.0)),""),"") | AF14: =IF(ISNUMBER(T14),IF(ISNUMBER(T16),IF(T14>T16,1.0,IF(T14=T16,0.5,0.0)),""),"") | AG14: =IF(AND(ISNUMBER(S14),ISNUMBER(S10)),VLOOKUP(ABS(S14-S10),'IMP Table'!$A$2:$C$26,3)*SIGN(S14-S10),0) | AH14: =IF(AND(ISNUMBER(S14),ISNUMBER(S11)),VLOOKUP(ABS(S14-S11),'IMP Table'!$A$2:$C$26,3)*SIGN(S14-S11),0) | AI14: =IF(AND(ISNUMBER(S14),ISNUMBER(S12)),VLOOKUP(ABS(S14-S12),'IMP Table'!$A$2:$C$26,3)*SIGN(S14-S12),0) | AJ14: =IF(AND(ISNUMBER(S14),ISNUMBER(S13)),VLOOKUP(ABS(S14-S13),'IMP Table'!$A$2:$C$26,3)*SIGN(S14-S13),0) | AK14: =IF(AND(ISNUMBER(S14),ISNUMBER(S15)),VLOOKUP(ABS(S14-S15),'IMP Table'!$A$2:$C$26,3)*SIGN(S14-S15),0) | AL14: =IF(AND(ISNUMBER(S14),ISNUMBER(S16)),VLOOKUP(ABS(S14-S16),'IMP Table'!$A$2:$C$26,3)*SIGN(S14-S16),0) | AM14: =IF(AND(ISNUMBER(T14),ISNUMBER(T10)),VLOOKUP(ABS(T14-T10),'IMP Table'!$A$2:$C$26,3)*SIGN(T14-T10),0) | AN14: =IF(AND(ISNUMBER(T14),ISNUMBER(T11)),VLOOKUP(ABS(T14-T11),'IMP Table'!$A$2:$C$26,3)*SIGN(T14-T11),0) | AO14: =IF(AND(ISNUMBER(T14),ISNUMBER(T12)),VLOOKUP(ABS(T14-T12),'IMP Table'!$A$2:$C$26,3)*SIGN(T14-T12),0) | AP14: =IF(AND(ISNUMBER(T14),ISNUMBER(T13)),VLOOKUP(ABS(T14-T13),'IMP Table'!$A$2:$C$26,3)*SIGN(T14-T13),0) | AQ14: =IF(AND(ISNUMBER(T14),ISNUMBER(T15)),VLOOKUP(ABS(T14-T15),'IMP Table'!$A$2:$C$26,3)*SIGN(T14-T15),0) | AR14: =IF(AND(ISNUMBER(T14),ISNUMBER(T16)),VLOOKUP(ABS(T14-T16),'IMP Table'!$A$2:$C$26,3)*SIGN(T14-T16),0)
B15: ='By Round'!A143 | C15: ='By Round'!B147 | D15: ='By Round'!C147 | E15: ='By Round'!D147 | F15: =IF(ISBLANK('By Round'!F148),"",'By Round'!F148) | G15: =IF(ISBLANK('By Round'!G148),"",'By Round'!G148) | H15: =IF(ISBLANK('By Round'!H148),"",'By Round'!H148) | I15: =IF(ISBLANK('By Round'!I148),"",'By Round'!I148) | J15: =IF(ISBLANK('By Round'!J148),"",'By Round'!J148) | K15: =IF(ISBLANK('By Round'!K148),"",'By Round'!K148) | L15: =IF(ISBLANK('By Round'!L148),"",'By Round'!L148) | M15: =AVERAGE(AG15:AL15) | N15: =AVERAGE(AM15:AR15) | O15: =IF(COUNT(U15:Z15)>0,Q15/COUNT(U15:Z15),0.5) | P15: =IF(COUNT(AA15:AF15)>0,R15/COUNT(AA15:AF15),0.5) | Q15: =SUM(U15:Z15) | R15: =SUM(AA15:AF15) | S15: =IF(ISNUMBER(K15),K15,IF(ISNUMBER(L15),-L15,"")) | T15: =IF(ISNUMBER(L15),L15,IF(ISNUMBER(K15),-K15,"")) | U15: =IF(ISNUMBER(S15),IF(ISNUMBER(S10),IF(S15>S10,1.0,IF(S15=S10,0.5,0.0)),""),"") | V15: =IF(ISNUMBER(S15),IF(ISNUMBER(S11),IF(S15>S11,1.0,IF(S15=S11,0.5,0.0)),""),"") | W15: =IF(ISNUMBER(S15),IF(ISNUMBER(S12),IF(S15>S12,1.0,IF(S15=S12,0.5,0.0)),""),"") | X15: =IF(ISNUMBER(S15),IF(ISNUMBER(S13),IF(S15>S13,1.0,IF(S15=S13,0.5,0.0)),""),"") | Y15: =IF(ISNUMBER(S15),IF(ISNUMBER(S14),IF(S15>S14,1.0,IF(S15=S14,0.5,0.0)),""),"") | Z15: =IF(ISNUMBER(S15),IF(ISNUMBER(S16),IF(S15>S16,1.0,IF(S15=S16,0.5,0.0)),""),"") | AA15: =IF(ISNUMBER(T15),IF(ISNUMBER(T10),IF(T15>T10,1.0,IF(T15=T10,0.5,0.0)),""),"") | AB15: =IF(ISNUMBER(T15),IF(ISNUMBER(T11),IF(T15>T11,1.0,IF(T15=T11,0.5,0.0)),""),"") | AC15: =IF(ISNUMBER(T15),IF(ISNUMBER(T12),IF(T15>T12,1.0,IF(T15=T12,0.5,0.0)),""),"") | AD15: =IF(ISNUMBER(T15),IF(ISNUMBER(T13),IF(T15>T13,1.0,IF(T15=T13,0.5,0.0)),""),"") | AE15: =IF(ISNUMBER(T15),IF(ISNUMBER(T14),IF(T15>T14,1.0,IF(T15=T14,0.5,0.0)),""),"") | AF15: =IF(ISNUMBER(T15),IF(ISNUMBER(T16),IF(T15>T16,1.0,IF(T15=T16,0.5,0.0)),""),"") | AG15: =IF(AND(ISNUMBER(S15),ISNUMBER(S10)),VLOOKUP(ABS(S15-S10),'IMP Table'!$A$2:$C$26,3)*SIGN(S15-S10),0) | AH15: =IF(AND(ISNUMBER(S15),ISNUMBER(S11)),VLOOKUP(ABS(S15-S11),'IMP Table'!$A$2:$C$26,3)*SIGN(S15-S11),0) | AI15: =IF(AND(ISNUMBER(S15),ISNUMBER(S12)),VLOOKUP(ABS(S15-S12),'IMP Table'!$A$2:$C$26,3)*SIGN(S15-S12),0) | AJ15: =IF(AND(ISNUMBER(S15),ISNUMBER(S13)),VLOOKUP(ABS(S15-S13),'IMP Table'!$A$2:$C$26,3)*SIGN(S15-S13),0) | AK15: =IF(AND(ISNUMBER(S15),ISNUMBER(S14)),VLOOKUP(ABS(S15-S14),'IMP Table'!$A$2:$C$26,3)*SIGN(S15-S14),0) | AL15: =IF(AND(ISNUMBER(S15),ISNUMBER(S16)),VLOOKUP(ABS(S15-S16),'IMP Table'!$A$2:$C$26,3)*SIGN(S15-S16),0) | AM15: =IF(AND(ISNUMBER(T15),ISNUMBER(T10)),VLOOKUP(ABS(T15-T10),'IMP Table'!$A$2:$C$26,3)*SIGN(T15-T10),0) | AN15: =IF(AND(ISNUMBER(T15),ISNUMBER(T11)),VLOOKUP(ABS(T15-T11),'IMP Table'!$A$2:$C$26,3)*SIGN(T15-T11),0) | AO15: =IF(AND(ISNUMBER(T15),ISNUMBER(T12)),VLOOKUP(ABS(T15-T12),'IMP Table'!$A$2:$C$26,3)*SIGN(T15-T12),0) | AP15: =IF(AND(ISNUMBER(T15),ISNUMBER(T13)),VLOOKUP(ABS(T15-T13),'IMP Table'!$A$2:$C$26,3)*SIGN(T15-T13),0) | AQ15: =IF(AND(ISNUMBER(T15),ISNUMBER(T14)),VLOOKUP(ABS(T15-T14),'IMP Table'!$A$2:$C$26,3)*SIGN(T15-T14),0) | AR15: =IF(AND(ISNUMBER(T15),ISNUMBER(T16)),VLOOKUP(ABS(T15-T16),'IMP Table'!$A$2:$C$26,3)*SIGN(T15-T16),0)
B16: ='By Round'!A3 | C16: ='By Round'!B3 | D16: ='By Round'!C3 | E16: ='By Round'!D3 | F16: =IF(ISBLANK('By Round'!F4),"",'By Round'!F4) | G16: =IF(ISBLANK('By Round'!G4),"",'By Round'!G4) | H16: =IF(ISBLANK('By Round'!H4),"",'By Round'!H4) | I16: =IF(ISBLANK('By Round'!I4),"",'By Round'!I4) | J16: =IF(ISBLANK('By Round'!J4),"",'By Round'!J4) | K16: =IF(ISBLANK('By Round'!K4),"",'By Round'!K4) | L16: =IF(ISBLANK('By Round'!L4),"",'By Round'!L4) | M16: =AVERAGE(AG16:AL16) | N16: =AVERAGE(AM16:AR16) | O16: =IF(COUNT(U16:Z16)>0,Q16/COUNT(U16:Z16),0.5) | P16: =IF(COUNT(AA16:AF16)>0,R16/COUNT(AA16:AF16),0.5) | Q16: =SUM(U16:Z16) | R16: =SUM(AA16:AF16) | S16: =IF(ISNUMBER(K16),K16,IF(ISNUMBER(L16),-L16,"")) | T16: =IF(ISNUMBER(L16),L16,IF(ISNUMBER(K16),-K16,"")) | U16: =IF(ISNUMBER(S16),IF(ISNUMBER(S10),IF(S16>S10,1.0,IF(S16=S10,0.5,0.0)),""),"") | V16: =IF(ISNUMBER(S16),IF(ISNUMBER(S11),IF(S16>S11,1.0,IF(S16=S11,0.5,0.0)),""),"") | W16: =IF(ISNUMBER(S16),IF(ISNUMBER(S12),IF(S16>S12,1.0,IF(S16=S12,0.5,0.0)),""),"") | X16: =IF(ISNUMBER(S16),IF(ISNUMBER(S13),IF(S16>S13,1.0,IF(S16=S13,0.5,0.0)),""),"") | Y16: =IF(ISNUMBER(S16),IF(ISNUMBER(S14),IF(S16>S14,1.0,IF(S16=S14,0.5,0.0)),""),"") | Z16: =IF(ISNUMBER(S16),IF(ISNUMBER(S15),IF(S16>S15,1.0,IF(S16=S15,0.5,0.0)),""),"") | AA16: =IF(ISNUMBER(T16),IF(ISNUMBER(T10),IF(T16>T10,1.0,IF(T16=T10,0.5,0.0)),""),"") | AB16: =IF(ISNUMBER(T16),IF(ISNUMBER(T11),IF(T16>T11,1.0,IF(T16=T11,0.5,0.0)),""),"") | AC16: =IF(ISNUMBER(T16),IF(ISNUMBER(T12),IF(T16>T12,1.0,IF(T16=T12,0.5,0.0)),""),"") | AD16: =IF(ISNUMBER(T16),IF(ISNUMBER(T13),IF(T16>T13,1.0,IF(T16=T13,0.5,0.0)),""),"") | AE16: =IF(ISNUMBER(T16),IF(ISNUMBER(T14),IF(T16>T14,1.0,IF(T16=T14,0.5,0.0)),""),"") | AF16: =IF(ISNUMBER(T16),IF(ISNUMBER(T15),IF(T16>T15,1.0,IF(T16=T15,0.5,0.0)),""),"") | AG16: =IF(AND(ISNUMBER(S16),ISNUMBER(S10)),VLOOKUP(ABS(S16-S10),'IMP Table'!$A$2:$C$26,3)*SIGN(S16-S10),0) | AH16: =IF(AND(ISNUMBER(S16),ISNUMBER(S11)),VLOOKUP(ABS(S16-S11),'IMP Table'!$A$2:$C$26,3)*SIGN(S16-S11),0) | AI16: =IF(AND(ISNUMBER(S16),ISNUMBER(S12)),VLOOKUP(ABS(S16-S12),'IMP Table'!$A$2:$C$26,3)*SIGN(S16-S12),0) | AJ16: =IF(AND(ISNUMBER(S16),ISNUMBER(S13)),VLOOKUP(ABS(S16-S13),'IMP Table'!$A$2:$C$26,3)*SIGN(S16-S13),0) | AK16: =IF(AND(ISNUMBER(S16),ISNUMBER(S14)),VLOOKUP(ABS(S16-S14),'IMP Table'!$A$2:$C$26,3)*SIGN(S16-S14),0) | AL16: =IF(AND(ISNUMBER(S16),ISNUMBER(S15)),VLOOKUP(ABS(S16-S15),'IMP Table'!$A$2:$C$26,3)*SIGN(S16-S15),0) | AM16: =IF(AND(ISNUMBER(T16),ISNUMBER(T10)),VLOOKUP(ABS(T16-T10),'IMP Table'!$A$2:$C$26,3)*SIGN(T16-T10),0) | AN16: =IF(AND(ISNUMBER(T16),ISNUMBER(T11)),VLOOKUP(ABS(T16-T11),'IMP Table'!$A$2:$C$26,3)*SIGN(T16-T11),0) | AO16: =IF(AND(ISNUMBER(T16),ISNUMBER(T12)),VLOOKUP(ABS(T16-T12),'IMP Table'!$A$2:$C$26,3)*SIGN(T16-T12),0) | AP16: =IF(AND(ISNUMBER(T16),ISNUMBER(T13)),VLOOKUP(ABS(T16-T13),'IMP Table'!$A$2:$C$26,3)*SIGN(T16-T13),0) | AQ16: =IF(AND(ISNUMBER(T16),ISNUMBER(T14)),VLOOKUP(ABS(T16-T14),'IMP Table'!$A$2:$C$26,3)*SIGN(T16-T14),0) | AR16: =IF(AND(ISNUMBER(T16),ISNUMBER(T15)),VLOOKUP(ABS(T16-T15),'IMP Table'!$A$2:$C$26,3)*SIGN(T16-T15),0)
A17: 3 | B17: ='By Round'!A171 | C17: ='By Round'!B173 | D17: ='By Round'!C173 | E17: ='By Round'!D173 | F17: =IF(ISBLANK('By Round'!F173),"",'By Round'!F173) | G17: =IF(ISBLANK('By Round'!G173),"",'By Round'!G173) | H17: =IF(ISBLANK('By Round'!H173),"",'By Round'!H173) | I17: =IF(ISBLANK('By Round'!I173),"",'By Round'!I173) | J17: =IF(ISBLANK('By Round'!J173),"",'By Round'!J173) | K17: =IF(ISBLANK('By Round'!K173),"",'By Round'!K173) | L17: =IF(ISBLANK('By Round'!L173),"",'By Round'!L173) | M17: =AVERAGE(AG17:AL17) | N17: =AVERAGE(AM17:AR17) | O17: =IF(COUNT(U17:Z17)>0,Q17/COUNT(U17:Z17),0.5) | P17: =IF(COUNT(AA17:AF17)>0,R17/COUNT(AA17:AF17),0.5) | Q17: =SUM(U17:Z17) | R17: =SUM(AA17:AF17) | S17: =IF(ISNUMBER(K17),K17,IF(ISNUMBER(L17),-L17,"")) | T17: =IF(ISNUMBER(L17),L17,IF(ISNUMBER(K17),-K17,"")) | U17: =IF(ISNUMBER(S17),IF(ISNUMBER(S18),IF(S17>S18,1.0,IF(S17=S18,0.5,0.0)),""),"") | V17: =IF(ISNUMBER(S17),IF(ISNUMBER(S19),IF(S17>S19,1.0,IF(S17=S19,0.5,0.0)),""),"") | W17: =IF(ISNUMBER(S17),IF(ISNUMBER(S20),IF(S17>S20,1.0,IF(S17=S20,0.5,0.0)),""),"") | X17: =IF(ISNUMBER(S17),IF(ISNUMBER(S21),IF(S17>S21,1.0,IF(S17=S21,0.5,0.0)),""),"") | Y17: =IF(ISNUMBER(S17),IF(ISNUMBER(S22),IF(S17>S22,1.0,IF(S17=S22,0.5,0.0)),""),"") | Z17: =IF(ISNUMBER(S17),IF(ISNUMBER(S23),IF(S17>S23,1.0,IF(S17=S23,0.5,0.0)),""),"") | AA17: =IF(ISNUMBER(T17),IF(ISNUMBER(T18),IF(T17>T18,1.0,IF(T17=T18,0.5,0.0)),""),"") | AB17: =IF(ISNUMBER(T17),IF(ISNUMBER(T19),IF(T17>T19,1.0,IF(T17=T19,0.5,0.0)),""),"") | AC17: =IF(ISNUMBER(T17),IF(ISNUMBER(T20),IF(T17>T20,1.0,IF(T17=T20,0.5,0.0)),""),"") | AD17: =IF(ISNUMBER(T17),IF(ISNUMBER(T21),IF(T17>T21,1.0,IF(T17=T21,0.5,0.0)),""),"") | AE17: =IF(ISNUMBER(T17),IF(ISNUMBER(T22),IF(T17>T22,1.0,IF(T17=T22,0.5,0.0)),""),"") | AF17: =IF(ISNUMBER(T17),IF(ISNUMBER(T23),IF(T17>T23,1.0,IF(T17=T23,0.5,0.0)),""),"") | AG17: =IF(AND(ISNUMBER(S17),ISNUMBER(S18)),VLOOKUP(ABS(S17-S18),'IMP Table'!$A$2:$C$26,3)*SIGN(S17-S18),0) | AH17: =IF(AND(ISNUMBER(S17),ISNUMBER(S19)),VLOOKUP(ABS(S17-S19),'IMP Table'!$A$2:$C$26,3)*SIGN(S17-S19),0) | AI17: =IF(AND(ISNUMBER(S17),ISNUMBER(S20)),VLOOKUP(ABS(S17-S20),'IMP Table'!$A$2:$C$26,3)*SIGN(S17-S20),0) | AJ17: =IF(AND(ISNUMBER(S17),ISNUMBER(S21)),VLOOKUP(ABS(S17-S21),'IMP Table'!$A$2:$C$26,3)*SIGN(S17-S21),0) | AK17: =IF(AND(ISNUMBER(S17),ISNUMBER(S22)),VLOOKUP(ABS(S17-S22),'IMP Table'!$A$2:$C$26,3)*SIGN(S17-S22),0) | AL17: =IF(AND(ISNUMBER(S17),ISNUMBER(S23)),VLOOKUP(ABS(S17-S23),'IMP Table'!$A$2:$C$26,3)*SIGN(S17-S23),0) | AM17: =IF(AND(ISNUMBER(T17),ISNUMBER(T18)),VLOOKUP(ABS(T17-T18),'IMP Table'!$A$2:$C$26,3)*SIGN(T17-T18),0) | AN17: =IF(AND(ISNUMBER(T17),ISNUMBER(T19)),VLOOKUP(ABS(T17-T19),'IMP Table'!$A$2:$C$26,3)*SIGN(T17-T19),0) | AO17: =IF(AND(ISNUMBER(T17),ISNUMBER(T20)),VLOOKUP(ABS(T17-T20),'IMP Table'!$A$2:$C$26,3)*SIGN(T17-T20),0) | AP17: =IF(AND(ISNUMBER(T17),ISNUMBER(T21)),VLOOKUP(ABS(T17-T21),'IMP Table'!$A$2:$C$26,3)*SIGN(T17-T21),0) | AQ17: =IF(AND(ISNUMBER(T17),ISNUMBER(T22)),VLOOKUP(ABS(T17-T22),'IMP Table'!$A$2:$C$26,3)*SIGN(T17-T22),0) | AR17: =IF(AND(ISNUMBER(T17),ISNUMBER(T23)),VLOOKUP(ABS(T17-T23),'IMP Table'!$A$2:$C$26,3)*SIGN(T17-T23),0)
B18: ='By Round'!A143 | C18: ='By Round'!B149 | D18: ='By Round'!C149 | E18: ='By Round'!D149 | F18: =IF(ISBLANK('By Round'!F149),"",'By Round'!F149) | G18: =IF(ISBLANK('By Round'!G149),"",'By Round'!G149) | H18: =IF(ISBLANK('By Round'!H149),"",'By Round'!H149) | I18: =IF(ISBLANK('By Round'!I149),"",'By Round'!I149) | J18: =IF(ISBLANK('By Round'!J149),"",'By Round'!J149) | K18: =IF(ISBLANK('By Round'!K149),"",'By Round'!K149) | L18: =IF(ISBLANK('By Round'!L149),"",'By Round'!L149) | M18: =AVERAGE(AG18:AL18) | N18: =AVERAGE(AM18:AR18) | O18: =IF(COUNT(U18:Z18)>0,Q18/COUNT(U18:Z18),0.5) | P18: =IF(COUNT(AA18:AF18)>0,R18/COUNT(AA18:AF18),0.5) | Q18: =SUM(U18:Z18) | R18: =SUM(AA18:AF18) | S18: =IF(ISNUMBER(K18),K18,IF(ISNUMBER(L18),-L18,"")) | T18: =IF(ISNUMBER(L18),L18,IF(ISNUMBER(K18),-K18,"")) | U18: =IF(ISNUMBER(S18),IF(ISNUMBER(S17),IF(S18>S17,1.0,IF(S18=S17,0.5,0.0)),""),"") | V18: =IF(ISNUMBER(S18),IF(ISNUMBER(S19),IF(S18>S19,1.0,IF(S18=S19,0.5,0.0)),""),"") | W18: =IF(ISNUMBER(S18),IF(ISNUMBER(S20),IF(S18>S20,1.0,IF(S18=S20,0.5,0.0)),""),"") | X18: =IF(ISNUMBER(S18),IF(ISNUMBER(S21),IF(S18>S21,1.0,IF(S18=S21,0.5,0.0)),""),"") | Y18: =IF(ISNUMBER(S18),IF(ISNUMBER(S22),IF(S18>S22,1.0,IF(S18=S22,0.5,0.0)),""),"") | Z18: =IF(ISNUMBER(S18),IF(ISNUMBER(S23),IF(S18>S23,1.0,IF(S18=S23,0.5,0.0)),""),"") | AA18: =IF(ISNUMBER(T18),IF(ISNUMBER(T17),IF(T18>T17,1.0,IF(T18=T17,0.5,0.0)),""),"") | AB18: =IF(ISNUMBER(T18),IF(ISNUMBER(T19),IF(T18>T19,1.0,IF(T18=T19,0.5,0.0)),""),"") | AC18: =IF(ISNUMBER(T18),IF(ISNUMBER(T20),IF(T18>T20,1.0,IF(T18=T20,0.5,0.0)),""),"") | AD18: =IF(ISNUMBER(T18),IF(ISNUMBER(T21),IF(T18>T21,1.0,IF(T18=T21,0.5,0.0)),""),"") | AE18: =IF(ISNUMBER(T18),IF(ISNUMBER(T22),IF(T18>T22,1.0,IF(T18=T22,0.5,0.0)),""),"") | AF18: =IF(ISNUMBER(T18),IF(ISNUMBER(T23),IF(T18>T23,1.0,IF(T18=T23,0.5,0.0)),""),"") | AG18: =IF(AND(ISNUMBER(S18),ISNUMBER(S17)),VLOOKUP(ABS(S18-S17),'IMP Table'!$A$2:$C$26,3)*SIGN(S18-S17),0) | AH18: =IF(AND(ISNUMBER(S18),ISNUMBER(S19)),VLOOKUP(ABS(S18-S19),'IMP Table'!$A$2:$C$26,3)*SIGN(S18-S19),0) | AI18: =IF(AND(ISNUMBER(S18),ISNUMBER(S20)),VLOOKUP(ABS(S18-S20),'IMP Table'!$A$2:$C$26,3)*SIGN(S18-S20),0) | AJ18: =IF(AND(ISNUMBER(S18),ISNUMBER(S21)),VLOOKUP(ABS(S18-S21),'IMP Table'!$A$2:$C$26,3)*SIGN(S18-S21),0) | AK18: =IF(AND(ISNUMBER(S18),ISNUMBER(S22)),VLOOKUP(ABS(S18-S22),'IMP Table'!$A$2:$C$26,3)*SIGN(S18-S22),0) | AL18: =IF(AND(ISNUMBER(S18),ISNUMBER(S23)),VLOOKUP(ABS(S18-S23),'IMP Table'!$A$2:$C$26,3)*SIGN(S18-S23),0) | AM18: =IF(AND(ISNUMBER(T18),ISNUMBER(T17)),VLOOKUP(ABS(T18-T17),'IMP Table'!$A$2:$C$26,3)*SIGN(T18-T17),0) | AN18: =IF(AND(ISNUMBER(T18),ISNUMBER(T19)),VLOOKUP(ABS(T18-T19),'IMP Table'!$A$2:$C$26,3)*SIGN(T18-T19),0) | AO18: =IF(AND(ISNUMBER(T18),ISNUMBER(T20)),VLOOKUP(ABS(T18-T20),'IMP Table'!$A$2:$C$26,3)*SIGN(T18-T20),0) | AP18: =IF(AND(ISNUMBER(T18),ISNUMBER(T21)),VLOOKUP(ABS(T18-T21),'IMP Table'!$A$2:$C$26,3)*SIGN(T18-T21),0) | AQ18: =IF(AND(ISNUMBER(T18),ISNUMBER(T22)),VLOOKUP(ABS(T18-T22),'IMP Table'!$A$2:$C$26,3)*SIGN(T18-T22),0) | AR18: =IF(AND(ISNUMBER(T18),ISNUMBER(T23)),VLOOKUP(ABS(T18-T23),'IMP Table'!$A$2:$C$26,3)*SIGN(T18-T23),0)
B19: ='By Round'!A45 | C19: ='By Round'!B57 | D19: ='By Round'!C57 | E19: ='By Round'!D57 | F19: =IF(ISBLANK('By Round'!F57),"",'By Round'!F57) | G19: =IF(ISBLANK('By Round'!G57),"",'By Round'!G57) | H19: =IF(ISBLANK('By Round'!H57),"",'By Round'!H57) | I19: =IF(ISBLANK('By Round'!I57),"",'By Round'!I57) | J19: =IF(ISBLANK('By Round'!J57),"",'By Round'!J57) | K19: =IF(ISBLANK('By Round'!K57),"",'By Round'!K57) | L19: =IF(ISBLANK('By Round'!L57),"",'By Round'!L57) | M19: =AVERAGE(AG19:AL19) | N19: =AVERAGE(AM19:AR19) | O19: =IF(COUNT(U19:Z19)>0,Q19/COUNT(U19:Z19),0.5) | P19: =IF(COUNT(AA19:AF19)>0,R19/COUNT(AA19:AF19),0.5) | Q19: =SUM(U19:Z19) | R19: =SUM(AA19:AF19) | S19: =IF(ISNUMBER(K19),K19,IF(ISNUMBER(L19),-L19,"")) | T19: =IF(ISNUMBER(L19),L19,IF(ISNUMBER(K19),-K19,"")) | U19: =IF(ISNUMBER(S19),IF(ISNUMBER(S17),IF(S19>S17,1.0,IF(S19=S17,0.5,0.0)),""),"") | V19: =IF(ISNUMBER(S19),IF(ISNUMBER(S18),IF(S19>S18,1.0,IF(S19=S18,0.5,0.0)),""),"") | W19: =IF(ISNUMBER(S19),IF(ISNUMBER(S20),IF(S19>S20,1.0,IF(S19=S20,0.5,0.0)),""),"") | X19: =IF(ISNUMBER(S19),IF(ISNUMBER(S21),IF(S19>S21,1.0,IF(S19=S21,0.5,0.0)),""),"") | Y19: =IF(ISNUMBER(S19),IF(ISNUMBER(S22),IF(S19>S22,1.0,IF(S19=S22,0.5,0.0)),""),"") | Z19: =IF(ISNUMBER(S19),IF(ISNUMBER(S23),IF(S19>S23,1.0,IF(S19=S23,0.5,0.0)),""),"") | AA19: =IF(ISNUMBER(T19),IF(ISNUMBER(T17),IF(T19>T17,1.0,IF(T19=T17,0.5,0.0)),""),"") | AB19: =IF(ISNUMBER(T19),IF(ISNUMBER(T18),IF(T19>T18,1.0,IF(T19=T18,0.5,0.0)),""),"") | AC19: =IF(ISNUMBER(T19),IF(ISNUMBER(T20),IF(T19>T20,1.0,IF(T19=T20,0.5,0.0)),""),"") | AD19: =IF(ISNUMBER(T19),IF(ISNUMBER(T21),IF(T19>T21,1.0,IF(T19=T21,0.5,0.0)),""),"") | AE19: =IF(ISNUMBER(T19),IF(ISNUMBER(T22),IF(T19>T22,1.0,IF(T19=T22,0.5,0.0)),""),"") | AF19: =IF(ISNUMBER(T19),IF(ISNUMBER(T23),IF(T19>T23,1.0,IF(T19=T23,0.5,0.0)),""),"") | AG19: =IF(AND(ISNUMBER(S19),ISNUMBER(S17)),VLOOKUP(ABS(S19-S17),'IMP Table'!$A$2:$C$26,3)*SIGN(S19-S17),0) | AH19: =IF(AND(ISNUMBER(S19),ISNUMBER(S18)),VLOOKUP(ABS(S19-S18),'IMP Table'!$A$2:$C$26,3)*SIGN(S19-S18),0) | AI19: =IF(AND(ISNUMBER(S19),ISNUMBER(S20)),VLOOKUP(ABS(S19-S20),'IMP Table'!$A$2:$C$26,3)*SIGN(S19-S20),0) | AJ19: =IF(AND(ISNUMBER(S19),ISNUMBER(S21)),VLOOKUP(ABS(S19-S21),'IMP Table'!$A$2:$C$26,3)*SIGN(S19-S21),0) | AK19: =IF(AND(ISNUMBER(S19),ISNUMBER(S22)),VLOOKUP(ABS(S19-S22),'IMP Table'!$A$2:$C$26,3)*SIGN(S19-S22),0) | AL19: =IF(AND(ISNUMBER(S19),ISNUMBER(S23)),VLOOKUP(ABS(S19-S23),'IMP Table'!$A$2:$C$26,3)*SIGN(S19-S23),0) | AM19: =IF(AND(ISNUMBER(T19),ISNUMBER(T17)),VLOOKUP(ABS(T19-T17),'IMP Table'!$A$2:$C$26,3)*SIGN(T19-T17),0) | AN19: =IF(AND(ISNUMBER(T19),ISNUMBER(T18)),VLOOKUP(ABS(T19-T18),'IMP Table'!$A$2:$C$26,3)*SIGN(T19-T18),0) | AO19: =IF(AND(ISNUMBER(T19),ISNUMBER(T20)),VLOOKUP(ABS(T19-T20),'IMP Table'!$A$2:$C$26,3)*SIGN(T19-T20),0) | AP19: =IF(AND(ISNUMBER(T19),ISNUMBER(T21)),VLOOKUP(ABS(T19-T21),'IMP Table'!$A$2:$C$26,3)*SIGN(T19-T21),0) | AQ19: =IF(AND(ISNUMBER(T19),ISNUMBER(T22)),VLOOKUP(ABS(T19-T22),'IMP Table'!$A$2:$C$26,3)*SIGN(T19-T22),0) | AR19: =IF(AND(ISNUMBER(T19),ISNUMBER(T23)),VLOOKUP(ABS(T19-T23),'IMP Table'!$A$2:$C$26,3)*SIGN(T19-T23),0)
B20: ='By Round'!A73 | C20: ='By Round'!B81 | D20: ='By Round'!C81 | E20: ='By Round'!D81 | F20: =IF(ISBLANK('By Round'!F81),"",'By Round'!F81) | G20: =IF(ISBLANK('By Round'!G81),"",'By Round'!G81) | H20: =IF(ISBLANK('By Round'!H81),"",'By Round'!H81) | I20: =IF(ISBLANK('By Round'!I81),"",'By Round'!I81) | J20: =IF(ISBLANK('By Round'!J81),"",'By Round'!J81) | K20: =IF(ISBLANK('By Round'!K81),"",'By Round'!K81) | L20: =IF(ISBLANK('By Round'!L81),"",'By Round'!L81) | M20: =AVERAGE(AG20:AL20) | N20: =AVERAGE(AM20:AR20) | O20: =IF(COUNT(U20:Z20)>0,Q20/COUNT(U20:Z20),0.5) | P20: =IF(COUNT(AA20:AF20)>0,R20/COUNT(AA20:AF20),0.5) | Q20: =SUM(U20:Z20) | R20: =SUM(AA20:AF20) | S20: =IF(ISNUMBER(K20),K20,IF(ISNUMBER(L20),-L20,"")) | T20: =IF(ISNUMBER(L20),L20,IF(ISNUMBER(K20),-K20,"")) | U20: =IF(ISNUMBER(S20),IF(ISNUMBER(S17),IF(S20>S17,1.0,IF(S20=S17,0.5,0.0)),""),"") | V20: =IF(ISNUMBER(S20),IF(ISNUMBER(S18),IF(S20>S18,1.0,IF(S20=S18,0.5,0.0)),""),"") | W20: =IF(ISNUMBER(S20),IF(ISNUMBER(S19),IF(S20>S19,1.0,IF(S20=S19,0.5,0.0)),""),"") | X20: =IF(ISNUMBER(S20),IF(ISNUMBER(S21),IF(S20>S21,1.0,IF(S20=S21,0.5,0.0)),""),"") | Y20: =IF(ISNUMBER(S20),IF(ISNUMBER(S22),IF(S20>S22,1.0,IF(S20=S22,0.5,0.0)),""),"") | Z20: =IF(ISNUMBER(S20),IF(ISNUMBER(S23),IF(S20>S23,1.0,IF(S20=S23,0.5,0.0)),""),"") | AA20: =IF(ISNUMBER(T20),IF(ISNUMBER(T17),IF(T20>T17,1.0,IF(T20=T17,0.5,0.0)),""),"") | AB20: =IF(ISNUMBER(T20),IF(ISNUMBER(T18),IF(T20>T18,1.0,IF(T20=T18,0.5,0.0)),""),"") | AC20: =IF(ISNUMBER(T20),IF(ISNUMBER(T19),IF(T20>T19,1.0,IF(T20=T19,0.5,0.0)),""),"") | AD20: =IF(ISNUMBER(T20),IF(ISNUMBER(T21),IF(T20>T21,1.0,IF(T20=T21,0.5,0.0)),""),"") | AE20: =IF(ISNUMBER(T20),IF(ISNUMBER(T22),IF(T20>T22,1.0,IF(T20=T22,0.5,0.0)),""),"") | AF20: =IF(ISNUMBER(T20),IF(ISNUMBER(T23),IF(T20>T23,1.0,IF(T20=T23,0.5,0.0)),""),"") | AG20: =IF(AND(ISNUMBER(S20),ISNUMBER(S17)),VLOOKUP(ABS(S20-S17),'IMP Table'!$A$2:$C$26,3)*SIGN(S20-S17),0) | AH20: =IF(AND(ISNUMBER(S20),ISNUMBER(S18)),VLOOKUP(ABS(S20-S18),'IMP Table'!$A$2:$C$26,3)*SIGN(S20-S18),0) | AI20: =IF(AND(ISNUMBER(S20),ISNUMBER(S19)),VLOOKUP(ABS(S20-S19),'IMP Table'!$A$2:$C$26,3)*SIGN(S20-S19),0) | AJ20: =IF(AND(ISNUMBER(S20),ISNUMBER(S21)),VLOOKUP(ABS(S20-S21),'IMP Table'!$A$2:$C$26,3)*SIGN(S20-S21),0) | AK20: =IF(AND(ISNUMBER(S20),ISNUMBER(S22)),VLOOKUP(ABS(S20-S22),'IMP Table'!$A$2:$C$26,3)*SIGN(S20-S22),0) | AL20: =IF(AND(ISNUMBER(S20),ISNUMBER(S23)),VLOOKUP(ABS(S20-S23),'IMP Table'!$A$2:$C$26,3)*SIGN(S20-S23),0) | AM20: =IF(AND(ISNUMBER(T20),ISNUMBER(T17)),VLOOKUP(ABS(T20-T17),'IMP Table'!$A$2:$C$26,3)*SIGN(T20-T17),0) | AN20: =IF(AND(ISNUMBER(T20),ISNUMBER(T18)),VLOOKUP(ABS(T20-T18),'IMP Table'!$A$2:$C$26,3)*SIGN(T20-T18),0) | AO20: =IF(AND(ISNUMBER(T20),ISNUMBER(T19)),VLOOKUP(ABS(T20-T19),'IMP Table'!$A$2:$C$26,3)*SIGN(T20-T19),0) | AP20: =IF(AND(ISNUMBER(T20),ISNUMBER(T21)),VLOOKUP(ABS(T20-T21),'IMP Table'!$A$2:$C$26,3)*SIGN(T20-T21),0) | AQ20: =IF(AND(ISNUMBER(T20),ISNUMBER(T22)),VLOOKUP(ABS(T20-T22),'IMP Table'!$A$2:$C$26,3)*SIGN(T20-T22),0) | AR20: =IF(AND(ISNUMBER(T20),ISNUMBER(T23)),VLOOKUP(ABS(T20-T23),'IMP Table'!$A$2:$C$26,3)*SIGN(T20-T23),0)
