Workbook

Sheet Roster
A1: For public domain. No rights reserved. Generated on Mar 08, 2026.
A2: Howell Tournament
A3: Pairs | C3: 9
A4: Tables | C4: 5
A5: Rounds | C5: 9
A6: Boards per round | C6: 2
A7: Total Boards to play | C7: 18
A9: Pairs | D9: MP | E9: IMP
A10: 1 | B10: Name 15 | C10: Name 76 | D10: =SUMIF('By Board'!$D$3:$D$82,"=1",'By Board'!$O$3:$O$82)/16+SUMIF('By Board'!$E$3:$E$82,"=1",'By Board'!$P$3:$P$82)/16 | E10: =SUMIF('By Board'!$D$3:$D$82,"=1",'By Board'!$M$3:$M$82)+SUMIF('By Board'!$E$3:$E$82,"=1",'By Board'!$N$3:$N$82)
A11: 2 | B11: Name 80 | C11: Name 21 | D11: =SUMIF('By Board'!$D$3:$D$82,"=2",'By Board'!$O$3:$O$82)/16+SUMIF('By Board'!$E$3:$E$82,"=2",'By Board'!$P$3:$P$82)/16 | E11: =SUMIF('By Board'!$D$3:$D$82,"=2",'By Board'!$M$3:$M$82)+SUMIF('By Board'!$E$3:$E$82,"=2",'By Board'!$N$3:$N$82)
A12: 3 | B12: Name 85 | C12: Name 36 | D12: =SUMIF('By Board'!$D$3:$D$82,"=3",'By Board'!$O$3:$O$82)/16+SUMIF('By Board'!$E$3:$E$82,"=3",'By Board'!$P$3:$P$82)/16 | E12: =SUMIF('By Board'!$D$3:$D$82,"=3",'By Board'!$M$3:$M$82)+SUMIF('By Board'!$E$3:$E$82,"=3",'By Board'!$N$3:$N$82)
A13: 4 | B13: Name 13 | C13: Name 43 | D13: =SUMIF('By Board'!$D$3:$D$82,"=4",'By Board'!$O$3:$O$82)/16+SUMIF('By Board'!$E$3:$E$82,"=4",'By Board'!$P$3:$P$82)/16 | E13: =SUMIF('By Board'!$D$3:$D$82,"=4",'By Board'!$M$3:$M$82)+SUMIF('By Board'!$E$3:$E$82,"=4",'By Board'!$N$3:$N$82)
A14: 5 | B14: Name 20 | C14: Name 66 | D14: =SUMIF('By Board'!$D$3:$D$82,"=5",'By Board'!$O$3:$O$82)/16+SUMIF('By Board'!$E$3:$E$82,"=5",'By Board'!$P$3:$P$82)/16 | E14: =SUMIF('By Board'!$D$3:$D$82,"=5",'By Board'!$M$3:$M$82)+SUMIF('By Board'!$E$3:$E$82,"=5",'By Board'!$N$3:$N$82)
A15: 6 | B15: Name 65 | C15: Name 64 | D15: =SUMIF('By Board'!$D$3:$D$82,"=6",'By Board'!$O$3:$O$82)/16+SUMIF('By Board'!$E$3:$E$82,"=6",'By Board'!$P$3:$P$82)/16 | E15: =SUMIF('By Board'!$D$3:$D$82,"=6",'By Board'!$M$3:$M$82)+SUMIF('By Board'!$E$3:$E$82,"=6",'By Board'!$N$3:$N$82)
A16: 7 | B16: Name 53 | C16: Name 29 | D16: =SUMIF('By Board'!$D$3:$D$82,"=7",'By Board'!$O$3:$O$82)/16+SUMIF('By Board'!$E$3:$E$82,"=7",'By Board'!$P$3:$P$82)/16 | E16: =SUMIF('By Board'!$D$3:$D$82,"=7",'By Board'!$M$3:$M$82)+SUMIF('By Board'!$E$3:$E$82,"=7",'By Board'!$N$3:$N$82)
A17: 8 | B17: Name 69 | C17: Name 17 | D17: =SUMIF('By Board'!$D$3:$D$82,"=8",'By Board'!$O$3:$O$82)/16+SUMIF('By Board'!$E$3:$E$82,"=8",'By Board'!$P$3:$P$82)/16 | E17: =SUMIF('By Board'!$D$3:$D$82,"=8",'By Board'!$M$3:$M$82)+SUMIF('By Board'!$E$3:$E$82,"=8",'By Board'!$N$3:$N$82)
A18: 9 | B18: Name 79 | C18: Name 55 | D18: =SUMIF('By Board'!$D$3:$D$82,"=9",'By Board'!$O$3:$O$82)/16+SUMIF('By Board'!$E$3:$E$82,"=9",'By Board'!$P$3:$P$82)/16 | E18: =SUMIF('By Board'!$D$3:$D$82,"=9",'By Board'!$M$3:$M$82)+SUMIF('By Board'!$E$3:$E$82,"=9",'By Board'!$N$3:$N$82)
D19: =AVERAGE(D10:D18) | E19: =SUM(E10:E18)

Sheet By Board
I1: Result | K1: Score | M1: IMP | O1: MP % | Q1: MP Pts | S1: Net | U1: MP Calculation | AC1: IMP Calculation
A2: Board | B2: Round | C2: Table | D2: NS | E2: EW | F2: Vul | G2: Contract | H2: By | I2: Made | J2: Down | K2: NS | L2: EW | M2: NS | N2: EW | O2: NS | P2: EW | Q2: NS | R2: EW | S2: NS | T2: EW | U2: NS MP Scores | Y2: EW MP Scores | AC2: NS IMP Pair-wise | AG2: EW IMP Pair-wise
A3: 1 | B3: ='By Round'!A3 | C3: ='By Round'!B3 | D3: ='By Round'!C3 | E3: ='By Round'!D3 | F3: =IF(ISBLANK('By Round'!F3),"",'By Round'!F3) | G3: =IF(ISBLANK('By Round'!G3),"",'By Round'!G3) | H3: =IF(ISBLANK('By Round'!H3),"",'By Round'!H3) | I3: =IF(ISBLANK('By Round'!I3),"",'By Round'!I3) | J3: =IF(ISBLANK('By Round'!J3),"",'By Round'!J3) | K3: =IF(ISBLANK('By Round'!K3),"",'By Round'!K3) | L3: =IF(ISBLANK('By Round'!L3),"",'By Round'!L3) | M3: =AVERAGE(AC3:AF3) | N3: =AVERAGE(AG3:AJ3) | O3: =IF(COUNT(U3:X3)>0,Q3/COUNT(U3:X3),0.5) | P3: =IF(COUNT(Y3:AB3)>0,R3/COUNT(Y3:AB3),0.5) | Q3: =SUM(U3:X3) | R3: =SUM(Y3:AB3) | S3: =IF(ISNUMBER(K3),K3,IF(ISNUMBER(L3),-L3,"")) | T3: =IF(ISNUMBER(L3),L3,IF(ISNUMBER(K3),-K3,"")) | U3: =IF(ISNUMBER(S3),IF(ISNUMBER(S4),IF(S3>S4,1.0,IF(S3=S4,0.5,0.0)),""),"") | V3: =IF(ISNUMBER(S3),IF(ISNUMBER(S5),IF(S3>S5,1.0,IF(S3=S5,0.5,0.0)),""),"") | W3: =IF(ISNUMBER(S3),IF(ISNUMBER(S6),IF(S3>S6,1.0,IF(S3=S6,0.5,0.0)),""),"") | X3: =IF(ISNUMBER(S3),IF(ISNUMBER(S7),IF(S3>S7,1.0,IF(S3=S7,0.5,0.0)),""),"") | Y3: =IF(ISNUMBER(T3),IF(ISNUMBER(T4),IF(T3>T4,1.0,IF(T3=T4,0.5,0.0)),""),"") | Z3: =IF(ISNUMBER(T3),IF(ISNUMBER(T5),IF(T3>T5,1.0,IF(T3=T5,0.5,0.0)),""),"") | AA3: =IF(ISNUMBER(T3),IF(ISNUMBER(T6),IF(T3>T6,1.0,IF(T3=T6,0.5,0.0)),""),"") | AB3: =IF(ISNUMBER(T3),IF(ISNUMBER(T7),IF(T3>T7,1.0,IF(T3=T7,0.5,0.0)),""),"") | AC3: =IF(AND(ISNUMBER(S3),ISNUMBER(S4)),VLOOKUP(ABS(S3-S4),'IMP Table'!$A$2:$C$26,3)*SIGN(S3-S4),0) | AD3: =IF(AND(ISNUMBER(S3),ISNUMBER(S5)),VLOOKUP(ABS(S3-S5),'IMP Table'!$A$2:$C$26,3)*SIGN(S3-S5),0) | AE3: =IF(AND(ISNUMBER(S3),ISNUMBER(S6)),VLOOKUP(ABS(S3-S6),'IMP Table'!$A$2:$C$26,3)*SIGN(S3-S6),0) | AF3: =IF(AND(ISNUMBER(S3),ISNUMBER(S7)),VLOOKUP(ABS(S3-S7),'IMP Table'!$A$2:$C$26,3)*SIGN(S3-S7),0) | AG3: =IF(AND(ISNUMBER(T3),ISNUMBER(T4)),VLOOKUP(ABS(T3-T4),'IMP Table'!$A$2:$C$26,3)*SIGN(T3-T4),0) | AH3: =IF(AND(ISNUMBER(T3),ISNUMBER(T5)),VLOOKUP(ABS(T3-T5),'IMP Table'!$A$2:$C$26,3)*SIGN(T3-T5),0) | AI3: =IF(AND(ISNUMBER(T3),ISNUMBER(T6)),VLOOKUP(ABS(T3-T6),'IMP Table'!$A$2:$C$26,3)*SIGN(T3-T6),0) | AJ3: =IF(AND(ISNUMBER(T3),ISNUMBER(T7)),VLOOKUP(ABS(T3-T7),'IMP Table'!$A$2:$C$26,3)*SIGN(T3-T7),0)
B4: ='By Round'!A73 | C4: ='By Round'!B77 | D4: ='By Round'!C77 | E4: ='By Round'!D77 | F4: =IF(ISBLANK('By Round'!F77),"",'By Round'!F77) | G4: =IF(ISBLANK('By Round'!G77),"",'By Round'!G77) | H4: =IF(ISBLANK('By Round'!H77),"",'By Round'!H77) | I4: =IF(ISBLANK('By Round'!I77),"",'By Round'!I77) | J4: =IF(ISBLANK('By Round'!J77),"",'By Round'!J77) | K4: =IF(ISBLANK('By Round'!K77),"",'By Round'!K77) | L4: =IF(ISBLANK('By Round'!L77),"",'By Round'!L77) | M4: =AVERAGE(AC4:AF4) | N4: =AVERAGE(AG4:AJ4) | O4: =IF(COUNT(U4:X4)>0,Q4/COUNT(U4:X4),0.5) | P4: =IF(COUNT(Y4:AB4)>0,R4/COUNT(Y4:AB4),0.5) | Q4: =SUM(U4:X4) | R4: =SUM(Y4:AB4) | S4: =IF(ISNUMBER(K4),K4,IF(ISNUMBER(L4),-L4,"")) | T4: =IF(ISNUMBER(L4),L4,IF(ISNUMBER(K4),-K4,"")) | U4: =IF(ISNUMBER(S4),IF(ISNUMBER(S3),IF(S4>S3,1.0,IF(S4=S3,0.5,0.0)),""),"") | V4: =IF(ISNUMBER(S4),IF(ISNUMBER(S5),IF(S4>S5,1.0,IF(S4=S5,0.5,0.0)),""),"") | W4: =IF(ISNUMBER(S4),IF(ISNUMBER(S6),IF(S4>S6,1.0,IF(S4=S6,0.5,0.0)),""),"") | X4: =IF(ISNUMBER(S4),IF(ISNUMBER(S7),IF(S4>S7,1.0,IF(S4=S7,0.5,0.0)),""),"") | Y4: =IF(ISNUMBER(T4),IF(ISNUMBER(T3),IF(T4>T3,1.0,IF(T4=T3,0.5,0.0)),""),"") | Z4: =IF(ISNUMBER(T4),IF(ISNUMBER(T5),IF(T4>T5,1.0,IF(T4=T5,0.5,0.0)),""),"") | AA4: =IF(ISNUMBER(T4),IF(ISNUMBER(T6),IF(T4>T6,1.0,IF(T4=T6,0.5,0.0)),""),"") | AB4: =IF(ISNUMBER(T4),IF(ISNUMBER(T7),IF(T4>T7,1.0,IF(T4=T7,0.5,0.0)),""),"") | AC4: =IF(AND(ISNUMBER(S4),ISNUMBER(S3)),VLOOKUP(ABS(S4-S3),'IMP Table'!$A$2:$C$26,3)*SIGN(S4-S3),0) | AD4: =IF(AND(ISNUMBER(S4),ISNUMBER(S5)),VLOOKUP(ABS(S4-S5),'IMP Table'!$A$2:$C$26,3)*SIGN(S4-S5),0) | AE4: =IF(AND(ISNUMBER(S4),ISNUMBER(S6)),VLOOKUP(ABS(S4-S6),'IMP Table'!$A$2:$C$26,3)*SIGN(S4-S6),0) | AF4: =IF(AND(ISNUMBER(S4),ISNUMBER(S7)),VLOOKUP(ABS(S4-S7),'IMP Table'!$A$2:$C$26,3)*SIGN(S4-S7),0) | AG4: =IF(AND(ISNUMBER(T4),ISNUMBER(T3)),VLOOKUP(ABS(T4-T3),'IMP Table'!$A$2:$C$26,3)*SIGN(T4-T3),0) | AH4: =IF(AND(ISNUMBER(T4),ISNUMBER(T5)),VLOOKUP(ABS(T4-T5),'IMP Table'!$A$2:$C$26,3)*SIGN(T4-T5),0) | AI4: =IF(AND(ISNUMBER(T4),ISNUMBER(T6)),VLOOKUP(ABS(T4-T6),'IMP Table'!$A$2:$C$26,3)*SIGN(T4-T6),0) | AJ4: =IF(AND(ISNUMBER(T4),ISNUMBER(T7)),VLOOKUP(ABS(T4-T7),'IMP Table'!$A$2:$C$26,3)*SIGN(T4-T7),0)
B5: ='By Round'!A23 | C5: ='By Round'!B29 | D5: ='By Round'!C29 | E5: ='By Round'!D29 | F5: =IF(ISBLANK('By Round'!F29),"",'By Round'!F29) | G5: =IF(ISBLANK('By Round'!G29),"",'By Round'!G29) | H5: =IF(ISBLANK('By Round'!H29),"",'By Round'!H29) | I5: =IF(ISBLANK('By Round'!I29),"",'By Round'!I29) | J5: =IF(ISBLANK('By Round'!J29),"",'By Round'!J29) | K5: =IF(ISBLANK('By Round'!K29),"",'By Round'!K29) | L5: =IF(ISBLANK('By Round'!L29),"",'By Round'!L29) | M5: =AVERAGE(AC5:AF5) | N5: =AVERAGE(AG5:AJ5) | O5: =IF(COUNT(U5:X5)>0,Q5/COUNT(U5:X5),0.5) | P5: =IF(COUNT(Y5:AB5)>0,R5/COUNT(Y5:AB5),0.5) | Q5: =SUM(U5:X5) | R5: =SUM(Y5:AB5) | S5: =IF(ISNUMBER(K5),K5,IF(ISNUMBER(L5),-L5,"")) | T5: =IF(ISNUMBER(L5),L5,IF(ISNUMBER(K5),-K5,"")) | U5: =IF(ISNUMBER(S5),IF(ISNUMBER(S3),IF(S5>S3,1.0,IF(S5=S3,0.5,0.0)),""),"") | V5: =IF(ISNUMBER(S5),IF(ISNUMBER(S4),IF(S5>S4,1.0,IF(S5=S4,0.5,0.0)),""),"") | W5: =IF(ISNUMBER(S5),IF(ISNUMBER(S6),IF(S5>S6,1.0,IF(S5=S6,0.5,0.0)),""),"") | X5: =IF(ISNUMBER(S5),IF(ISNUMBER(S7),IF(S5>S7,1.0,IF(S5=S7,0.5,0.0)),""),"") | Y5: =IF(ISNUMBER(T5),IF(ISNUMBER(T3),IF(T5>T3,1.0,IF(T5=T3,0.5,0.0)),""),"") | Z5: =IF(ISNUMBER(T5),IF(ISNUMBER(T4),IF(T5>T4,1.0,IF(T5=T4,0.5,0.0)),""),"") | AA5: =IF(ISNUMBER(T5),IF(ISNUMBER(T6),IF(T5>T6,1.0,IF(T5=T6,0.5,0.0)),""),"") | AB5: =IF(ISNUMBER(T5),IF(ISNUMBER(T7),IF(T5>T7,1.0,IF(T5=T7,0.5,0.0)),""),"") | AC5: =IF(AND(ISNUMBER(S5),ISNUMBER(S3)),VLOOKUP(ABS(S5-S3),'IMP Table'!$A$2:$C$26,3)*SIGN(S5-S3),0) | AD5: =IF(AND(ISNUMBER(S5),ISNUMBER(S4)),VLOOKUP(ABS(S5-S4),'IMP Table'!$A$2:$C$26,3)*SIGN(S5-S4),0) | AE5: =IF(AND(ISNUMBER(S5),ISNUMBER(S6)),VLOOKUP(ABS(S5-S6),'IMP Table'!$A$2:$C$26,3)*SIGN(S5-S6),0) | AF5: =IF(AND(ISNUMBER(S5),ISNUMBER(S7)),VLOOKUP(ABS(S5-S7),'IMP Table'!$A$2:$C$26,3)*SIGN(S5-S7),0) | AG5: =IF(AND(ISNUMBER(T5),ISNUMBER(T3)),VLOOKUP(ABS(T5-T3),'IMP Table'!$A$2:$C$26,3)*SIGN(T5-T3),0) | AH5: =IF(AND(ISNUMBER(T5),ISNUMBER(T4)),VLOOKUP(ABS(T5-T4),'IMP Table'!$A$2:$C$26,3)*SIGN(T5-T4),0) | AI5: =IF(AND(ISNUMBER(T5),ISNUMBER(T6)),VLOOKUP(ABS(T5-T6),'IMP Table'!$A$2:$C$26,3)*SIGN(T5-T6),0) | AJ5: =IF(AND(ISNUMBER(T5),ISNUMBER(T7)),VLOOKUP(ABS(T5-T7),'IMP Table'!$A$2:$C$26,3)*SIGN(T5-T7),0)
B6: ='By Round'!A13 | C6: ='By Round'!B21 | D6: ='By Round'!C21 | E6: ='By Round'!D21 | F6: =IF(ISBLANK('By Round'!F21),"",'By Round'!F21) | G6: =IF(ISBLANK('By Round'!G21),"",'By Round'!G21) | H6: =IF(ISBLANK('By Round'!H21),"",'By Round'!H21) | I6: =IF(ISBLANK('By Round'!I21),"",'By Round'!I21) | J6: =IF(ISBLANK('By Round'!J21),"",'By Round'!J21) | K6: =IF(ISBLANK('By Round'!K21),"",'By Round'!K21) | L6: =IF(ISBLANK('By Round'!L21),"",'By Round'!L21) | M6: =AVERAGE(AC6:AF6) | N6: =AVERAGE(AG6:AJ6) | O6: =IF(COUNT(U6:X6)>0,Q6/COUNT(U6:X6),0.5) | P6: =IF(COUNT(Y6:AB6)>0,R6/COUNT(Y6:AB6),0.5) | Q6: =SUM(U6:X6) | R6: =SUM(Y6:AB6) | S6: =IF(ISNUMBER(K6),K6,IF(ISNUMBER(L6),-L6,"")) | T6: =IF(ISNUMBER(L6),L6,IF(ISNUMBER(K6),-K6,"")) | U6: =IF(ISNUMBER(S6),IF(ISNUMBER(S3),IF(S6>S3,1.0,IF(S6=S3,0.5,0.0)),""),"") | V6: =IF(ISNUMBER(S6),IF(ISNUMBER(S4),IF(S6>S4,1.0,IF(S6=S4,0.5,0.0)),""),"") | W6: =IF(ISNUMBER(S6),IF(ISNUMBER(S5),IF(S6>S5,1.0,IF(S6=S5,0.5,0.0)),""),"") | X6: =IF(ISNUMBER(S6),IF(ISNUMBER(S7),IF(S6>S7,1.0,IF(S6=S7,0.5,0.0)),""),"") | Y6: =IF(ISNUMBER(T6),IF(ISNUMBER(T3),IF(T6>T3,1.0,IF(T6=T3,0.5,0.0)),""),"") | Z6: =IF(ISNUMBER(T6),IF(ISNUMBER(T4),IF(T6>T4,1.0,IF(T6=T4,0.5,0.0)),""),"") | AA6: =IF(ISNUMBER(T6),IF(ISNUMBER(T5),IF(T6>T5,1.0,IF(T6=T5,0.5,0.0)),""),"") | AB6: =IF(ISNUMBER(T6),IF(ISNUMBER(T7),IF(T6>T7,1.0,IF(T6=T7,0.5,0.0)),""),"") | AC6: =IF(AND(ISNUMBER(S6),ISNUMBER(S3)),VLOOKUP(ABS(S6-S3),'IMP Table'!$A$2:$C$26,3)*SIGN(S6-S3),0) | AD6: =IF(AND(ISNUMBER(S6),ISNUMBER(S4)),VLOOKUP(ABS(S6-S4),'IMP Table'!$A$2:$C$26,3)*SIGN(S6-S4),0) | AE6: =IF(AND(ISNUMBER(S6),ISNUMBER(S5)),VLOOKUP(ABS(S6-S5),'IMP Table'!$A$2:$C$26,3)*SIGN(S6-S5),0) | AF6: =IF(AND(ISNUMBER(S6),ISNUMBER(S7)),VLOOKUP(ABS(S6-S7),'IMP Table'!$A$2:$C$26,3)*SIGN(S6-S7),0) | AG6: =IF(AND(ISNUMBER(T6),ISNUMBER(T3)),VLOOKUP(ABS(T6-T3),'IMP Table'!$A$2:$C$26,3)*SIGN(T6-T3),0) | AH6: =IF(AND(ISNUMBER(T6),ISNUMBER(T4)),VLOOKUP(ABS(T6-T4),'IMP Table'!$A$2:$C$26,3)*SIGN(T6-T4),0) | AI6: =IF(AND(ISNUMBER(T6),ISNUMBER(T5)),VLOOKUP(ABS(T6-T5),'IMP Table'!$A$2:$C$26,3)*SIGN(T6-T5),0) | AJ6: =IF(AND(ISNUMBER(T6),ISNUMBER(T7)),VLOOKUP(ABS(T6-T7),'IMP Table'!$A$2:$C$26,3)*SIGN(T6-T7),0)
B7: ='By Round'!A83 | C7: ='By Round'!B85 | D7: ='By Round'!C85 | E7: ='By Round'!D85 | F7: =IF(ISBLANK('By Round'!F85),"",'By Round'!F85) | G7: =IF(ISBLANK('By Round'!G85),"",'By Round'!G85) | H7: =IF(ISBLANK('By Round'!H85),"",'By Round'!H85) | I7: =IF(ISBLANK('By Round'!I85),"",'By Round'!I85) | J7: =IF(ISBLANK('By Round'!J85),"",'By Round'!J85) | K7: =IF(ISBLANK('By Round'!K85),"",'By Round'!K85) | L7: =IF(ISBLANK('By Round'!L85),"",'By Round'!L85) | M7: =AVERAGE(AC7:AF7) | N7: =AVERAGE(AG7:AJ7) | O7: =IF(COUNT(U7:X7)>0,Q7/COUNT(U7:X7),0.5) | P7: =IF(COUNT(Y7:AB7)>0,R7/COUNT(Y7:AB7),0.5) | Q7: =SUM(U7:X7) | R7: =SUM(Y7:AB7) | S7: =IF(ISNUMBER(K7),K7,IF(ISNUMBER(L7),-L7,"")) | T7: =IF(ISNUMBER(L7),L7,IF(ISNUMBER(K7),-K7,"")) | U7: =IF(ISNUMBER(S7),IF(ISNUMBER(S3),IF(S7>S3,1.0,IF(S7=S3,0.5,0.0)),""),"") | V7: =IF(ISNUMBER(S7),IF(ISNUMBER(S4),IF(S7>S4,1.0,IF(S7=S4,0.5,0.0)),""),"") | W7: =IF(ISNUMBER(S7),IF(ISNUMBER(S5),IF(S7>S5,1.0,IF(S7=S5,0.5,0.0)),""),"") | X7: =IF(ISNUMBER(S7),IF(ISNUMBER(S6),IF(S7>S6,1.0,IF(S7=S6,0.5,0.0)),""),"") | Y7: =IF(ISNUMBER(T7),IF(ISNUMBER(T3),IF(T7>T3,1.0,IF(T7=T3,0.5,0.0)),""),"") | Z7: =IF(ISNUMBER(T7),IF(ISNUMBER(T4),IF(T7>T4,1.0,IF(T7=T4,0.5,0.0)),""),"") | AA7: =IF(ISNUMBER(T7),IF(ISNUMBER(T5),IF(T7>T5,1.0,IF(T7=T5,0.5,0.0)),""),"") | AB7: =IF(ISNUMBER(T7),IF(ISNUMBER(T6),IF(T7>T6,1.0,IF(T7=T6,0.5,0.0)),""),"") | AC7: =IF(AND(ISNUMBER(S7),ISNUMBER(S3)),VLOOKUP(ABS(S7-S3),'IMP Table'!$A$2:$C$26,3)*SIGN(S7-S3),0) | AD7: =IF(AND(ISNUMBER(S7),ISNUMBER(S4)),VLOOKUP(ABS(S7-S4),'IMP Table'!$A$2:$C$26,3)*SIGN(S7-S4),0) | AE7: =IF(AND(ISNUMBER(S7),ISNUMBER(S5)),VLOOKUP(ABS(S7-S5),'IMP Table'!$A$2:$C$26,3)*SIGN(S7-S5),0) | AF7: =IF(AND(ISNUMBER(S7),ISNUMBER(S6)),VLOOKUP(ABS(S7-S6),'IMP Table'!$A$2:$C$26,3)*SIGN(S7-S6),0) | AG7: =IF(AND(ISNUMBER(T7),ISNUMBER(T3)),VLOOKUP(ABS(T7-T3),'IMP Table'!$A$2:$C$26,3)*SIGN(T7-T3),0) | AH7: =IF(AND(ISNUMBER(T7),ISNUMBER(T4)),VLOOKUP(ABS(T7-T4),'IMP Table'!$A$2:$C$26,3)*SIGN(T7-T4),0) | AI7: =IF(AND(ISNUMBER(T7),ISNUMBER(T5)),VLOOKUP(ABS(T7-T5),'IMP Table'!$A$2:$C$26,3)*SIGN(T7-T5),0) | AJ7: =IF(AND(ISNUMBER(T7),ISNUMBER(T6)),VLOOKUP(ABS(T7-T6),'IMP Table'!$A$2:$C$26,3)*SIGN(T7-T6),0)
A8: 2 | B8: ='By Round'!A3 | C8: ='By Round'!B3 | D8: ='By Round'!C3 | E8: ='By Round'!D3 | F8: =IF(ISBLANK('By Round'!F4),"",'By Round'!F4) | G8: =IF(ISBLANK('By Round'!G4),"",'By Round'!G4) | H8: =IF(ISBLANK('By Round'!H4),"",'By Round'!H4) | I8: =IF(ISBLANK('By Round'!I4),"",'By Round'!I4) | J8: =IF(ISBLANK('By Round'!J4),"",'By Round'!J4) | K8: =IF(ISBLANK('By Round'!K4),"",'By Round'!K4) | L8: =IF(ISBLANK('By Round'!L4),"",'By Round'!L4) | M8: =AVERAGE(AC8:AF8) | N8: =AVERAGE(AG8:AJ8) | O8: =IF(COUNT(U8:X8)>0,Q8/COUNT(U8:X8),0.5) | P8: =IF(COUNT(Y8:AB8)>0,R8/COUNT(Y8:AB8),0.5) | Q8: =SUM(U8:X8) | R8: =SUM(Y8:AB8) | S8: =IF(ISNUMBER(K8),K8,IF(ISNUMBER(L8),-L8,"")) | T8: =IF(ISNUMBER(L8),L8,IF(ISNUMBER(K8),-K8,"")) | U8: =IF(ISNUMBER(S8),IF(ISNUMBER(S9),IF(S8>S9,1.0,IF(S8=S9,0.5,0.0)),""),"") | V8: =IF(ISNUMBER(S8),IF(ISNUMBER(S10),IF(S8>S10,1.0,IF(S8=S10,0.5,0.0)),""),"") | W8: =IF(ISNUMBER(S8),IF(ISNUMBER(S11),IF(S8>S11,1.0,IF(S8=S11,0.5,0.0)),""),"") | X8: =IF(ISNUMBER(S8),IF(ISNUMBER(S12),IF(S8>S12,1.0,IF(S8=S12,0.5,0.0)),""),"") | Y8: =IF(ISNUMBER(T8),IF(ISNUMBER(T9),IF(T8>T9,1.0,IF(T8=T9,0.5,0.0)),""),"") | Z8: =IF(ISNUMBER(T8),IF(ISNUMBER(T10),IF(T8>T10,1.0,IF(T8=T10,0.5,0.0)),""),"") | AA8: =IF(ISNUMBER(T8),IF(ISNUMBER(T11),IF(T8>T11,1.0,IF(T8=T11,0.5,0.0)),""),"") | AB8: =IF(ISNUMBER(T8),IF(ISNUMBER(T12),IF(T8>T12,1.0,IF(T8=T12,0.5,0.0)),""),"") | AC8: =IF(AND(ISNUMBER(S8),ISNUMBER(S9)),VLOOKUP(ABS(S8-S9),'IMP Table'!$A$2:$C$26,3)*SIGN(S8-S9),0) | AD8: =IF(AND(ISNUMBER(S8),ISNUMBER(S10)),VLOOKUP(ABS(S8-S10),'IMP Table'!$A$2:$C$26,3)*SIGN(S8-S10),0) | AE8: =IF(AND(ISNUMBER(S8),ISNUMBER(S11)),VLOOKUP(ABS(S8-S11),'IMP Table'!$A$2:$C$26,3)*SIGN(S8-S11),0) | AF8: =IF(AND(ISNUMBER(S8),ISNUMBER(S12)),VLOOKUP(ABS(S8-S12),'IMP Table'!$A$2:$C$26,3)*SIGN(S8-S12),0) | AG8: =IF(AND(ISNUMBER(T8),ISNUMBER(T9)),VLOOKUP(ABS(T8-T9),'IMP Table'!$A$2:$C$26,3)*SIGN(T8-T9),0) | AH8: =IF(AND(ISNUMBER(T8),ISNUMBER(T10)),VLOOKUP(ABS(T8-T10),'IMP Table'!$A$2:$C$26,3)*SIGN(T8-T10),0) | AI8: =IF(AND(ISNUMBER(T8),ISNUMBER(T11)),VLOOKUP(ABS(T8-T11),'IMP Table'!$A$2:$C$26,3)*SIGN(T8-T11),0) | AJ8: =IF(AND(ISNUMBER(T8),ISNUMBER(T12)),VLOOKUP(ABS(T8-T12),'IMP Table'!$A$2:$C$26,3)*SIGN(T8-T12),0)
B9: ='By Round'!A73 | C9: ='By Round'!B77 | D9: ='By Round'!C77 | E9: ='By Round'!D77 | F9: =IF(ISBLANK('By Round'!F78),"",'By Round'!F78) | G9: =IF(ISBLANK('By Round'!G78),"",'By Round'!G78) | H9: =IF(ISBLANK('By Round'!H78),"",'By Round'!H78) | I9: =IF(ISBLANK('By Round'!I78),"",'By Round'!I78) | J9: =IF(ISBLANK('By Round'!J78),"",'By Round'!J78) | K9: =IF(ISBLANK('By Round'!K78),"",'By Round'!K78) | L9: =IF(ISBLANK('By Round'!L78),"",'By Round'!L78) | M9: =AVERAGE(AC9:AF9) | N9: =AVERAGE(AG9:AJ9) | O9: =IF(COUNT(U9:X9)>0,Q9/COUNT(U9:X9),0.5) | P9: =IF(COUNT(Y9:AB9)>0,R9/COUNT(Y9:AB9),0.5) | Q9: =SUM(U9:X9) | R9: =SUM(Y9:AB9) | S9: =IF(ISNUMBER(K9),K9,IF(ISNUMBER(L9),-L9,"")) | T9: =IF(ISNUMBER(L9),L9,IF(ISNUMBER(K9),-K9,"")) | U9: =IF(ISNUMBER(S9),IF(ISNUMBER(S8),IF(S9>S8,1.0,IF(S9=S8,0.5,0.0)),""),"") | V9: =IF(ISNUMBER(S9),IF(ISNUMBER(S10),IF(S9>S10,1.0,IF(S9=S10,0.5,0.0)),""),"") | W9: =IF(ISNUMBER(S9),IF(ISNUMBER(S11),IF(S9>S11,1.0,IF(S9=S11,0.5,0.0)),""),"") | X9: =IF(ISNUMBER(S9),IF(ISNUMBER(S12),IF(S9>S12,1.0,IF(S9=S12,0.5,0.0)),""),"") | Y9: =IF(ISNUMBER(T9),IF(ISNUMBER(T8),IF(T9>T8,1.0,IF(T9=T8,0.5,0.0)),""),"") | Z9: =IF(ISNUMBER(T9),IF(ISNUMBER(T10),IF(T9>T10,1.0,IF(T9=T10,0.5,0.0)),""),"") | AA9: =IF(ISNUMBER(T9),IF(ISNUMBER(T11),IF(T9>T11,1.0,IF(T9=T11,0.5,0.0)),""),"") | AB9: =IF(ISNUMBER(T9),IF(ISNUMBER(T12),IF(T9>T12,1.0,IF(T9=T12,0.5,0.0)),""),"") | AC9: =IF(AND(ISNUMBER(S9),ISNUMBER(S8)),VLOOKUP(ABS(S9-S8),'IMP Table'!$A$2:$C$26,3)*SIGN(S9-S8),0) | AD9: =IF(AND(ISNUMBER(S9),ISNUMBER(S10)),VLOOKUP(ABS(S9-S10),'IMP Table'!$A$2:$C$26,3)*SIGN(S9-S10),0) | AE9: =IF(AND(ISNUMBER(S9),ISNUMBER(S11)),VLOOKUP(ABS(S9-S11),'IMP Table'!$A$2:$C$26,3)*SIGN(S9-S11),0) | AF9: =IF(AND(ISNUMBER(S9),ISNUMBER(S12)),VLOOKUP(ABS(S9-S12),'IMP Table'!$A$2:$C$26,3)*SIGN(S9-S12),0) | AG9: =IF(AND(ISNUMBER(T9),ISNUMBER(T8)),VLOOKUP(ABS(T9-T8),'IMP Table'!$A$2:$C$26,3)*SIGN(T9-T8),0) | AH9: =IF(AND(ISNUMBER(T9),ISNUMBER(T10)),VLOOKUP(ABS(T9-T10),'IMP Table'!$A$2:$C$26,3)*SIGN(T9-T10),0) | AI9: =IF(AND(ISNUMBER(T9),ISNUMBER(T11)),VLOOKUP(ABS(T9-T11),'IMP Table'!$A$2:$C$26,3)*SIGN(T9-T11),0) | AJ9: =IF(AND(ISNUMBER(T9),ISNUMBER(T12)),VLOOKUP(ABS(T9-T12),'IMP Table'!$A$2:$C$26,3)*SIGN(T9-T12),0)
B10: ='By Round'!A23 | C10: ='By Round'!B29 | D10: ='By Round'!C29 | E10: ='By Round'!D29 | F10: =IF(ISBLANK('By Round'!F30),"",'By Round'!F30) | G10: =IF(ISBLANK('By Round'!G30),"",'By Round'!G30) | H10: =IF(ISBLANK('By Round'!H30),"",'By Round'!H30) | I10: =IF(ISBLANK('By Round'!I30),"",'By Round'!I30) | J10: =IF(ISBLANK('By Round'!J30),"",'By Round'!J30) | K10: =IF(ISBLANK('By Round'!K30),"",'By Round'!K30) | L10: =IF(ISBLANK('By Round'!L30),"",'By Round'!L30) | M10: =AVERAGE(AC10:AF10) | N10: =AVERAGE(AG10:AJ10) | O10: =IF(COUNT(U10:X10)>0,Q10/COUNT(U10:X10),0.5) | P10: =IF(COUNT(Y10:AB10)>0,R10/COUNT(Y10:AB10),0.5) | Q10: =SUM(U10:X10) | R10: =SUM(Y10:AB10) | S10: =IF(ISNUMBER(K10),K10,IF(ISNUMBER(L10),-L10,"")) | T10: =IF(ISNUMBER(L10),L10,IF(ISNUMBER(K10),-K10,"")) | U10: =IF(ISNUMBER(S10),IF(ISNUMBER(S8),IF(S10>S8,1.0,IF(S10=S8,0.5,0.0)),""),"") | V10: =IF(ISNUMBER(S10),IF(ISNUMBER(S9),IF(S10>S9,1.0,IF(S10=S9,0.5,0.0)),""),"") | W10: =IF(ISNUMBER(S10),IF(ISNUMBER(S11),IF(S10>S11,1.0,IF(S10=S11,0.5,0.0)),""),"") | X10: =IF(ISNUMBER(S10),IF(ISNUMBER(S12),IF(S10>S12,1.0,IF(S10=S12,0.5,0.0)),""),"") | Y10: =IF(ISNUMBER(T10),IF(ISNUMBER(T8),IF(T10>T8,1.0,IF(T10=T8,0.5,0.0)),""),"") | Z10: =IF(ISNUMBER(T10),IF(ISNUMBER(T9),IF(T10>T9,1.0,IF(T10=T9,0.5,0.0)),""),"") | AA10: =IF(ISNUMBER(T10),IF(ISNUMBER(T11),IF(T10>T11,1.0,IF(T10=T11,0.5,0.0)),""),"") | AB10: =IF(ISNUMBER(T10),IF(ISNUMBER(T12),IF(T10>T12,1.0,IF(T10=T12,0.5,0.0)),""),"") | AC10: =IF(AND(ISNUMBER(S10),ISNUMBER(S8)),VLOOKUP(ABS(S10-S8),'IMP Table'!$A$2:$C$26,3)*SIGN(S10-S8),0) | AD10: =IF(AND(ISNUMBER(S10),ISNUMBER(S9)),VLOOKUP(ABS(S10-S9),'IMP Table'!$A$2:$C$26,3)*SIGN(S10-S9),0) | AE10: =IF(AND(ISNUMBER(S10),ISNUMBER(S11)),VLOOKUP(ABS(S10-S11),'IMP Table'!$A$2:$C$26,3)*SIGN(S10-S11),0) | AF10: =IF(AND(ISNUMBER(S10),ISNUMBER(S12)),VLOOKUP(ABS(S10-S12),'IMP Table'!$A$2:$C$26,3)*SIGN(S10-S12),0) | AG10: =IF(AND(ISNUMBER(T10),ISNUMBER(T8)),VLOOKUP(ABS(T10-T8),'IMP Table'!$A$2:$C$26,3)*SIGN(T10-T8),0) | AH10: =IF(AND(ISNUMBER(T10),ISNUMBER(T9)),VLOOKUP(ABS(T10-T9),'IMP Table'!$A$2:$C$26,3)*SIGN(T10-T9),0) | AI10: =IF(AND(ISNUMBER(T10),ISNUMBER(T11)),VLOOKUP(ABS(T10-T11),'IMP Table'!$A$2:$C$26,3)*SIGN(T10-T11),0) | AJ10: =IF(AND(ISNUMBER(T10),ISNUMBER(T12)),VLOOKUP(ABS(T10-T12),'IMP Table'!$A$2:$C$26,3)*SIGN(T10-T12),0)
B11: ='By Round'!A13 | C11: ='By Round'!B21 | D11: ='By Round'!C21 | E11: ='By Round'!D21 | F11: =IF(ISBLANK('By Round'!F22),"",'By Round'!F22) | G11: =IF(ISBLANK('By Round'!G22),"",'By Round'!G22) | H11: =IF(ISBLANK('By Round'!H22),"",'By Round'!H22) | I11: =IF(ISBLANK('By Round'!I22),"",'By Round'!I22) | J11: =IF(ISBLANK('By Round'!J22),"",'By Round'!J22) | K11: =IF(ISBLANK('By Round'!K22),"",'By Round'!K22) | L11: =IF(ISBLANK('By Round'!L22),"",'By Round'!L22) | M11: =AVERAGE(AC11:AF11) | N11: =AVERAGE(AG11:AJ11) | O11: =IF(COUNT(U11:X11)>0,Q11/COUNT(U11:X11),0.5) | P11: =IF(COUNT(Y11:AB11)>0,R11/COUNT(Y11:AB11),0.5) | Q11: =SUM(U11:X11) | R11: =SUM(Y11:AB11) | S11: =IF(ISNUMBER(K11),K11,IF(ISNUMBER(L11),-L11,"")) | T11: =IF(ISNUMBER(L11),L11,IF(ISNUMBER(K11),-K11,"")) | U11: =IF(ISNUMBER(S11),IF(ISNUMBER(S8),IF(S11>S8,1.0,IF(S11=S8,0.5,0.0)),""),"") | V11: =IF(ISNUMBER(S11),IF(ISNUMBER(S9),IF(S11>S9,1.0,IF(S11=S9,0.5,0.0)),""),"") | W11: =IF(ISNUMBER(S11),IF(ISNUMBER(S10),IF(S11>S10,1.0,IF(S11=S10,0.5,0.0)),""),"") | X11: =IF(ISNUMBER(S11),IF(ISNUMBER(S12),IF(S11>S12,1.0,IF(S11=S12,0.5,0.0)),""),"") | Y11: =IF(ISNUMBER(T11),IF(ISNUMBER(T8),IF(T11>T8,1.0,IF(T11=T8,0.5,0.0)),""),"") | Z11: =IF(ISNUMBER(T11),IF(ISNUMBER(T9),IF(T11>T9,1.0,IF(T11=T9,0.5,0.0)),""),"") | AA11: =IF(ISNUMBER(T11),IF(ISNUMBER(T10),IF(T11>T10,1.0,IF(T11=T10,0.5,0.0)),""),"") | AB11: =IF(ISNUMBER(T11),IF(ISNUMBER(T12),IF(T11>T12,1.0,IF(T11=T12,0.5,0.0)),""),"") | AC11: =IF(AND(ISNUMBER(S11),ISNUMBER(S8)),VLOOKUP(ABS(S11-S8),'IMP Table'!$A$2:$C$26,3)*SIGN(S11-S8),0) | AD11: =IF(AND(ISNUMBER(S11),ISNUMBER(S9)),VLOOKUP(ABS(S11-S9),'IMP Table'!$A$2:$C$26,3)*SIGN(S11-S9),0) | AE11: =IF(AND(ISNUMBER(S11),ISNUMBER(S10)),VLOOKUP(ABS(S11-S10),'IMP Table'!$A$2:$C$26,3)*SIGN(S11-S10),0) | AF11: =IF(AND(ISNUMBER(S11),ISNUMBER(S12)),VLOOKUP(ABS(S11-S12),'IMP Table'!$A$2:$C$26,3)*SIGN(S11-S12),0) | AG11: =IF(AND(ISNUMBER(T11),ISNUMBER(T8)),VLOOKUP(ABS(T11-T8),'IMP Table'!$A$2:$C$26,3)*SIGN(T11-T8),0) | AH11: =IF(AND(ISNUMBER(T11),ISNUMBER(T9)),VLOOKUP(ABS(T11-T9),'IMP Table'!$A$2:$C$26,3)*SIGN(T11-T9),0) | AI11: =IF(AND(ISNUMBER(T11),ISNUMBER(T10)),VLOOKUP(ABS(T11-T10),'IMP Table'!$A$2:$C$26,3)*SIGN(T11-T10),0) | AJ11: =IF(AND(ISNUMBER(T11),ISNUMBER(T12)),VLOOKUP(ABS(T11-T12),'IMP Table'!$A$2:$C$26,3)*SIGN(T11-T12),0)
B12: ='By Round'!A83 | C12: ='By Round'!B85 | D12: ='By Round'!C85 | E12: ='By Round'!D85 | F12: =IF(ISBLANK('By Round'!F86),"",'By Round'!F86) | G12: =IF(ISBLANK('By Round'!G86),"",'By Round'!G86) | H12: =IF(ISBLANK('By Round'!H86),"",'By Round'!H86) | I12: =IF(ISBLANK('By Round'!I86),"",'By Round'!I86) | J12: =IF(ISBLANK('By Round'!J86),"",'By Round'!J86) | K12: =IF(ISBLANK('By Round'!K86),"",'By Round'!K86) | L12: =IF(ISBLANK('By Round'!L86),"",'By Round'!L86) | M12: =AVERAGE(AC12:AF12) | N12: =AVERAGE(AG12:AJ12) | O12: =IF(COUNT(U12:X12)>0,Q12/COUNT(U12:X12),0.5) | P12: =IF(COUNT(Y12:AB12)>0,R12/COUNT(Y12:AB12),0.5) | Q12: =SUM(U12:X12) | R12: =SUM(Y12:AB12) | S12: =IF(ISNUMBER(K12),K12,IF(ISNUMBER(L12),-L12,"")) | T12: =IF(ISNUMBER(L12),L12,IF(ISNUMBER(K12),-K12,"")) | U12: =IF(ISNUMBER(S12),IF(ISNUMBER(S8),IF(S12>S8,1.0,IF(S12=S8,0.5,0.0)),""),"") | V12: =IF(ISNUMBER(S12),IF(ISNUMBER(S9),IF(S12>S9,1.0,IF(S12=S9,0.5,0.0)),""),"") | W12: =IF(ISNUMBER(S12),IF(ISNUMBER(S10),IF(S12>S10,1.0,IF(S12=S10,0.5,0.0)),""),"") | X12: =IF(ISNUMBER(S12),IF(ISNUMBER(S11),IF(S12>S11,1.0,IF(S12=S11,0.5,0.0)),""),"") | Y12: =IF(ISNUMBER(T12),IF(ISNUMBER(T8),IF(T12>T8,1.0,IF(T12=T8,0.5,0.0)),""),"") | Z12: =IF(ISNUMBER(T12),IF(ISNUMBER(T9),IF(T12>T9,1.0,IF(T12=T9,0.5,0.0)),""),"") | AA12: =IF(ISNUMBER(T12),IF(ISNUMBER(T10),IF(T12>T10,1.0,IF(T12=T10,0.5,0.0)),""),"") | AB12: =IF(ISNUMBER(T12),IF(ISNUMBER(T11),IF(T12>T11,1.0,IF(T12=T11,0.5,0.0)),""),"") | AC12: =IF(AND(ISNUMBER(S12),ISNUMBER(S8)),VLOOKUP(ABS(S12-S8),'IMP Table'!$A$2:$C$26,3)*SIGN(S12-S8),0) | AD12: =IF(AND(ISNUMBER(S12),ISNUMBER(S9)),VLOOKUP(ABS(S12-S9),'IMP Table'!$A$2:$C$26,3)*SIGN(S12-S9),0) | AE12: =IF(AND(ISNUMBER(S12),ISNUMBER(S10)),VLOOKUP(ABS(S12-S10),'IMP Table'!$A$2:$C$26,3)*SIGN(S12-S10),0) | AF12: =IF(AND(ISNUMBER(S12),ISNUMBER(S11)),VLOOKUP(ABS(S12-S11),'IMP Table'!$A$2:$C$26,3)*SIGN(S12-S11),0) | AG12: =IF(AND(ISNUMBER(T12),ISNUMBER(T8)),VLOOKUP(ABS(T12-T8),'IMP Table'!$A$2:$C$26,3)*SIGN(T12-T8),0) | AH12: =IF(AND(ISNUMBER(T12),ISNUMBER(T9)),VLOOKUP(ABS(T12-T9),'IMP Table'!$A$2:$C$26,3)*SIGN(T12-T9),0) | AI12: =IF(AND(ISNUMBER(T12),ISNUMBER(T10)),VLOOKUP(ABS(T12-T10),'IMP Table'!$A$2:$C$26,3)*SIGN(T12-T10),0) | AJ12: =IF(AND(ISNUMBER(T12),ISNUMBER(T11)),VLOOKUP(ABS(T12-T11),'IMP Table'!$A$2:$C$26,3)*SIGN(T12-T11),0)
A13: 3 | B13: ='By Round'!A13 | C13: ='By Round'!B13 | D13: ='By Round'!C13 | E13: ='By Round'!D13 | F13: =IF(ISBLANK('By Round'!F13),"",'By Round'!F13) | G13: =IF(ISBLANK('By Round'!G13),"",'By Round'!G13) | H13: =IF(ISBLANK('By Round'!H13),"",'By Round'!H13) | I13: =IF(ISBLANK('By Round'!I13),"",'By Round'!I13) | J13: =IF(ISBLANK('By Round'!J13),"",'By Round'!J13) | K13: =IF(ISBLANK('By Round'!K13),"",'By Round'!K13) | L13: =IF(ISBLANK('By Round'!L13),"",'By Round'!L13) | M13: =AVERAGE(AC13:AF13) | N13: =AVERAGE(AG13:AJ13) | O13: =IF(COUNT(U13:X13)>0,Q13/COUNT(U13:X13),0.5) | P13: =IF(COUNT(Y13:AB13)>0,R13/COUNT(Y13:AB13),0.5) | Q13: =SUM(U13:X13) | R13: =SUM(Y13:AB13) | S13: =IF(ISNUMBER(K13),K13,IF(ISNUMBER(L13),-L13,"")) | T13: =IF(ISNUMBER(L13),L13,IF(ISNUMBER(K13),-K13,"")) | U13: =IF(ISNUMBER(S13),IF(ISNUMBER(S14),IF(S13>S14,1.0,IF(S13=S14,0.5,0.0)),""),"") | V13: =IF(ISNUMBER(S13),IF(ISNUMBER(S15),IF(S13>S15,1.0,IF(S13=S15,0.5,0.0)),""),"") | W13: =IF(ISNUMBER(S13),IF(ISNUMBER(S16),IF(S13>S16,1.0,IF(S13=S16,0.5,0.0)),""),"") | X13: =IF(ISNUMBER(S13),IF(ISNUMBER(S17),IF(S13>S17,1.0,IF(S13=S17,0.5,0.0)),""),"") | Y13: =IF(ISNUMBER(T13),IF(ISNUMBER(T14),IF(T13>T14,1.0,IF(T13=T14,0.5,0.0)),""),"") | Z13: =IF(ISNUMBER(T13),IF(ISNUMBER(T15),IF(T13>T15,1.0,IF(T13=T15,0.5,0.0)),""),"") | AA13: =IF(ISNUMBER(T13),IF(ISNUMBER(T16),IF(T13>T16,1.0,IF(T13=T16,0.5,0.0)),""),"") | AB13: =IF(ISNUMBER(T13),IF(ISNUMBER(T17),IF(T13>T17,1.0,IF(T13=T17,0.5,0.0)),""),"") | AC13: =IF(AND(ISNUMBER(S13),ISNUMBER(S14)),VLOOKUP(ABS(S13-S14),'IMP Table'!$A$2:$C$26,3)*SIGN(S13-S14),0) | AD13: =IF(AND(ISNUMBER(S13),ISNUMBER(S15)),VLOOKUP(ABS(S13-S15),'IMP Table'!$A$2:$C$26,3)*SIGN(S13-S15),0) | AE13: =IF(AND(ISNUMBER(S13),ISNUMBER(S16)),VLOOKUP(ABS(S13-S16),'IMP Table'!$A$2:$C$26,3)*SIGN(S13-S16),0) | AF13: =IF(AND(ISNUMBER(S13),ISNUMBER(S17)),VLOOKUP(ABS(S13-S17),'IMP Table'!$A$2:$C$26,3)*SIGN(S13-S17),0) | AG13: =IF(AND(ISNUMBER(T13),ISNUMBER(T14)),VLOOKUP(ABS(T13-T14),'IMP Table'!$A$2:$C$26,3)*SIGN(T13-T14),0) | AH13: =IF(AND(ISNUMBER(T13),ISNUMBER(T15)),VLOOKUP(ABS(T13-T15),'IMP Table'!$A$2:$C$26,3)*SIGN(T13-T15),0) | AI13: =IF(AND(ISNUMBER(T13),ISNUMBER(T16)),VLOOKUP(ABS(T13-T16),'IMP Table'!$A$2:$C$26,3)*SIGN(T13-T16),0) | AJ13: =IF(AND(ISNUMBER(T13),ISNUMBER(T17)),VLOOKUP(ABS(T13-T17),'IMP Table'!$A$2:$C$26,3)*SIGN(T13-T17),0)
B14: ='By Round'!A83 | C14: ='By Round'!B87 | D14: ='By Round'!C87 | E14: ='By Round'!D87 | F14: =IF(ISBLANK('By Round'!F87),"",'By Round'!F87) | G14: =IF(ISBLANK('By Round'!G87),"",'By Round'!G87) | H14: =IF(ISBLANK('By Round'!H87),"",'By Round'!H87) | I14: =IF(ISBLANK('By Round'!I87),"",'By Round'!I87) | J14: =IF(ISBLANK('By Round'!J87),"",'By Round'!J87) | K14: =IF(ISBLANK('By Round'!K87),"",'By Round'!K87) | L14: =IF(ISBLANK('By Round'!L87),"",'By Round'!L87) | M14: =AVERAGE(AC14:AF14) | N14: =AVERAGE(AG14:AJ14) | O14: =IF(COUNT(U14:X14)>0,Q14/COUNT(U14:X14),0.5) | P14: =IF(COUNT(Y14:AB14)>0,R14/COUNT(Y14:AB14),0.5) | Q14: =SUM(U14:X14) | R14: =SUM(Y14:AB14) | S14: =IF(ISNUMBER(K14),K14,IF(ISNUMBER(L14),-L14,"")) | T14: =IF(ISNUMBER(L14),L14,IF(ISNUMBER(K14),-K14,"")) | U14: =IF(ISNUMBER(S14),IF(ISNUMBER(S13),IF(S14>S13,1.0,IF(S14=S13,0.5,0.0)),""),"") | V14: =IF(ISNUMBER(S14),IF(ISNUMBER(S15),IF(S14>S15,1.0,IF(S14=S15,0.5,0.0)),""),"") | W14: =IF(ISNUMBER(S14),IF(ISNUMBER(S16),IF(S14>S16,1.0,IF(S14=S16,0.5,0.0)),""),"") | X14: =IF(ISNUMBER(S14),IF(ISNUMBER(S17),IF(S14>S17,1.0,IF(S14=S17,0.5,0.0)),""),"") | Y14: =IF(ISNUMBER(T14),IF(ISNUMBER(T13),IF(T14>T13,1.0,IF(T14=T13,0.5,0.0)),""),"") | Z14: =IF(ISNUMBER(T14),IF(ISNUMBER(T15),IF(T14>T15,1.0,IF(T14=T15,0.5,0.0)),""),"") | AA14: =IF(ISNUMBER(T14),IF(ISNUMBER(T16),IF(T14>T16,1.0,IF(T14=T16,0.5,0.0)),""),"") | AB14: =IF(ISNUMBER(T14),IF(ISNUMBER(T17),IF(T14>T17,1.0,IF(T14=T17,0.5,0.0)),""),"") | AC14: =IF(AND(ISNUMBER(S14),ISNUMBER(S13)),VLOOKUP(ABS(S14-S13),'IMP Table'!$A$2:$C$26,3)*SIGN(S14-S13),0) | AD14: =IF(AND(ISNUMBER(S14),ISNUMBER(S15)),VLOOKUP(ABS(S14-S15),'IMP Table'!$A$2:$C$26,3)*SIGN(S14-S15),0) | AE14: =IF(AND(ISNUMBER(S14),ISNUMBER(S16)),VLOOKUP(ABS(S14-S16),'IMP Table'!$A$2:$C$26,3)*SIGN(S14-S16),0) | AF14: =IF(AND(ISNUMBER(S14),ISNUMBER(S17)),VLOOKUP(ABS(S14-S17),'IMP Table'!$A$2:$C$26,3)*SIGN(S14-S17),0) | AG14: =IF(AND(ISNUMBER(T14),ISNUMBER(T13)),VLOOKUP(ABS(T14-T13),'IMP Table'!$A$2:$C$26,3)*SIGN(T14-T13),0) | AH14: =IF(AND(ISNUMBER(T14),ISNUMBER(T15)),VLOOKUP(ABS(T14-T15),'IMP Table'!$A$2:$C$26,3)*SIGN(T14-T15),0) | AI14: =IF(AND(ISNUMBER(T14),ISNUMBER(T16)),VLOOKUP(ABS(T14-T16),'IMP Table'!$A$2:$C$26,3)*SIGN(T14-T16),0) | AJ14: =IF(AND(ISNUMBER(T14),ISNUMBER(T17)),VLOOKUP(ABS(T14-T17),'IMP Table'!$A$2:$C$26,3)*SIGN(T14-T17),0)
B15: ='By Round'!A33 | C15: ='By Round'!B39 | D15: ='By Round'!C39 | E15: ='By Round'!D39 | F15: =IF(ISBLANK('By Round'!F39),"",'By Round'!F39) | G15: =IF(ISBLANK('By Round'!G39),"",'By Round'!G39) | H15: =IF(ISBLANK('By Round'!H39),"",'By Round'!H39) | I15: =IF(ISBLANK('By Round'!I39),"",'By Round'!I39) | J15: =IF(ISBLANK('By Round'!J39),"",'By Round'!J39) | K15: =IF(ISBLANK('By Round'!K39),"",'By Round'!K39) | L15: =IF(ISBLANK('By Round'!L39),"",'By Round'!L39) | M15: =AVERAGE(AC15:AF15) | N15: =AVERAGE(AG15:AJ15) | O15: =IF(COUNT(U15:X15)>0,Q15/COUNT(U15:X15),0.5) | P15: =IF(COUNT(Y15:AB15)>0,R15/COUNT(Y15:AB15),0.5) | Q15: =SUM(U15:X15) | R15: =SUM(Y15:AB15) | S15: =IF(ISNUMBER(K15),K15,IF(ISNUMBER(L15),-L15,"")) | T15: =IF(ISNUMBER(L15),L15,IF(ISNUMBER(K15),-K15,"")) | U15: =IF(ISNUMBER(S15),IF(ISNUMBER(S13),IF(S15>S13,1.0,IF(S15=S13,0.5,0.0)),""),"") | V15: =IF(ISNUMBER(S15),IF(ISNUMBER(S14),IF(S15>S14,1.0,IF(S15=S14,0.5,0.0)),""),"") | W15: =IF(ISNUMBER(S15),IF(ISNUMBER(S16),IF(S15>S16,1.0,IF(S15=S16,0.5,0.0)),""),"") | X15: =IF(ISNUMBER(S15),IF(ISNUMBER(S17),IF(S15>S17,1.0,IF(S15=S17,0.5,0.0)),""),"") | Y15: =IF(ISNUMBER(T15),IF(ISNUMBER(T13),IF(T15>T13,1.0,IF(T15=T13,0.5,0.0)),""),"") | Z15: =IF(ISNUMBER(T15),IF(ISNUMBER(T14),IF(T15>T14,1.0,IF(T15=T14,0.5,0.0)),""),"") | AA15: =IF(ISNUMBER(T15),IF(ISNUMBER(T16),IF(T15>T16,1.0,IF(T15=T16,0.5,0.0)),""),"") | AB15: =IF(ISNUMBER(T15),IF(ISNUMBER(T17),IF(T15>T17,1.0,IF(T15=T17,0.5,0.0)),""),"") | AC15: =IF(AND(ISNUMBER(S15),ISNUMBER(S13)),VLOOKUP(ABS(S15-S13),'IMP Table'!$A$2:$C$26,3)*SIGN(S15-S13),0) | AD15: =IF(AND(ISNUMBER(S15),ISNUMBER(S14)),VLOOKUP(ABS(S15-S14),'IMP Table'!$A$2:$C$26,3)*SIGN(S15-S14),0) | AE15: =IF(AND(ISNUMBER(S15),ISNUMBER(S16)),VLOOKUP(ABS(S15-S16),'IMP Table'!$A$2:$C$26,3)*SIGN(S15-S16),0) | AF15: =IF(AND(ISNUMBER(S15),ISNUMBER(S17)),VLOOKUP(ABS(S15-S17),'IMP Table'!$A$2:$C$26,3)*SIGN(S15-S17),0) | AG15: =IF(AND(ISNUMBER(T15),ISNUMBER(T13)),VLOOKUP(ABS(T15-T13),'IMP Table'!$A$2:$C$26,3)*SIGN(T15-T13),0) | AH15: =IF(AND(ISNUMBER(T15),ISNUMBER(T14)),VLOOKUP(ABS(T15-T14),'IMP Table'!$A$2:$C$26,3)*SIGN(T15-T14),0) | AI15: =IF(AND(ISNUMBER(T15),ISNUMBER(T16)),VLOOKUP(ABS(T15-T16),'IMP Table'!$A$2:$C$26,3)*SIGN(T15-T16),0) | AJ15: =IF(AND(ISNUMBER(T15),ISNUMBER(T17)),VLOOKUP(ABS(T15-T17),'IMP Table'!$A$2:$C$26,3)*SIGN(T15-T17),0)
B16: ='By Round'!A23 | C16: ='By Round'!B31 | D16: ='By Round'!C31 | E16: ='By Round'!D31 | F16: =IF(ISBLANK('By Round'!F31),"",'By Round'!F31) | G16: =IF(ISBLANK('By Round'!G31),"",'By Round'!G31) | H16: =IF(ISBLANK('By Round'!H31),"",'By Round'!H31) | I16: =IF(ISBLANK('By Round'!I31),"",'By Round'!I31) | J16: =IF(ISBLANK('By Round'!J31),"",'By Round'!J31) | K16: =IF(ISBLANK('By Round'!K31),"",'By Round'!K31) | L16: =IF(ISBLANK('By Round'!L31),"",'By Round'!L31) | M16: =AVERAGE(AC16:AF16) | N16: =AVERAGE(AG16:AJ16) | O16: =IF(COUNT(U16:X16)>0,Q16/COUNT(U16:X16),0.5) | P16: =IF(COUNT(Y16:AB16)>0,R16/COUNT(Y16:AB16),0.5) | Q16: =SUM(U16:X16) | R16: =SUM(Y16:AB16) | S16: =IF(ISNUMBER(K16),K16,IF(ISNUMBER(L16),-L16,"")) | T16: =IF(ISNUMBER(L16),L16,IF(ISNUMBER(K16),-K16,"")) | U16: =IF(ISNUMBER(S16),IF(ISNUMBER(S13),IF(S16>S13,1.0,IF(S16=S13,0.5,0.0)),""),"") | V16: =IF(ISNUMBER(S16),IF(ISNUMBER(S14),IF(S16>S14,1.0,IF(S16=S14,0.5,0.0)),""),"") | W16: =IF(ISNUMBER(S16),IF(ISNUMBER(S15),IF(S16>S15,1.0,IF(S16=S15,0.5,0.0)),""),"") | X16: =IF(ISNUMBER(S16),IF(ISNUMBER(S17),IF(S16>S17,1.0,IF(S16=S17,0.5,0.0)),""),"") | Y16: =IF(ISNUMBER(T16),IF(ISNUMBER(T13),IF(T16>T13,1.0,IF(T16=T13,0.5,0.0)),""),"") | Z16: =IF(ISNUMBER(T16),IF(ISNUMBER(T14),IF(T16>T14,1.0,IF(T16=T14,0.5,0.0)),""),"") | AA16: =IF(ISNUMBER(T16),IF(ISNUMBER(T15),IF(T16>T15,1.0,IF(T16=T15,0.5,0.0)),""),"") | AB16: =IF(ISNUMBER(T16),IF(ISNUMBER(T17),IF(T16>T17,1.0,IF(T16=T17,0.5,0.0)),""),"") | AC16: =IF(AND(ISNUMBER(S16),ISNUMBER(S13)),VLOOKUP(ABS(S16-S13),'IMP Table'!$A$2:$C$26,3)*SIGN(S16-S13),0) | AD16: =IF(AND(ISNUMBER(S16),ISNUMBER(S14)),VLOOKUP(ABS(S16-S14),'IMP Table'!$A$2:$C$26,3)*SIGN(S16-S14),0) | AE16: =IF(AND(ISNUMBER(S16),ISNUMBER(S15)),VLOOKUP(ABS(S16-S15),'IMP Table'!$A$2:$C$26,3)*SIGN(S16-S15),0) | AF16: =IF(AND(ISNUMBER(S16),ISNUMBER(S17)),VLOOKUP(ABS(S16-S17),'IMP Table'!$A$2:$C$26,3)*SIGN(S16-S17),0) | AG16: =IF(AND(ISNUMBER(T16),ISNUMBER(T13)),VLOOKUP(ABS(T16-T13),'IMP Table'!$A$2:$C$26,3)*SIGN(T16-T13),0) | AH16: =IF(AND(ISNUMBER(T16),ISNUMBER(T14)),VLOOKUP(ABS(T16-T14),'IMP Table'!$A$2:$C$26,3)*SIGN(T16-T14),0) | AI16: =IF(AND(ISNUMBER(T16),ISNUMBER(T15)),VLOOKUP(ABS(T16-T15),'IMP Table'!$A$2:$C$26,3)*SIGN(T16-T15),0) | AJ16: =IF(AND(ISNUMBER(T16),ISNUMBER(T17)),VLOOKUP(ABS(T16-T17),'IMP Table'!$A$2:$C$26,3)*SIGN(T16-T17),0)
B17: ='By Round'!A3 | C17: ='By Round'!B5 | D17: ='By Round'!C5 | E17: ='By Round'!D5 | F17: =IF(ISBLANK('By Round'!F5),"",'By Round'!F5) | G17: =IF(ISBLANK('By Round'!G5),"",'By Round'!G5) | H17: =IF(ISBLANK('By Round'!H5),"",'By Round'!H5) | I17: =IF(ISBLANK('By Round'!I5),"",'By Round'!I5) | J17: =IF(ISBLANK('By Round'!J5),"",'By Round'!J5) | K17: =IF(ISBLANK('By Round'!K5),"",'By Round'!K5) | L17: =IF(ISBLANK('By Round'!L5),"",'By Round'!L5) | M17: =AVERAGE(AC17:AF17) | N17: =AVERAGE(AG17:AJ17) | O17: =IF(COUNT(U17:X17)>0,Q17/COUNT(U17:X17),0.5) | P17: =IF(COUNT(Y17:AB17)>0,R17/COUNT(Y17:AB17),0.5) | Q17: =SUM(U17:X17) | R17: =SUM(Y17:AB17) | S17: =IF(ISNUMBER(K17),K17,IF(ISNUMBER(L17),-L17,"")) | T17: =IF(ISNUMBER(L17),L17,IF(ISNUMBER(K17),-K17,"")) | U17: =IF(ISNUMBER(S17),IF(ISNUMBER(S13),IF(S17>S13,1.0,IF(S17=S13,0.5,0.0)),""),"") | V17: =IF(ISNUMBER(S17),IF(ISNUMBER(S14),IF(S17>S14,1.0,IF(S17=S14,0.5,0.0)),""),"") | W17: =IF(ISNUMBER(S17),IF(ISNUMBER(S15),IF(S17>S15,1.0,IF(S17=S15,0.5,0.0)),""),"") | X17: =IF(ISNUMBER(S17),IF(ISNUMBER(S16),IF(S17>S16,1.0,IF(S17=S16,0.5,0.0)),""),"") | Y17: =IF(ISNUMBER(T17),IF(ISNUMBER(T13),IF(T17>T13,1.0,IF(T17=T13,0.5,0.0)),""),"") | Z17: =IF(ISNUMBER(T17),IF(ISNUMBER(T14),IF(T17>T14,1.0,IF(T17=T14,0.5,0.0)),""),"") | AA17: =IF(ISNUMBER(T17),IF(ISNUMBER(T15),IF(T17>T15,1.0,IF(T17=T15,0.5,0.0)),""),"") | AB17: =IF(ISNUMBER(T17),IF(ISNUMBER(T16),IF(T17>T16,1.0,IF(T17=T16,0.5,0.0)),""),"") | AC17: =IF(AND(ISNUMBER(S17),ISNUMBER(S13)),VLOOKUP(ABS(S17-S13),'IMP Table'!$A$2:$C$26,3)*SIGN(S17-S13),0) | AD17: =IF(AND(ISNUMBER(S17),ISNUMBER(S14)),VLOOKUP(ABS(S17-S14),'IMP Table'!$A$2:$C$26,3)*SIGN(S17-S14),0) | AE17: =IF(AND(ISNUMBER(S17),ISNUMBER(S15)),VLOOKUP(ABS(S17-S15),'IMP Table'!$A$2:$C$26,3)*SIGN(S17-S15),0) | AF17: =IF(AND(ISNUMBER(S17),ISNUMBER(S16)),VLOOKUP(ABS(S17-S16),'IMP Table'!$A$2:$C$26,3)*SIGN(S17-S16),0) | AG17: =IF(AND(ISNUMBER(T17),ISNUMBER(T13)),VLOOKUP(ABS(T17-T13),'IMP Table'!$A$2:$C$26,3)*SIGN(T17-T13),0) | AH17: =IF(AND(ISNUMBER(T17),ISNUMBER(T14)),VLOOKUP(ABS(T17-T14),'IMP Table'!$A$2:$C$26,3)*SIGN(T17-T14),0) | AI17: =IF(AND(ISNUMBER(T17),ISNUMBER(T15)),VLOOKUP(ABS(T17-T15),'IMP Table'!$A$2:$C$26,3)*SIGN(T17-T15),0) | AJ17: =IF(AND(ISNUMBER(T17),ISNUMBER(T16)),VLOOKUP(ABS(T17-T16),'IMP Table'!$A$2:$C$26,3)*SIGN(T17-T16),0)
A18: 4 | B18: ='By Round'!A13 | C18: ='By Round'!B13 | D18: ='By Round'!C13 | E18: ='By Round'!D13 | F18: =IF(ISBLANK('By Round'!F14),"",'By Round'!F14) | G18: =IF(ISBLANK('By Round'!G14),"",'By Round'!G14) | H18: =IF(ISBLANK('By Round'!H14),"",'By Round'!H14) | I18: =IF(ISBLANK('By Round'!I14),"",'By Round'!I14) | J18: =IF(ISBLANK('By Round'!J14),"",'By Round'!J14) | K18: =IF(ISBLANK('By Round'!K14),"",'By Round'!K14) | L18: =IF(ISBLANK('By Round'!L14),"",'By Round'!L14) | M18: =AVERAGE(AC18:AF18) | N18: =AVERAGE(AG18:AJ18) | O18: =IF(COUNT(U18:X18)>0,Q18/COUNT(U18:X18),0.5) | P18: =IF(COUNT(Y18:AB18)>0,R18/COUNT(Y18:AB18),0.5) | Q18: =SUM(U18:X18) | R18: =SUM(Y18:AB18) | S18: =IF(ISNUMBER(K18),K18,IF(ISNUMBER(L18),-L18,"")) | T18: =IF(ISNUMBER(L18),L18,IF(ISNUMBER(K18),-K18,"")) | U18: =IF(ISNUMBER(S18),IF(ISNUMBER(S19),IF(S18>S19,1.0,IF(S18=S19,0.5,0.0)),""),"") | V18: =IF(ISNUMBER(S18),IF(ISNUMBER(S20),IF(S18>S20,1.0,IF(S18=S20,0.5,0.0)),""),"") | W18: =IF(ISNUMBER(S18),IF(ISNUMBER(S21),IF(S18>S21,1.0,IF(S18=S21,0.5,0.0)),""),"") | X18: =IF(ISNUMBER(S18),IF(ISNUMBER(S22),IF(S18>S22,1.0,IF(S18=S22,0.5,0.0)),""),"") | Y18: =IF(ISNUMBER(T18),IF(ISNUMBER(T19),IF(T18>T19,1.0,IF(T18=T19,0.5,0.0)),""),"") | Z18: =IF(ISNUMBER(T18),IF(ISNUMBER(T20),IF(T18>T20,1.0,IF(T18=T20,0.5,0.0)),""),"") | AA18: =IF(ISNUMBER(T18),IF(ISNUMBER(T21),IF(T18>T21,1.0,IF(T18=T21,0.5,0.0)),""),"") | AB18: =IF(ISNUMBER(T18),IF(ISNUMBER(T22),IF(T18>T22,1.0,IF(T18=T22,0.5,0.0)),""),"") | AC18: =IF(AND(ISNUMBER(S18),ISNUMBER(S19)),VLOOKUP(ABS(S18-S19),'IMP Table'!$A$2:$C$26,3)*SIGN(S18-S19),0) | AD18: =IF(AND(ISNUMBER(S18),ISNUMBER(S20)),VLOOKUP(ABS(S18-S20),'IMP Table'!$A$2:$C$26,3)*SIGN(S18-S20),0) | AE18: =IF(AND(ISNUMBER(S18),ISNUMBER(S21)),VLOOKUP(ABS(S18-S21),'IMP Table'!$A$2:$C$26,3)*SIGN(S18-S21),0) | AF18: =IF(AND(ISNUMBER(S18),ISNUMBER(S22)),VLOOKUP(ABS(S18-S22),'IMP Table'!$A$2:$C$26,3)*SIGN(S18-S22),0) | AG18: =IF(AND(ISNUMBER(T18),ISNUMBER(T19)),VLOOKUP(ABS(T18-T19),'IMP Table'!$A$2:$C$26,3)*SIGN(T18-T19),0) | AH18: =IF(AND(ISNUMBER(T18),ISNUMBER(T20)),VLOOKUP(ABS(T18-T20),'IMP Table'!$A$2:$C$26,3)*SIGN(T18-T20),0) | AI18: =IF(AND(ISNUMBER(T18),ISNUMBER(T21)),VLOOKUP(ABS(T18-T21),'IMP Table'!$A$2:$C$26,3)*SIGN(T18-T21),0) | AJ18: =IF(AND(ISNUMBER(T18),ISNUMBER(T22)),VLOOKUP(ABS(T18-T22),'IMP Table'!$A$2:$C$26,3)*SIGN(T18-T22),0)
B19: ='By Round'!A83 | C19: ='By Round'!B87 | D19: ='By Round'!C87 | E19: ='By Round'!D87 | F19: =IF(ISBLANK('By Round'!F88),"",'By Round'!F88) | G19: =IF(ISBLANK('By Round'!G88),"",'By Round'!G88) | H19: =IF(ISBLANK('By Round'!H88),"",'By Round'!H88) | I19: =IF(ISBLANK('By Round'!I88),"",'By Round'!I88) | J19: =IF(ISBLANK('By Round'!J88),"",'By Round'!J88) | K19: =IF(ISBLANK('By Round'!K88),"",'By Round'!K88) | L19: =IF(ISBLANK('By Round'!L88),"",'By Round'!L88) | M19: =AVERAGE(AC19:AF19) | N19: =AVERAGE(AG19:AJ19) | O19: =IF(COUNT(U19:X19)>0,Q19/COUNT(U19:X19),0.5) | P19: =IF(COUNT(Y19:AB19)>0,R19/COUNT(Y19:AB19),0.5) | Q19: =SUM(U19:X19) | R19: =SUM(Y19:AB19) | S19: =IF(ISNUMBER(K19),K19,IF(ISNUMBER(L19),-L19,"")) | T19: =IF(ISNUMBER(L19),L19,IF(ISNUMBER(K19),-K19,"")) | U19: =IF(ISNUMBER(S19),IF(ISNUMBER(S18),IF(S19>S18,1.0,IF(S19=S18,0.5,0.0)),""),"") | V19: =IF(ISNUMBER(S19),IF(ISNUMBER(S20),IF(S19>S20,1.0,IF(S19=S20,0.5,0.0)),""),"") | W19: =IF(ISNUMBER(S19),IF(ISNUMBER(S21),IF(S19>S21,1.0,IF(S19=S21,0.5,0.0)),""),"") | X19: =IF(ISNUMBER(S19),IF(ISNUMBER(S22),IF(S19>S22,1.0,IF(S19=S22,0.5,0.0)),""),"") | Y19: =IF(ISNUMBER(T19),IF(ISNUMBER(T18),IF(T19>T18,1.0,IF(T19=T18,0.5,0.0)),""),"") | Z19: =IF(ISNUMBER(T19),IF(ISNUMBER(T20),IF(T19>T20,1.0,IF(T19=T20,0.5,0.0)),""),"") | AA19: =IF(ISNUMBER(T19),IF(ISNUMBER(T21),IF(T19>T21,1.0,IF(T19=T21,0.5,0.0)),""),"") | AB19: =IF(ISNUMBER(T19),IF(ISNUMBER(T22),IF(T19>T22,1.0,IF(T19=T22,0.5,0.0)),""),"") | AC19: =IF(AND(ISNUMBER(S19),ISNUMBER(S18)),VLOOKUP(ABS(S19-S18),'IMP Table'!$A$2:$C$26,3)*SIGN(S19-S18),0) | AD19: =IF(AND(ISNUMBER(S19),ISNUMBER(S20)),VLOOKUP(ABS(S19-S20),'IMP Table'!$A$2:$C$26,3)*SIGN(S19-S20),0) | AE19: =IF(AND(ISNUMBER(S19),ISNUMBER(S21)),VLOOKUP(ABS(S19-S21),'IMP Table'!$A$2:$C$26,3)*SIGN(S19-S21),0) | AF19: =IF(AND(ISNUMBER(S19),ISNUMBER(S22)),VLOOKUP(ABS(S19-S22),'IMP Table'!$A$2:$C$26,3)*SIGN(S19-S22),0) | AG19: =IF(AND(ISNUMBER(T19),ISNUMBER(T18)),VLOOKUP(ABS(T19-T18),'IMP Table'!$A$2:$C$26,3)*SIGN(T19-T18),0) | AH19: =IF(AND(ISNUMBER(T19),ISNUMBER(T20)),VLOOKUP(ABS(T19-T20),'IMP Table'!$A$2:$C$26,3)*SIGN(T19-T20),0) | AI19: =IF(AND(ISNUMBER(T19),ISNUMBER(T21)),VLOOKUP(ABS(T19-T21),'IMP Table'!$A$2:$C$26,3)*SIGN(T19-T21),0) | AJ19: =IF(AND(ISNUMBER(T19),ISNUMBER(T22)),VLOOKUP(ABS(T19-T22),'IMP Table'!$A$2:$C$26,3)*SIGN(T19-T22),0)
B20: ='By Round'!A33 | C20: ='By Round'!B39 | D20: ='By Round'!C39 | E20: ='By Round'!D39 | F20: =IF(ISBLANK('By Round'!F40),"",'By Round'!F40) | G20: =IF(ISBLANK('By Round'!G40),"",'By Round'!G40) | H20: =IF(ISBLANK('By Round'!H40),"",'By Round'!H40) | I20: =IF(ISBLANK('By Round'!I40),"",'By Round'!I40) | J20: =IF(ISBLANK('By Round'!J40),"",'By Round'!J40) | K20: =IF(ISBLANK('By Round'!K40),"",'By Round'!K40) | L20: =IF(ISBLANK('By Round'!L40),"",'By Round'!L40) | M20: =AVERAGE(AC20:AF20) | N20: =AVERAGE(AG20:AJ20) | O20: =IF(COUNT(U20:X20)>0,Q20/COUNT(U20:X20),0.5) | P20: =IF(COUNT(Y20:AB20)>0,R20/COUNT(Y20:AB20),0.5) | Q20: =SUM(U20:X20) | R20: =SUM(Y20:AB20) | S20: =IF(ISNUMBER(K20),K20,IF(ISNUMBER(L20),-L20,"")) | T20: =IF(ISNUMBER(L20),L20,IF(ISNUMBER(K20),-K20,"")) | U20: =IF(ISNUMBER(S20),IF(ISNUMBER(S18),IF(S20>S18,1.0,IF(S20=S18,0.5,0.0)),""),"") | V20: =IF(ISNUMBER(S20),IF(ISNUMBER(S19),IF(S20>S19,1.0,IF(S20=S19,0.5,0.0)),""),"") | W20: =IF(ISNUMBER(S20),IF(ISNUMBER(S21),IF(S20>S21,1.0,IF(S20=S21,0.5,0.0)),""),"") | X20: =IF(ISNUMBER(S20),IF(ISNUMBER(S22),IF(S20>S22,1.0,IF(S20=S22,0.5,0.0)),""),"") | Y20: =IF(ISNUMBER(T20),IF(ISNUMBER(T18),IF(T20>T18,1.0,IF(T20=T18,0.5,0.0)),""),"") | Z20: =IF(ISNUMBER(T20),IF(ISNUMBER(T19),IF(T20>T19,1.0,IF(T20=T19,0.5,0.0)),""),"") | AA20: =IF(ISNUMBER(T20),IF(ISNUMBER(T21),IF(T20>T21,1.0,IF(T20=T21,0.5,0.0)),""),"") | AB20: =IF(ISNUMBER(T20),IF(ISNUMBER(T22),IF(T20>T22,1.0,IF(T20=T22,0.5,0.0)),""),"") | AC20: =IF(AND(ISNUMBER(S20),ISNUMBER(S18)),VLOOKUP(ABS(S20-S18),'IMP Table'!$A$2:$C$26,3)*SIGN(S20-S18),0) | AD20: =IF(AND(ISNUMBER(S20),ISNUMBER(S19)),VLOOKUP(ABS(S20-S19),'IMP Table'!$A$2:$C$26,3)*SIGN(S20-S19),0) | AE20: =IF(AND(ISNUMBER(S20),ISNUMBER(S21)),VLOOKUP(ABS(S20-S21),'IMP Table'!$A$2:$C$26,3)*SIGN(S20-S21),0) | AF20: =IF(AND(ISNUMBER(S20),ISNUMBER(S22)),VLOOKUP(ABS(S20-S22),'IMP Table'!$A$2:$C$26,3)*SIGN(S20-S22),0) | AG20: =IF(AND(ISNUMBER(T20),ISNUMBER(T18)),VLOOKUP(ABS(T20-T18),'IMP Table'!$A$2:$C$26,3)*SIGN(T20-T18),0) | AH20: =IF(AND(ISNUMBER(T20),ISNUMBER(T19)),VLOOKUP(ABS(T20-T19),'IMP Table'!$A$2:$C$26,3)*SIGN(T20-T19),0) | AI20: =IF(AND(ISNUMBER(T20),ISNUMBER(T21)),VLOOKUP(ABS(T20-T21),'IMP Table'!$A$2:$C$26,3)*SIGN(T20-T21),0) | AJ20: =IF(AND(ISNUMBER(T20),ISNUMBER(T22)),VLOOKUP(ABS(T20-T22),'IMP Table'!$A$2:$C$26,3)*SIGN(T20-T22),0)
B21: ='By Round'!A23 | C21: ='By Round'!B31 | D21: ='By Round'!C31 | E21: ='By Round'!D31 | F21: =IF(ISBLANK('By Round'!F32),"",'By Round'!F32) | G21: =IF(ISBLANK('By Round'!G32),"",'By Round'!G32) | H21: =IF(ISBLANK('By Round'!H32),"",'By Round'!H32) | I21: =IF(ISBLANK('By Round'!I32),"",'By Round'!I32) | J21: =IF(ISBLANK('By Round'!J32),"",'By Round'!J32) | K21: =IF(ISBLANK('By Round'!K32),"",'By Round'!K32) | L21: =IF(ISBLANK('By Round'!L32),"",'By Round'!L32) | M21: =AVERAGE(AC21:AF21) | N21: =AVERAGE(AG21:AJ21) | O21: =IF(COUNT(U21:X21)>0,Q21/COUNT(U21:X21),0.5) | P21: =IF(COUNT(Y21:AB21)>0,R21/COUNT(Y21:AB21),0.5) | Q21: =SUM(U21:X21) | R21: =SUM(Y21:AB21) | S21: =IF(ISNUMBER(K21),K21,IF(ISNUMBER(L21),-L21,"")) | T21: =IF(ISNUMBER(L21),L21,IF(ISNUMBER(K21),-K21,"")) | U21: =IF(ISNUMBER(S21),IF(ISNUMBER(S18),IF(S21>S18,1.0,IF(S21=S18,0.5,0.0)),""),"") | V21: =IF(ISNUMBER(S21),IF(ISNUMBER(S19),IF(S21>S19,1.0,IF(S21=S19,0.5,0.0)),""),"") | W21: =IF(ISNUMBER(S21),IF(ISNUMBER(S20),IF(S21>S20,1.0,IF(S21=S20,0.5,0.0)),""),"") | X21: =IF(ISNUMBER(S21),IF(ISNUMBER(S22),IF(S21>S22,1.0,IF(S21=S22,0.5,0.0)),""),"") | Y21: =IF(ISNUMBER(T21),IF(ISNUMBER(T18),IF(T21>T18,1.0,IF(T21=T18,0.5,0.0)),""),"") | Z21: =IF(ISNUMBER(T21),IF(ISNUMBER(T19),IF(T21>T19,1.0,IF(T21=T19,0.5,0.0)),""),"") | AA21: =IF(ISNUMBER(T21),IF(ISNUMBER(T20),IF(T21>T20,1.0,IF(T21=T20,0.5,0.0)),""),"") | AB21: =IF(ISNUMBER(T21),IF(ISNUMBER(T22),IF(T21>T22,1.0,IF(T21=T22,0.5,0.0)),""),"") | AC21: =IF(AND(ISNUMBER(S21),ISNUMBER(S18)),VLOOKUP(ABS(S21-S18),'IMP Table'!$A$2:$C$26,3)*SIGN(S21-S18),0) | AD21: =IF(AND(ISNUMBER(S21),ISNUMBER(S19)),VLOOKUP(ABS(S21-S19),'IMP Table'!$A$2:$C$26,3)*SIGN(S21-S19),0) | AE21: =IF(AND(ISNUMBER(S21),ISNUMBER(S20)),VLOOKUP(ABS(S21-S20),'IMP Table'!$A$2:$C$26,3)*SIGN(S21-S20),0) | AF21: =IF(AND(ISNUMBER(S21),ISNUMBER(S22)),VLOOKUP(ABS(S21-S22),'IMP Table'!$A$2:$C$26,3)*SIGN(S21-S22),0) | AG21: =IF(AND(ISNUMBER(T21),ISNUMBER(T18)),VLOOKUP(ABS(T21-T18),'IMP Table'!$A$2:$C$26,3)*SIGN(T21-T18),0) | AH21: =IF(AND(ISNUMBER(T21),ISNUMBER(T19)),VLOOKUP(ABS(T21-T19),'IMP Table'!$A$2:$C$26,3)*SIGN(T21-T19),0) | AI21: =IF(AND(ISNUMBER(T21),ISNUMBER(T20)),VLOOKUP(ABS(T21-T20),'IMP Table'!$A$2:$C$26,3)*SIGN(T21-T20),0) | AJ21: =IF(AND(ISNUMBER(T21),ISNUMBER(T22)),VLOOKUP(ABS(T21-T22),'IMP Table'!$A$2:$C$26,3)*SIGN(T21-T22),0)
B22: ='By Round'!A3 | C22: ='By Round'!B5 | D22: ='By Round'!C5 | E22: ='By Round'!D5 | F22: =IF(ISBLANK('By Round'!F6),"",'By Round'!F6) | G22: =IF(ISBLANK('By Round'!G6),"",'By Round'!G6) | H22: =IF(ISBLANK('By Round'!H6),"",'By Round'!H6) | I22: =IF(ISBLANK('By Round'!I6),"",'By Round'!I6) | J22: =IF(ISBLANK('By Round'!J6),"",'By Round'!J6) | K22: =IF(ISBLANK('By Round'!K6),"",'By Round'!K6) | L22: =IF(ISBLANK('By Round'!L6),"",'By Round'!L6) | M22: =AVERAGE(AC22:AF22) | N22: =AVERAGE(AG22:AJ22) | O22: =IF(COUNT(U22:X22)>0,Q22/COUNT(U22:X22),0.5) | P22: =IF(COUNT(Y22:AB22)>0,R22/COUNT(Y22:AB22),0.5) | Q22: =SUM(U22:X22) | R22: =SUM(Y22:AB22) | S22: =IF(ISNUMBER(K22),K22,IF(ISNUMBER(L22),-L22,"")) | T22: =IF(ISNUMBER(L22),L22,IF(ISNUMBER(K22),-K22,"")) | U22: =IF(ISNUMBER(S22),IF(ISNUMBER(S18),IF(S22>S18,1.0,IF(S22=S18,0.5,0.0)),""),"") | V22: =IF(ISNUMBER(S22),IF(ISNUMBER(S19),IF(S22>S19,1.0,IF(S22=S19,0.5,0.0)),""),"") | W22: =IF(ISNUMBER(S22),IF(ISNUMBER(S20),IF(S22>S20,1.0,IF(S22=S20,0.5,0.0)),""),"") | X22: =IF(ISNUMBER(S22),IF(ISNUMBER(S21),IF(S22>S21,1.0,IF(S22=S21,0.5,0.0)),""),"") | Y22: =IF(ISNUMBER(T22),IF(ISNUMBER(T18),IF(T22>T18,1.0,IF(T22=T18,0.5,0.0)),""),"") | Z22: =IF(ISNUMBER(T22),IF(ISNUMBER(T19),IF(T22>T19,1.0,IF(T22=T19,0.5,0.0)),""),"") | AA22: =IF(ISNUMBER(T22),IF(ISNUMBER(T20),IF(T22>T20,1.0,IF(T22=T20,0.5,0.0)),""),"") | AB22: =IF(ISNUMBER(T22),IF(ISNUMBER(T21),IF(T22>T21,1.0,IF(T22=T21,0.5,0.0)),""),"") | AC22: =IF(AND(ISNUMBER(S22),ISNUMBER(S18)),VLOOKUP(ABS(S22-S18),'IMP Table'!$A$2:$C$26,3)*SIGN(S22-S18),0) | AD22: =IF(AND(ISNUMBER(S22),ISNUMBER(S19)),VLOOKUP(ABS(S22-S19),'IMP Table'!$A$2:$C$26,3)*SIGN(S22-S19),0) | AE22: =IF(AND(ISNUMBER(S22),ISNUMBER(S20)),VLOOKUP(ABS(S22-S20),'IMP Table'!$A$2:$C$26,3)*SIGN(S22-S20),0) | AF22: =IF(AND(ISNUMBER(S22),ISNUMBER(S21)),VLOOKUP(ABS(S22-S21),'IMP Table'!$A$2:$C$26,3)*SIGN(S22-S21),0) | AG22: =IF(AND(ISNUMBER(T22),ISNUMBER(T18)),VLOOKUP(ABS(T22-T18),'IMP Table'!$A$2:$C$26,3)*SIGN(T22-T18),0) | AH22: =IF(AND(ISNUMBER(T22),ISNUMBER(T19)),VLOOKUP(ABS(T22-T19),'IMP Table'!$A$2:$C$26,3)*SIGN(T22-T19),0) | AI22: =IF(AND(ISNUMBER(T22),ISNUMBER(T20)),VLOOKUP(ABS(T22-T20),'IMP Table'!$A$2:$C$26,3)*SIGN(T22-T20),0) | AJ22: =IF(AND(ISNUMBER(T22),ISNUMBER(T21)),VLOOKUP(ABS(T22-T21),'IMP Table'!$A$2:$C$26,3)*SIGN(T22-T21),0)
A23: 5 | B23: ='By Round'!A23 | C23: ='By Round'!B23 | D23: ='By Round'!C23 | E23: ='By Round'!D23 | F23: =IF(ISBLANK('By Round'!F23),"",'By Round'!F23) | G23: =IF(ISBLANK('By Round'!G23),"",'By Round'!G23) | H23: =IF(ISBLANK('By Round'!H23),"",'By Round'!H23) | I23: =IF(ISBLANK('By Round'!I23),"",'By Round'!I23) | J23: =IF(ISBLANK('By Round'!J23),"",'By Round'!J23) | K23: =IF(ISBLANK('By Round'!K23),"",'By Round'!K23) | L23: =IF(ISBLANK('By Round'!L23),"",'By Round'!L23) | M23: =AVERAGE(AC23:AF23) | N23: =AVERAGE(AG23:AJ23) | O23: =IF(COUNT(U23:X23)>0,Q23/COUNT(U23:X23),0.5) | P23: =IF(COUNT(Y23:AB23)>0,R23/COUNT(Y23:AB23),0.5) | Q23: =SUM(U23:X23) | R23: =SUM(Y23:AB23) | S23: =IF(ISNUMBER(K23),K23,IF(ISNUMBER(L23),-L23,"")) | T23: =IF(ISNUMBER(L23),L23,IF(ISNUMBER(K23),-K23,"")) | U23: =IF(ISNUMBER(S23),IF(ISNUMBER(S24),IF(S23>S24,1.0,IF(S23=S24,0.5,0.0)),""),"") | V23: =IF(ISNUMBER(S23),IF(ISNUMBER(S25),IF(S23>S25,1.0,IF(S23=S25,0.5,0.0)),""),"") | W23: =IF(ISNUMBER(S23),IF(ISNUMBER(S26),IF(S23>S26,1.0,IF(S23=S26,0.5,0.0)),""),"") | X23: =IF(ISNUMBER(S23),IF(ISNUMBER(S27),IF(S23>S27,1.0,IF(S23=S27,0.5,0.0)),""),"") | Y23: =IF(ISNUMBER(T23),IF(ISNUMBER(T24),IF(T23>T24,1.0,IF(T23=T24,0.5,0.0)),""),"") | Z23: =IF(ISNUMBER(T23),IF(ISNUMBER(T25),IF(T23>T25,1.0,IF(T23=T25,0.5,0.0)),""),"") | AA23: =IF(ISNUMBER(T23),IF(ISNUMBER(T26),IF(T23>T26,1.0,IF(T23=T26,0.5,0.0)),""),"") | AB23: =IF(ISNUMBER(T23),IF(ISNUMBER(T27),IF(T23>T27,1.0,IF(T23=T27,0.5,0.0)),""),"") | AC23: =IF(AND(ISNUMBER(S23),ISNUMBER(S24)),VLOOKUP(ABS(S23-S24),'IMP Table'!$A$2:$C$26,3)*SIGN(S23-S24),0) | AD23: =IF(AND(ISNUMBER(S23),ISNUMBER(S25)),VLOOKUP(ABS(S23-S25),'IMP Table'!$A$2:$C$26,3)*SIGN(S23-S25),0) | AE23: =IF(AND(ISNUMBER(S23),ISNUMBER(S26)),VLOOKUP(ABS(S23-S26),'IMP Table'!$A$2:$C$26,3)*SIGN(S23-S26),0) | AF23: =IF(AND(ISNUMBER(S23),ISNUMBER(S27)),VLOOKUP(ABS(S23-S27),'IMP Table'!$A$2:$C$26,3)*SIGN(S23-S27),0) | AG23: =IF(AND(ISNUMBER(T23),ISNUMBER(T24)),VLOOKUP(ABS(T23-T24),'IMP Table'!$A$2:$C$26,3)*SIGN(T23-T24),0) | AH23: =IF(AND(ISNUMBER(T23),ISNUMBER(T25)),VLOOKUP(ABS(T23-T25),'IMP Table'!$A$2:$C$26,3)*SIGN(T23-T25),0) | AI23: =IF(AND(ISNUMBER(T23),ISNUMBER(T26)),VLOOKUP(ABS(T23-T26),'IMP Table'!$A$2:$C$26,3)*SIGN(T23-T26),0) | AJ23: =IF(AND(ISNUMBER(T23),ISNUMBER(T27)),VLOOKUP(ABS(T23-T27),'IMP Table'!$A$2:$C$26,3)*SIGN(T23-T27),0)
B24: ='By Round'!A13 | C24: ='By Round'!B15 | D24: ='By Round'!C15 | E24: ='By Round'!D15 | F24: =IF(ISBLANK('By Round'!F15),"",'By Round'!F15) | G24: =IF(ISBLANK('By Round'!G15),"",'By Round'!G15) | H24: =IF(ISBLANK('By Round'!H15),"",'By Round'!H15) | I24: =IF(ISBLANK('By Round'!I15),"",'By Round'!I15) | J24: =IF(ISBLANK('By Round'!J15),"",'By Round'!J15) | K24: =IF(ISBLANK('By Round'!K15),"",'By Round'!K15) | L24: =IF(ISBLANK('By Round'!L15),"",'By Round'!L15) | M24: =AVERAGE(AC24:AF24) | N24: =AVERAGE(AG24:AJ24) | O24: =IF(COUNT(U24:X24)>0,Q24/COUNT(U24:X24),0.5) | P24: =IF(COUNT(Y24:AB24)>0,R24/COUNT(Y24:AB24),0.5) | Q24: =SUM(U24:X24) | R24: =SUM(Y24:AB24) | S24: =IF(ISNUMBER(K24),K24,IF(ISNUMBER(L24),-L24,"")) | T24: =IF(ISNUMBER(L24),L24,IF(ISNUMBER(K24),-K24,"")) | U24: =IF(ISNUMBER(S24),IF(ISNUMBER(S23),IF(S24>S23,1.0,IF(S24=S23,0.5,0.0)),""),"") | V24: =IF(ISNUMBER(S24),IF(ISNUMBER(S25),IF(S24>S25,1.0,IF(S24=S25,0.5,0.0)),""),"") | W24: =IF(ISNUMBER(S24),IF(ISNUMBER(S26),IF(S24>S26,1.0,IF(S24=S26,0.5,0.0)),""),"") | X24: =IF(ISNUMBER(S24),IF(ISNUMBER(S27),IF(S24>S27,1.0,IF(S24=S27,0.5,0.0)),""),"") | Y24: =IF(ISNUMBER(T24),IF(ISNUMBER(T23),IF(T24>T23,1.0,IF(T24=T23,0.5,0.0)),""),"") | Z24: =IF(ISNUMBER(T24),IF(ISNUMBER(T25),IF(T24>T25,1.0,IF(T24=T25,0.5,0.0)),""),"") | AA24: =IF(ISNUMBER(T24),IF(ISNUMBER(T26),IF(T24>T26,1.0,IF(T24=T26,0.5,0.0)),""),"") | AB24: =IF(ISNUMBER(T24),IF(ISNUMBER(T27),IF(T24>T27,1.0,IF(T24=T27,0.5,0.0)),""),"") | AC24: =IF(AND(ISNUMBER(S24),ISNUMBER(S23)),VLOOKUP(ABS(S24-S23),'IMP Table'!$A$2:$C$26,3)*SIGN(S24-S23),0) | AD24: =IF(AND(ISNUMBER(S24),ISNUMBER(S25)),VLOOKUP(ABS(S24-S25),'IMP Table'!$A$2:$C$26,3)*SIGN(S24-S25),0) | AE24: =IF(AND(ISNUMBER(S24),ISNUMBER(S26)),VLOOKUP(ABS(S24-S26),'IMP Table'!$A$2:$C$26,3)*SIGN(S24-S26),0) | AF24: =IF(AND(ISNUMBER(S24),ISNUMBER(S27)),VLOOKUP(ABS(S24-S27),'IMP Table'!$A$2:$C$26,3)*SIGN(S24-S27),0) | AG24: =IF(AND(ISNUMBER(T24),ISNUMBER(T23)),VLOOKUP(ABS(T24-T23),'IMP Table'!$A$2:$C$26,3)*SIGN(T24-T23),0) | AH24: =IF(AND(ISNUMBER(T24),ISNUMBER(T25)),VLOOKUP(ABS(T24-T25),'IMP Table'!$A$2:$C$26,3)*SIGN(T24-T25),0) | AI24: =IF(AND(ISNUMBER(T24),ISNUMBER(T26)),VLOOKUP(ABS(T24-T26),'IMP Table'!$A$2:$C$26,3)*SIGN(T24-T26),0) | AJ24: =IF(AND(ISNUMBER(T24),ISNUMBER(T27)),VLOOKUP(ABS(T24-T27),'IMP Table'!$A$2:$C$26,3)*SIGN(T24-T27),0)
B25: ='By Round'!A3 | C25: ='By Round'!B7 | D25: ='By Round'!C7 | E25: ='By Round'!D7 | F25: =IF(ISBLANK('By Round'!F7),"",'By Round'!F7) | G25: =IF(ISBLANK('By Round'!G7),"",'By Round'!G7) | H25: =IF(ISBLANK('By Round'!H7),"",'By Round'!H7) | I25: =IF(ISBLANK('By Round'!I7),"",'By Round'!I7) | J25: =IF(ISBLANK('By Round'!J7),"",'By Round'!J7) | K25: =IF(ISBLANK('By Round'!K7),"",'By Round'!K7) | L25: =IF(ISBLANK('By Round'!L7),"",'By Round'!L7) | M25: =AVERAGE(AC25:AF25) | N25: =AVERAGE(AG25:AJ25) | O25: =IF(COUNT(U25:X25)>0,Q25/COUNT(U25:X25),0.5) | P25: =IF(COUNT(Y25:AB25)>0,R25/COUNT(Y25:AB25),0.5) | Q25: =SUM(U25:X25) | R25: =SUM(Y25:AB25) | S25: =IF(ISNUMBER(K25),K25,IF(ISNUMBER(L25),-L25,"")) | T25: =IF(ISNUMBER(L25),L25,IF(ISNUMBER(K25),-K25,"")) | U25: =IF(ISNUMBER(S25),IF(ISNUMBER(S23),IF(S25>S23,1.0,IF(S25=S23,0.5,0.0)),""),"") | V25: =IF(ISNUMBER(S25),IF(ISNUMBER(S24),IF(S25>S24,1.0,IF(S25=S24,0.5,0.0)),""),"") | W25: =IF(ISNUMBER(S25),IF(ISNUMBER(S26),IF(S25>S26,1.0,IF(S25=S26,0.5,0.0)),""),"") | X25: =IF(ISNUMBER(S25),IF(ISNUMBER(S27),IF(S25>S27,1.0,IF(S25=S27,0.5,0.0)),""),"") | Y25: =IF(ISNUMBER(T25),IF(ISNUMBER(T23),IF(T25>T23,1.0,IF(T25=T23,0.5,0.0)),""),"") | Z25: =IF(ISNUMBER(T25),IF(ISNUMBER(T24),IF(T25>T24,1.0,IF(T25=T24,0.5,0.0)),""),"") | AA25: =IF(ISNUMBER(T25),IF(ISNUMBER(T26),IF(T25>T26,1.0,IF(T25=T26,0.5,0.0)),""),"") | AB25: =IF(ISNUMBER(T25),IF(ISNUMBER(T27),IF(T25>T27,1.0,IF(T25=T27,0.5,0.0)),""),"") | AC25: =IF(AND(ISNUMBER(S25),ISNUMBER(S23)),VLOOKUP(ABS(S25-S23),'IMP Table'!$A$2:$C$26,3)*SIGN(S25-S23),0) | AD25: =IF(AND(ISNUMBER(S25),ISNUMBER(S24)),VLOOKUP(ABS(S25-S24),'IMP Table'!$A$2:$C$26,3)*SIGN(S25-S24),0) | AE25: =IF(AND(ISNUMBER(S25),ISNUMBER(S26)),VLOOKUP(ABS(S25-S26),'IMP Table'!$A$2:$C$26,3)*SIGN(S25-S26),0) | AF25: =IF(AND(ISNUMBER(S25),ISNUMBER(S27)),VLOOKUP(ABS(S25-S27),'IMP Table'!$A$2:$C$26,3)*SIGN(S25-S27),0) | AG25: =IF(AND(ISNUMBER(T25),ISNUMBER(T23)),VLOOKUP(ABS(T25-T23),'IMP Table'!$A$2:$C$26,3)*SIGN(T25-T23),0) | AH25: =IF(AND(ISNUMBER(T25),ISNUMBER(T24)),VLOOKUP(ABS(T25-T24),'IMP Table'!$A$2:$C$26,3)*SIGN(T25-T24),0) | AI25: =IF(AND(ISNUMBER(T25),ISNUMBER(T26)),VLOOKUP(ABS(T25-T26),'IMP Table'!$A$2:$C$26,3)*SIGN(T25-T26),0) | AJ25: =IF(AND(ISNUMBER(T25),ISNUMBER(T27)),VLOOKUP(ABS(T25-T27),'IMP Table'!$A$2:$C$26,3)*SIGN(T25-T27),0)
B26: ='By Round'!A43 | C26: ='By Round'!B49 | D26: ='By Round'!C49 | E26: ='By Round'!D49 | F26: =IF(ISBLANK('By Round'!F49),"",'By Round'!F49) | G26: =IF(ISBLANK('By Round'!G49),"",'By Round'!G49) | H26: =IF(ISBLANK('By Round'!H49),"",'By Round'!H49) | I26: =IF(ISBLANK('By Round'!I49),"",'By Round'!I49) | J26: =IF(ISBLANK('By Round'!J49),"",'By Round'!J49) | K26: =IF(ISBLANK('By Round'!K49),"",'By Round'!K49) | L26: =IF(ISBLANK('By Round'!L49),"",'By Round'!L49) | M26: =AVERAGE(AC26:AF26) | N26: =AVERAGE(AG26:AJ26) | O26: =IF(COUNT(U26:X26)>0,Q26/COUNT(U26:X26),0.5) | P26: =IF(COUNT(Y26:AB26)>0,R26/COUNT(Y26:AB26),0.5) | Q26: =SUM(U26:X26) | R26: =SUM(Y26:AB26) | S26: =IF(ISNUMBER(K26),K26,IF(ISNUMBER(L26),-L26,"")) | T26: =IF(ISNUMBER(L26),L26,IF(ISNUMBER(K26),-K26,"")) | U26: =IF(ISNUMBER(S26),IF(ISNUMBER(S23),IF(S26>S23,1.0,IF(S26=S23,0.5,0.0)),""),"") | V26: =IF(ISNUMBER(S26),IF(ISNUMBER(S24),IF(S26>S24,1.0,IF(S26=S24,0.5,0.0)),""),"") | W26: =IF(ISNUMBER(S26),IF(ISNUMBER(S25),IF(S26>S25,1.0,IF(S26=S25,0.5,0.0)),""),"") | X26: =IF(ISNUMBER(S26),IF(ISNUMBER(S27),IF(S26>S27,1.0,IF(S26=S27,0.5,0.0)),""),"") | Y26: =IF(ISNUMBER(T26),IF(ISNUMBER(T23),IF(T26>T23,1.0,IF(T26=T23,0.5,0.0)),""),"") | Z26: =IF(ISNUMBER(T26),IF(ISNUMBER(T24),IF(T26>T24,1.0,IF(T26=T24,0.5,0.0)),""),"") | AA26: =IF(ISNUMBER(T26),IF(ISNUMBER(T25),IF(T26>T25,1.0,IF(T26=T25,0.5,0.0)),""),"") | AB26: =IF(ISNUMBER(T26),IF(ISNUMBER(T27),IF(T26>T27,1.0,IF(T26=T27,0.5,0.0)),""),"") | AC26: =IF(AND(ISNUMBER(S26),ISNUMBER(S23)),VLOOKUP(ABS(S26-S23),'IMP Table'!$A$2:$C$26,3)*SIGN(S26-S23),0) | AD26: =IF(AND(ISNUMBER(S26),ISNUMBER(S24)),VLOOKUP(ABS(S26-S24),'IMP Table'!$A$2:$C$26,3)*SIGN(S26-S24),0) | AE26: =IF(AND(ISNUMBER(S26),ISNUMBER(S25)),VLOOKUP(ABS(S26-S25),'IMP Table'!$A$2:$C$26,3)*SIGN(S26-S25),0) | AF26: =IF(AND(ISNUMBER(S26),ISNUMBER(S27)),VLOOKUP(ABS(S26-S27),'IMP Table'!$A$2:$C$26,3)*SIGN(S26-S27),0) | AG26: =IF(AND(ISNUMBER(T26),ISNUMBER(T23)),VLOOKUP(ABS(T26-T23),'IMP Table'!$A$2:$C$26,3)*SIGN(T26-T23),0) | AH26: =IF(AND(ISNUMBER(T26),ISNUMBER(T24)),VLOOKUP(ABS(T26-T24),'IMP Table'!$A$2:$C$26,3)*SIGN(T26-T24),0) | AI26: =IF(AND(ISNUMBER(T26),ISNUMBER(T25)),VLOOKUP(ABS(T26-T25),'IMP Table'!$A$2:$C$26,3)*SIGN(T26-T25),0) | AJ26: =IF(AND(ISNUMBER(T26),ISNUMBER(T27)),VLOOKUP(ABS(T26-T27),'IMP Table'!$A$2:$C$26,3)*SIGN(T26-T27),0)
