Workbook

Sheet Roster
A1: For public domain. No rights reserved. Generated on Apr 23, 2026.
A2: Howell Tournament
A3: Pairs | C3: 4
A4: Tables | C4: 2
A5: Rounds | C5: 6
A6: Boards per round | C6: 3
A7: Total Boards to play | C7: 18
A9: Pairs | D9: MP | E9: IMP
A10: 1 | B10: Name 87 | C10: Name 81 | D10: =SUMIF('By Board'!D3:D38,"="&A10,'By Board'!Q3:Q38)/18+SUMIF('By Board'!E3:E38,"="&A10,'By Board'!R3:R38)/18 | E10: =SUMIF('By Board'!D3:D38,"="&A10,'By Board'!M3:M38)+SUMIF('By Board'!E3:E38,"="&A10,'By Board'!N3:N38)
A11: 2 | B11: Name 74 | C11: Name 65 | D11: =SUMIF('By Board'!D3:D38,"="&A11,'By Board'!Q3:Q38)/18+SUMIF('By Board'!E3:E38,"="&A11,'By Board'!R3:R38)/18 | E11: =SUMIF('By Board'!D3:D38,"="&A11,'By Board'!M3:M38)+SUMIF('By Board'!E3:E38,"="&A11,'By Board'!N3:N38)
A12: 3 | B12: Name 26 | C12: Name 49 | D12: =SUMIF('By Board'!D3:D38,"="&A12,'By Board'!Q3:Q38)/18+SUMIF('By Board'!E3:E38,"="&A12,'By Board'!R3:R38)/18 | E12: =SUMIF('By Board'!D3:D38,"="&A12,'By Board'!M3:M38)+SUMIF('By Board'!E3:E38,"="&A12,'By Board'!N3:N38)
A13: 4 | B13: Name 49 | C13: Name 38 | D13: =SUMIF('By Board'!D3:D38,"="&A13,'By Board'!Q3:Q38)/18+0/18 | E13: =SUMIF('By Board'!D3:D38,"="&A13,'By Board'!M3:M38)+0
D14: =AVERAGE(D10:D13) | E14: =SUM(E10:E13)

Sheet By Board
I1: Result | K1: Score | M1: IMP | O1: MP % | Q1: MP Pts | S1: Net | U1: MP Calculation | W1: IMP Calculation
A2: Board | B2: Round | C2: Table | D2: NS | E2: EW | F2: Vul | G2: Contract | H2: By | I2: Made | J2: Down | K2: NS | L2: EW | M2: NS | N2: EW | O2: NS | P2: EW | Q2: NS | R2: EW | S2: NS | T2: EW | U2: NS MP Scores | V2: EW MP Scores | W2: NS IMP Pair-wise | X2: EW IMP Pair-wise
A3: 1 | B3: ='By Round'!A21 | C3: ='By Round'!B24 | D3: ='By Round'!C24 | E3: ='By Round'!D24 | F3: =IF(ISBLANK('By Round'!F24),"",'By Round'!F24) | G3: =IF(ISBLANK('By Round'!G24),"",'By Round'!G24) | H3: =IF(ISBLANK('By Round'!H24),"",'By Round'!H24) | I3: =IF(ISBLANK('By Round'!I24),"",'By Round'!I24) | J3: =IF(ISBLANK('By Round'!J24),"",'By Round'!J24) | K3: =IF(ISBLANK('By Round'!K24),"",'By Round'!K24) | L3: =IF(ISBLANK('By Round'!L24),"",'By Round'!L24) | M3: =AVERAGE(W3:W3) | N3: =AVERAGE(X3:X3) | O3: =IF(COUNT(U3:U3)>0,Q3/COUNT(U3:U3),0.5) | P3: =IF(COUNT(V3:V3)>0,R3/COUNT(V3:V3),0.5) | Q3: =SUM(U3:U3) | R3: =SUM(V3:V3) | S3: =IF(ISNUMBER(K3),K3,IF(ISNUMBER(L3),-L3,"")) | T3: =IF(ISNUMBER(L3),L3,IF(ISNUMBER(K3),-K3,"")) | U3: =IF(ISNUMBER(S3),IF(ISNUMBER(S4),IF(S3>S4,1.0,IF(S3=S4,0.5,0.0)),0.5),0.5) | V3: =IF(ISNUMBER(T3),IF(ISNUMBER(T4),IF(T3>T4,1.0,IF(T3=T4,0.5,0.0)),0.5),0.5) | W3: =IF(AND(ISNUMBER(S3),ISNUMBER(S4)),VLOOKUP(ABS(S3-S4),'IMP Table'!$A$2:$C$26,3)*SIGN(S3-S4),0) | X3: =IF(AND(ISNUMBER(T3),ISNUMBER(T4)),VLOOKUP(ABS(T3-T4),'IMP Table'!$A$2:$C$26,3)*SIGN(T3-T4),0)
B4: ='By Round'!A3 | C4: ='By Round'!B3 | D4: ='By Round'!C3 | E4: ='By Round'!D3 | F4: =IF(ISBLANK('By Round'!F3),"",'By Round'!F3) | G4: =IF(ISBLANK('By Round'!G3),"",'By Round'!G3) | H4: =IF(ISBLANK('By Round'!H3),"",'By Round'!H3) | I4: =IF(ISBLANK('By Round'!I3),"",'By Round'!I3) | J4: =IF(ISBLANK('By Round'!J3),"",'By Round'!J3) | K4: =IF(ISBLANK('By Round'!K3),"",'By Round'!K3) | L4: =IF(ISBLANK('By Round'!L3),"",'By Round'!L3) | M4: =AVERAGE(W4:W4) | N4: =AVERAGE(X4:X4) | O4: =IF(COUNT(U4:U4)>0,Q4/COUNT(U4:U4),0.5) | P4: =IF(COUNT(V4:V4)>0,R4/COUNT(V4:V4),0.5) | Q4: =SUM(U4:U4) | R4: =SUM(V4:V4) | S4: =IF(ISNUMBER(K4),K4,IF(ISNUMBER(L4),-L4,"")) | T4: =IF(ISNUMBER(L4),L4,IF(ISNUMBER(K4),-K4,"")) | U4: =IF(ISNUMBER(S4),IF(ISNUMBER(S3),IF(S4>S3,1.0,IF(S4=S3,0.5,0.0)),0.5),0.5) | V4: =IF(ISNUMBER(T4),IF(ISNUMBER(T3),IF(T4>T3,1.0,IF(T4=T3,0.5,0.0)),0.5),0.5) | W4: =IF(AND(ISNUMBER(S4),ISNUMBER(S3)),VLOOKUP(ABS(S4-S3),'IMP Table'!$A$2:$C$26,3)*SIGN(S4-S3),0) | X4: =IF(AND(ISNUMBER(T4),ISNUMBER(T3)),VLOOKUP(ABS(T4-T3),'IMP Table'!$A$2:$C$26,3)*SIGN(T4-T3),0)
A5: 2 | B5: ='By Round'!A21 | C5: ='By Round'!B24 | D5: ='By Round'!C24 | E5: ='By Round'!D24 | F5: =IF(ISBLANK('By Round'!F25),"",'By Round'!F25) | G5: =IF(ISBLANK('By Round'!G25),"",'By Round'!G25) | H5: =IF(ISBLANK('By Round'!H25),"",'By Round'!H25) | I5: =IF(ISBLANK('By Round'!I25),"",'By Round'!I25) | J5: =IF(ISBLANK('By Round'!J25),"",'By Round'!J25) | K5: =IF(ISBLANK('By Round'!K25),"",'By Round'!K25) | L5: =IF(ISBLANK('By Round'!L25),"",'By Round'!L25) | M5: =AVERAGE(W5:W5) | N5: =AVERAGE(X5:X5) | O5: =IF(COUNT(U5:U5)>0,Q5/COUNT(U5:U5),0.5) | P5: =IF(COUNT(V5:V5)>0,R5/COUNT(V5:V5),0.5) | Q5: =SUM(U5:U5) | R5: =SUM(V5:V5) | S5: =IF(ISNUMBER(K5),K5,IF(ISNUMBER(L5),-L5,"")) | T5: =IF(ISNUMBER(L5),L5,IF(ISNUMBER(K5),-K5,"")) | U5: =IF(ISNUMBER(S5),IF(ISNUMBER(S6),IF(S5>S6,1.0,IF(S5=S6,0.5,0.0)),0.5),0.5) | V5: =IF(ISNUMBER(T5),IF(ISNUMBER(T6),IF(T5>T6,1.0,IF(T5=T6,0.5,0.0)),0.5),0.5) | W5: =IF(AND(ISNUMBER(S5),ISNUMBER(S6)),VLOOKUP(ABS(S5-S6),'IMP Table'!$A$2:$C$26,3)*SIGN(S5-S6),0) | X5: =IF(AND(ISNUMBER(T5),ISNUMBER(T6)),VLOOKUP(ABS(T5-T6),'IMP Table'!$A$2:$C$26,3)*SIGN(T5-T6),0)
B6: ='By Round'!A3 | C6: ='By Round'!B3 | D6: ='By Round'!C3 | E6: ='By Round'!D3 | F6: =IF(ISBLANK('By Round'!F4),"",'By Round'!F4) | G6: =IF(ISBLANK('By Round'!G4),"",'By Round'!G4) | H6: =IF(ISBLANK('By Round'!H4),"",'By Round'!H4) | I6: =IF(ISBLANK('By Round'!I4),"",'By Round'!I4) | J6: =IF(ISBLANK('By Round'!J4),"",'By Round'!J4) | K6: =IF(ISBLANK('By Round'!K4),"",'By Round'!K4) | L6: =IF(ISBLANK('By Round'!L4),"",'By Round'!L4) | M6: =AVERAGE(W6:W6) | N6: =AVERAGE(X6:X6) | O6: =IF(COUNT(U6:U6)>0,Q6/COUNT(U6:U6),0.5) | P6: =IF(COUNT(V6:V6)>0,R6/COUNT(V6:V6),0.5) | Q6: =SUM(U6:U6) | R6: =SUM(V6:V6) | S6: =IF(ISNUMBER(K6),K6,IF(ISNUMBER(L6),-L6,"")) | T6: =IF(ISNUMBER(L6),L6,IF(ISNUMBER(K6),-K6,"")) | U6: =IF(ISNUMBER(S6),IF(ISNUMBER(S5),IF(S6>S5,1.0,IF(S6=S5,0.5,0.0)),0.5),0.5) | V6: =IF(ISNUMBER(T6),IF(ISNUMBER(T5),IF(T6>T5,1.0,IF(T6=T5,0.5,0.0)),0.5),0.5) | W6: =IF(AND(ISNUMBER(S6),ISNUMBER(S5)),VLOOKUP(ABS(S6-S5),'IMP Table'!$A$2:$C$26,3)*SIGN(S6-S5),0) | X6: =IF(AND(ISNUMBER(T6),ISNUMBER(T5)),VLOOKUP(ABS(T6-T5),'IMP Table'!$A$2:$C$26,3)*SIGN(T6-T5),0)
A7: 3 | B7: ='By Round'!A21 | C7: ='By Round'!B24 | D7: ='By Round'!C24 | E7: ='By Round'!D24 | F7: =IF(ISBLANK('By Round'!F26),"",'By Round'!F26) | G7: =IF(ISBLANK('By Round'!G26),"",'By Round'!G26) | H7: =IF(ISBLANK('By Round'!H26),"",'By Round'!H26) | I7: =IF(ISBLANK('By Round'!I26),"",'By Round'!I26) | J7: =IF(ISBLANK('By Round'!J26),"",'By Round'!J26) | K7: =IF(ISBLANK('By Round'!K26),"",'By Round'!K26) | L7: =IF(ISBLANK('By Round'!L26),"",'By Round'!L26) | M7: =AVERAGE(W7:W7) | N7: =AVERAGE(X7:X7) | O7: =IF(COUNT(U7:U7)>0,Q7/COUNT(U7:U7),0.5) | P7: =IF(COUNT(V7:V7)>0,R7/COUNT(V7:V7),0.5) | Q7: =SUM(U7:U7) | R7: =SUM(V7:V7) | S7: =IF(ISNUMBER(K7),K7,IF(ISNUMBER(L7),-L7,"")) | T7: =IF(ISNUMBER(L7),L7,IF(ISNUMBER(K7),-K7,"")) | U7: =IF(ISNUMBER(S7),IF(ISNUMBER(S8),IF(S7>S8,1.0,IF(S7=S8,0.5,0.0)),0.5),0.5) | V7: =IF(ISNUMBER(T7),IF(ISNUMBER(T8),IF(T7>T8,1.0,IF(T7=T8,0.5,0.0)),0.5),0.5) | W7: =IF(AND(ISNUMBER(S7),ISNUMBER(S8)),VLOOKUP(ABS(S7-S8),'IMP Table'!$A$2:$C$26,3)*SIGN(S7-S8),0) | X7: =IF(AND(ISNUMBER(T7),ISNUMBER(T8)),VLOOKUP(ABS(T7-T8),'IMP Table'!$A$2:$C$26,3)*SIGN(T7-T8),0)
B8: ='By Round'!A3 | C8: ='By Round'!B3 | D8: ='By Round'!C3 | E8: ='By Round'!D3 | F8: =IF(ISBLANK('By Round'!F5),"",'By Round'!F5) | G8: =IF(ISBLANK('By Round'!G5),"",'By Round'!G5) | H8: =IF(ISBLANK('By Round'!H5),"",'By Round'!H5) | I8: =IF(ISBLANK('By Round'!I5),"",'By Round'!I5) | J8: =IF(ISBLANK('By Round'!J5),"",'By Round'!J5) | K8: =IF(ISBLANK('By Round'!K5),"",'By Round'!K5) | L8: =IF(ISBLANK('By Round'!L5),"",'By Round'!L5) | M8: =AVERAGE(W8:W8) | N8: =AVERAGE(X8:X8) | O8: =IF(COUNT(U8:U8)>0,Q8/COUNT(U8:U8),0.5) | P8: =IF(COUNT(V8:V8)>0,R8/COUNT(V8:V8),0.5) | Q8: =SUM(U8:U8) | R8: =SUM(V8:V8) | S8: =IF(ISNUMBER(K8),K8,IF(ISNUMBER(L8),-L8,"")) | T8: =IF(ISNUMBER(L8),L8,IF(ISNUMBER(K8),-K8,"")) | U8: =IF(ISNUMBER(S8),IF(ISNUMBER(S7),IF(S8>S7,1.0,IF(S8=S7,0.5,0.0)),0.5),0.5) | V8: =IF(ISNUMBER(T8),IF(ISNUMBER(T7),IF(T8>T7,1.0,IF(T8=T7,0.5,0.0)),0.5),0.5) | W8: =IF(AND(ISNUMBER(S8),ISNUMBER(S7)),VLOOKUP(ABS(S8-S7),'IMP Table'!$A$2:$C$26,3)*SIGN(S8-S7),0) | X8: =IF(AND(ISNUMBER(T8),ISNUMBER(T7)),VLOOKUP(ABS(T8-T7),'IMP Table'!$A$2:$C$26,3)*SIGN(T8-T7),0)
A9: 4 | B9: ='By Round'!A27 | C9: ='By Round'!B30 | D9: ='By Round'!C30 | E9: ='By Round'!D30 | F9: =IF(ISBLANK('By Round'!F30),"",'By Round'!F30) | G9: =IF(ISBLANK('By Round'!G30),"",'By Round'!G30) | H9: =IF(ISBLANK('By Round'!H30),"",'By Round'!H30) | I9: =IF(ISBLANK('By Round'!I30),"",'By Round'!I30) | J9: =IF(ISBLANK('By Round'!J30),"",'By Round'!J30) | K9: =IF(ISBLANK('By Round'!K30),"",'By Round'!K30) | L9: =IF(ISBLANK('By Round'!L30),"",'By Round'!L30) | M9: =AVERAGE(W9:W9) | N9: =AVERAGE(X9:X9) | O9: =IF(COUNT(U9:U9)>0,Q9/COUNT(U9:U9),0.5) | P9: =IF(COUNT(V9:V9)>0,R9/COUNT(V9:V9),0.5) | Q9: =SUM(U9:U9) | R9: =SUM(V9:V9) | S9: =IF(ISNUMBER(K9),K9,IF(ISNUMBER(L9),-L9,"")) | T9: =IF(ISNUMBER(L9),L9,IF(ISNUMBER(K9),-K9,"")) | U9: =IF(ISNUMBER(S9),IF(ISNUMBER(S10),IF(S9>S10,1.0,IF(S9=S10,0.5,0.0)),0.5),0.5) | V9: =IF(ISNUMBER(T9),IF(ISNUMBER(T10),IF(T9>T10,1.0,IF(T9=T10,0.5,0.0)),0.5),0.5) | W9: =IF(AND(ISNUMBER(S9),ISNUMBER(S10)),VLOOKUP(ABS(S9-S10),'IMP Table'!$A$2:$C$26,3)*SIGN(S9-S10),0) | X9: =IF(AND(ISNUMBER(T9),ISNUMBER(T10)),VLOOKUP(ABS(T9-T10),'IMP Table'!$A$2:$C$26,3)*SIGN(T9-T10),0)
B10: ='By Round'!A9 | C10: ='By Round'!B9 | D10: ='By Round'!C9 | E10: ='By Round'!D9 | F10: =IF(ISBLANK('By Round'!F9),"",'By Round'!F9) | G10: =IF(ISBLANK('By Round'!G9),"",'By Round'!G9) | H10: =IF(ISBLANK('By Round'!H9),"",'By Round'!H9) | I10: =IF(ISBLANK('By Round'!I9),"",'By Round'!I9) | J10: =IF(ISBLANK('By Round'!J9),"",'By Round'!J9) | K10: =IF(ISBLANK('By Round'!K9),"",'By Round'!K9) | L10: =IF(ISBLANK('By Round'!L9),"",'By Round'!L9) | M10: =AVERAGE(W10:W10) | N10: =AVERAGE(X10:X10) | O10: =IF(COUNT(U10:U10)>0,Q10/COUNT(U10:U10),0.5) | P10: =IF(COUNT(V10:V10)>0,R10/COUNT(V10:V10),0.5) | Q10: =SUM(U10:U10) | R10: =SUM(V10:V10) | S10: =IF(ISNUMBER(K10),K10,IF(ISNUMBER(L10),-L10,"")) | T10: =IF(ISNUMBER(L10),L10,IF(ISNUMBER(K10),-K10,"")) | U10: =IF(ISNUMBER(S10),IF(ISNUMBER(S9),IF(S10>S9,1.0,IF(S10=S9,0.5,0.0)),0.5),0.5) | V10: =IF(ISNUMBER(T10),IF(ISNUMBER(T9),IF(T10>T9,1.0,IF(T10=T9,0.5,0.0)),0.5),0.5) | W10: =IF(AND(ISNUMBER(S10),ISNUMBER(S9)),VLOOKUP(ABS(S10-S9),'IMP Table'!$A$2:$C$26,3)*SIGN(S10-S9),0) | X10: =IF(AND(ISNUMBER(T10),ISNUMBER(T9)),VLOOKUP(ABS(T10-T9),'IMP Table'!$A$2:$C$26,3)*SIGN(T10-T9),0)
A11: 5 | B11: ='By Round'!A27 | C11: ='By Round'!B30 | D11: ='By Round'!C30 | E11: ='By Round'!D30 | F11: =IF(ISBLANK('By Round'!F31),"",'By Round'!F31) | G11: =IF(ISBLANK('By Round'!G31),"",'By Round'!G31) | H11: =IF(ISBLANK('By Round'!H31),"",'By Round'!H31) | I11: =IF(ISBLANK('By Round'!I31),"",'By Round'!I31) | J11: =IF(ISBLANK('By Round'!J31),"",'By Round'!J31) | K11: =IF(ISBLANK('By Round'!K31),"",'By Round'!K31) | L11: =IF(ISBLANK('By Round'!L31),"",'By Round'!L31) | M11: =AVERAGE(W11:W11) | N11: =AVERAGE(X11:X11) | O11: =IF(COUNT(U11:U11)>0,Q11/COUNT(U11:U11),0.5) | P11: =IF(COUNT(V11:V11)>0,R11/COUNT(V11:V11),0.5) | Q11: =SUM(U11:U11) | R11: =SUM(V11:V11) | S11: =IF(ISNUMBER(K11),K11,IF(ISNUMBER(L11),-L11,"")) | T11: =IF(ISNUMBER(L11),L11,IF(ISNUMBER(K11),-K11,"")) | U11: =IF(ISNUMBER(S11),IF(ISNUMBER(S12),IF(S11>S12,1.0,IF(S11=S12,0.5,0.0)),0.5),0.5) | V11: =IF(ISNUMBER(T11),IF(ISNUMBER(T12),IF(T11>T12,1.0,IF(T11=T12,0.5,0.0)),0.5),0.5) | W11: =IF(AND(ISNUMBER(S11),ISNUMBER(S12)),VLOOKUP(ABS(S11-S12),'IMP Table'!$A$2:$C$26,3)*SIGN(S11-S12),0) | X11: =IF(AND(ISNUMBER(T11),ISNUMBER(T12)),VLOOKUP(ABS(T11-T12),'IMP Table'!$A$2:$C$26,3)*SIGN(T11-T12),0)
B12: ='By Round'!A9 | C12: ='By Round'!B9 | D12: ='By Round'!C9 | E12: ='By Round'!D9 | F12: =IF(ISBLANK('By Round'!F10),"",'By Round'!F10) | G12: =IF(ISBLANK('By Round'!G10),"",'By Round'!G10) | H12: =IF(ISBLANK('By Round'!H10),"",'By Round'!H10) | I12: =IF(ISBLANK('By Round'!I10),"",'By Round'!I10) | J12: =IF(ISBLANK('By Round'!J10),"",'By Round'!J10) | K12: =IF(ISBLANK('By Round'!K10),"",'By Round'!K10) | L12: =IF(ISBLANK('By Round'!L10),"",'By Round'!L10) | M12: =AVERAGE(W12:W12) | N12: =AVERAGE(X12:X12) | O12: =IF(COUNT(U12:U12)>0,Q12/COUNT(U12:U12),0.5) | P12: =IF(COUNT(V12:V12)>0,R12/COUNT(V12:V12),0.5) | Q12: =SUM(U12:U12) | R12: =SUM(V12:V12) | S12: =IF(ISNUMBER(K12),K12,IF(ISNUMBER(L12),-L12,"")) | T12: =IF(ISNUMBER(L12),L12,IF(ISNUMBER(K12),-K12,"")) | U12: =IF(ISNUMBER(S12),IF(ISNUMBER(S11),IF(S12>S11,1.0,IF(S12=S11,0.5,0.0)),0.5),0.5) | V12: =IF(ISNUMBER(T12),IF(ISNUMBER(T11),IF(T12>T11,1.0,IF(T12=T11,0.5,0.0)),0.5),0.5) | W12: =IF(AND(ISNUMBER(S12),ISNUMBER(S11)),VLOOKUP(ABS(S12-S11),'IMP Table'!$A$2:$C$26,3)*SIGN(S12-S11),0) | X12: =IF(AND(ISNUMBER(T12),ISNUMBER(T11)),VLOOKUP(ABS(T12-T11),'IMP Table'!$A$2:$C$26,3)*SIGN(T12-T11),0)
A13: 6 | B13: ='By Round'!A27 | C13: ='By Round'!B30 | D13: ='By Round'!C30 | E13: ='By Round'!D30 | F13: =IF(ISBLANK('By Round'!F32),"",'By Round'!F32) | G13: =IF(ISBLANK('By Round'!G32),"",'By Round'!G32) | H13: =IF(ISBLANK('By Round'!H32),"",'By Round'!H32) | I13: =IF(ISBLANK('By Round'!I32),"",'By Round'!I32) | J13: =IF(ISBLANK('By Round'!J32),"",'By Round'!J32) | K13: =IF(ISBLANK('By Round'!K32),"",'By Round'!K32) | L13: =IF(ISBLANK('By Round'!L32),"",'By Round'!L32) | M13: =AVERAGE(W13:W13) | N13: =AVERAGE(X13:X13) | O13: =IF(COUNT(U13:U13)>0,Q13/COUNT(U13:U13),0.5) | P13: =IF(COUNT(V13:V13)>0,R13/COUNT(V13:V13),0.5) | Q13: =SUM(U13:U13) | R13: =SUM(V13:V13) | S13: =IF(ISNUMBER(K13),K13,IF(ISNUMBER(L13),-L13,"")) | T13: =IF(ISNUMBER(L13),L13,IF(ISNUMBER(K13),-K13,"")) | U13: =IF(ISNUMBER(S13),IF(ISNUMBER(S14),IF(S13>S14,1.0,IF(S13=S14,0.5,0.0)),0.5),0.5) | V13: =IF(ISNUMBER(T13),IF(ISNUMBER(T14),IF(T13>T14,1.0,IF(T13=T14,0.5,0.0)),0.5),0.5) | W13: =IF(AND(ISNUMBER(S13),ISNUMBER(S14)),VLOOKUP(ABS(S13-S14),'IMP Table'!$A$2:$C$26,3)*SIGN(S13-S14),0) | X13: =IF(AND(ISNUMBER(T13),ISNUMBER(T14)),VLOOKUP(ABS(T13-T14),'IMP Table'!$A$2:$C$26,3)*SIGN(T13-T14),0)
B14: ='By Round'!A9 | C14: ='By Round'!B9 | D14: ='By Round'!C9 | E14: ='By Round'!D9 | F14: =IF(ISBLANK('By Round'!F11),"",'By Round'!F11) | G14: =IF(ISBLANK('By Round'!G11),"",'By Round'!G11) | H14: =IF(ISBLANK('By Round'!H11),"",'By Round'!H11) | I14: =IF(ISBLANK('By Round'!I11),"",'By Round'!I11) | J14: =IF(ISBLANK('By Round'!J11),"",'By Round'!J11) | K14: =IF(ISBLANK('By Round'!K11),"",'By Round'!K11) | L14: =IF(ISBLANK('By Round'!L11),"",'By Round'!L11) | M14: =AVERAGE(W14:W14) | N14: =AVERAGE(X14:X14) | O14: =IF(COUNT(U14:U14)>0,Q14/COUNT(U14:U14),0.5) | P14: =IF(COUNT(V14:V14)>0,R14/COUNT(V14:V14),0.5) | Q14: =SUM(U14:U14) | R14: =SUM(V14:V14) | S14: =IF(ISNUMBER(K14),K14,IF(ISNUMBER(L14),-L14,"")) | T14: =IF(ISNUMBER(L14),L14,IF(ISNUMBER(K14),-K14,"")) | U14: =IF(ISNUMBER(S14),IF(ISNUMBER(S13),IF(S14>S13,1.0,IF(S14=S13,0.5,0.0)),0.5),0.5) | V14: =IF(ISNUMBER(T14),IF(ISNUMBER(T13),IF(T14>T13,1.0,IF(T14=T13,0.5,0.0)),0.5),0.5) | W14: =IF(AND(ISNUMBER(S14),ISNUMBER(S13)),VLOOKUP(ABS(S14-S13),'IMP Table'!$A$2:$C$26,3)*SIGN(S14-S13),0) | X14: =IF(AND(ISNUMBER(T14),ISNUMBER(T13)),VLOOKUP(ABS(T14-T13),'IMP Table'!$A$2:$C$26,3)*SIGN(T14-T13),0)
A15: 7 | B15: ='By Round'!A33 | C15: ='By Round'!B36 | D15: ='By Round'!C36 | E15: ='By Round'!D36 | F15: =IF(ISBLANK('By Round'!F36),"",'By Round'!F36) | G15: =IF(ISBLANK('By Round'!G36),"",'By Round'!G36) | H15: =IF(ISBLANK('By Round'!H36),"",'By Round'!H36) | I15: =IF(ISBLANK('By Round'!I36),"",'By Round'!I36) | J15: =IF(ISBLANK('By Round'!J36),"",'By Round'!J36) | K15: =IF(ISBLANK('By Round'!K36),"",'By Round'!K36) | L15: =IF(ISBLANK('By Round'!L36),"",'By Round'!L36) | M15: =AVERAGE(W15:W15) | N15: =AVERAGE(X15:X15) | O15: =IF(COUNT(U15:U15)>0,Q15/COUNT(U15:U15),0.5) | P15: =IF(COUNT(V15:V15)>0,R15/COUNT(V15:V15),0.5) | Q15: =SUM(U15:U15) | R15: =SUM(V15:V15) | S15: =IF(ISNUMBER(K15),K15,IF(ISNUMBER(L15),-L15,"")) | T15: =IF(ISNUMBER(L15),L15,IF(ISNUMBER(K15),-K15,"")) | U15: =IF(ISNUMBER(S15),IF(ISNUMBER(S16),IF(S15>S16,1.0,IF(S15=S16,0.5,0.0)),0.5),0.5) | V15: =IF(ISNUMBER(T15),IF(ISNUMBER(T16),IF(T15>T16,1.0,IF(T15=T16,0.5,0.0)),0.5),0.5) | W15: =IF(AND(ISNUMBER(S15),ISNUMBER(S16)),VLOOKUP(ABS(S15-S16),'IMP Table'!$A$2:$C$26,3)*SIGN(S15-S16),0) | X15: =IF(AND(ISNUMBER(T15),ISNUMBER(T16)),VLOOKUP(ABS(T15-T16),'IMP Table'!$A$2:$C$26,3)*SIGN(T15-T16),0)
B16: ='By Round'!A15 | C16: ='By Round'!B15 | D16: ='By Round'!C15 | E16: ='By Round'!D15 | F16: =IF(ISBLANK('By Round'!F15),"",'By Round'!F15) | G16: =IF(ISBLANK('By Round'!G15),"",'By Round'!G15) | H16: =IF(ISBLANK('By Round'!H15),"",'By Round'!H15) | I16: =IF(ISBLANK('By Round'!I15),"",'By Round'!I15) | J16: =IF(ISBLANK('By Round'!J15),"",'By Round'!J15) | K16: =IF(ISBLANK('By Round'!K15),"",'By Round'!K15) | L16: =IF(ISBLANK('By Round'!L15),"",'By Round'!L15) | M16: =AVERAGE(W16:W16) | N16: =AVERAGE(X16:X16) | O16: =IF(COUNT(U16:U16)>0,Q16/COUNT(U16:U16),0.5) | P16: =IF(COUNT(V16:V16)>0,R16/COUNT(V16:V16),0.5) | Q16: =SUM(U16:U16) | R16: =SUM(V16:V16) | S16: =IF(ISNUMBER(K16),K16,IF(ISNUMBER(L16),-L16,"")) | T16: =IF(ISNUMBER(L16),L16,IF(ISNUMBER(K16),-K16,"")) | U16: =IF(ISNUMBER(S16),IF(ISNUMBER(S15),IF(S16>S15,1.0,IF(S16=S15,0.5,0.0)),0.5),0.5) | V16: =IF(ISNUMBER(T16),IF(ISNUMBER(T15),IF(T16>T15,1.0,IF(T16=T15,0.5,0.0)),0.5),0.5) | W16: =IF(AND(ISNUMBER(S16),ISNUMBER(S15)),VLOOKUP(ABS(S16-S15),'IMP Table'!$A$2:$C$26,3)*SIGN(S16-S15),0) | X16: =IF(AND(ISNUMBER(T16),ISNUMBER(T15)),VLOOKUP(ABS(T16-T15),'IMP Table'!$A$2:$C$26,3)*SIGN(T16-T15),0)
A17: 8 | B17: ='By Round'!A33 | C17: ='By Round'!B36 | D17: ='By Round'!C36 | E17: ='By Round'!D36 | F17: =IF(ISBLANK('By Round'!F37),"",'By Round'!F37) | G17: =IF(ISBLANK('By Round'!G37),"",'By Round'!G37) | H17: =IF(ISBLANK('By Round'!H37),"",'By Round'!H37) | I17: =IF(ISBLANK('By Round'!I37),"",'By Round'!I37) | J17: =IF(ISBLANK('By Round'!J37),"",'By Round'!J37) | K17: =IF(ISBLANK('By Round'!K37),"",'By Round'!K37) | L17: =IF(ISBLANK('By Round'!L37),"",'By Round'!L37) | M17: =AVERAGE(W17:W17) | N17: =AVERAGE(X17:X17) | O17: =IF(COUNT(U17:U17)>0,Q17/COUNT(U17:U17),0.5) | P17: =IF(COUNT(V17:V17)>0,R17/COUNT(V17:V17),0.5) | Q17: =SUM(U17:U17) | R17: =SUM(V17:V17) | S17: =IF(ISNUMBER(K17),K17,IF(ISNUMBER(L17),-L17,"")) | T17: =IF(ISNUMBER(L17),L17,IF(ISNUMBER(K17),-K17,"")) | U17: =IF(ISNUMBER(S17),IF(ISNUMBER(S18),IF(S17>S18,1.0,IF(S17=S18,0.5,0.0)),0.5),0.5) | V17: =IF(ISNUMBER(T17),IF(ISNUMBER(T18),IF(T17>T18,1.0,IF(T17=T18,0.5,0.0)),0.5),0.5) | W17: =IF(AND(ISNUMBER(S17),ISNUMBER(S18)),VLOOKUP(ABS(S17-S18),'IMP Table'!$A$2:$C$26,3)*SIGN(S17-S18),0) | X17: =IF(AND(ISNUMBER(T17),ISNUMBER(T18)),VLOOKUP(ABS(T17-T18),'IMP Table'!$A$2:$C$26,3)*SIGN(T17-T18),0)
B18: ='By Round'!A15 | C18: ='By Round'!B15 | D18: ='By Round'!C15 | E18: ='By Round'!D15 | F18: =IF(ISBLANK('By Round'!F16),"",'By Round'!F16) | G18: =IF(ISBLANK('By Round'!G16),"",'By Round'!G16) | H18: =IF(ISBLANK('By Round'!H16),"",'By Round'!H16) | I18: =IF(ISBLANK('By Round'!I16),"",'By Round'!I16) | J18: =IF(ISBLANK('By Round'!J16),"",'By Round'!J16) | K18: =IF(ISBLANK('By Round'!K16),"",'By Round'!K16) | L18: =IF(ISBLANK('By Round'!L16),"",'By Round'!L16) | M18: =AVERAGE(W18:W18) | N18: =AVERAGE(X18:X18) | O18: =IF(COUNT(U18:U18)>0,Q18/COUNT(U18:U18),0.5) | P18: =IF(COUNT(V18:V18)>0,R18/COUNT(V18:V18),0.5) | Q18: =SUM(U18:U18) | R18: =SUM(V18:V18) | S18: =IF(ISNUMBER(K18),K18,IF(ISNUMBER(L18),-L18,"")) | T18: =IF(ISNUMBER(L18),L18,IF(ISNUMBER(K18),-K18,"")) | U18: =IF(ISNUMBER(S18),IF(ISNUMBER(S17),IF(S18>S17,1.0,IF(S18=S17,0.5,0.0)),0.5),0.5) | V18: =IF(ISNUMBER(T18),IF(ISNUMBER(T17),IF(T18>T17,1.0,IF(T18=T17,0.5,0.0)),0.5),0.5) | W18: =IF(AND(ISNUMBER(S18),ISNUMBER(S17)),VLOOKUP(ABS(S18-S17),'IMP Table'!$A$2:$C$26,3)*SIGN(S18-S17),0) | X18: =IF(AND(ISNUMBER(T18),ISNUMBER(T17)),VLOOKUP(ABS(T18-T17),'IMP Table'!$A$2:$C$26,3)*SIGN(T18-T17),0)
A19: 9 | B19: ='By Round'!A33 | C19: ='By Round'!B36 | D19: ='By Round'!C36 | E19: ='By Round'!D36 | F19: =IF(ISBLANK('By Round'!F38),"",'By Round'!F38) | G19: =IF(ISBLANK('By Round'!G38),"",'By Round'!G38) | H19: =IF(ISBLANK('By Round'!H38),"",'By Round'!H38) | I19: =IF(ISBLANK('By Round'!I38),"",'By Round'!I38) | J19: =IF(ISBLANK('By Round'!J38),"",'By Round'!J38) | K19: =IF(ISBLANK('By Round'!K38),"",'By Round'!K38) | L19: =IF(ISBLANK('By Round'!L38),"",'By Round'!L38) | M19: =AVERAGE(W19:W19) | N19: =AVERAGE(X19:X19) | O19: =IF(COUNT(U19:U19)>0,Q19/COUNT(U19:U19),0.5) | P19: =IF(COUNT(V19:V19)>0,R19/COUNT(V19:V19),0.5) | Q19: =SUM(U19:U19) | R19: =SUM(V19:V19) | S19: =IF(ISNUMBER(K19),K19,IF(ISNUMBER(L19),-L19,"")) | T19: =IF(ISNUMBER(L19),L19,IF(ISNUMBER(K19),-K19,"")) | U19: =IF(ISNUMBER(S19),IF(ISNUMBER(S20),IF(S19>S20,1.0,IF(S19=S20,0.5,0.0)),0.5),0.5) | V19: =IF(ISNUMBER(T19),IF(ISNUMBER(T20),IF(T19>T20,1.0,IF(T19=T20,0.5,0.0)),0.5),0.5) | W19: =IF(AND(ISNUMBER(S19),ISNUMBER(S20)),VLOOKUP(ABS(S19-S20),'IMP Table'!$A$2:$C$26,3)*SIGN(S19-S20),0) | X19: =IF(AND(ISNUMBER(T19),ISNUMBER(T20)),VLOOKUP(ABS(T19-T20),'IMP Table'!$A$2:$C$26,3)*SIGN(T19-T20),0)
B20: ='By Round'!A15 | C20: ='By Round'!B15 | D20: ='By Round'!C15 | E20: ='By Round'!D15 | F20: =IF(ISBLANK('By Round'!F17),"",'By Round'!F17) | G20: =IF(ISBLANK('By Round'!G17),"",'By Round'!G17) | H20: =IF(ISBLANK('By Round'!H17),"",'By Round'!H17) | I20: =IF(ISBLANK('By Round'!I17),"",'By Round'!I17) | J20: =IF(ISBLANK('By Round'!J17),"",'By Round'!J17) | K20: =IF(ISBLANK('By Round'!K17),"",'By Round'!K17) | L20: =IF(ISBLANK('By Round'!L17),"",'By Round'!L17) | M20: =AVERAGE(W20:W20) | N20: =AVERAGE(X20:X20) | O20: =IF(COUNT(U20:U20)>0,Q20/COUNT(U20:U20),0.5) | P20: =IF(COUNT(V20:V20)>0,R20/COUNT(V20:V20),0.5) | Q20: =SUM(U20:U20) | R20: =SUM(V20:V20) | S20: =IF(ISNUMBER(K20),K20,IF(ISNUMBER(L20),-L20,"")) | T20: =IF(ISNUMBER(L20),L20,IF(ISNUMBER(K20),-K20,"")) | U20: =IF(ISNUMBER(S20),IF(ISNUMBER(S19),IF(S20>S19,1.0,IF(S20=S19,0.5,0.0)),0.5),0.5) | V20: =IF(ISNUMBER(T20),IF(ISNUMBER(T19),IF(T20>T19,1.0,IF(T20=T19,0.5,0.0)),0.5),0.5) | W20: =IF(AND(ISNUMBER(S20),ISNUMBER(S19)),VLOOKUP(ABS(S20-S19),'IMP Table'!$A$2:$C$26,3)*SIGN(S20-S19),0) | X20: =IF(AND(ISNUMBER(T20),ISNUMBER(T19)),VLOOKUP(ABS(T20-T19),'IMP Table'!$A$2:$C$26,3)*SIGN(T20-T19),0)
A21: 10 | B21: ='By Round'!A3 | C21: ='By Round'!B6 | D21: ='By Round'!C6 | E21: ='By Round'!D6 | F21: =IF(ISBLANK('By Round'!F6),"",'By Round'!F6) | G21: =IF(ISBLANK('By Round'!G6),"",'By Round'!G6) | H21: =IF(ISBLANK('By Round'!H6),"",'By Round'!H6) | I21: =IF(ISBLANK('By Round'!I6),"",'By Round'!I6) | J21: =IF(ISBLANK('By Round'!J6),"",'By Round'!J6) | K21: =IF(ISBLANK('By Round'!K6),"",'By Round'!K6) | L21: =IF(ISBLANK('By Round'!L6),"",'By Round'!L6) | M21: =AVERAGE(W21:W21) | N21: =AVERAGE(X21:X21) | O21: =IF(COUNT(U21:U21)>0,Q21/COUNT(U21:U21),0.5) | P21: =IF(COUNT(V21:V21)>0,R21/COUNT(V21:V21),0.5) | Q21: =SUM(U21:U21) | R21: =SUM(V21:V21) | S21: =IF(ISNUMBER(K21),K21,IF(ISNUMBER(L21),-L21,"")) | T21: =IF(ISNUMBER(L21),L21,IF(ISNUMBER(K21),-K21,"")) | U21: =IF(ISNUMBER(S21),IF(ISNUMBER(S22),IF(S21>S22,1.0,IF(S21=S22,0.5,0.0)),0.5),0.5) | V21: =IF(ISNUMBER(T21),IF(ISNUMBER(T22),IF(T21>T22,1.0,IF(T21=T22,0.5,0.0)),0.5),0.5) | W21: =IF(AND(ISNUMBER(S21),ISNUMBER(S22)),VLOOKUP(ABS(S21-S22),'IMP Table'!$A$2:$C$26,3)*SIGN(S21-S22),0) | X21: =IF(AND(ISNUMBER(T21),ISNUMBER(T22)),VLOOKUP(ABS(T21-T22),'IMP Table'!$A$2:$C$26,3)*SIGN(T21-T22),0)
B22: ='By Round'!A21 | C22: ='By Round'!B21 | D22: ='By Round'!C21 | E22: ='By Round'!D21 | F22: =IF(ISBLANK('By Round'!F21),"",'By Round'!F21) | G22: =IF(ISBLANK('By Round'!G21),"",'By Round'!G21) | H22: =IF(ISBLANK('By Round'!H21),"",'By Round'!H21) | I22: =IF(ISBLANK('By Round'!I21),"",'By Round'!I21) | J22: =IF(ISBLANK('By Round'!J21),"",'By Round'!J21) | K22: =IF(ISBLANK('By Round'!K21),"",'By Round'!K21) | L22: =IF(ISBLANK('By Round'!L21),"",'By Round'!L21) | M22: =AVERAGE(W22:W22) | N22: =AVERAGE(X22:X22) | O22: =IF(COUNT(U22:U22)>0,Q22/COUNT(U22:U22),0.5) | P22: =IF(COUNT(V22:V22)>0,R22/COUNT(V22:V22),0.5) | Q22: =SUM(U22:U22) | R22: =SUM(V22:V22) | S22: =IF(ISNUMBER(K22),K22,IF(ISNUMBER(L22),-L22,"")) | T22: =IF(ISNUMBER(L22),L22,IF(ISNUMBER(K22),-K22,"")) | U22: =IF(ISNUMBER(S22),IF(ISNUMBER(S21),IF(S22>S21,1.0,IF(S22=S21,0.5,0.0)),0.5),0.5) | V22: =IF(ISNUMBER(T22),IF(ISNUMBER(T21),IF(T22>T21,1.0,IF(T22=T21,0.5,0.0)),0.5),0.5) | W22: =IF(AND(ISNUMBER(S22),ISNUMBER(S21)),VLOOKUP(ABS(S22-S21),'IMP Table'!$A$2:$C$26,3)*SIGN(S22-S21),0) | X22: =IF(AND(ISNUMBER(T22),ISNUMBER(T21)),VLOOKUP(ABS(T22-T21),'IMP Table'!$A$2:$C$26,3)*SIGN(T22-T21),0)
A23: 11 | B23: ='By Round'!A3 | C23: ='By Round'!B6 | D23: ='By Round'!C6 | E23: ='By Round'!D6 | F23: =IF(ISBLANK('By Round'!F7),"",'By Round'!F7) | G23: =IF(ISBLANK('By Round'!G7),"",'By Round'!G7) | H23: =IF(ISBLANK('By Round'!H7),"",'By Round'!H7) | I23: =IF(ISBLANK('By Round'!I7),"",'By Round'!I7) | J23: =IF(ISBLANK('By Round'!J7),"",'By Round'!J7) | K23: =IF(ISBLANK('By Round'!K7),"",'By Round'!K7) | L23: =IF(ISBLANK('By Round'!L7),"",'By Round'!L7) | M23: =AVERAGE(W23:W23) | N23: =AVERAGE(X23:X23) | O23: =IF(COUNT(U23:U23)>0,Q23/COUNT(U23:U23),0.5) | P23: =IF(COUNT(V23:V23)>0,R23/COUNT(V23:V23),0.5) | Q23: =SUM(U23:U23) | R23: =SUM(V23:V23) | S23: =IF(ISNUMBER(K23),K23,IF(ISNUMBER(L23),-L23,"")) | T23: =IF(ISNUMBER(L23),L23,IF(ISNUMBER(K23),-K23,"")) | U23: =IF(ISNUMBER(S23),IF(ISNUMBER(S24),IF(S23>S24,1.0,IF(S23=S24,0.5,0.0)),0.5),0.5) | V23: =IF(ISNUMBER(T23),IF(ISNUMBER(T24),IF(T23>T24,1.0,IF(T23=T24,0.5,0.0)),0.5),0.5) | W23: =IF(AND(ISNUMBER(S23),ISNUMBER(S24)),VLOOKUP(ABS(S23-S24),'IMP Table'!$A$2:$C$26,3)*SIGN(S23-S24),0) | X23: =IF(AND(ISNUMBER(T23),ISNUMBER(T24)),VLOOKUP(ABS(T23-T24),'IMP Table'!$A$2:$C$26,3)*SIGN(T23-T24),0)
B24: ='By Round'!A21 | C24: ='By Round'!B21 | D24: ='By Round'!C21 | E24: ='By Round'!D21 | F24: =IF(ISBLANK('By Round'!F22),"",'By Round'!F22) | G24: =IF(ISBLANK('By Round'!G22),"",'By Round'!G22) | H24: =IF(ISBLANK('By Round'!H22),"",'By Round'!H22) | I24: =IF(ISBLANK('By Round'!I22),"",'By Round'!I22) | J24: =IF(ISBLANK('By Round'!J22),"",'By Round'!J22) | K24: =IF(ISBLANK('By Round'!K22),"",'By Round'!K22) | L24: =IF(ISBLANK('By Round'!L22),"",'By Round'!L22) | M24: =AVERAGE(W24:W24) | N24: =AVERAGE(X24:X24) | O24: =IF(COUNT(U24:U24)>0,Q24/COUNT(U24:U24),0.5) | P24: =IF(COUNT(V24:V24)>0,R24/COUNT(V24:V24),0.5) | Q24: =SUM(U24:U24) | R24: =SUM(V24:V24) | S24: =IF(ISNUMBER(K24),K24,IF(ISNUMBER(L24),-L24,"")) | T24: =IF(ISNUMBER(L24),L24,IF(ISNUMBER(K24),-K24,"")) | U24: =IF(ISNUMBER(S24),IF(ISNUMBER(S23),IF(S24>S23,1.0,IF(S24=S23,0.5,0.0)),0.5),0.5) | V24: =IF(ISNUMBER(T24),IF(ISNUMBER(T23),IF(T24>T23,1.0,IF(T24=T23,0.5,0.0)),0.5),0.5) | W24: =IF(AND(ISNUMBER(S24),ISNUMBER(S23)),VLOOKUP(ABS(S24-S23),'IMP Table'!$A$2:$C$26,3)*SIGN(S24-S23),0) | X24: =IF(AND(ISNUMBER(T24),ISNUMBER(T23)),VLOOKUP(ABS(T24-T23),'IMP Table'!$A$2:$C$26,3)*SIGN(T24-T23),0)
A25: 12 | B25: ='By Round'!A3 | C25: ='By Round'!B6 | D25: ='By Round'!C6 | E25: ='By Round'!D6 | F25: =IF(ISBLANK('By Round'!F8),"",'By Round'!F8) | G25: =IF(ISBLANK('By Round'!G8),"",'By Round'!G8) | H25: =IF(ISBLANK('By Round'!H8),"",'By Round'!H8) | I25: =IF(ISBLANK('By Round'!I8),"",'By Round'!I8) | J25: =IF(ISBLANK('By Round'!J8),"",'By Round'!J8) | K25: =IF(ISBLANK('By Round'!K8),"",'By Round'!K8) | L25: =IF(ISBLANK('By Round'!L8),"",'By Round'!L8) | M25: =AVERAGE(W25:W25) | N25: =AVERAGE(X25:X25) | O25: =IF(COUNT(U25:U25)>0,Q25/COUNT(U25:U25),0.5) | P25: =IF(COUNT(V25:V25)>0,R25/COUNT(V25:V25),0.5) | Q25: =SUM(U25:U25) | R25: =SUM(V25:V25) | S25: =IF(ISNUMBER(K25),K25,IF(ISNUMBER(L25),-L25,"")) | T25: =IF(ISNUMBER(L25),L25,IF(ISNUMBER(K25),-K25,"")) | U25: =IF(ISNUMBER(S25),IF(ISNUMBER(S26),IF(S25>S26,1.0,IF(S25=S26,0.5,0.0)),0.5),0.5) | V25: =IF(ISNUMBER(T25),IF(ISNUMBER(T26),IF(T25>T26,1.0,IF(T25=T26,0.5,0.0)),0.5),0.5) | W25: =IF(AND(ISNUMBER(S25),ISNUMBER(S26)),VLOOKUP(ABS(S25-S26),'IMP Table'!$A$2:$C$26,3)*SIGN(S25-S26),0) | X25: =IF(AND(ISNUMBER(T25),ISNUMBER(T26)),VLOOKUP(ABS(T25-T26),'IMP Table'!$A$2:$C$26,3)*SIGN(T25-T26),0)
B26: ='By Round'!A21 | C26: ='By Round'!B21 | D26: ='By Round'!C21 | E26: ='By Round'!D21 | F26: =IF(ISBLANK('By Round'!F23),"",'By Round'!F23) | G26: =IF(ISBLANK('By Round'!G23),"",'By Round'!G23) | H26: =IF(ISBLANK('By Round'!H23),"",'By Round'!H23) | I26: =IF(ISBLANK('By Round'!I23),"",'By Round'!I23) | J26: =IF(ISBLANK('By Round'!J23),"",'By Round'!J23) | K26: =IF(ISBLANK('By Round'!K23),"",'By Round'!K23) | L26: =IF(ISBLANK('By Round'!L23),"",'By Round'!L23) | M26: =AVERAGE(W26:W26) | N26: =AVERAGE(X26:X26) | O26: =IF(COUNT(U26:U26)>0,Q26/COUNT(U26:U26),0.5) | P26: =IF(COUNT(V26:V26)>0,R26/COUNT(V26:V26),0.5) | Q26: =SUM(U26:U26) | R26: =SUM(V26:V26) | S26: =IF(ISNUMBER(K26),K26,IF(ISNUMBER(L26),-L26,"")) | T26: =IF(ISNUMBER(L26),L26,IF(ISNUMBER(K26),-K26,"")) | U26: =IF(ISNUMBER(S26),IF(ISNUMBER(S25),IF(S26>S25,1.0,IF(S26=S25,0.5,0.0)),0.5),0.5) | V26: =IF(ISNUMBER(T26),IF(ISNUMBER(T25),IF(T26>T25,1.0,IF(T26=T25,0.5,0.0)),0.5),0.5) | W26: =IF(AND(ISNUMBER(S26),ISNUMBER(S25)),VLOOKUP(ABS(S26-S25),'IMP Table'!$A$2:$C$26,3)*SIGN(S26-S25),0) | X26: =IF(AND(ISNUMBER(T26),ISNUMBER(T25)),VLOOKUP(ABS(T26-T25),'IMP Table'!$A$2:$C$26,3)*SIGN(T26-T25),0)
A27: 13 | B27: ='By Round'!A9 | C27: ='By Round'!B12 | D27: ='By Round'!C12 | E27: ='By Round'!D12 | F27: =IF(ISBLANK('By Round'!F12),"",'By Round'!F12) | G27: =IF(ISBLANK('By Round'!G12),"",'By Round'!G12) | H27: =IF(ISBLANK('By Round'!H12),"",'By Round'!H12) | I27: =IF(ISBLANK('By Round'!I12),"",'By Round'!I12) | J27: =IF(ISBLANK('By Round'!J12),"",'By Round'!J12) | K27: =IF(ISBLANK('By Round'!K12),"",'By Round'!K12) | L27: =IF(ISBLANK('By Round'!L12),"",'By Round'!L12) | M27: =AVERAGE(W27:W27) | N27: =AVERAGE(X27:X27) | O27: =IF(COUNT(U27:U27)>0,Q27/COUNT(U27:U27),0.5) | P27: =IF(COUNT(V27:V27)>0,R27/COUNT(V27:V27),0.5) | Q27: =SUM(U27:U27) | R27: =SUM(V27:V27) | S27: =IF(ISNUMBER(K27),K27,IF(ISNUMBER(L27),-L27,"")) | T27: =IF(ISNUMBER(L27),L27,IF(ISNUMBER(K27),-K27,"")) | U27: =IF(ISNUMBER(S27),IF(ISNUMBER(S28),IF(S27>S28,1.0,IF(S27=S28,0.5,0.0)),0.5),0.5) | V27: =IF(ISNUMBER(T27),IF(ISNUMBER(T28),IF(T27>T28,1.0,IF(T27=T28,0.5,0.0)),0.5),0.5) | W27: =IF(AND(ISNUMBER(S27),ISNUMBER(S28)),VLOOKUP(ABS(S27-S28),'IMP Table'!$A$2:$C$26,3)*SIGN(S27-S28),0) | X27: =IF(AND(ISNUMBER(T27),ISNUMBER(T28)),VLOOKUP(ABS(T27-T28),'IMP Table'!$A$2:$C$26,3)*SIGN(T27-T28),0)
B28: ='By Round'!A27 | C28: ='By Round'!B27 | D28: ='By Round'!C27 | E28: ='By Round'!D27 | F28: =IF(ISBLANK('By Round'!F27),"",'By Round'!F27) | G28: =IF(ISBLANK('By Round'!G27),"",'By Round'!G27) | H28: =IF(ISBLANK('By Round'!H27),"",'By Round'!H27) | I28: =IF(ISBLANK('By Round'!I27),"",'By Round'!I27) | J28: =IF(ISBLANK('By Round'!J27),"",'By Round'!J27) | K28: =IF(ISBLANK('By Round'!K27),"",'By Round'!K27) | L28: =IF(ISBLANK('By Round'!L27),"",'By Round'!L27) | M28: =AVERAGE(W28:W28) | N28: =AVERAGE(X28:X28) | O28: =IF(COUNT(U28:U28)>0,Q28/COUNT(U28:U28),0.5) | P28: =IF(COUNT(V28:V28)>0,R28/COUNT(V28:V28),0.5) | Q28: =SUM(U28:U28) | R28: =SUM(V28:V28) | S28: =IF(ISNUMBER(K28),K28,IF(ISNUMBER(L28),-L28,"")) | T28: =IF(ISNUMBER(L28),L28,IF(ISNUMBER(K28),-K28,"")) | U28: =IF(ISNUMBER(S28),IF(ISNUMBER(S27),IF(S28>S27,1.0,IF(S28=S27,0.5,0.0)),0.5),0.5) | V28: =IF(ISNUMBER(T28),IF(ISNUMBER(T27),IF(T28>T27,1.0,IF(T28=T27,0.5,0.0)),0.5),0.5) | W28: =IF(AND(ISNUMBER(S28),ISNUMBER(S27)),VLOOKUP(ABS(S28-S27),'IMP Table'!$A$2:$C$26,3)*SIGN(S28-S27),0) | X28: =IF(AND(ISNUMBER(T28),ISNUMBER(T27)),VLOOKUP(ABS(T28-T27),'IMP Table'!$A$2:$C$26,3)*SIGN(T28-T27),0)
A29: 14 | B29: ='By Round'!A9 | C29: ='By Round'!B12 | D29: ='By Round'!C12 | E29: ='By Round'!D12 | F29: =IF(ISBLANK('By Round'!F13),"",'By Round'!F13) | G29: =IF(ISBLANK('By Round'!G13),"",'By Round'!G13) | H29: =IF(ISBLANK('By Round'!H13),"",'By Round'!H13) | I29: =IF(ISBLANK('By Round'!I13),"",'By Round'!I13) | J29: =IF(ISBLANK('By Round'!J13),"",'By Round'!J13) | K29: =IF(ISBLANK('By Round'!K13),"",'By Round'!K13) | L29: =IF(ISBLANK('By Round'!L13),"",'By Round'!L13) | M29: =AVERAGE(W29:W29) | N29: =AVERAGE(X29:X29) | O29: =IF(COUNT(U29:U29)>0,Q29/COUNT(U29:U29),0.5) | P29: =IF(COUNT(V29:V29)>0,R29/COUNT(V29:V29),0.5) | Q29: =SUM(U29:U29) | R29: =SUM(V29:V29) | S29: =IF(ISNUMBER(K29),K29,IF(ISNUMBER(L29),-L29,"")) | T29: =IF(ISNUMBER(L29),L29,IF(ISNUMBER(K29),-K29,"")) | U29: =IF(ISNUMBER(S29),IF(ISNUMBER(S30),IF(S29>S30,1.0,IF(S29=S30,0.5,0.0)),0.5),0.5) | V29: =IF(ISNUMBER(T29),IF(ISNUMBER(T30),IF(T29>T30,1.0,IF(T29=T30,0.5,0.0)),0.5),0.5) | W29: =IF(AND(ISNUMBER(S29),ISNUMBER(S30)),VLOOKUP(ABS(S29-S30),'IMP Table'!$A$2:$C$26,3)*SIGN(S29-S30),0) | X29: =IF(AND(ISNUMBER(T29),ISNUMBER(T30)),VLOOKUP(ABS(T29-T30),'IMP Table'!$A$2:$C$26,3)*SIGN(T29-T30),0)
B30: ='By Round'!A27 | C30: ='By Round'!B27 | D30: ='By Round'!C27 | E30: ='By Round'!D27 | F30: =IF(ISBLANK('By Round'!F28),"",'By Round'!F28) | G30: =IF(ISBLANK('By Round'!G28),"",'By Round'!G28) | H30: =IF(ISBLANK('By Round'!H28),"",'By Round'!H28) | I30: =IF(ISBLANK('By Round'!I28),"",'By Round'!I28) | J30: =IF(ISBLANK('By Round'!J28),"",'By Round'!J28) | K30: =IF(ISBLANK('By Round'!K28),"",'By Round'!K28) | L30: =IF(ISBLANK('By Round'!L28),"",'By Round'!L28) | M30: =AVERAGE(W30:W30) | N30: =AVERAGE(X30:X30) | O30: =IF(COUNT(U30:U30)>0,Q30/COUNT(U30:U30),0.5) | P30: =IF(COUNT(V30:V30)>0,R30/COUNT(V30:V30),0.5) | Q30: =SUM(U30:U30) | R30: =SUM(V30:V30) | S30: =IF(ISNUMBER(K30),K30,IF(ISNUMBER(L30),-L30,"")) | T30: =IF(ISNUMBER(L30),L30,IF(ISNUMBER(K30),-K30,"")) | U30: =IF(ISNUMBER(S30),IF(ISNUMBER(S29),IF(S30>S29,1.0,IF(S30=S29,0.5,0.0)),0.5),0.5) | V30: =IF(ISNUMBER(T30),IF(ISNUMBER(T29),IF(T30>T29,1.0,IF(T30=T29,0.5,0.0)),0.5),0.5) | W30: =IF(AND(ISNUMBER(S30),ISNUMBER(S29)),VLOOKUP(ABS(S30-S29),'IMP Table'!$A$2:$C$26,3)*SIGN(S30-S29),0) | X30: =IF(AND(ISNUMBER(T30),ISNUMBER(T29)),VLOOKUP(ABS(T30-T29),'IMP Table'!$A$2:$C$26,3)*SIGN(T30-T29),0)
A31: 15 | B31: ='By Round'!A9 | C31: ='By Round'!B12 | D31: ='By Round'!C12 | E31: ='By Round'!D12 | F31: =IF(ISBLANK('By Round'!F14),"",'By Round'!F14) | G31: =IF(ISBLANK('By Round'!G14),"",'By Round'!G14) | H31: =IF(ISBLANK('By Round'!H14),"",'By Round'!H14) | I31: =IF(ISBLANK('By Round'!I14),"",'By Round'!I14) | J31: =IF(ISBLANK('By Round'!J14),"",'By Round'!J14) | K31: =IF(ISBLANK('By Round'!K14),"",'By Round'!K14) | L31: =IF(ISBLANK('By Round'!L14),"",'By Round'!L14) | M31: =AVERAGE(W31:W31) | N31: =AVERAGE(X31:X31) | O31: =IF(COUNT(U31:U31)>0,Q31/COUNT(U31:U31),0.5) | P31: =IF(COUNT(V31:V31)>0,R31/COUNT(V31:V31),0.5) | Q31: =SUM(U31:U31) | R31: =SUM(V31:V31) | S31: =IF(ISNUMBER(K31),K31,IF(ISNUMBER(L31),-L31,"")) | T31: =IF(ISNUMBER(L31),L31,IF(ISNUMBER(K31),-K31,"")) | U31: =IF(ISNUMBER(S31),IF(ISNUMBER(S32),IF(S31>S32,1.0,IF(S31=S32,0.5,0.0)),0.5),0.5) | V31: =IF(ISNUMBER(T31),IF(ISNUMBER(T32),IF(T31>T32,1.0,IF(T31=T32,0.5,0.0)),0.5),0.5) | W31: =IF(AND(ISNUMBER(S31),ISNUMBER(S32)),VLOOKUP(ABS(S31-S32),'IMP Table'!$A$2:$C$26,3)*SIGN(S31-S32),0) | X31: =IF(AND(ISNUMBER(T31),ISNUMBER(T32)),VLOOKUP(ABS(T31-T32),'IMP Table'!$A$2:$C$26,3)*SIGN(T31-T32),0)
B32: ='By Round'!A27 | C32: ='By Round'!B27 | D32: ='By Round'!C27 | E32: ='By Round'!D27 | F32: =IF(ISBLANK('By Round'!F29),"",'By Round'!F29) | G32: =IF(ISBLANK('By Round'!G29),"",'By Round'!G29) | H32: =IF(ISBLANK('By Round'!H29),"",'By Round'!H29) | I32: =IF(ISBLANK('By Round'!I29),"",'By Round'!I29) | J32: =IF(ISBLANK('By Round'!J29),"",'By Round'!J29) | K32: =IF(ISBLANK('By Round'!K29),"",'By Round'!K29) | L32: =IF(ISBLANK('By Round'!L29),"",'By Round'!L29) | M32: =AVERAGE(W32:W32) | N32: =AVERAGE(X32:X32) | O32: =IF(COUNT(U32:U32)>0,Q32/COUNT(U32:U32),0.5) | P32: =IF(COUNT(V32:V32)>0,R32/COUNT(V32:V32),0.5) | Q32: =SUM(U32:U32) | R32: =SUM(V32:V32) | S32: =IF(ISNUMBER(K32),K32,IF(ISNUMBER(L32),-L32,"")) | T32: =IF(ISNUMBER(L32),L32,IF(ISNUMBER(K32),-K32,"")) | U32: =IF(ISNUMBER(S32),IF(ISNUMBER(S31),IF(S32>S31,1.0,IF(S32=S31,0.5,0.0)),0.5),0.5) | V32: =IF(ISNUMBER(T32),IF(ISNUMBER(T31),IF(T32>T31,1.0,IF(T32=T31,0.5,0.0)),0.5),0.5) | W32: =IF(AND(ISNUMBER(S32),ISNUMBER(S31)),VLOOKUP(ABS(S32-S31),'IMP Table'!$A$2:$C$26,3)*SIGN(S32-S31),0) | X32: =IF(AND(ISNUMBER(T32),ISNUMBER(T31)),VLOOKUP(ABS(T32-T31),'IMP Table'!$A$2:$C$26,3)*SIGN(T32-T31),0)
A33: 16 | B33: ='By Round'!A15 | C33: ='By Round'!B18 | D33: ='By Round'!C18 | E33: ='By Round'!D18 | F33: =IF(ISBLANK('By Round'!F18),"",'By Round'!F18) | G33: =IF(ISBLANK('By Round'!G18),"",'By Round'!G18) | H33: =IF(ISBLANK('By Round'!H18),"",'By Round'!H18) | I33: =IF(ISBLANK('By Round'!I18),"",'By Round'!I18) | J33: =IF(ISBLANK('By Round'!J18),"",'By Round'!J18) | K33: =IF(ISBLANK('By Round'!K18),"",'By Round'!K18) | L33: =IF(ISBLANK('By Round'!L18),"",'By Round'!L18) | M33: =AVERAGE(W33:W33) | N33: =AVERAGE(X33:X33) | O33: =IF(COUNT(U33:U33)>0,Q33/COUNT(U33:U33),0.5) | P33: =IF(COUNT(V33:V33)>0,R33/COUNT(V33:V33),0.5) | Q33: =SUM(U33:U33) | R33: =SUM(V33:V33) | S33: =IF(ISNUMBER(K33),K33,IF(ISNUMBER(L33),-L33,"")) | T33: =IF(ISNUMBER(L33),L33,IF(ISNUMBER(K33),-K33,"")) | U33: =IF(ISNUMBER(S33),IF(ISNUMBER(S34),IF(S33>S34,1.0,IF(S33=S34,0.5,0.0)),0.5),0.5) | V33: =IF(ISNUMBER(T33),IF(ISNUMBER(T34),IF(T33>T34,1.0,IF(T33=T34,0.5,0.0)),0.5),0.5) | W33: =IF(AND(ISNUMBER(S33),ISNUMBER(S34)),VLOOKUP(ABS(S33-S34),'IMP Table'!$A$2:$C$26,3)*SIGN(S33-S34),0) | X33: =IF(AND(ISNUMBER(T33),ISNUMBER(T34)),VLOOKUP(ABS(T33-T34),'IMP Table'!$A$2:$C$26,3)*SIGN(T33-T34),0)
B34: ='By Round'!A33 | C34: ='By Round'!B33 | D34: ='By Round'!C33 | E34: ='By Round'!D33 | F34: =IF(ISBLANK('By Round'!F33),"",'By Round'!F33) | G34: =IF(ISBLANK('By Round'!G33),"",'By Round'!G33) | H34: =IF(ISBLANK('By Round'!H33),"",'By Round'!H33) | I34: =IF(ISBLANK('By Round'!I33),"",'By Round'!I33) | J34: =IF(ISBLANK('By Round'!J33),"",'By Round'!J33) | K34: =IF(ISBLANK('By Round'!K33),"",'By Round'!K33) | L34: =IF(ISBLANK('By Round'!L33),"",'By Round'!L33) | M34: =AVERAGE(W34:W34) | N34: =AVERAGE(X34:X34) | O34: =IF(COUNT(U34:U34)>0,Q34/COUNT(U34:U34),0.5) | P34: =IF(COUNT(V34:V34)>0,R34/COUNT(V34:V34),0.5) | Q34: =SUM(U34:U34) | R34: =SUM(V34:V34) | S34: =IF(ISNUMBER(K34),K34,IF(ISNUMBER(L34),-L34,"")) | T34: =IF(ISNUMBER(L34),L34,IF(ISNUMBER(K34),-K34,"")) | U34: =IF(ISNUMBER(S34),IF(ISNUMBER(S33),IF(S34>S33,1.0,IF(S34=S33,0.5,0.0)),0.5),0.5) | V34: =IF(ISNUMBER(T34),IF(ISNUMBER(T33),IF(T34>T33,1.0,IF(T34=T33,0.5,0.0)),0.5),0.5) | W34: =IF(AND(ISNUMBER(S34),ISNUMBER(S33)),VLOOKUP(ABS(S34-S33),'IMP Table'!$A$2:$C$26,3)*SIGN(S34-S33),0) | X34: =IF(AND(ISNUMBER(T34),ISNUMBER(T33)),VLOOKUP(ABS(T34-T33),'IMP Table'!$A$2:$C$26,3)*SIGN(T34-T33),0)
A35: 17 | B35: ='By Round'!A15 | C35: ='By Round'!B18 | D35: ='By Round'!C18 | E35: ='By Round'!D18 | F35: =IF(ISBLANK('By Round'!F19),"",'By Round'!F19) | G35: =IF(ISBLANK('By Round'!G19),"",'By Round'!G19) | H35: =IF(ISBLANK('By Round'!H19),"",'By Round'!H19) | I35: =IF(ISBLANK('By Round'!I19),"",'By Round'!I19) | J35: =IF(ISBLANK('By Round'!J19),"",'By Round'!J19) | K35: =IF(ISBLANK('By Round'!K19),"",'By Round'!K19) | L35: =IF(ISBLANK('By Round'!L19),"",'By Round'!L19) | M35: =AVERAGE(W35:W35) | N35: =AVERAGE(X35:X35) | O35: =IF(COUNT(U35:U35)>0,Q35/COUNT(U35:U35),0.5) | P35: =IF(COUNT(V35:V35)>0,R35/COUNT(V35:V35),0.5) | Q35: =SUM(U35:U35) | R35: =SUM(V35:V35) | S35: =IF(ISNUMBER(K35),K35,IF(ISNUMBER(L35),-L35,"")) | T35: =IF(ISNUMBER(L35),L35,IF(ISNUMBER(K35),-K35,"")) | U35: =IF(ISNUMBER(S35),IF(ISNUMBER(S36),IF(S35>S36,1.0,IF(S35=S36,0.5,0.0)),0.5),0.5) | V35: =IF(ISNUMBER(T35),IF(ISNUMBER(T36),IF(T35>T36,1.0,IF(T35=T36,0.5,0.0)),0.5),0.5) | W35: =IF(AND(ISNUMBER(S35),ISNUMBER(S36)),VLOOKUP(ABS(S35-S36),'IMP Table'!$A$2:$C$26,3)*SIGN(S35-S36),0) | X35: =IF(AND(ISNUMBER(T35),ISNUMBER(T36)),VLOOKUP(ABS(T35-T36),'IMP Table'!$A$2:$C$26,3)*SIGN(T35-T36),0)
B36: ='By Round'!A33 | C36: ='By Round'!B33 | D36: ='By Round'!C33 | E36: ='By Round'!D33 | F36: =IF(ISBLANK('By Round'!F34),"",'By Round'!F34) | G36: =IF(ISBLANK('By Round'!G34),"",'By Round'!G34) | H36: =IF(ISBLANK('By Round'!H34),"",'By Round'!H34) | I36: =IF(ISBLANK('By Round'!I34),"",'By Round'!I34) | J36: =IF(ISBLANK('By Round'!J34),"",'By Round'!J34) | K36: =IF(ISBLANK('By Round'!K34),"",'By Round'!K34) | L36: =IF(ISBLANK('By Round'!L34),"",'By Round'!L34) | M36: =AVERAGE(W36:W36) | N36: =AVERAGE(X36:X36) | O36: =IF(COUNT(U36:U36)>0,Q36/COUNT(U36:U36),0.5) | P36: =IF(COUNT(V36:V36)>0,R36/COUNT(V36:V36),0.5) | Q36: =SUM(U36:U36) | R36: =SUM(V36:V36) | S36: =IF(ISNUMBER(K36),K36,IF(ISNUMBER(L36),-L36,"")) | T36: =IF(ISNUMBER(L36),L36,IF(ISNUMBER(K36),-K36,"")) | U36: =IF(ISNUMBER(S36),IF(ISNUMBER(S35),IF(S36>S35,1.0,IF(S36=S35,0.5,0.0)),0.5),0.5) | V36: =IF(ISNUMBER(T36),IF(ISNUMBER(T35),IF(T36>T35,1.0,IF(T36=T35,0.5,0.0)),0.5),0.5) | W36: =IF(AND(ISNUMBER(S36),ISNUMBER(S35)),VLOOKUP(ABS(S36-S35),'IMP Table'!$A$2:$C$26,3)*SIGN(S36-S35),0) | X36: =IF(AND(ISNUMBER(T36),ISNUMBER(T35)),VLOOKUP(ABS(T36-T35),'IMP Table'!$A$2:$C$26,3)*SIGN(T36-T35),0)
A37: 18 | B37: ='By Round'!A15 | C37: ='By Round'!B18 | D37: ='By Round'!C18 | E37: ='By Round'!D18 | F37: =IF(ISBLANK('By Round'!F20),"",'By Round'!F20) | G37: =IF(ISBLANK('By Round'!G20),"",'By Round'!G20) | H37: =IF(ISBLANK('By Round'!H20),"",'By Round'!H20) | I37: =IF(ISBLANK('By Round'!I20),"",'By Round'!I20) | J37: =IF(ISBLANK('By Round'!J20),"",'By Round'!J20) | K37: =IF(ISBLANK('By Round'!K20),"",'By Round'!K20) | L37: =IF(ISBLANK('By Round'!L20),"",'By Round'!L20) | M37: =AVERAGE(W37:W37) | N37: =AVERAGE(X37:X37) | O37: =IF(COUNT(U37:U37)>0,Q37/COUNT(U37:U37),0.5) | P37: =IF(COUNT(V37:V37)>0,R37/COUNT(V37:V37),0.5) | Q37: =SUM(U37:U37) | R37: =SUM(V37:V37) | S37: =IF(ISNUMBER(K37),K37,IF(ISNUMBER(L37),-L37,"")) | T37: =IF(ISNUMBER(L37),L37,IF(ISNUMBER(K37),-K37,"")) | U37: =IF(ISNUMBER(S37),IF(ISNUMBER(S38),IF(S37>S38,1.0,IF(S37=S38,0.5,0.0)),0.5),0.5) | V37: =IF(ISNUMBER(T37),IF(ISNUMBER(T38),IF(T37>T38,1.0,IF(T37=T38,0.5,0.0)),0.5),0.5) | W37: =IF(AND(ISNUMBER(S37),ISNUMBER(S38)),VLOOKUP(ABS(S37-S38),'IMP Table'!$A$2:$C$26,3)*SIGN(S37-S38),0) | X37: =IF(AND(ISNUMBER(T37),ISNUMBER(T38)),VLOOKUP(ABS(T37-T38),'IMP Table'!$A$2:$C$26,3)*SIGN(T37-T38),0)
B38: ='By Round'!A33 | C38: ='By Round'!B33 | D38: ='By Round'!C33 | E38: ='By Round'!D33 | F38: =IF(ISBLANK('By Round'!F35),"",'By Round'!F35) | G38: =IF(ISBLANK('By Round'!G35),"",'By Round'!G35) | H38: =IF(ISBLANK('By Round'!H35),"",'By Round'!H35) | I38: =IF(ISBLANK('By Round'!I35),"",'By Round'!I35) | J38: =IF(ISBLANK('By Round'!J35),"",'By Round'!J35) | K38: =IF(ISBLANK('By Round'!K35),"",'By Round'!K35) | L38: =IF(ISBLANK('By Round'!L35),"",'By Round'!L35) | M38: =AVERAGE(W38:W38) | N38: =AVERAGE(X38:X38) | O38: =IF(COUNT(U38:U38)>0,Q38/COUNT(U38:U38),0.5) | P38: =IF(COUNT(V38:V38)>0,R38/COUNT(V38:V38),0.5) | Q38: =SUM(U38:U38) | R38: =SUM(V38:V38) | S38: =IF(ISNUMBER(K38),K38,IF(ISNUMBER(L38),-L38,"")) | T38: =IF(ISNUMBER(L38),L38,IF(ISNUMBER(K38),-K38,"")) | U38: =IF(ISNUMBER(S38),IF(ISNUMBER(S37),IF(S38>S37,1.0,IF(S38=S37,0.5,0.0)),0.5),0.5) | V38: =IF(ISNUMBER(T38),IF(ISNUMBER(T37),IF(T38>T37,1.0,IF(T38=T37,0.5,0.0)),0.5),0.5) | W38: =IF(AND(ISNUMBER(S38),ISNUMBER(S37)),VLOOKUP(ABS(S38-S37),'IMP Table'!$A$2:$C$26,3)*SIGN(S38-S37),0) | X38: =IF(AND(ISNUMBER(T38),ISNUMBER(T37)),VLOOKUP(ABS(T38-T37),'IMP Table'!$A$2:$C$26,3)*SIGN(T38-T37),0)

Sheet By Round
I1: Result | K1: Score
A2: Round | B2: Table | C2: NS | D2: EW | E2: Board | F2: Vul | G2: Contract | H2: By | I2: Made | J2: Down | K2: NS | L2: EW
A3: 1 | B3: 1 | C3: 4 | D3: 1 | E3: 1 | F3: None
E4: 2 | F4: NS
E5: 3 | F5: EW
B6: 2 | C6: 3 | D6: 2 | E6: 10 | F6: Both
E7: 11 | F7: None
E8: 12 | F8: NS
A9: 2 | B9: 1 | C9: 4 | D9: 2 | E9: 4 | F9: Both
E10: 5 | F10: NS
E11: 6 | F11: EW
B12: 2 | C12: 1 | D12: 3 | E12: 13 | F12: Both
E13: 14 | F13: None
E14: 15 | F14: NS
A15: 3 | B15: 1 | C15: 4 | D15: 3 | E15: 7 | F15: Both
E16: 8 | F16: None
E17: 9 | F17: EW
B18: 2 | C18: 2 | D18: 1 | E18: 16 | F18: EW
E19: 17 | F19: None
E20: 18 | F20: NS
A21: 4 | B21: 1 | C21: 4 | D21: 1 | E21: 10 | F21: Both
E22: 11 | F22: None
E23: 12 | F23: NS
B24: 2 | C24: 3 | D24: 2 | E24: 1 | F24: None
E25: 2 | F25: NS
E26: 3 | F26: EW
A27: 5 | B27: 1 | C27: 4 | D27: 2 | E27: 13 | F27: Both
E28: 14 | F28: None
E29: 15 | F29: NS
B30: 2 | C30: 1 | D30: 3 | E30: 4 | F30: Both
E31: 5 | F31: NS
E32: 6 | F32: EW
A33: 6 | B33: 1 | C33: 4 | D33: 3 | E33: 16 | F33: EW
E34: 17 | F34: None
E35: 18 | F35: NS
B36: 2 | C36: 2 | D36: 1 | E36: 7 | F36: Both
E37: 8 | F37: None
E38: 9 | F38: EW

Sheet IMP Table
A1: From | B1: To | C1: IMP
A2: 0 | B2: 10 | C2: 0
A3: 20 | B3: 40 | C3: 1
A4: 50 | B4: 80 | C4: 2
A5: 90 | B5: 120 | C5: 3
A6: 130 | B6: 160 | C6: 4
A7: 170 | B7: 210 | C7: 5
A8: 220 | B8: 260 | C8: 6
A9: 270 | B9: 310 | C9: 7
A10: 320 | B10: 360 | C10: 8
A11: 370 | B11: 420 | C11: 9
A12: 430 | B12: 490 | C12: 10
A13: 500 | B13: 590 | C13: 11
... A26: 4000 | B26: 10000 | C26: 24

Sheet Scoring Table
C1: Not Vulnerable | F1: Vulnerable | K1: Not Vulnerable | N1: Vulnerable
A2: Contract | B2: Made | D2: X | E2: XX | G2: X | H2: XX | J2: Down by | L2: X | M2: XX | O2: X | P2: XX
A3: 1 D/C | B3: 1 | C3: 70 | D3: 140 | E3: 230 | F3: 70 | G3: 140 | H3: 230 | J3: -1 | K3: -50 | L3: -100 | M3: =L3*2 | N3: -100 | O3: -200 | P3: =O3*2
B4: 2 | C4: 90 | D4: 240 | E4: 430 | F4: 90 | G4: 340 | H4: 630 | J4: -2 | K4: =K3-50 | L4: =L3-200 | M4: =L4*2 | N4: =K3-100 | O4: =L3-300 | P4: =L4*2
B5: 3 | C5: 110 | D5: 340 | E5: 630 | F5: 110 | G5: 540 | H5: 1030 | J5: -3 | K5: =K4-50 | L5: =L4-200 | M5: =L5*2 | N5: =K4-100 | O5: =L4-300 | P5: =L5*2
B6: 4 | C6: 130 | D6: 440 | E6: 830 | F6: 130 | G6: 740 | H6: 1430 | J6: -4 | K6: =K5-50 | L6: =L5-300 | M6: =L6*2 | N6: =K5-100 | O6: =L5-300 | P6: =L6*2
B7: 5 | C7: 150 | D7: 540 | E7: 1030 | F7: 150 | G7: 940 | H7: 1830 | J7: -5 | K7: =K6-50 | L7: =L6-300 | M7: =L7*2 | N7: =K6-100 | O7: =L6-300 | P7: =L7*2
B8: 6 | C8: 170 | D8: 640 | E8: 1230 | F8: 170 | G8: 1140 | H8: 2230 | J8: -6 | K8: =K7-50 | L8: =L7-300 | M8: =L8*2 | N8: =K7-100 | O8: =L7-300 | P8: =L8*2
B9: 7 | C9: 190 | D9: 740 | E9: 1430 | F9: 190 | G9: 1340 | H9: 2630 | J9: -7 | K9: =K8-50 | L9: =L8-300 | M9: =L9*2 | N9: =K8-100 | O9: =L8-300 | P9: =L9*2
A10: 1 H/S | B10: 1 | C10: 80 | D10: 160 | E10: 520 | F10: 80 | G10: 160 | H10: 720 | J10: -8 | K10: =K9-50 | L10: =L9-300 | M10: =L10*2 | N10: =K9-100 | O10: =L9-300 | P10: =L10*2
B11: 2 | C11: 110 | D11: 260 | E11: 720 | F11: 110 | G11: 360 | H11: 1120 | J11: -9 | K11: =K10-50 | L11: =L10-300 | M11: =L11*2 | N11: =K10-100 | O11: =L10-300 | P11: =L11*2
B12: 3 | C12: 140 | D12: 360 | E12: 920 | F12: 140 | G12: 560 | H12: 1520 | J12: -10 | K12: =K11-50 | L12: =L11-300 | M12: =L12*2 | N12: =K11-100 | O12: =L11-300 | P12: =L12*2
B13: 4 | C13: 170 | D13: 460 | E13: 1120 | F13: 170 | G13: 760 | H13: 1920 | J13: -11 | K13: =K12-50 | L13: =L12-300 | M13: =L13*2 | N13: =K12-100 | O13: =L12-300 | P13: =L13*2
B14: 5 | C14: 200 | D14: 560 | E14: 1320 | F14: 200 | G14: 960 | H14: 2320 | J14: -12 | K14: =K13-50 | L14: =L13-300 | M14: =L14*2 | N14: =K13-100 | O14: =L13-300 | P14: =L14*2
B15: 6 | C15: 230 | D15: 660 | E15: 1520 | F15: 230 | G15: 1160 | H15: 2720 | J15: -13 | K15: =K14-50 | L15: =L14-300 | M15: =L15*2 | N15: =K14-100 | O15: =L14-300 | P15: =L15*2
B16: 7 | C16: 260 | D16: 760 | E16: 1720 | F16: 260 | G16: 1360 | H16: 3120
A17: 1 NT | B17: 1 | C17: 90 | D17: 180 | E17: 560 | F17: 90 | G17: 180 | H17: 760
B18: 2 | C18: 120 | D18: 280 | E18: 760 | F18: 120 | G18: 380 | H18: 1160
B19: 3 | C19: 150 | D19: 380 | E19: 960 | F19: 150 | G19: 580 | H19: 1560
B20: 4 | C20: 180 | D20: 480 | E20: 1160 | F20: 180 | G20: 780 | H20: 1960
B21: 5 | C21: 210 | D21: 580 | E21: 1360 | F21: 210 | G21: 980 | H21: 2360
B22: 6 | C22: 240 | D22: 680 | E22: 1560 | F22: 240 | G22: 1180 | H22: 2760
B23: 7 | C23: 270 | D23: 780 | E23: 1760 | F23: 270 | G23: 1380 | H23: 3160
A24: 2 D/C | B24: 2 | C24: 90 | D24: 180 | E24: 560 | F24: 90 | G24: 180 | H24: 760
B25: 3 | C25: 110 | D25: 280 | E25: 760 | F25: 110 | G25: 380 | H25: 1160
B26: 4 | C26: 130 | D26: 380 | E26: 960 | F26: 130 | G26: 580 | H26: 1560
B27: 5 | C27: 150 | D27: 480 | E27: 1160 | F27: 150 | G27: 780 | H27: 1960
B28: 6 | C28: 170 | D28: 580 | E28: 1360 | F28: 170 | G28: 980 | H28: 2360
B29: 7 | C29: 190 | D29: 680 | E29: 1560 | F29: 190 | G29: 1180 | H29: 2760
A30: 2 H/S | B30: 2 | C30: 110 | D30: 470 | E30: 640 | F30: 110 | G30: 670 | H30: 840
B31: 3 | C31: 140 | D31: 570 | E31: 840 | F31: 140 | G31: 870 | H31: 1240
B32: 4 | C32: 170 | D32: 670 | E32: 1040 | F32: 170 | G32: 1070 | H32: 1640
B33: 5 | C33: 200 | D33: 770 | E33: 1240 | F33: 200 | G33: 1270 | H33: 2040
B34: 6 | C34: 230 | D34: 870 | E34: 1440 | F34: 230 | G34: 1470 | H34: 2440
B35: 7 | C35: 260 | D35: 970 | E35: 1640 | F35: 260 | G35: 1670 | H35: 2840
A36: 2 NT | B36: 2 | C36: 120 | D36: 490 | E36: 680 | F36: 120 | G36: 690 | H36: 880
B37: 3 | C37: 150 | D37: 590 | E37: 880 | F37: 150 | G37: 890 | H37: 1280
B38: 4 | C38: 180 | D38: 690 | E38: 1080 | F38: 180 | G38: 1090 | H38: 1680
B39: 5 | C39: 210 | D39: 790 | E39: 1280 | F39: 210 | G39: 1290 | H39: 2080
B40: 6 | C40: 240 | D40: 890 | E40: 1480 | F40: 240 | G40: 1490 | H40: 2480
...
