Workbook

Sheet Roster
A1: For public domain. No rights reserved. Generated on Jul 29, 2026.
A2: Mitchell Tournament
A3: Pairs | C3: 8
A4: Tables | C4: 4
A5: Rounds | C5: 3
A6: Boards per round | C6: 4
A7: EW pairs skip a table after round 2
A9: NS Pairs | D9: MP | E9: IMP
A10: 1 | B10: Name 37 | C10: Name 43 | D10: =SUMIF('By Board'!D3:D50,"="&A10,'By Board'!Q3:Q50)/24 | E10: =SUMIF('By Board'!D3:D50,"="&A10,'By Board'!M3:M50)
A11: 2 | B11: Name 53 | C11: Name 11 | D11: =SUMIF('By Board'!D3:D50,"="&A11,'By Board'!Q3:Q50)/24 | E11: =SUMIF('By Board'!D3:D50,"="&A11,'By Board'!M3:M50)
A12: 3 | B12: Name 62 | C12: Name 31 | D12: =SUMIF('By Board'!D3:D50,"="&A12,'By Board'!Q3:Q50)/24 | E12: =SUMIF('By Board'!D3:D50,"="&A12,'By Board'!M3:M50)
A13: 4 | B13: Name 89 | C13: Name 61 | D13: =SUMIF('By Board'!D3:D50,"="&A13,'By Board'!Q3:Q50)/24 | E13: =SUMIF('By Board'!D3:D50,"="&A13,'By Board'!M3:M50)
C14: Average | D14: =AVERAGE(D10:D13) | E14: =SUM(F10:F13)
A16: EW Pairs | D16: MP | E16: IMP
A17: 1 | B17: Name 18 | C17: Name 70 | D17: =SUMIF('By Board'!E3:E50,"="&A17,'By Board'!R3:R50)/24 | E17: =SUMIF('By Board'!E3:E50,"="&A17,'By Board'!N3:N50)
A18: 2 | B18: Name 65 | C18: Name 26 | D18: =SUMIF('By Board'!E3:E50,"="&A18,'By Board'!R3:R50)/24 | E18: =SUMIF('By Board'!E3:E50,"="&A18,'By Board'!N3:N50)
A19: 3 | B19: Name 81 | C19: Name 79 | D19: =SUMIF('By Board'!E3:E50,"="&A19,'By Board'!R3:R50)/24 | E19: =SUMIF('By Board'!E3:E50,"="&A19,'By Board'!N3:N50)
A20: 4 | B20: Name 51 | C20: Name 84 | D20: =SUMIF('By Board'!E3:E50,"="&A20,'By Board'!R3:R50)/24 | E20: =SUMIF('By Board'!E3:E50,"="&A20,'By Board'!N3:N50)
C21: Average | D21: =AVERAGE(D17:D20) | E21: =SUM(F17:F20)

Sheet By Board
I1: Result | K1: Score | M1: IMP | O1: MP % | Q1: MP Pts | S1: Net | U1: MP Calculation | Y1: IMP Calculation
A2: Board | B2: Round | C2: Table | D2: NS | E2: EW | F2: Vul | G2: Contract | H2: By | I2: Made | J2: Down | K2: NS | L2: EW | M2: NS | N2: EW | O2: NS | P2: EW | Q2: NS | R2: EW | S2: NS | T2: EW | U2: NS MP Scores | W2: EW MP Scores | Y2: NS IMP Pair-wise | AA2: EW IMP Pair-wise
A3: 1 | B3: ='By Round'!A3 | C3: ='By Round'!B3 | D3: ='By Round'!C3 | E3: ='By Round'!D3 | F3: =IF(ISBLANK('By Round'!F3),"",'By Round'!F3) | G3: =IF(ISBLANK('By Round'!G3),"",'By Round'!G3) | H3: =IF(ISBLANK('By Round'!H3),"",'By Round'!H3) | I3: =IF(ISBLANK('By Round'!I3),"",'By Round'!I3) | J3: =IF(ISBLANK('By Round'!J3),"",'By Round'!J3) | K3: =IF(ISBLANK('By Round'!K3),"",'By Round'!K3) | L3: =IF(ISBLANK('By Round'!L3),"",'By Round'!L3) | M3: =AVERAGE(Y3:Z3) | N3: =AVERAGE(AA3:AB3) | O3: =IF(COUNT(U3:V3)>0,Q3/COUNT(U3:V3),0.5) | P3: =IF(COUNT(W3:X3)>0,R3/COUNT(W3:X3),0.5) | Q3: =SUM(U3:V3) | R3: =SUM(W3:X3) | S3: =IF(ISNUMBER(K3),K3,IF(ISNUMBER(L3),-L3,"")) | T3: =IF(ISNUMBER(L3),L3,IF(ISNUMBER(K3),-K3,"")) | U3: =IF(ISNUMBER(S3),IF(ISNUMBER(S4),IF(S3>S4,1.0,IF(S3=S4,0.5,0.0)),0.5),0.5) | V3: =IF(ISNUMBER(S3),IF(ISNUMBER(S5),IF(S3>S5,1.0,IF(S3=S5,0.5,0.0)),0.5),0.5) | W3: =IF(ISNUMBER(T3),IF(ISNUMBER(T4),IF(T3>T4,1.0,IF(T3=T4,0.5,0.0)),0.5),0.5) | X3: =IF(ISNUMBER(T3),IF(ISNUMBER(T5),IF(T3>T5,1.0,IF(T3=T5,0.5,0.0)),0.5),0.5) | Y3: =IF(AND(ISNUMBER(S3),ISNUMBER(S4)),VLOOKUP(ABS(S3-S4),'IMP Table'!$A$2:$C$26,3)*SIGN(S3-S4),0) | Z3: =IF(AND(ISNUMBER(S3),ISNUMBER(S5)),VLOOKUP(ABS(S3-S5),'IMP Table'!$A$2:$C$26,3)*SIGN(S3-S5),0) | AA3: =IF(AND(ISNUMBER(T3),ISNUMBER(T4)),VLOOKUP(ABS(T3-T4),'IMP Table'!$A$2:$C$26,3)*SIGN(T3-T4),0) | AB3: =IF(AND(ISNUMBER(T3),ISNUMBER(T5)),VLOOKUP(ABS(T3-T5),'IMP Table'!$A$2:$C$26,3)*SIGN(T3-T5),0)
B4: ='By Round'!A19 | C4: ='By Round'!B23 | D4: ='By Round'!C23 | E4: ='By Round'!D23 | F4: =IF(ISBLANK('By Round'!F23),"",'By Round'!F23) | G4: =IF(ISBLANK('By Round'!G23),"",'By Round'!G23) | H4: =IF(ISBLANK('By Round'!H23),"",'By Round'!H23) | I4: =IF(ISBLANK('By Round'!I23),"",'By Round'!I23) | J4: =IF(ISBLANK('By Round'!J23),"",'By Round'!J23) | K4: =IF(ISBLANK('By Round'!K23),"",'By Round'!K23) | L4: =IF(ISBLANK('By Round'!L23),"",'By Round'!L23) | M4: =AVERAGE(Y4:Z4) | N4: =AVERAGE(AA4:AB4) | O4: =IF(COUNT(U4:V4)>0,Q4/COUNT(U4:V4),0.5) | P4: =IF(COUNT(W4:X4)>0,R4/COUNT(W4:X4),0.5) | Q4: =SUM(U4:V4) | R4: =SUM(W4:X4) | S4: =IF(ISNUMBER(K4),K4,IF(ISNUMBER(L4),-L4,"")) | T4: =IF(ISNUMBER(L4),L4,IF(ISNUMBER(K4),-K4,"")) | U4: =IF(ISNUMBER(S4),IF(ISNUMBER(S3),IF(S4>S3,1.0,IF(S4=S3,0.5,0.0)),0.5),0.5) | V4: =IF(ISNUMBER(S4),IF(ISNUMBER(S5),IF(S4>S5,1.0,IF(S4=S5,0.5,0.0)),0.5),0.5) | W4: =IF(ISNUMBER(T4),IF(ISNUMBER(T3),IF(T4>T3,1.0,IF(T4=T3,0.5,0.0)),0.5),0.5) | X4: =IF(ISNUMBER(T4),IF(ISNUMBER(T5),IF(T4>T5,1.0,IF(T4=T5,0.5,0.0)),0.5),0.5) | Y4: =IF(AND(ISNUMBER(S4),ISNUMBER(S3)),VLOOKUP(ABS(S4-S3),'IMP Table'!$A$2:$C$26,3)*SIGN(S4-S3),0) | Z4: =IF(AND(ISNUMBER(S4),ISNUMBER(S5)),VLOOKUP(ABS(S4-S5),'IMP Table'!$A$2:$C$26,3)*SIGN(S4-S5),0) | AA4: =IF(AND(ISNUMBER(T4),ISNUMBER(T3)),VLOOKUP(ABS(T4-T3),'IMP Table'!$A$2:$C$26,3)*SIGN(T4-T3),0) | AB4: =IF(AND(ISNUMBER(T4),ISNUMBER(T5)),VLOOKUP(ABS(T4-T5),'IMP Table'!$A$2:$C$26,3)*SIGN(T4-T5),0)
B5: ='By Round'!A35 | C5: ='By Round'!B43 | D5: ='By Round'!C43 | E5: ='By Round'!D43 | F5: =IF(ISBLANK('By Round'!F43),"",'By Round'!F43) | G5: =IF(ISBLANK('By Round'!G43),"",'By Round'!G43) | H5: =IF(ISBLANK('By Round'!H43),"",'By Round'!H43) | I5: =IF(ISBLANK('By Round'!I43),"",'By Round'!I43) | J5: =IF(ISBLANK('By Round'!J43),"",'By Round'!J43) | K5: =IF(ISBLANK('By Round'!K43),"",'By Round'!K43) | L5: =IF(ISBLANK('By Round'!L43),"",'By Round'!L43) | M5: =AVERAGE(Y5:Z5) | N5: =AVERAGE(AA5:AB5) | O5: =IF(COUNT(U5:V5)>0,Q5/COUNT(U5:V5),0.5) | P5: =IF(COUNT(W5:X5)>0,R5/COUNT(W5:X5),0.5) | Q5: =SUM(U5:V5) | R5: =SUM(W5:X5) | S5: =IF(ISNUMBER(K5),K5,IF(ISNUMBER(L5),-L5,"")) | T5: =IF(ISNUMBER(L5),L5,IF(ISNUMBER(K5),-K5,"")) | U5: =IF(ISNUMBER(S5),IF(ISNUMBER(S3),IF(S5>S3,1.0,IF(S5=S3,0.5,0.0)),0.5),0.5) | V5: =IF(ISNUMBER(S5),IF(ISNUMBER(S4),IF(S5>S4,1.0,IF(S5=S4,0.5,0.0)),0.5),0.5) | W5: =IF(ISNUMBER(T5),IF(ISNUMBER(T3),IF(T5>T3,1.0,IF(T5=T3,0.5,0.0)),0.5),0.5) | X5: =IF(ISNUMBER(T5),IF(ISNUMBER(T4),IF(T5>T4,1.0,IF(T5=T4,0.5,0.0)),0.5),0.5) | Y5: =IF(AND(ISNUMBER(S5),ISNUMBER(S3)),VLOOKUP(ABS(S5-S3),'IMP Table'!$A$2:$C$26,3)*SIGN(S5-S3),0) | Z5: =IF(AND(ISNUMBER(S5),ISNUMBER(S4)),VLOOKUP(ABS(S5-S4),'IMP Table'!$A$2:$C$26,3)*SIGN(S5-S4),0) | AA5: =IF(AND(ISNUMBER(T5),ISNUMBER(T3)),VLOOKUP(ABS(T5-T3),'IMP Table'!$A$2:$C$26,3)*SIGN(T5-T3),0) | AB5: =IF(AND(ISNUMBER(T5),ISNUMBER(T4)),VLOOKUP(ABS(T5-T4),'IMP Table'!$A$2:$C$26,3)*SIGN(T5-T4),0)
A6: 2 | B6: ='By Round'!A3 | C6: ='By Round'!B3 | D6: ='By Round'!C3 | E6: ='By Round'!D3 | F6: =IF(ISBLANK('By Round'!F4),"",'By Round'!F4) | G6: =IF(ISBLANK('By Round'!G4),"",'By Round'!G4) | H6: =IF(ISBLANK('By Round'!H4),"",'By Round'!H4) | I6: =IF(ISBLANK('By Round'!I4),"",'By Round'!I4) | J6: =IF(ISBLANK('By Round'!J4),"",'By Round'!J4) | K6: =IF(ISBLANK('By Round'!K4),"",'By Round'!K4) | L6: =IF(ISBLANK('By Round'!L4),"",'By Round'!L4) | M6: =AVERAGE(Y6:Z6) | N6: =AVERAGE(AA6:AB6) | O6: =IF(COUNT(U6:V6)>0,Q6/COUNT(U6:V6),0.5) | P6: =IF(COUNT(W6:X6)>0,R6/COUNT(W6:X6),0.5) | Q6: =SUM(U6:V6) | R6: =SUM(W6:X6) | S6: =IF(ISNUMBER(K6),K6,IF(ISNUMBER(L6),-L6,"")) | T6: =IF(ISNUMBER(L6),L6,IF(ISNUMBER(K6),-K6,"")) | U6: =IF(ISNUMBER(S6),IF(ISNUMBER(S7),IF(S6>S7,1.0,IF(S6=S7,0.5,0.0)),0.5),0.5) | V6: =IF(ISNUMBER(S6),IF(ISNUMBER(S8),IF(S6>S8,1.0,IF(S6=S8,0.5,0.0)),0.5),0.5) | W6: =IF(ISNUMBER(T6),IF(ISNUMBER(T7),IF(T6>T7,1.0,IF(T6=T7,0.5,0.0)),0.5),0.5) | X6: =IF(ISNUMBER(T6),IF(ISNUMBER(T8),IF(T6>T8,1.0,IF(T6=T8,0.5,0.0)),0.5),0.5) | Y6: =IF(AND(ISNUMBER(S6),ISNUMBER(S7)),VLOOKUP(ABS(S6-S7),'IMP Table'!$A$2:$C$26,3)*SIGN(S6-S7),0) | Z6: =IF(AND(ISNUMBER(S6),ISNUMBER(S8)),VLOOKUP(ABS(S6-S8),'IMP Table'!$A$2:$C$26,3)*SIGN(S6-S8),0) | AA6: =IF(AND(ISNUMBER(T6),ISNUMBER(T7)),VLOOKUP(ABS(T6-T7),'IMP Table'!$A$2:$C$26,3)*SIGN(T6-T7),0) | AB6: =IF(AND(ISNUMBER(T6),ISNUMBER(T8)),VLOOKUP(ABS(T6-T8),'IMP Table'!$A$2:$C$26,3)*SIGN(T6-T8),0)
B7: ='By Round'!A19 | C7: ='By Round'!B23 | D7: ='By Round'!C23 | E7: ='By Round'!D23 | F7: =IF(ISBLANK('By Round'!F24),"",'By Round'!F24) | G7: =IF(ISBLANK('By Round'!G24),"",'By Round'!G24) | H7: =IF(ISBLANK('By Round'!H24),"",'By Round'!H24) | I7: =IF(ISBLANK('By Round'!I24),"",'By Round'!I24) | J7: =IF(ISBLANK('By Round'!J24),"",'By Round'!J24) | K7: =IF(ISBLANK('By Round'!K24),"",'By Round'!K24) | L7: =IF(ISBLANK('By Round'!L24),"",'By Round'!L24) | M7: =AVERAGE(Y7:Z7) | N7: =AVERAGE(AA7:AB7) | O7: =IF(COUNT(U7:V7)>0,Q7/COUNT(U7:V7),0.5) | P7: =IF(COUNT(W7:X7)>0,R7/COUNT(W7:X7),0.5) | Q7: =SUM(U7:V7) | R7: =SUM(W7:X7) | S7: =IF(ISNUMBER(K7),K7,IF(ISNUMBER(L7),-L7,"")) | T7: =IF(ISNUMBER(L7),L7,IF(ISNUMBER(K7),-K7,"")) | U7: =IF(ISNUMBER(S7),IF(ISNUMBER(S6),IF(S7>S6,1.0,IF(S7=S6,0.5,0.0)),0.5),0.5) | V7: =IF(ISNUMBER(S7),IF(ISNUMBER(S8),IF(S7>S8,1.0,IF(S7=S8,0.5,0.0)),0.5),0.5) | W7: =IF(ISNUMBER(T7),IF(ISNUMBER(T6),IF(T7>T6,1.0,IF(T7=T6,0.5,0.0)),0.5),0.5) | X7: =IF(ISNUMBER(T7),IF(ISNUMBER(T8),IF(T7>T8,1.0,IF(T7=T8,0.5,0.0)),0.5),0.5) | Y7: =IF(AND(ISNUMBER(S7),ISNUMBER(S6)),VLOOKUP(ABS(S7-S6),'IMP Table'!$A$2:$C$26,3)*SIGN(S7-S6),0) | Z7: =IF(AND(ISNUMBER(S7),ISNUMBER(S8)),VLOOKUP(ABS(S7-S8),'IMP Table'!$A$2:$C$26,3)*SIGN(S7-S8),0) | AA7: =IF(AND(ISNUMBER(T7),ISNUMBER(T6)),VLOOKUP(ABS(T7-T6),'IMP Table'!$A$2:$C$26,3)*SIGN(T7-T6),0) | AB7: =IF(AND(ISNUMBER(T7),ISNUMBER(T8)),VLOOKUP(ABS(T7-T8),'IMP Table'!$A$2:$C$26,3)*SIGN(T7-T8),0)
B8: ='By Round'!A35 | C8: ='By Round'!B43 | D8: ='By Round'!C43 | E8: ='By Round'!D43 | F8: =IF(ISBLANK('By Round'!F44),"",'By Round'!F44) | G8: =IF(ISBLANK('By Round'!G44),"",'By Round'!G44) | H8: =IF(ISBLANK('By Round'!H44),"",'By Round'!H44) | I8: =IF(ISBLANK('By Round'!I44),"",'By Round'!I44) | J8: =IF(ISBLANK('By Round'!J44),"",'By Round'!J44) | K8: =IF(ISBLANK('By Round'!K44),"",'By Round'!K44) | L8: =IF(ISBLANK('By Round'!L44),"",'By Round'!L44) | M8: =AVERAGE(Y8:Z8) | N8: =AVERAGE(AA8:AB8) | O8: =IF(COUNT(U8:V8)>0,Q8/COUNT(U8:V8),0.5) | P8: =IF(COUNT(W8:X8)>0,R8/COUNT(W8:X8),0.5) | Q8: =SUM(U8:V8) | R8: =SUM(W8:X8) | S8: =IF(ISNUMBER(K8),K8,IF(ISNUMBER(L8),-L8,"")) | T8: =IF(ISNUMBER(L8),L8,IF(ISNUMBER(K8),-K8,"")) | U8: =IF(ISNUMBER(S8),IF(ISNUMBER(S6),IF(S8>S6,1.0,IF(S8=S6,0.5,0.0)),0.5),0.5) | V8: =IF(ISNUMBER(S8),IF(ISNUMBER(S7),IF(S8>S7,1.0,IF(S8=S7,0.5,0.0)),0.5),0.5) | W8: =IF(ISNUMBER(T8),IF(ISNUMBER(T6),IF(T8>T6,1.0,IF(T8=T6,0.5,0.0)),0.5),0.5) | X8: =IF(ISNUMBER(T8),IF(ISNUMBER(T7),IF(T8>T7,1.0,IF(T8=T7,0.5,0.0)),0.5),0.5) | Y8: =IF(AND(ISNUMBER(S8),ISNUMBER(S6)),VLOOKUP(ABS(S8-S6),'IMP Table'!$A$2:$C$26,3)*SIGN(S8-S6),0) | Z8: =IF(AND(ISNUMBER(S8),ISNUMBER(S7)),VLOOKUP(ABS(S8-S7),'IMP Table'!$A$2:$C$26,3)*SIGN(S8-S7),0) | AA8: =IF(AND(ISNUMBER(T8),ISNUMBER(T6)),VLOOKUP(ABS(T8-T6),'IMP Table'!$A$2:$C$26,3)*SIGN(T8-T6),0) | AB8: =IF(AND(ISNUMBER(T8),ISNUMBER(T7)),VLOOKUP(ABS(T8-T7),'IMP Table'!$A$2:$C$26,3)*SIGN(T8-T7),0)
A9: 3 | B9: ='By Round'!A3 | C9: ='By Round'!B3 | D9: ='By Round'!C3 | E9: ='By Round'!D3 | F9: =IF(ISBLANK('By Round'!F5),"",'By Round'!F5) | G9: =IF(ISBLANK('By Round'!G5),"",'By Round'!G5) | H9: =IF(ISBLANK('By Round'!H5),"",'By Round'!H5) | I9: =IF(ISBLANK('By Round'!I5),"",'By Round'!I5) | J9: =IF(ISBLANK('By Round'!J5),"",'By Round'!J5) | K9: =IF(ISBLANK('By Round'!K5),"",'By Round'!K5) | L9: =IF(ISBLANK('By Round'!L5),"",'By Round'!L5) | M9: =AVERAGE(Y9:Z9) | N9: =AVERAGE(AA9:AB9) | O9: =IF(COUNT(U9:V9)>0,Q9/COUNT(U9:V9),0.5) | P9: =IF(COUNT(W9:X9)>0,R9/COUNT(W9:X9),0.5) | Q9: =SUM(U9:V9) | R9: =SUM(W9:X9) | S9: =IF(ISNUMBER(K9),K9,IF(ISNUMBER(L9),-L9,"")) | T9: =IF(ISNUMBER(L9),L9,IF(ISNUMBER(K9),-K9,"")) | U9: =IF(ISNUMBER(S9),IF(ISNUMBER(S10),IF(S9>S10,1.0,IF(S9=S10,0.5,0.0)),0.5),0.5) | V9: =IF(ISNUMBER(S9),IF(ISNUMBER(S11),IF(S9>S11,1.0,IF(S9=S11,0.5,0.0)),0.5),0.5) | W9: =IF(ISNUMBER(T9),IF(ISNUMBER(T10),IF(T9>T10,1.0,IF(T9=T10,0.5,0.0)),0.5),0.5) | X9: =IF(ISNUMBER(T9),IF(ISNUMBER(T11),IF(T9>T11,1.0,IF(T9=T11,0.5,0.0)),0.5),0.5) | Y9: =IF(AND(ISNUMBER(S9),ISNUMBER(S10)),VLOOKUP(ABS(S9-S10),'IMP Table'!$A$2:$C$26,3)*SIGN(S9-S10),0) | Z9: =IF(AND(ISNUMBER(S9),ISNUMBER(S11)),VLOOKUP(ABS(S9-S11),'IMP Table'!$A$2:$C$26,3)*SIGN(S9-S11),0) | AA9: =IF(AND(ISNUMBER(T9),ISNUMBER(T10)),VLOOKUP(ABS(T9-T10),'IMP Table'!$A$2:$C$26,3)*SIGN(T9-T10),0) | AB9: =IF(AND(ISNUMBER(T9),ISNUMBER(T11)),VLOOKUP(ABS(T9-T11),'IMP Table'!$A$2:$C$26,3)*SIGN(T9-T11),0)
B10: ='By Round'!A19 | C10: ='By Round'!B23 | D10: ='By Round'!C23 | E10: ='By Round'!D23 | F10: =IF(ISBLANK('By Round'!F25),"",'By Round'!F25) | G10: =IF(ISBLANK('By Round'!G25),"",'By Round'!G25) | H10: =IF(ISBLANK('By Round'!H25),"",'By Round'!H25) | I10: =IF(ISBLANK('By Round'!I25),"",'By Round'!I25) | J10: =IF(ISBLANK('By Round'!J25),"",'By Round'!J25) | K10: =IF(ISBLANK('By Round'!K25),"",'By Round'!K25) | L10: =IF(ISBLANK('By Round'!L25),"",'By Round'!L25) | M10: =AVERAGE(Y10:Z10) | N10: =AVERAGE(AA10:AB10) | O10: =IF(COUNT(U10:V10)>0,Q10/COUNT(U10:V10),0.5) | P10: =IF(COUNT(W10:X10)>0,R10/COUNT(W10:X10),0.5) | Q10: =SUM(U10:V10) | R10: =SUM(W10:X10) | S10: =IF(ISNUMBER(K10),K10,IF(ISNUMBER(L10),-L10,"")) | T10: =IF(ISNUMBER(L10),L10,IF(ISNUMBER(K10),-K10,"")) | U10: =IF(ISNUMBER(S10),IF(ISNUMBER(S9),IF(S10>S9,1.0,IF(S10=S9,0.5,0.0)),0.5),0.5) | V10: =IF(ISNUMBER(S10),IF(ISNUMBER(S11),IF(S10>S11,1.0,IF(S10=S11,0.5,0.0)),0.5),0.5) | W10: =IF(ISNUMBER(T10),IF(ISNUMBER(T9),IF(T10>T9,1.0,IF(T10=T9,0.5,0.0)),0.5),0.5) | X10: =IF(ISNUMBER(T10),IF(ISNUMBER(T11),IF(T10>T11,1.0,IF(T10=T11,0.5,0.0)),0.5),0.5) | Y10: =IF(AND(ISNUMBER(S10),ISNUMBER(S9)),VLOOKUP(ABS(S10-S9),'IMP Table'!$A$2:$C$26,3)*SIGN(S10-S9),0) | Z10: =IF(AND(ISNUMBER(S10),ISNUMBER(S11)),VLOOKUP(ABS(S10-S11),'IMP Table'!$A$2:$C$26,3)*SIGN(S10-S11),0) | AA10: =IF(AND(ISNUMBER(T10),ISNUMBER(T9)),VLOOKUP(ABS(T10-T9),'IMP Table'!$A$2:$C$26,3)*SIGN(T10-T9),0) | AB10: =IF(AND(ISNUMBER(T10),ISNUMBER(T11)),VLOOKUP(ABS(T10-T11),'IMP Table'!$A$2:$C$26,3)*SIGN(T10-T11),0)
B11: ='By Round'!A35 | C11: ='By Round'!B43 | D11: ='By Round'!C43 | E11: ='By Round'!D43 | F11: =IF(ISBLANK('By Round'!F45),"",'By Round'!F45) | G11: =IF(ISBLANK('By Round'!G45),"",'By Round'!G45) | H11: =IF(ISBLANK('By Round'!H45),"",'By Round'!H45) | I11: =IF(ISBLANK('By Round'!I45),"",'By Round'!I45) | J11: =IF(ISBLANK('By Round'!J45),"",'By Round'!J45) | K11: =IF(ISBLANK('By Round'!K45),"",'By Round'!K45) | L11: =IF(ISBLANK('By Round'!L45),"",'By Round'!L45) | M11: =AVERAGE(Y11:Z11) | N11: =AVERAGE(AA11:AB11) | O11: =IF(COUNT(U11:V11)>0,Q11/COUNT(U11:V11),0.5) | P11: =IF(COUNT(W11:X11)>0,R11/COUNT(W11:X11),0.5) | Q11: =SUM(U11:V11) | R11: =SUM(W11:X11) | S11: =IF(ISNUMBER(K11),K11,IF(ISNUMBER(L11),-L11,"")) | T11: =IF(ISNUMBER(L11),L11,IF(ISNUMBER(K11),-K11,"")) | U11: =IF(ISNUMBER(S11),IF(ISNUMBER(S9),IF(S11>S9,1.0,IF(S11=S9,0.5,0.0)),0.5),0.5) | V11: =IF(ISNUMBER(S11),IF(ISNUMBER(S10),IF(S11>S10,1.0,IF(S11=S10,0.5,0.0)),0.5),0.5) | W11: =IF(ISNUMBER(T11),IF(ISNUMBER(T9),IF(T11>T9,1.0,IF(T11=T9,0.5,0.0)),0.5),0.5) | X11: =IF(ISNUMBER(T11),IF(ISNUMBER(T10),IF(T11>T10,1.0,IF(T11=T10,0.5,0.0)),0.5),0.5) | Y11: =IF(AND(ISNUMBER(S11),ISNUMBER(S9)),VLOOKUP(ABS(S11-S9),'IMP Table'!$A$2:$C$26,3)*SIGN(S11-S9),0) | Z11: =IF(AND(ISNUMBER(S11),ISNUMBER(S10)),VLOOKUP(ABS(S11-S10),'IMP Table'!$A$2:$C$26,3)*SIGN(S11-S10),0) | AA11: =IF(AND(ISNUMBER(T11),ISNUMBER(T9)),VLOOKUP(ABS(T11-T9),'IMP Table'!$A$2:$C$26,3)*SIGN(T11-T9),0) | AB11: =IF(AND(ISNUMBER(T11),ISNUMBER(T10)),VLOOKUP(ABS(T11-T10),'IMP Table'!$A$2:$C$26,3)*SIGN(T11-T10),0)
A12: 4 | B12: ='By Round'!A3 | C12: ='By Round'!B3 | D12: ='By Round'!C3 | E12: ='By Round'!D3 | F12: =IF(ISBLANK('By Round'!F6),"",'By Round'!F6) | G12: =IF(ISBLANK('By Round'!G6),"",'By Round'!G6) | H12: =IF(ISBLANK('By Round'!H6),"",'By Round'!H6) | I12: =IF(ISBLANK('By Round'!I6),"",'By Round'!I6) | J12: =IF(ISBLANK('By Round'!J6),"",'By Round'!J6) | K12: =IF(ISBLANK('By Round'!K6),"",'By Round'!K6) | L12: =IF(ISBLANK('By Round'!L6),"",'By Round'!L6) | M12: =AVERAGE(Y12:Z12) | N12: =AVERAGE(AA12:AB12) | O12: =IF(COUNT(U12:V12)>0,Q12/COUNT(U12:V12),0.5) | P12: =IF(COUNT(W12:X12)>0,R12/COUNT(W12:X12),0.5) | Q12: =SUM(U12:V12) | R12: =SUM(W12:X12) | S12: =IF(ISNUMBER(K12),K12,IF(ISNUMBER(L12),-L12,"")) | T12: =IF(ISNUMBER(L12),L12,IF(ISNUMBER(K12),-K12,"")) | U12: =IF(ISNUMBER(S12),IF(ISNUMBER(S13),IF(S12>S13,1.0,IF(S12=S13,0.5,0.0)),0.5),0.5) | V12: =IF(ISNUMBER(S12),IF(ISNUMBER(S14),IF(S12>S14,1.0,IF(S12=S14,0.5,0.0)),0.5),0.5) | W12: =IF(ISNUMBER(T12),IF(ISNUMBER(T13),IF(T12>T13,1.0,IF(T12=T13,0.5,0.0)),0.5),0.5) | X12: =IF(ISNUMBER(T12),IF(ISNUMBER(T14),IF(T12>T14,1.0,IF(T12=T14,0.5,0.0)),0.5),0.5) | Y12: =IF(AND(ISNUMBER(S12),ISNUMBER(S13)),VLOOKUP(ABS(S12-S13),'IMP Table'!$A$2:$C$26,3)*SIGN(S12-S13),0) | Z12: =IF(AND(ISNUMBER(S12),ISNUMBER(S14)),VLOOKUP(ABS(S12-S14),'IMP Table'!$A$2:$C$26,3)*SIGN(S12-S14),0) | AA12: =IF(AND(ISNUMBER(T12),ISNUMBER(T13)),VLOOKUP(ABS(T12-T13),'IMP Table'!$A$2:$C$26,3)*SIGN(T12-T13),0) | AB12: =IF(AND(ISNUMBER(T12),ISNUMBER(T14)),VLOOKUP(ABS(T12-T14),'IMP Table'!$A$2:$C$26,3)*SIGN(T12-T14),0)
B13: ='By Round'!A19 | C13: ='By Round'!B23 | D13: ='By Round'!C23 | E13: ='By Round'!D23 | F13: =IF(ISBLANK('By Round'!F26),"",'By Round'!F26) | G13: =IF(ISBLANK('By Round'!G26),"",'By Round'!G26) | H13: =IF(ISBLANK('By Round'!H26),"",'By Round'!H26) | I13: =IF(ISBLANK('By Round'!I26),"",'By Round'!I26) | J13: =IF(ISBLANK('By Round'!J26),"",'By Round'!J26) | K13: =IF(ISBLANK('By Round'!K26),"",'By Round'!K26) | L13: =IF(ISBLANK('By Round'!L26),"",'By Round'!L26) | M13: =AVERAGE(Y13:Z13) | N13: =AVERAGE(AA13:AB13) | O13: =IF(COUNT(U13:V13)>0,Q13/COUNT(U13:V13),0.5) | P13: =IF(COUNT(W13:X13)>0,R13/COUNT(W13:X13),0.5) | Q13: =SUM(U13:V13) | R13: =SUM(W13:X13) | S13: =IF(ISNUMBER(K13),K13,IF(ISNUMBER(L13),-L13,"")) | T13: =IF(ISNUMBER(L13),L13,IF(ISNUMBER(K13),-K13,"")) | U13: =IF(ISNUMBER(S13),IF(ISNUMBER(S12),IF(S13>S12,1.0,IF(S13=S12,0.5,0.0)),0.5),0.5) | V13: =IF(ISNUMBER(S13),IF(ISNUMBER(S14),IF(S13>S14,1.0,IF(S13=S14,0.5,0.0)),0.5),0.5) | W13: =IF(ISNUMBER(T13),IF(ISNUMBER(T12),IF(T13>T12,1.0,IF(T13=T12,0.5,0.0)),0.5),0.5) | X13: =IF(ISNUMBER(T13),IF(ISNUMBER(T14),IF(T13>T14,1.0,IF(T13=T14,0.5,0.0)),0.5),0.5) | Y13: =IF(AND(ISNUMBER(S13),ISNUMBER(S12)),VLOOKUP(ABS(S13-S12),'IMP Table'!$A$2:$C$26,3)*SIGN(S13-S12),0) | Z13: =IF(AND(ISNUMBER(S13),ISNUMBER(S14)),VLOOKUP(ABS(S13-S14),'IMP Table'!$A$2:$C$26,3)*SIGN(S13-S14),0) | AA13: =IF(AND(ISNUMBER(T13),ISNUMBER(T12)),VLOOKUP(ABS(T13-T12),'IMP Table'!$A$2:$C$26,3)*SIGN(T13-T12),0) | AB13: =IF(AND(ISNUMBER(T13),ISNUMBER(T14)),VLOOKUP(ABS(T13-T14),'IMP Table'!$A$2:$C$26,3)*SIGN(T13-T14),0)
B14: ='By Round'!A35 | C14: ='By Round'!B43 | D14: ='By Round'!C43 | E14: ='By Round'!D43 | F14: =IF(ISBLANK('By Round'!F46),"",'By Round'!F46) | G14: =IF(ISBLANK('By Round'!G46),"",'By Round'!G46) | H14: =IF(ISBLANK('By Round'!H46),"",'By Round'!H46) | I14: =IF(ISBLANK('By Round'!I46),"",'By Round'!I46) | J14: =IF(ISBLANK('By Round'!J46),"",'By Round'!J46) | K14: =IF(ISBLANK('By Round'!K46),"",'By Round'!K46) | L14: =IF(ISBLANK('By Round'!L46),"",'By Round'!L46) | M14: =AVERAGE(Y14:Z14) | N14: =AVERAGE(AA14:AB14) | O14: =IF(COUNT(U14:V14)>0,Q14/COUNT(U14:V14),0.5) | P14: =IF(COUNT(W14:X14)>0,R14/COUNT(W14:X14),0.5) | Q14: =SUM(U14:V14) | R14: =SUM(W14:X14) | S14: =IF(ISNUMBER(K14),K14,IF(ISNUMBER(L14),-L14,"")) | T14: =IF(ISNUMBER(L14),L14,IF(ISNUMBER(K14),-K14,"")) | U14: =IF(ISNUMBER(S14),IF(ISNUMBER(S12),IF(S14>S12,1.0,IF(S14=S12,0.5,0.0)),0.5),0.5) | V14: =IF(ISNUMBER(S14),IF(ISNUMBER(S13),IF(S14>S13,1.0,IF(S14=S13,0.5,0.0)),0.5),0.5) | W14: =IF(ISNUMBER(T14),IF(ISNUMBER(T12),IF(T14>T12,1.0,IF(T14=T12,0.5,0.0)),0.5),0.5) | X14: =IF(ISNUMBER(T14),IF(ISNUMBER(T13),IF(T14>T13,1.0,IF(T14=T13,0.5,0.0)),0.5),0.5) | Y14: =IF(AND(ISNUMBER(S14),ISNUMBER(S12)),VLOOKUP(ABS(S14-S12),'IMP Table'!$A$2:$C$26,3)*SIGN(S14-S12),0) | Z14: =IF(AND(ISNUMBER(S14),ISNUMBER(S13)),VLOOKUP(ABS(S14-S13),'IMP Table'!$A$2:$C$26,3)*SIGN(S14-S13),0) | AA14: =IF(AND(ISNUMBER(T14),ISNUMBER(T12)),VLOOKUP(ABS(T14-T12),'IMP Table'!$A$2:$C$26,3)*SIGN(T14-T12),0) | AB14: =IF(AND(ISNUMBER(T14),ISNUMBER(T13)),VLOOKUP(ABS(T14-T13),'IMP Table'!$A$2:$C$26,3)*SIGN(T14-T13),0)
A15: 5 | B15: ='By Round'!A3 | C15: ='By Round'!B7 | D15: ='By Round'!C7 | E15: ='By Round'!D7 | F15: =IF(ISBLANK('By Round'!F7),"",'By Round'!F7) | G15: =IF(ISBLANK('By Round'!G7),"",'By Round'!G7) | H15: =IF(ISBLANK('By Round'!H7),"",'By Round'!H7) | I15: =IF(ISBLANK('By Round'!I7),"",'By Round'!I7) | J15: =IF(ISBLANK('By Round'!J7),"",'By Round'!J7) | K15: =IF(ISBLANK('By Round'!K7),"",'By Round'!K7) | L15: =IF(ISBLANK('By Round'!L7),"",'By Round'!L7) | M15: =AVERAGE(Y15:Z15) | N15: =AVERAGE(AA15:AB15) | O15: =IF(COUNT(U15:V15)>0,Q15/COUNT(U15:V15),0.5) | P15: =IF(COUNT(W15:X15)>0,R15/COUNT(W15:X15),0.5) | Q15: =SUM(U15:V15) | R15: =SUM(W15:X15) | S15: =IF(ISNUMBER(K15),K15,IF(ISNUMBER(L15),-L15,"")) | T15: =IF(ISNUMBER(L15),L15,IF(ISNUMBER(K15),-K15,"")) | U15: =IF(ISNUMBER(S15),IF(ISNUMBER(S16),IF(S15>S16,1.0,IF(S15=S16,0.5,0.0)),0.5),0.5) | V15: =IF(ISNUMBER(S15),IF(ISNUMBER(S17),IF(S15>S17,1.0,IF(S15=S17,0.5,0.0)),0.5),0.5) | W15: =IF(ISNUMBER(T15),IF(ISNUMBER(T16),IF(T15>T16,1.0,IF(T15=T16,0.5,0.0)),0.5),0.5) | X15: =IF(ISNUMBER(T15),IF(ISNUMBER(T17),IF(T15>T17,1.0,IF(T15=T17,0.5,0.0)),0.5),0.5) | Y15: =IF(AND(ISNUMBER(S15),ISNUMBER(S16)),VLOOKUP(ABS(S15-S16),'IMP Table'!$A$2:$C$26,3)*SIGN(S15-S16),0) | Z15: =IF(AND(ISNUMBER(S15),ISNUMBER(S17)),VLOOKUP(ABS(S15-S17),'IMP Table'!$A$2:$C$26,3)*SIGN(S15-S17),0) | AA15: =IF(AND(ISNUMBER(T15),ISNUMBER(T16)),VLOOKUP(ABS(T15-T16),'IMP Table'!$A$2:$C$26,3)*SIGN(T15-T16),0) | AB15: =IF(AND(ISNUMBER(T15),ISNUMBER(T17)),VLOOKUP(ABS(T15-T17),'IMP Table'!$A$2:$C$26,3)*SIGN(T15-T17),0)
B16: ='By Round'!A19 | C16: ='By Round'!B27 | D16: ='By Round'!C27 | E16: ='By Round'!D27 | F16: =IF(ISBLANK('By Round'!F27),"",'By Round'!F27) | G16: =IF(ISBLANK('By Round'!G27),"",'By Round'!G27) | H16: =IF(ISBLANK('By Round'!H27),"",'By Round'!H27) | I16: =IF(ISBLANK('By Round'!I27),"",'By Round'!I27) | J16: =IF(ISBLANK('By Round'!J27),"",'By Round'!J27) | K16: =IF(ISBLANK('By Round'!K27),"",'By Round'!K27) | L16: =IF(ISBLANK('By Round'!L27),"",'By Round'!L27) | M16: =AVERAGE(Y16:Z16) | N16: =AVERAGE(AA16:AB16) | O16: =IF(COUNT(U16:V16)>0,Q16/COUNT(U16:V16),0.5) | P16: =IF(COUNT(W16:X16)>0,R16/COUNT(W16:X16),0.5) | Q16: =SUM(U16:V16) | R16: =SUM(W16:X16) | S16: =IF(ISNUMBER(K16),K16,IF(ISNUMBER(L16),-L16,"")) | T16: =IF(ISNUMBER(L16),L16,IF(ISNUMBER(K16),-K16,"")) | U16: =IF(ISNUMBER(S16),IF(ISNUMBER(S15),IF(S16>S15,1.0,IF(S16=S15,0.5,0.0)),0.5),0.5) | V16: =IF(ISNUMBER(S16),IF(ISNUMBER(S17),IF(S16>S17,1.0,IF(S16=S17,0.5,0.0)),0.5),0.5) | W16: =IF(ISNUMBER(T16),IF(ISNUMBER(T15),IF(T16>T15,1.0,IF(T16=T15,0.5,0.0)),0.5),0.5) | X16: =IF(ISNUMBER(T16),IF(ISNUMBER(T17),IF(T16>T17,1.0,IF(T16=T17,0.5,0.0)),0.5),0.5) | Y16: =IF(AND(ISNUMBER(S16),ISNUMBER(S15)),VLOOKUP(ABS(S16-S15),'IMP Table'!$A$2:$C$26,3)*SIGN(S16-S15),0) | Z16: =IF(AND(ISNUMBER(S16),ISNUMBER(S17)),VLOOKUP(ABS(S16-S17),'IMP Table'!$A$2:$C$26,3)*SIGN(S16-S17),0) | AA16: =IF(AND(ISNUMBER(T16),ISNUMBER(T15)),VLOOKUP(ABS(T16-T15),'IMP Table'!$A$2:$C$26,3)*SIGN(T16-T15),0) | AB16: =IF(AND(ISNUMBER(T16),ISNUMBER(T17)),VLOOKUP(ABS(T16-T17),'IMP Table'!$A$2:$C$26,3)*SIGN(T16-T17),0)
B17: ='By Round'!A35 | C17: ='By Round'!B47 | D17: ='By Round'!C47 | E17: ='By Round'!D47 | F17: =IF(ISBLANK('By Round'!F47),"",'By Round'!F47) | G17: =IF(ISBLANK('By Round'!G47),"",'By Round'!G47) | H17: =IF(ISBLANK('By Round'!H47),"",'By Round'!H47) | I17: =IF(ISBLANK('By Round'!I47),"",'By Round'!I47) | J17: =IF(ISBLANK('By Round'!J47),"",'By Round'!J47) | K17: =IF(ISBLANK('By Round'!K47),"",'By Round'!K47) | L17: =IF(ISBLANK('By Round'!L47),"",'By Round'!L47) | M17: =AVERAGE(Y17:Z17) | N17: =AVERAGE(AA17:AB17) | O17: =IF(COUNT(U17:V17)>0,Q17/COUNT(U17:V17),0.5) | P17: =IF(COUNT(W17:X17)>0,R17/COUNT(W17:X17),0.5) | Q17: =SUM(U17:V17) | R17: =SUM(W17:X17) | S17: =IF(ISNUMBER(K17),K17,IF(ISNUMBER(L17),-L17,"")) | T17: =IF(ISNUMBER(L17),L17,IF(ISNUMBER(K17),-K17,"")) | U17: =IF(ISNUMBER(S17),IF(ISNUMBER(S15),IF(S17>S15,1.0,IF(S17=S15,0.5,0.0)),0.5),0.5) | V17: =IF(ISNUMBER(S17),IF(ISNUMBER(S16),IF(S17>S16,1.0,IF(S17=S16,0.5,0.0)),0.5),0.5) | W17: =IF(ISNUMBER(T17),IF(ISNUMBER(T15),IF(T17>T15,1.0,IF(T17=T15,0.5,0.0)),0.5),0.5) | X17: =IF(ISNUMBER(T17),IF(ISNUMBER(T16),IF(T17>T16,1.0,IF(T17=T16,0.5,0.0)),0.5),0.5) | Y17: =IF(AND(ISNUMBER(S17),ISNUMBER(S15)),VLOOKUP(ABS(S17-S15),'IMP Table'!$A$2:$C$26,3)*SIGN(S17-S15),0) | Z17: =IF(AND(ISNUMBER(S17),ISNUMBER(S16)),VLOOKUP(ABS(S17-S16),'IMP Table'!$A$2:$C$26,3)*SIGN(S17-S16),0) | AA17: =IF(AND(ISNUMBER(T17),ISNUMBER(T15)),VLOOKUP(ABS(T17-T15),'IMP Table'!$A$2:$C$26,3)*SIGN(T17-T15),0) | AB17: =IF(AND(ISNUMBER(T17),ISNUMBER(T16)),VLOOKUP(ABS(T17-T16),'IMP Table'!$A$2:$C$26,3)*SIGN(T17-T16),0)
A18: 6 | B18: ='By Round'!A3 | C18: ='By Round'!B7 | D18: ='By Round'!C7 | E18: ='By Round'!D7 | F18: =IF(ISBLANK('By Round'!F8),"",'By Round'!F8) | G18: =IF(ISBLANK('By Round'!G8),"",'By Round'!G8) | H18: =IF(ISBLANK('By Round'!H8),"",'By Round'!H8) | I18: =IF(ISBLANK('By Round'!I8),"",'By Round'!I8) | J18: =IF(ISBLANK('By Round'!J8),"",'By Round'!J8) | K18: =IF(ISBLANK('By Round'!K8),"",'By Round'!K8) | L18: =IF(ISBLANK('By Round'!L8),"",'By Round'!L8) | M18: =AVERAGE(Y18:Z18) | N18: =AVERAGE(AA18:AB18) | O18: =IF(COUNT(U18:V18)>0,Q18/COUNT(U18:V18),0.5) | P18: =IF(COUNT(W18:X18)>0,R18/COUNT(W18:X18),0.5) | Q18: =SUM(U18:V18) | R18: =SUM(W18:X18) | S18: =IF(ISNUMBER(K18),K18,IF(ISNUMBER(L18),-L18,"")) | T18: =IF(ISNUMBER(L18),L18,IF(ISNUMBER(K18),-K18,"")) | U18: =IF(ISNUMBER(S18),IF(ISNUMBER(S19),IF(S18>S19,1.0,IF(S18=S19,0.5,0.0)),0.5),0.5) | V18: =IF(ISNUMBER(S18),IF(ISNUMBER(S20),IF(S18>S20,1.0,IF(S18=S20,0.5,0.0)),0.5),0.5) | W18: =IF(ISNUMBER(T18),IF(ISNUMBER(T19),IF(T18>T19,1.0,IF(T18=T19,0.5,0.0)),0.5),0.5) | X18: =IF(ISNUMBER(T18),IF(ISNUMBER(T20),IF(T18>T20,1.0,IF(T18=T20,0.5,0.0)),0.5),0.5) | Y18: =IF(AND(ISNUMBER(S18),ISNUMBER(S19)),VLOOKUP(ABS(S18-S19),'IMP Table'!$A$2:$C$26,3)*SIGN(S18-S19),0) | Z18: =IF(AND(ISNUMBER(S18),ISNUMBER(S20)),VLOOKUP(ABS(S18-S20),'IMP Table'!$A$2:$C$26,3)*SIGN(S18-S20),0) | AA18: =IF(AND(ISNUMBER(T18),ISNUMBER(T19)),VLOOKUP(ABS(T18-T19),'IMP Table'!$A$2:$C$26,3)*SIGN(T18-T19),0) | AB18: =IF(AND(ISNUMBER(T18),ISNUMBER(T20)),VLOOKUP(ABS(T18-T20),'IMP Table'!$A$2:$C$26,3)*SIGN(T18-T20),0)
B19: ='By Round'!A19 | C19: ='By Round'!B27 | D19: ='By Round'!C27 | E19: ='By Round'!D27 | F19: =IF(ISBLANK('By Round'!F28),"",'By Round'!F28) | G19: =IF(ISBLANK('By Round'!G28),"",'By Round'!G28) | H19: =IF(ISBLANK('By Round'!H28),"",'By Round'!H28) | I19: =IF(ISBLANK('By Round'!I28),"",'By Round'!I28) | J19: =IF(ISBLANK('By Round'!J28),"",'By Round'!J28) | K19: =IF(ISBLANK('By Round'!K28),"",'By Round'!K28) | L19: =IF(ISBLANK('By Round'!L28),"",'By Round'!L28) | M19: =AVERAGE(Y19:Z19) | N19: =AVERAGE(AA19:AB19) | O19: =IF(COUNT(U19:V19)>0,Q19/COUNT(U19:V19),0.5) | P19: =IF(COUNT(W19:X19)>0,R19/COUNT(W19:X19),0.5) | Q19: =SUM(U19:V19) | R19: =SUM(W19:X19) | S19: =IF(ISNUMBER(K19),K19,IF(ISNUMBER(L19),-L19,"")) | T19: =IF(ISNUMBER(L19),L19,IF(ISNUMBER(K19),-K19,"")) | U19: =IF(ISNUMBER(S19),IF(ISNUMBER(S18),IF(S19>S18,1.0,IF(S19=S18,0.5,0.0)),0.5),0.5) | V19: =IF(ISNUMBER(S19),IF(ISNUMBER(S20),IF(S19>S20,1.0,IF(S19=S20,0.5,0.0)),0.5),0.5) | W19: =IF(ISNUMBER(T19),IF(ISNUMBER(T18),IF(T19>T18,1.0,IF(T19=T18,0.5,0.0)),0.5),0.5) | X19: =IF(ISNUMBER(T19),IF(ISNUMBER(T20),IF(T19>T20,1.0,IF(T19=T20,0.5,0.0)),0.5),0.5) | Y19: =IF(AND(ISNUMBER(S19),ISNUMBER(S18)),VLOOKUP(ABS(S19-S18),'IMP Table'!$A$2:$C$26,3)*SIGN(S19-S18),0) | Z19: =IF(AND(ISNUMBER(S19),ISNUMBER(S20)),VLOOKUP(ABS(S19-S20),'IMP Table'!$A$2:$C$26,3)*SIGN(S19-S20),0) | AA19: =IF(AND(ISNUMBER(T19),ISNUMBER(T18)),VLOOKUP(ABS(T19-T18),'IMP Table'!$A$2:$C$26,3)*SIGN(T19-T18),0) | AB19: =IF(AND(ISNUMBER(T19),ISNUMBER(T20)),VLOOKUP(ABS(T19-T20),'IMP Table'!$A$2:$C$26,3)*SIGN(T19-T20),0)
B20: ='By Round'!A35 | C20: ='By Round'!B47 | D20: ='By Round'!C47 | E20: ='By Round'!D47 | F20: =IF(ISBLANK('By Round'!F48),"",'By Round'!F48) | G20: =IF(ISBLANK('By Round'!G48),"",'By Round'!G48) | H20: =IF(ISBLANK('By Round'!H48),"",'By Round'!H48) | I20: =IF(ISBLANK('By Round'!I48),"",'By Round'!I48) | J20: =IF(ISBLANK('By Round'!J48),"",'By Round'!J48) | K20: =IF(ISBLANK('By Round'!K48),"",'By Round'!K48) | L20: =IF(ISBLANK('By Round'!L48),"",'By Round'!L48) | M20: =AVERAGE(Y20:Z20) | N20: =AVERAGE(AA20:AB20) | O20: =IF(COUNT(U20:V20)>0,Q20/COUNT(U20:V20),0.5) | P20: =IF(COUNT(W20:X20)>0,R20/COUNT(W20:X20),0.5) | Q20: =SUM(U20:V20) | R20: =SUM(W20:X20) | S20: =IF(ISNUMBER(K20),K20,IF(ISNUMBER(L20),-L20,"")) | T20: =IF(ISNUMBER(L20),L20,IF(ISNUMBER(K20),-K20,"")) | U20: =IF(ISNUMBER(S20),IF(ISNUMBER(S18),IF(S20>S18,1.0,IF(S20=S18,0.5,0.0)),0.5),0.5) | V20: =IF(ISNUMBER(S20),IF(ISNUMBER(S19),IF(S20>S19,1.0,IF(S20=S19,0.5,0.0)),0.5),0.5) | W20: =IF(ISNUMBER(T20),IF(ISNUMBER(T18),IF(T20>T18,1.0,IF(T20=T18,0.5,0.0)),0.5),0.5) | X20: =IF(ISNUMBER(T20),IF(ISNUMBER(T19),IF(T20>T19,1.0,IF(T20=T19,0.5,0.0)),0.5),0.5) | Y20: =IF(AND(ISNUMBER(S20),ISNUMBER(S18)),VLOOKUP(ABS(S20-S18),'IMP Table'!$A$2:$C$26,3)*SIGN(S20-S18),0) | Z20: =IF(AND(ISNUMBER(S20),ISNUMBER(S19)),VLOOKUP(ABS(S20-S19),'IMP Table'!$A$2:$C$26,3)*SIGN(S20-S19),0) | AA20: =IF(AND(ISNUMBER(T20),ISNUMBER(T18)),VLOOKUP(ABS(T20-T18),'IMP Table'!$A$2:$C$26,3)*SIGN(T20-T18),0) | AB20: =IF(AND(ISNUMBER(T20),ISNUMBER(T19)),VLOOKUP(ABS(T20-T19),'IMP Table'!$A$2:$C$26,3)*SIGN(T20-T19),0)
A21: 7 | B21: ='By Round'!A3 | C21: ='By Round'!B7 | D21: ='By Round'!C7 | E21: ='By Round'!D7 | F21: =IF(ISBLANK('By Round'!F9),"",'By Round'!F9) | G21: =IF(ISBLANK('By Round'!G9),"",'By Round'!G9) | H21: =IF(ISBLANK('By Round'!H9),"",'By Round'!H9) | I21: =IF(ISBLANK('By Round'!I9),"",'By Round'!I9) | J21: =IF(ISBLANK('By Round'!J9),"",'By Round'!J9) | K21: =IF(ISBLANK('By Round'!K9),"",'By Round'!K9) | L21: =IF(ISBLANK('By Round'!L9),"",'By Round'!L9) | M21: =AVERAGE(Y21:Z21) | N21: =AVERAGE(AA21:AB21) | O21: =IF(COUNT(U21:V21)>0,Q21/COUNT(U21:V21),0.5) | P21: =IF(COUNT(W21:X21)>0,R21/COUNT(W21:X21),0.5) | Q21: =SUM(U21:V21) | R21: =SUM(W21:X21) | S21: =IF(ISNUMBER(K21),K21,IF(ISNUMBER(L21),-L21,"")) | T21: =IF(ISNUMBER(L21),L21,IF(ISNUMBER(K21),-K21,"")) | U21: =IF(ISNUMBER(S21),IF(ISNUMBER(S22),IF(S21>S22,1.0,IF(S21=S22,0.5,0.0)),0.5),0.5) | V21: =IF(ISNUMBER(S21),IF(ISNUMBER(S23),IF(S21>S23,1.0,IF(S21=S23,0.5,0.0)),0.5),0.5) | W21: =IF(ISNUMBER(T21),IF(ISNUMBER(T22),IF(T21>T22,1.0,IF(T21=T22,0.5,0.0)),0.5),0.5) | X21: =IF(ISNUMBER(T21),IF(ISNUMBER(T23),IF(T21>T23,1.0,IF(T21=T23,0.5,0.0)),0.5),0.5) | Y21: =IF(AND(ISNUMBER(S21),ISNUMBER(S22)),VLOOKUP(ABS(S21-S22),'IMP Table'!$A$2:$C$26,3)*SIGN(S21-S22),0) | Z21: =IF(AND(ISNUMBER(S21),ISNUMBER(S23)),VLOOKUP(ABS(S21-S23),'IMP Table'!$A$2:$C$26,3)*SIGN(S21-S23),0) | AA21: =IF(AND(ISNUMBER(T21),ISNUMBER(T22)),VLOOKUP(ABS(T21-T22),'IMP Table'!$A$2:$C$26,3)*SIGN(T21-T22),0) | AB21: =IF(AND(ISNUMBER(T21),ISNUMBER(T23)),VLOOKUP(ABS(T21-T23),'IMP Table'!$A$2:$C$26,3)*SIGN(T21-T23),0)
B22: ='By Round'!A19 | C22: ='By Round'!B27 | D22: ='By Round'!C27 | E22: ='By Round'!D27 | F22: =IF(ISBLANK('By Round'!F29),"",'By Round'!F29) | G22: =IF(ISBLANK('By Round'!G29),"",'By Round'!G29) | H22: =IF(ISBLANK('By Round'!H29),"",'By Round'!H29) | I22: =IF(ISBLANK('By Round'!I29),"",'By Round'!I29) | J22: =IF(ISBLANK('By Round'!J29),"",'By Round'!J29) | K22: =IF(ISBLANK('By Round'!K29),"",'By Round'!K29) | L22: =IF(ISBLANK('By Round'!L29),"",'By Round'!L29) | M22: =AVERAGE(Y22:Z22) | N22: =AVERAGE(AA22:AB22) | O22: =IF(COUNT(U22:V22)>0,Q22/COUNT(U22:V22),0.5) | P22: =IF(COUNT(W22:X22)>0,R22/COUNT(W22:X22),0.5) | Q22: =SUM(U22:V22) | R22: =SUM(W22:X22) | S22: =IF(ISNUMBER(K22),K22,IF(ISNUMBER(L22),-L22,"")) | T22: =IF(ISNUMBER(L22),L22,IF(ISNUMBER(K22),-K22,"")) | U22: =IF(ISNUMBER(S22),IF(ISNUMBER(S21),IF(S22>S21,1.0,IF(S22=S21,0.5,0.0)),0.5),0.5) | V22: =IF(ISNUMBER(S22),IF(ISNUMBER(S23),IF(S22>S23,1.0,IF(S22=S23,0.5,0.0)),0.5),0.5) | W22: =IF(ISNUMBER(T22),IF(ISNUMBER(T21),IF(T22>T21,1.0,IF(T22=T21,0.5,0.0)),0.5),0.5) | X22: =IF(ISNUMBER(T22),IF(ISNUMBER(T23),IF(T22>T23,1.0,IF(T22=T23,0.5,0.0)),0.5),0.5) | Y22: =IF(AND(ISNUMBER(S22),ISNUMBER(S21)),VLOOKUP(ABS(S22-S21),'IMP Table'!$A$2:$C$26,3)*SIGN(S22-S21),0) | Z22: =IF(AND(ISNUMBER(S22),ISNUMBER(S23)),VLOOKUP(ABS(S22-S23),'IMP Table'!$A$2:$C$26,3)*SIGN(S22-S23),0) | AA22: =IF(AND(ISNUMBER(T22),ISNUMBER(T21)),VLOOKUP(ABS(T22-T21),'IMP Table'!$A$2:$C$26,3)*SIGN(T22-T21),0) | AB22: =IF(AND(ISNUMBER(T22),ISNUMBER(T23)),VLOOKUP(ABS(T22-T23),'IMP Table'!$A$2:$C$26,3)*SIGN(T22-T23),0)
B23: ='By Round'!A35 | C23: ='By Round'!B47 | D23: ='By Round'!C47 | E23: ='By Round'!D47 | F23: =IF(ISBLANK('By Round'!F49),"",'By Round'!F49) | G23: =IF(ISBLANK('By Round'!G49),"",'By Round'!G49) | H23: =IF(ISBLANK('By Round'!H49),"",'By Round'!H49) | I23: =IF(ISBLANK('By Round'!I49),"",'By Round'!I49) | J23: =IF(ISBLANK('By Round'!J49),"",'By Round'!J49) | K23: =IF(ISBLANK('By Round'!K49),"",'By Round'!K49) | L23: =IF(ISBLANK('By Round'!L49),"",'By Round'!L49) | M23: =AVERAGE(Y23:Z23) | N23: =AVERAGE(AA23:AB23) | O23: =IF(COUNT(U23:V23)>0,Q23/COUNT(U23:V23),0.5) | P23: =IF(COUNT(W23:X23)>0,R23/COUNT(W23:X23),0.5) | Q23: =SUM(U23:V23) | R23: =SUM(W23:X23) | S23: =IF(ISNUMBER(K23),K23,IF(ISNUMBER(L23),-L23,"")) | T23: =IF(ISNUMBER(L23),L23,IF(ISNUMBER(K23),-K23,"")) | U23: =IF(ISNUMBER(S23),IF(ISNUMBER(S21),IF(S23>S21,1.0,IF(S23=S21,0.5,0.0)),0.5),0.5) | V23: =IF(ISNUMBER(S23),IF(ISNUMBER(S22),IF(S23>S22,1.0,IF(S23=S22,0.5,0.0)),0.5),0.5) | W23: =IF(ISNUMBER(T23),IF(ISNUMBER(T21),IF(T23>T21,1.0,IF(T23=T21,0.5,0.0)),0.5),0.5) | X23: =IF(ISNUMBER(T23),IF(ISNUMBER(T22),IF(T23>T22,1.0,IF(T23=T22,0.5,0.0)),0.5),0.5) | Y23: =IF(AND(ISNUMBER(S23),ISNUMBER(S21)),VLOOKUP(ABS(S23-S21),'IMP Table'!$A$2:$C$26,3)*SIGN(S23-S21),0) | Z23: =IF(AND(ISNUMBER(S23),ISNUMBER(S22)),VLOOKUP(ABS(S23-S22),'IMP Table'!$A$2:$C$26,3)*SIGN(S23-S22),0) | AA23: =IF(AND(ISNUMBER(T23),ISNUMBER(T21)),VLOOKUP(ABS(T23-T21),'IMP Table'!$A$2:$C$26,3)*SIGN(T23-T21),0) | AB23: =IF(AND(ISNUMBER(T23),ISNUMBER(T22)),VLOOKUP(ABS(T23-T22),'IMP Table'!$A$2:$C$26,3)*SIGN(T23-T22),0)
A24: 8 | B24: ='By Round'!A3 | C24: ='By Round'!B7 | D24: ='By Round'!C7 | E24: ='By Round'!D7 | F24: =IF(ISBLANK('By Round'!F10),"",'By Round'!F10) | G24: =IF(ISBLANK('By Round'!G10),"",'By Round'!G10) | H24: =IF(ISBLANK('By Round'!H10),"",'By Round'!H10) | I24: =IF(ISBLANK('By Round'!I10),"",'By Round'!I10) | J24: =IF(ISBLANK('By Round'!J10),"",'By Round'!J10) | K24: =IF(ISBLANK('By Round'!K10),"",'By Round'!K10) | L24: =IF(ISBLANK('By Round'!L10),"",'By Round'!L10) | M24: =AVERAGE(Y24:Z24) | N24: =AVERAGE(AA24:AB24) | O24: =IF(COUNT(U24:V24)>0,Q24/COUNT(U24:V24),0.5) | P24: =IF(COUNT(W24:X24)>0,R24/COUNT(W24:X24),0.5) | Q24: =SUM(U24:V24) | R24: =SUM(W24:X24) | S24: =IF(ISNUMBER(K24),K24,IF(ISNUMBER(L24),-L24,"")) | T24: =IF(ISNUMBER(L24),L24,IF(ISNUMBER(K24),-K24,"")) | U24: =IF(ISNUMBER(S24),IF(ISNUMBER(S25),IF(S24>S25,1.0,IF(S24=S25,0.5,0.0)),0.5),0.5) | V24: =IF(ISNUMBER(S24),IF(ISNUMBER(S26),IF(S24>S26,1.0,IF(S24=S26,0.5,0.0)),0.5),0.5) | W24: =IF(ISNUMBER(T24),IF(ISNUMBER(T25),IF(T24>T25,1.0,IF(T24=T25,0.5,0.0)),0.5),0.5) | X24: =IF(ISNUMBER(T24),IF(ISNUMBER(T26),IF(T24>T26,1.0,IF(T24=T26,0.5,0.0)),0.5),0.5) | Y24: =IF(AND(ISNUMBER(S24),ISNUMBER(S25)),VLOOKUP(ABS(S24-S25),'IMP Table'!$A$2:$C$26,3)*SIGN(S24-S25),0) | Z24: =IF(AND(ISNUMBER(S24),ISNUMBER(S26)),VLOOKUP(ABS(S24-S26),'IMP Table'!$A$2:$C$26,3)*SIGN(S24-S26),0) | AA24: =IF(AND(ISNUMBER(T24),ISNUMBER(T25)),VLOOKUP(ABS(T24-T25),'IMP Table'!$A$2:$C$26,3)*SIGN(T24-T25),0) | AB24: =IF(AND(ISNUMBER(T24),ISNUMBER(T26)),VLOOKUP(ABS(T24-T26),'IMP Table'!$A$2:$C$26,3)*SIGN(T24-T26),0)
B25: ='By Round'!A19 | C25: ='By Round'!B27 | D25: ='By Round'!C27 | E25: ='By Round'!D27 | F25: =IF(ISBLANK('By Round'!F30),"",'By Round'!F30) | G25: =IF(ISBLANK('By Round'!G30),"",'By Round'!G30) | H25: =IF(ISBLANK('By Round'!H30),"",'By Round'!H30) | I25: =IF(ISBLANK('By Round'!I30),"",'By Round'!I30) | J25: =IF(ISBLANK('By Round'!J30),"",'By Round'!J30) | K25: =IF(ISBLANK('By Round'!K30),"",'By Round'!K30) | L25: =IF(ISBLANK('By Round'!L30),"",'By Round'!L30) | M25: =AVERAGE(Y25:Z25) | N25: =AVERAGE(AA25:AB25) | O25: =IF(COUNT(U25:V25)>0,Q25/COUNT(U25:V25),0.5) | P25: =IF(COUNT(W25:X25)>0,R25/COUNT(W25:X25),0.5) | Q25: =SUM(U25:V25) | R25: =SUM(W25:X25) | S25: =IF(ISNUMBER(K25),K25,IF(ISNUMBER(L25),-L25,"")) | T25: =IF(ISNUMBER(L25),L25,IF(ISNUMBER(K25),-K25,"")) | U25: =IF(ISNUMBER(S25),IF(ISNUMBER(S24),IF(S25>S24,1.0,IF(S25=S24,0.5,0.0)),0.5),0.5) | V25: =IF(ISNUMBER(S25),IF(ISNUMBER(S26),IF(S25>S26,1.0,IF(S25=S26,0.5,0.0)),0.5),0.5) | W25: =IF(ISNUMBER(T25),IF(ISNUMBER(T24),IF(T25>T24,1.0,IF(T25=T24,0.5,0.0)),0.5),0.5) | X25: =IF(ISNUMBER(T25),IF(ISNUMBER(T26),IF(T25>T26,1.0,IF(T25=T26,0.5,0.0)),0.5),0.5) | Y25: =IF(AND(ISNUMBER(S25),ISNUMBER(S24)),VLOOKUP(ABS(S25-S24),'IMP Table'!$A$2:$C$26,3)*SIGN(S25-S24),0) | Z25: =IF(AND(ISNUMBER(S25),ISNUMBER(S26)),VLOOKUP(ABS(S25-S26),'IMP Table'!$A$2:$C$26,3)*SIGN(S25-S26),0) | AA25: =IF(AND(ISNUMBER(T25),ISNUMBER(T24)),VLOOKUP(ABS(T25-T24),'IMP Table'!$A$2:$C$26,3)*SIGN(T25-T24),0) | AB25: =IF(AND(ISNUMBER(T25),ISNUMBER(T26)),VLOOKUP(ABS(T25-T26),'IMP Table'!$A$2:$C$26,3)*SIGN(T25-T26),0)
B26: ='By Round'!A35 | C26: ='By Round'!B47 | D26: ='By Round'!C47 | E26: ='By Round'!D47 | F26: =IF(ISBLANK('By Round'!F50),"",'By Round'!F50) | G26: =IF(ISBLANK('By Round'!G50),"",'By Round'!G50) | H26: =IF(ISBLANK('By Round'!H50),"",'By Round'!H50) | I26: =IF(ISBLANK('By Round'!I50),"",'By Round'!I50) | J26: =IF(ISBLANK('By Round'!J50),"",'By Round'!J50) | K26: =IF(ISBLANK('By Round'!K50),"",'By Round'!K50) | L26: =IF(ISBLANK('By Round'!L50),"",'By Round'!L50) | M26: =AVERAGE(Y26:Z26) | N26: =AVERAGE(AA26:AB26) | O26: =IF(COUNT(U26:V26)>0,Q26/COUNT(U26:V26),0.5) | P26: =IF(COUNT(W26:X26)>0,R26/COUNT(W26:X26),0.5) | Q26: =SUM(U26:V26) | R26: =SUM(W26:X26) | S26: =IF(ISNUMBER(K26),K26,IF(ISNUMBER(L26),-L26,"")) | T26: =IF(ISNUMBER(L26),L26,IF(ISNUMBER(K26),-K26,"")) | U26: =IF(ISNUMBER(S26),IF(ISNUMBER(S24),IF(S26>S24,1.0,IF(S26=S24,0.5,0.0)),0.5),0.5) | V26: =IF(ISNUMBER(S26),IF(ISNUMBER(S25),IF(S26>S25,1.0,IF(S26=S25,0.5,0.0)),0.5),0.5) | W26: =IF(ISNUMBER(T26),IF(ISNUMBER(T24),IF(T26>T24,1.0,IF(T26=T24,0.5,0.0)),0.5),0.5) | X26: =IF(ISNUMBER(T26),IF(ISNUMBER(T25),IF(T26>T25,1.0,IF(T26=T25,0.5,0.0)),0.5),0.5) | Y26: =IF(AND(ISNUMBER(S26),ISNUMBER(S24)),VLOOKUP(ABS(S26-S24),'IMP Table'!$A$2:$C$26,3)*SIGN(S26-S24),0) | Z26: =IF(AND(ISNUMBER(S26),ISNUMBER(S25)),VLOOKUP(ABS(S26-S25),'IMP Table'!$A$2:$C$26,3)*SIGN(S26-S25),0) | AA26: =IF(AND(ISNUMBER(T26),ISNUMBER(T24)),VLOOKUP(ABS(T26-T24),'IMP Table'!$A$2:$C$26,3)*SIGN(T26-T24),0) | AB26: =IF(AND(ISNUMBER(T26),ISNUMBER(T25)),VLOOKUP(ABS(T26-T25),'IMP Table'!$A$2:$C$26,3)*SIGN(T26-T25),0)
A27: 9 | B27: ='By Round'!A35 | C27: ='By Round'!B35 | D27: ='By Round'!C35 | E27: ='By Round'!D35 | F27: =IF(ISBLANK('By Round'!F35),"",'By Round'!F35) | G27: =IF(ISBLANK('By Round'!G35),"",'By Round'!G35) | H27: =IF(ISBLANK('By Round'!H35),"",'By Round'!H35) | I27: =IF(ISBLANK('By Round'!I35),"",'By Round'!I35) | J27: =IF(ISBLANK('By Round'!J35),"",'By Round'!J35) | K27: =IF(ISBLANK('By Round'!K35),"",'By Round'!K35) | L27: =IF(ISBLANK('By Round'!L35),"",'By Round'!L35) | M27: =AVERAGE(Y27:Z27) | N27: =AVERAGE(AA27:AB27) | O27: =IF(COUNT(U27:V27)>0,Q27/COUNT(U27:V27),0.5) | P27: =IF(COUNT(W27:X27)>0,R27/COUNT(W27:X27),0.5) | Q27: =SUM(U27:V27) | R27: =SUM(W27:X27) | S27: =IF(ISNUMBER(K27),K27,IF(ISNUMBER(L27),-L27,"")) | T27: =IF(ISNUMBER(L27),L27,IF(ISNUMBER(K27),-K27,"")) | U27: =IF(ISNUMBER(S27),IF(ISNUMBER(S28),IF(S27>S28,1.0,IF(S27=S28,0.5,0.0)),0.5),0.5) | V27: =IF(ISNUMBER(S27),IF(ISNUMBER(S29),IF(S27>S29,1.0,IF(S27=S29,0.5,0.0)),0.5),0.5) | W27: =IF(ISNUMBER(T27),IF(ISNUMBER(T28),IF(T27>T28,1.0,IF(T27=T28,0.5,0.0)),0.5),0.5) | X27: =IF(ISNUMBER(T27),IF(ISNUMBER(T29),IF(T27>T29,1.0,IF(T27=T29,0.5,0.0)),0.5),0.5) | Y27: =IF(AND(ISNUMBER(S27),ISNUMBER(S28)),VLOOKUP(ABS(S27-S28),'IMP Table'!$A$2:$C$26,3)*SIGN(S27-S28),0) | Z27: =IF(AND(ISNUMBER(S27),ISNUMBER(S29)),VLOOKUP(ABS(S27-S29),'IMP Table'!$A$2:$C$26,3)*SIGN(S27-S29),0) | AA27: =IF(AND(ISNUMBER(T27),ISNUMBER(T28)),VLOOKUP(ABS(T27-T28),'IMP Table'!$A$2:$C$26,3)*SIGN(T27-T28),0) | AB27: =IF(AND(ISNUMBER(T27),ISNUMBER(T29)),VLOOKUP(ABS(T27-T29),'IMP Table'!$A$2:$C$26,3)*SIGN(T27-T29),0)
B28: ='By Round'!A3 | C28: ='By Round'!B11 | D28: ='By Round'!C11 | E28: ='By Round'!D11 | F28: =IF(ISBLANK('By Round'!F11),"",'By Round'!F11) | G28: =IF(ISBLANK('By Round'!G11),"",'By Round'!G11) | H28: =IF(ISBLANK('By Round'!H11),"",'By Round'!H11) | I28: =IF(ISBLANK('By Round'!I11),"",'By Round'!I11) | J28: =IF(ISBLANK('By Round'!J11),"",'By Round'!J11) | K28: =IF(ISBLANK('By Round'!K11),"",'By Round'!K11) | L28: =IF(ISBLANK('By Round'!L11),"",'By Round'!L11) | M28: =AVERAGE(Y28:Z28) | N28: =AVERAGE(AA28:AB28) | O28: =IF(COUNT(U28:V28)>0,Q28/COUNT(U28:V28),0.5) | P28: =IF(COUNT(W28:X28)>0,R28/COUNT(W28:X28),0.5) | Q28: =SUM(U28:V28) | R28: =SUM(W28:X28) | S28: =IF(ISNUMBER(K28),K28,IF(ISNUMBER(L28),-L28,"")) | T28: =IF(ISNUMBER(L28),L28,IF(ISNUMBER(K28),-K28,"")) | U28: =IF(ISNUMBER(S28),IF(ISNUMBER(S27),IF(S28>S27,1.0,IF(S28=S27,0.5,0.0)),0.5),0.5) | V28: =IF(ISNUMBER(S28),IF(ISNUMBER(S29),IF(S28>S29,1.0,IF(S28=S29,0.5,0.0)),0.5),0.5) | W28: =IF(ISNUMBER(T28),IF(ISNUMBER(T27),IF(T28>T27,1.0,IF(T28=T27,0.5,0.0)),0.5),0.5) | X28: =IF(ISNUMBER(T28),IF(ISNUMBER(T29),IF(T28>T29,1.0,IF(T28=T29,0.5,0.0)),0.5),0.5) | Y28: =IF(AND(ISNUMBER(S28),ISNUMBER(S27)),VLOOKUP(ABS(S28-S27),'IMP Table'!$A$2:$C$26,3)*SIGN(S28-S27),0) | Z28: =IF(AND(ISNUMBER(S28),ISNUMBER(S29)),VLOOKUP(ABS(S28-S29),'IMP Table'!$A$2:$C$26,3)*SIGN(S28-S29),0) | AA28: =IF(AND(ISNUMBER(T28),ISNUMBER(T27)),VLOOKUP(ABS(T28-T27),'IMP Table'!$A$2:$C$26,3)*SIGN(T28-T27),0) | AB28: =IF(AND(ISNUMBER(T28),ISNUMBER(T29)),VLOOKUP(ABS(T28-T29),'IMP Table'!$A$2:$C$26,3)*SIGN(T28-T29),0)
B29: ='By Round'!A19 | C29: ='By Round'!B31 | D29: ='By Round'!C31 | E29: ='By Round'!D31 | F29: =IF(ISBLANK('By Round'!F31),"",'By Round'!F31) | G29: =IF(ISBLANK('By Round'!G31),"",'By Round'!G31) | H29: =IF(ISBLANK('By Round'!H31),"",'By Round'!H31) | I29: =IF(ISBLANK('By Round'!I31),"",'By Round'!I31) | J29: =IF(ISBLANK('By Round'!J31),"",'By Round'!J31) | K29: =IF(ISBLANK('By Round'!K31),"",'By Round'!K31) | L29: =IF(ISBLANK('By Round'!L31),"",'By Round'!L31) | M29: =AVERAGE(Y29:Z29) | N29: =AVERAGE(AA29:AB29) | O29: =IF(COUNT(U29:V29)>0,Q29/COUNT(U29:V29),0.5) | P29: =IF(COUNT(W29:X29)>0,R29/COUNT(W29:X29),0.5) | Q29: =SUM(U29:V29) | R29: =SUM(W29:X29) | S29: =IF(ISNUMBER(K29),K29,IF(ISNUMBER(L29),-L29,"")) | T29: =IF(ISNUMBER(L29),L29,IF(ISNUMBER(K29),-K29,"")) | U29: =IF(ISNUMBER(S29),IF(ISNUMBER(S27),IF(S29>S27,1.0,IF(S29=S27,0.5,0.0)),0.5),0.5) | V29: =IF(ISNUMBER(S29),IF(ISNUMBER(S28),IF(S29>S28,1.0,IF(S29=S28,0.5,0.0)),0.5),0.5) | W29: =IF(ISNUMBER(T29),IF(ISNUMBER(T27),IF(T29>T27,1.0,IF(T29=T27,0.5,0.0)),0.5),0.5) | X29: =IF(ISNUMBER(T29),IF(ISNUMBER(T28),IF(T29>T28,1.0,IF(T29=T28,0.5,0.0)),0.5),0.5) | Y29: =IF(AND(ISNUMBER(S29),ISNUMBER(S27)),VLOOKUP(ABS(S29-S27),'IMP Table'!$A$2:$C$26,3)*SIGN(S29-S27),0) | Z29: =IF(AND(ISNUMBER(S29),ISNUMBER(S28)),VLOOKUP(ABS(S29-S28),'IMP Table'!$A$2:$C$26,3)*SIGN(S29-S28),0) | AA29: =IF(AND(ISNUMBER(T29),ISNUMBER(T27)),VLOOKUP(ABS(T29-T27),'IMP Table'!$A$2:$C$26,3)*SIGN(T29-T27),0) | AB29: =IF(AND(ISNUMBER(T29),ISNUMBER(T28)),VLOOKUP(ABS(T29-T28),'IMP Table'!$A$2:$C$26,3)*SIGN(T29-T28),0)
A30: 10 | B30: ='By Round'!A35 | C30: ='By Round'!B35 | D30: ='By Round'!C35 | E30: ='By Round'!D35 | F30: =IF(ISBLANK('By Round'!F36),"",'By Round'!F36) | G30: =IF(ISBLANK('By Round'!G36),"",'By Round'!G36) | H30: =IF(ISBLANK('By Round'!H36),"",'By Round'!H36) | I30: =IF(ISBLANK('By Round'!I36),"",'By Round'!I36) | J30: =IF(ISBLANK('By Round'!J36),"",'By Round'!J36) | K30: =IF(ISBLANK('By Round'!K36),"",'By Round'!K36) | L30: =IF(ISBLANK('By Round'!L36),"",'By Round'!L36) | M30: =AVERAGE(Y30:Z30) | N30: =AVERAGE(AA30:AB30) | O30: =IF(COUNT(U30:V30)>0,Q30/COUNT(U30:V30),0.5) | P30: =IF(COUNT(W30:X30)>0,R30/COUNT(W30:X30),0.5) | Q30: =SUM(U30:V30) | R30: =SUM(W30:X30) | S30: =IF(ISNUMBER(K30),K30,IF(ISNUMBER(L30),-L30,"")) | T30: =IF(ISNUMBER(L30),L30,IF(ISNUMBER(K30),-K30,"")) | U30: =IF(ISNUMBER(S30),IF(ISNUMBER(S31),IF(S30>S31,1.0,IF(S30=S31,0.5,0.0)),0.5),0.5) | V30: =IF(ISNUMBER(S30),IF(ISNUMBER(S32),IF(S30>S32,1.0,IF(S30=S32,0.5,0.0)),0.5),0.5) | W30: =IF(ISNUMBER(T30),IF(ISNUMBER(T31),IF(T30>T31,1.0,IF(T30=T31,0.5,0.0)),0.5),0.5) | X30: =IF(ISNUMBER(T30),IF(ISNUMBER(T32),IF(T30>T32,1.0,IF(T30=T32,0.5,0.0)),0.5),0.5) | Y30: =IF(AND(ISNUMBER(S30),ISNUMBER(S31)),VLOOKUP(ABS(S30-S31),'IMP Table'!$A$2:$C$26,3)*SIGN(S30-S31),0) | Z30: =IF(AND(ISNUMBER(S30),ISNUMBER(S32)),VLOOKUP(ABS(S30-S32),'IMP Table'!$A$2:$C$26,3)*SIGN(S30-S32),0) | AA30: =IF(AND(ISNUMBER(T30),ISNUMBER(T31)),VLOOKUP(ABS(T30-T31),'IMP Table'!$A$2:$C$26,3)*SIGN(T30-T31),0) | AB30: =IF(AND(ISNUMBER(T30),ISNUMBER(T32)),VLOOKUP(ABS(T30-T32),'IMP Table'!$A$2:$C$26,3)*SIGN(T30-T32),0)
B31: ='By Round'!A3 | C31: ='By Round'!B11 | D31: ='By Round'!C11 | E31: ='By Round'!D11 | F31: =IF(ISBLANK('By Round'!F12),"",'By Round'!F12) | G31: =IF(ISBLANK('By Round'!G12),"",'By Round'!G12) | H31: =IF(ISBLANK('By Round'!H12),"",'By Round'!H12) | I31: =IF(ISBLANK('By Round'!I12),"",'By Round'!I12) | J31: =IF(ISBLANK('By Round'!J12),"",'By Round'!J12) | K31: =IF(ISBLANK('By Round'!K12),"",'By Round'!K12) | L31: =IF(ISBLANK('By Round'!L12),"",'By Round'!L12) | M31: =AVERAGE(Y31:Z31) | N31: =AVERAGE(AA31:AB31) | O31: =IF(COUNT(U31:V31)>0,Q31/COUNT(U31:V31),0.5) | P31: =IF(COUNT(W31:X31)>0,R31/COUNT(W31:X31),0.5) | Q31: =SUM(U31:V31) | R31: =SUM(W31:X31) | S31: =IF(ISNUMBER(K31),K31,IF(ISNUMBER(L31),-L31,"")) | T31: =IF(ISNUMBER(L31),L31,IF(ISNUMBER(K31),-K31,"")) | U31: =IF(ISNUMBER(S31),IF(ISNUMBER(S30),IF(S31>S30,1.0,IF(S31=S30,0.5,0.0)),0.5),0.5) | V31: =IF(ISNUMBER(S31),IF(ISNUMBER(S32),IF(S31>S32,1.0,IF(S31=S32,0.5,0.0)),0.5),0.5) | W31: =IF(ISNUMBER(T31),IF(ISNUMBER(T30),IF(T31>T30,1.0,IF(T31=T30,0.5,0.0)),0.5),0.5) | X31: =IF(ISNUMBER(T31),IF(ISNUMBER(T32),IF(T31>T32,1.0,IF(T31=T32,0.5,0.0)),0.5),0.5) | Y31: =IF(AND(ISNUMBER(S31),ISNUMBER(S30)),VLOOKUP(ABS(S31-S30),'IMP Table'!$A$2:$C$26,3)*SIGN(S31-S30),0) | Z31: =IF(AND(ISNUMBER(S31),ISNUMBER(S32)),VLOOKUP(ABS(S31-S32),'IMP Table'!$A$2:$C$26,3)*SIGN(S31-S32),0) | AA31: =IF(AND(ISNUMBER(T31),ISNUMBER(T30)),VLOOKUP(ABS(T31-T30),'IMP Table'!$A$2:$C$26,3)*SIGN(T31-T30),0) | AB31: =IF(AND(ISNUMBER(T31),ISNUMBER(T32)),VLOOKUP(ABS(T31-T32),'IMP Table'!$A$2:$C$26,3)*SIGN(T31-T32),0)
B32: ='By Round'!A19 | C32: ='By Round'!B31 | D32: ='By Round'!C31 | E32: ='By Round'!D31 | F32: =IF(ISBLANK('By Round'!F32),"",'By Round'!F32) | G32: =IF(ISBLANK('By Round'!G32),"",'By Round'!G32) | H32: =IF(ISBLANK('By Round'!H32),"",'By Round'!H32) | I32: =IF(ISBLANK('By Round'!I32),"",'By Round'!I32) | J32: =IF(ISBLANK('By Round'!J32),"",'By Round'!J32) | K32: =IF(ISBLANK('By Round'!K32),"",'By Round'!K32) | L32: =IF(ISBLANK('By Round'!L32),"",'By Round'!L32) | M32: =AVERAGE(Y32:Z32) | N32: =AVERAGE(AA32:AB32) | O32: =IF(COUNT(U32:V32)>0,Q32/COUNT(U32:V32),0.5) | P32: =IF(COUNT(W32:X32)>0,R32/COUNT(W32:X32),0.5) | Q32: =SUM(U32:V32) | R32: =SUM(W32:X32) | S32: =IF(ISNUMBER(K32),K32,IF(ISNUMBER(L32),-L32,"")) | T32: =IF(ISNUMBER(L32),L32,IF(ISNUMBER(K32),-K32,"")) | U32: =IF(ISNUMBER(S32),IF(ISNUMBER(S30),IF(S32>S30,1.0,IF(S32=S30,0.5,0.0)),0.5),0.5) | V32: =IF(ISNUMBER(S32),IF(ISNUMBER(S31),IF(S32>S31,1.0,IF(S32=S31,0.5,0.0)),0.5),0.5) | W32: =IF(ISNUMBER(T32),IF(ISNUMBER(T30),IF(T32>T30,1.0,IF(T32=T30,0.5,0.0)),0.5),0.5) | X32: =IF(ISNUMBER(T32),IF(ISNUMBER(T31),IF(T32>T31,1.0,IF(T32=T31,0.5,0.0)),0.5),0.5) | Y32: =IF(AND(ISNUMBER(S32),ISNUMBER(S30)),VLOOKUP(ABS(S32-S30),'IMP Table'!$A$2:$C$26,3)*SIGN(S32-S30),0) | Z32: =IF(AND(ISNUMBER(S32),ISNUMBER(S31)),VLOOKUP(ABS(S32-S31),'IMP Table'!$A$2:$C$26,3)*SIGN(S32-S31),0) | AA32: =IF(AND(ISNUMBER(T32),ISNUMBER(T30)),VLOOKUP(ABS(T32-T30),'IMP Table'!$A$2:$C$26,3)*SIGN(T32-T30),0) | AB32: =IF(AND(ISNUMBER(T32),ISNUMBER(T31)),VLOOKUP(ABS(T32-T31),'IMP Table'!$A$2:$C$26,3)*SIGN(T32-T31),0)
A33: 11 | B33: ='By Round'!A35 | C33: ='By Round'!B35 | D33: ='By Round'!C35 | E33: ='By Round'!D35 | F33: =IF(ISBLANK('By Round'!F37),"",'By Round'!F37) | G33: =IF(ISBLANK('By Round'!G37),"",'By Round'!G37) | H33: =IF(ISBLANK('By Round'!H37),"",'By Round'!H37) | I33: =IF(ISBLANK('By Round'!I37),"",'By Round'!I37) | J33: =IF(ISBLANK('By Round'!J37),"",'By Round'!J37) | K33: =IF(ISBLANK('By Round'!K37),"",'By Round'!K37) | L33: =IF(ISBLANK('By Round'!L37),"",'By Round'!L37) | M33: =AVERAGE(Y33:Z33) | N33: =AVERAGE(AA33:AB33) | O33: =IF(COUNT(U33:V33)>0,Q33/COUNT(U33:V33),0.5) | P33: =IF(COUNT(W33:X33)>0,R33/COUNT(W33:X33),0.5) | Q33: =SUM(U33:V33) | R33: =SUM(W33:X33) | S33: =IF(ISNUMBER(K33),K33,IF(ISNUMBER(L33),-L33,"")) | T33: =IF(ISNUMBER(L33),L33,IF(ISNUMBER(K33),-K33,"")) | U33: =IF(ISNUMBER(S33),IF(ISNUMBER(S34),IF(S33>S34,1.0,IF(S33=S34,0.5,0.0)),0.5),0.5) | V33: =IF(ISNUMBER(S33),IF(ISNUMBER(S35),IF(S33>S35,1.0,IF(S33=S35,0.5,0.0)),0.5),0.5) | W33: =IF(ISNUMBER(T33),IF(ISNUMBER(T34),IF(T33>T34,1.0,IF(T33=T34,0.5,0.0)),0.5),0.5) | X33: =IF(ISNUMBER(T33),IF(ISNUMBER(T35),IF(T33>T35,1.0,IF(T33=T35,0.5,0.0)),0.5),0.5) | Y33: =IF(AND(ISNUMBER(S33),ISNUMBER(S34)),VLOOKUP(ABS(S33-S34),'IMP Table'!$A$2:$C$26,3)*SIGN(S33-S34),0) | Z33: =IF(AND(ISNUMBER(S33),ISNUMBER(S35)),VLOOKUP(ABS(S33-S35),'IMP Table'!$A$2:$C$26,3)*SIGN(S33-S35),0) | AA33: =IF(AND(ISNUMBER(T33),ISNUMBER(T34)),VLOOKUP(ABS(T33-T34),'IMP Table'!$A$2:$C$26,3)*SIGN(T33-T34),0) | AB33: =IF(AND(ISNUMBER(T33),ISNUMBER(T35)),VLOOKUP(ABS(T33-T35),'IMP Table'!$A$2:$C$26,3)*SIGN(T33-T35),0)
B34: ='By Round'!A3 | C34: ='By Round'!B11 | D34: ='By Round'!C11 | E34: ='By Round'!D11 | F34: =IF(ISBLANK('By Round'!F13),"",'By Round'!F13) | G34: =IF(ISBLANK('By Round'!G13),"",'By Round'!G13) | H34: =IF(ISBLANK('By Round'!H13),"",'By Round'!H13) | I34: =IF(ISBLANK('By Round'!I13),"",'By Round'!I13) | J34: =IF(ISBLANK('By Round'!J13),"",'By Round'!J13) | K34: =IF(ISBLANK('By Round'!K13),"",'By Round'!K13) | L34: =IF(ISBLANK('By Round'!L13),"",'By Round'!L13) | M34: =AVERAGE(Y34:Z34) | N34: =AVERAGE(AA34:AB34) | O34: =IF(COUNT(U34:V34)>0,Q34/COUNT(U34:V34),0.5) | P34: =IF(COUNT(W34:X34)>0,R34/COUNT(W34:X34),0.5) | Q34: =SUM(U34:V34) | R34: =SUM(W34:X34) | S34: =IF(ISNUMBER(K34),K34,IF(ISNUMBER(L34),-L34,"")) | T34: =IF(ISNUMBER(L34),L34,IF(ISNUMBER(K34),-K34,"")) | U34: =IF(ISNUMBER(S34),IF(ISNUMBER(S33),IF(S34>S33,1.0,IF(S34=S33,0.5,0.0)),0.5),0.5) | V34: =IF(ISNUMBER(S34),IF(ISNUMBER(S35),IF(S34>S35,1.0,IF(S34=S35,0.5,0.0)),0.5),0.5) | W34: =IF(ISNUMBER(T34),IF(ISNUMBER(T33),IF(T34>T33,1.0,IF(T34=T33,0.5,0.0)),0.5),0.5) | X34: =IF(ISNUMBER(T34),IF(ISNUMBER(T35),IF(T34>T35,1.0,IF(T34=T35,0.5,0.0)),0.5),0.5) | Y34: =IF(AND(ISNUMBER(S34),ISNUMBER(S33)),VLOOKUP(ABS(S34-S33),'IMP Table'!$A$2:$C$26,3)*SIGN(S34-S33),0) | Z34: =IF(AND(ISNUMBER(S34),ISNUMBER(S35)),VLOOKUP(ABS(S34-S35),'IMP Table'!$A$2:$C$26,3)*SIGN(S34-S35),0) | AA34: =IF(AND(ISNUMBER(T34),ISNUMBER(T33)),VLOOKUP(ABS(T34-T33),'IMP Table'!$A$2:$C$26,3)*SIGN(T34-T33),0) | AB34: =IF(AND(ISNUMBER(T34),ISNUMBER(T35)),VLOOKUP(ABS(T34-T35),'IMP Table'!$A$2:$C$26,3)*SIGN(T34-T35),0)
B35: ='By Round'!A19 | C35: ='By Round'!B31 | D35: ='By Round'!C31 | E35: ='By Round'!D31 | F35: =IF(ISBLANK('By Round'!F33),"",'By Round'!F33) | G35: =IF(ISBLANK('By Round'!G33),"",'By Round'!G33) | H35: =IF(ISBLANK('By Round'!H33),"",'By Round'!H33) | I35: =IF(ISBLANK('By Round'!I33),"",'By Round'!I33) | J35: =IF(ISBLANK('By Round'!J33),"",'By Round'!J33) | K35: =IF(ISBLANK('By Round'!K33),"",'By Round'!K33) | L35: =IF(ISBLANK('By Round'!L33),"",'By Round'!L33) | M35: =AVERAGE(Y35:Z35) | N35: =AVERAGE(AA35:AB35) | O35: =IF(COUNT(U35:V35)>0,Q35/COUNT(U35:V35),0.5) | P35: =IF(COUNT(W35:X35)>0,R35/COUNT(W35:X35),0.5) | Q35: =SUM(U35:V35) | R35: =SUM(W35:X35) | S35: =IF(ISNUMBER(K35),K35,IF(ISNUMBER(L35),-L35,"")) | T35: =IF(ISNUMBER(L35),L35,IF(ISNUMBER(K35),-K35,"")) | U35: =IF(ISNUMBER(S35),IF(ISNUMBER(S33),IF(S35>S33,1.0,IF(S35=S33,0.5,0.0)),0.5),0.5) | V35: =IF(ISNUMBER(S35),IF(ISNUMBER(S34),IF(S35>S34,1.0,IF(S35=S34,0.5,0.0)),0.5),0.5) | W35: =IF(ISNUMBER(T35),IF(ISNUMBER(T33),IF(T35>T33,1.0,IF(T35=T33,0.5,0.0)),0.5),0.5) | X35: =IF(ISNUMBER(T35),IF(ISNUMBER(T34),IF(T35>T34,1.0,IF(T35=T34,0.5,0.0)),0.5),0.5) | Y35: =IF(AND(ISNUMBER(S35),ISNUMBER(S33)),VLOOKUP(ABS(S35-S33),'IMP Table'!$A$2:$C$26,3)*SIGN(S35-S33),0) | Z35: =IF(AND(ISNUMBER(S35),ISNUMBER(S34)),VLOOKUP(ABS(S35-S34),'IMP Table'!$A$2:$C$26,3)*SIGN(S35-S34),0) | AA35: =IF(AND(ISNUMBER(T35),ISNUMBER(T33)),VLOOKUP(ABS(T35-T33),'IMP Table'!$A$2:$C$26,3)*SIGN(T35-T33),0) | AB35: =IF(AND(ISNUMBER(T35),ISNUMBER(T34)),VLOOKUP(ABS(T35-T34),'IMP Table'!$A$2:$C$26,3)*SIGN(T35-T34),0)
A36: 12 | B36: ='By Round'!A35 | C36: ='By Round'!B35 | D36: ='By Round'!C35 | E36: ='By Round'!D35 | F36: =IF(ISBLANK('By Round'!F38),"",'By Round'!F38) | G36: =IF(ISBLANK('By Round'!G38),"",'By Round'!G38) | H36: =IF(ISBLANK('By Round'!H38),"",'By Round'!H38) | I36: =IF(ISBLANK('By Round'!I38),"",'By Round'!I38) | J36: =IF(ISBLANK('By Round'!J38),"",'By Round'!J38) | K36: =IF(ISBLANK('By Round'!K38),"",'By Round'!K38) | L36: =IF(ISBLANK('By Round'!L38),"",'By Round'!L38) | M36: =AVERAGE(Y36:Z36) | N36: =AVERAGE(AA36:AB36) | O36: =IF(COUNT(U36:V36)>0,Q36/COUNT(U36:V36),0.5) | P36: =IF(COUNT(W36:X36)>0,R36/COUNT(W36:X36),0.5) | Q36: =SUM(U36:V36) | R36: =SUM(W36:X36) | S36: =IF(ISNUMBER(K36),K36,IF(ISNUMBER(L36),-L36,"")) | T36: =IF(ISNUMBER(L36),L36,IF(ISNUMBER(K36),-K36,"")) | U36: =IF(ISNUMBER(S36),IF(ISNUMBER(S37),IF(S36>S37,1.0,IF(S36=S37,0.5,0.0)),0.5),0.5) | V36: =IF(ISNUMBER(S36),IF(ISNUMBER(S38),IF(S36>S38,1.0,IF(S36=S38,0.5,0.0)),0.5),0.5) | W36: =IF(ISNUMBER(T36),IF(ISNUMBER(T37),IF(T36>T37,1.0,IF(T36=T37,0.5,0.0)),0.5),0.5) | X36: =IF(ISNUMBER(T36),IF(ISNUMBER(T38),IF(T36>T38,1.0,IF(T36=T38,0.5,0.0)),0.5),0.5) | Y36: =IF(AND(ISNUMBER(S36),ISNUMBER(S37)),VLOOKUP(ABS(S36-S37),'IMP Table'!$A$2:$C$26,3)*SIGN(S36-S37),0) | Z36: =IF(AND(ISNUMBER(S36),ISNUMBER(S38)),VLOOKUP(ABS(S36-S38),'IMP Table'!$A$2:$C$26,3)*SIGN(S36-S38),0) | AA36: =IF(AND(ISNUMBER(T36),ISNUMBER(T37)),VLOOKUP(ABS(T36-T37),'IMP Table'!$A$2:$C$26,3)*SIGN(T36-T37),0) | AB36: =IF(AND(ISNUMBER(T36),ISNUMBER(T38)),VLOOKUP(ABS(T36-T38),'IMP Table'!$A$2:$C$26,3)*SIGN(T36-T38),0)
B37: ='By Round'!A3 | C37: ='By Round'!B11 | D37: ='By Round'!C11 | E37: ='By Round'!D11 | F37: =IF(ISBLANK('By Round'!F14),"",'By Round'!F14) | G37: =IF(ISBLANK('By Round'!G14),"",'By Round'!G14) | H37: =IF(ISBLANK('By Round'!H14),"",'By Round'!H14) | I37: =IF(ISBLANK('By Round'!I14),"",'By Round'!I14) | J37: =IF(ISBLANK('By Round'!J14),"",'By Round'!J14) | K37: =IF(ISBLANK('By Round'!K14),"",'By Round'!K14) | L37: =IF(ISBLANK('By Round'!L14),"",'By Round'!L14) | M37: =AVERAGE(Y37:Z37) | N37: =AVERAGE(AA37:AB37) | O37: =IF(COUNT(U37:V37)>0,Q37/COUNT(U37:V37),0.5) | P37: =IF(COUNT(W37:X37)>0,R37/COUNT(W37:X37),0.5) | Q37: =SUM(U37:V37) | R37: =SUM(W37:X37) | S37: =IF(ISNUMBER(K37),K37,IF(ISNUMBER(L37),-L37,"")) | T37: =IF(ISNUMBER(L37),L37,IF(ISNUMBER(K37),-K37,"")) | U37: =IF(ISNUMBER(S37),IF(ISNUMBER(S36),IF(S37>S36,1.0,IF(S37=S36,0.5,0.0)),0.5),0.5) | V37: =IF(ISNUMBER(S37),IF(ISNUMBER(S38),IF(S37>S38,1.0,IF(S37=S38,0.5,0.0)),0.5),0.5) | W37: =IF(ISNUMBER(T37),IF(ISNUMBER(T36),IF(T37>T36,1.0,IF(T37=T36,0.5,0.0)),0.5),0.5) | X37: =IF(ISNUMBER(T37),IF(ISNUMBER(T38),IF(T37>T38,1.0,IF(T37=T38,0.5,0.0)),0.5),0.5) | Y37: =IF(AND(ISNUMBER(S37),ISNUMBER(S36)),VLOOKUP(ABS(S37-S36),'IMP Table'!$A$2:$C$26,3)*SIGN(S37-S36),0) | Z37: =IF(AND(ISNUMBER(S37),ISNUMBER(S38)),VLOOKUP(ABS(S37-S38),'IMP Table'!$A$2:$C$26,3)*SIGN(S37-S38),0) | AA37: =IF(AND(ISNUMBER(T37),ISNUMBER(T36)),VLOOKUP(ABS(T37-T36),'IMP Table'!$A$2:$C$26,3)*SIGN(T37-T36),0) | AB37: =IF(AND(ISNUMBER(T37),ISNUMBER(T38)),VLOOKUP(ABS(T37-T38),'IMP Table'!$A$2:$C$26,3)*SIGN(T37-T38),0)
B38: ='By Round'!A19 | C38: ='By Round'!B31 | D38: ='By Round'!C31 | E38: ='By Round'!D31 | F38: =IF(ISBLANK('By Round'!F34),"",'By Round'!F34) | G38: =IF(ISBLANK('By Round'!G34),"",'By Round'!G34) | H38: =IF(ISBLANK('By Round'!H34),"",'By Round'!H34) | I38: =IF(ISBLANK('By Round'!I34),"",'By Round'!I34) | J38: =IF(ISBLANK('By Round'!J34),"",'By Round'!J34) | K38: =IF(ISBLANK('By Round'!K34),"",'By Round'!K34) | L38: =IF(ISBLANK('By Round'!L34),"",'By Round'!L34) | M38: =AVERAGE(Y38:Z38) | N38: =AVERAGE(AA38:AB38) | O38: =IF(COUNT(U38:V38)>0,Q38/COUNT(U38:V38),0.5) | P38: =IF(COUNT(W38:X38)>0,R38/COUNT(W38:X38),0.5) | Q38: =SUM(U38:V38) | R38: =SUM(W38:X38) | S38: =IF(ISNUMBER(K38),K38,IF(ISNUMBER(L38),-L38,"")) | T38: =IF(ISNUMBER(L38),L38,IF(ISNUMBER(K38),-K38,"")) | U38: =IF(ISNUMBER(S38),IF(ISNUMBER(S36),IF(S38>S36,1.0,IF(S38=S36,0.5,0.0)),0.5),0.5) | V38: =IF(ISNUMBER(S38),IF(ISNUMBER(S37),IF(S38>S37,1.0,IF(S38=S37,0.5,0.0)),0.5),0.5) | W38: =IF(ISNUMBER(T38),IF(ISNUMBER(T36),IF(T38>T36,1.0,IF(T38=T36,0.5,0.0)),0.5),0.5) | X38: =IF(ISNUMBER(T38),IF(ISNUMBER(T37),IF(T38>T37,1.0,IF(T38=T37,0.5,0.0)),0.5),0.5) | Y38: =IF(AND(ISNUMBER(S38),ISNUMBER(S36)),VLOOKUP(ABS(S38-S36),'IMP Table'!$A$2:$C$26,3)*SIGN(S38-S36),0) | Z38: =IF(AND(ISNUMBER(S38),ISNUMBER(S37)),VLOOKUP(ABS(S38-S37),'IMP Table'!$A$2:$C$26,3)*SIGN(S38-S37),0) | AA38: =IF(AND(ISNUMBER(T38),ISNUMBER(T36)),VLOOKUP(ABS(T38-T36),'IMP Table'!$A$2:$C$26,3)*SIGN(T38-T36),0) | AB38: =IF(AND(ISNUMBER(T38),ISNUMBER(T37)),VLOOKUP(ABS(T38-T37),'IMP Table'!$A$2:$C$26,3)*SIGN(T38-T37),0)
A39: 13 | B39: ='By Round'!A19 | C39: ='By Round'!B19 | D39: ='By Round'!C19 | E39: ='By Round'!D19 | F39: =IF(ISBLANK('By Round'!F19),"",'By Round'!F19) | G39: =IF(ISBLANK('By Round'!G19),"",'By Round'!G19) | H39: =IF(ISBLANK('By Round'!H19),"",'By Round'!H19) | I39: =IF(ISBLANK('By Round'!I19),"",'By Round'!I19) | J39: =IF(ISBLANK('By Round'!J19),"",'By Round'!J19) | K39: =IF(ISBLANK('By Round'!K19),"",'By Round'!K19) | L39: =IF(ISBLANK('By Round'!L19),"",'By Round'!L19) | M39: =AVERAGE(Y39:Z39) | N39: =AVERAGE(AA39:AB39) | O39: =IF(COUNT(U39:V39)>0,Q39/COUNT(U39:V39),0.5) | P39: =IF(COUNT(W39:X39)>0,R39/COUNT(W39:X39),0.5) | Q39: =SUM(U39:V39) | R39: =SUM(W39:X39) | S39: =IF(ISNUMBER(K39),K39,IF(ISNUMBER(L39),-L39,"")) | T39: =IF(ISNUMBER(L39),L39,IF(ISNUMBER(K39),-K39,"")) | U39: =IF(ISNUMBER(S39),IF(ISNUMBER(S40),IF(S39>S40,1.0,IF(S39=S40,0.5,0.0)),0.5),0.5) | V39: =IF(ISNUMBER(S39),IF(ISNUMBER(S41),IF(S39>S41,1.0,IF(S39=S41,0.5,0.0)),0.5),0.5) | W39: =IF(ISNUMBER(T39),IF(ISNUMBER(T40),IF(T39>T40,1.0,IF(T39=T40,0.5,0.0)),0.5),0.5) | X39: =IF(ISNUMBER(T39),IF(ISNUMBER(T41),IF(T39>T41,1.0,IF(T39=T41,0.5,0.0)),0.5),0.5) | Y39: =IF(AND(ISNUMBER(S39),ISNUMBER(S40)),VLOOKUP(ABS(S39-S40),'IMP Table'!$A$2:$C$26,3)*SIGN(S39-S40),0) | Z39: =IF(AND(ISNUMBER(S39),ISNUMBER(S41)),VLOOKUP(ABS(S39-S41),'IMP Table'!$A$2:$C$26,3)*SIGN(S39-S41),0) | AA39: =IF(AND(ISNUMBER(T39),ISNUMBER(T40)),VLOOKUP(ABS(T39-T40),'IMP Table'!$A$2:$C$26,3)*SIGN(T39-T40),0) | AB39: =IF(AND(ISNUMBER(T39),ISNUMBER(T41)),VLOOKUP(ABS(T39-T41),'IMP Table'!$A$2:$C$26,3)*SIGN(T39-T41),0)
