Workbook

Sheet Roster
A1: For public domain. No rights reserved. Generated on Sep 06, 2026.
A2: Team Match, 4 boards round
A3: Matches | C3: 2
A4: Boards per Match | C4: 8
B6: Team 1
A7: 1 | B7: Name 24 | C7: Name 17
A8: 2 | B8: Name 17 | C8: Name 51
B11: Team 2
A12: 3 | B12: Name 63 | C12: Name 30
A13: 4 | B13: Name 48 | C13: Name 41
B16: IMP Summary | D16: VP Summary
A17: Match | B17: Team 1 | C17: Team 2 | D17: Team 1 | E17: Team 2
A18: 1 | B18: =SUMIF('By Board'!D3:D18,"="&A7,'By Board'!M3:M18)+SUMIF('By Board'!D3:D18,"="&A8,'By Board'!M3:M18) | C18: =SUMIF('By Board'!D3:D18,"="&A12,'By Board'!M3:M18)+SUMIF('By Board'!D3:D18,"="&A13,'By Board'!M3:M18) | D18: =IF(B18>=0,IF((10+10*((1-0.6180339887498949^(3*B18/42.42640687119285))/(1-0.6180339887498949^3)))>=20,20,(10+10*((1-0.6180339887498949^(3*B18/42.42640687119285))/(1-0.6180339887498949^3)))),20-E18) | E18: =IF(C18>=0,IF((10+10*((1-0.6180339887498949^(3*C18/42.42640687119285))/(1-0.6180339887498949^3)))>=20,20,(10+10*((1-0.6180339887498949^(3*C18/42.42640687119285))/(1-0.6180339887498949^3)))),20-D18)
A19: 2 | B19: =SUMIF('By Board'!D19:D34,"="&A7,'By Board'!M19:M34)+SUMIF('By Board'!D19:D34,"="&A8,'By Board'!M19:M34) | C19: =SUMIF('By Board'!D19:D34,"="&A12,'By Board'!M19:M34)+SUMIF('By Board'!D19:D34,"="&A13,'By Board'!M19:M34) | D19: =IF(B19>=0,IF((10+10*((1-0.6180339887498949^(3*B19/42.42640687119285))/(1-0.6180339887498949^3)))>=20,20,(10+10*((1-0.6180339887498949^(3*B19/42.42640687119285))/(1-0.6180339887498949^3)))),20-E19) | E19: =IF(C19>=0,IF((10+10*((1-0.6180339887498949^(3*C19/42.42640687119285))/(1-0.6180339887498949^3)))>=20,20,(10+10*((1-0.6180339887498949^(3*C19/42.42640687119285))/(1-0.6180339887498949^3)))),20-D19)
B20: =SUM(B18:B19) | C20: =SUM(C18:C19) | D20: =SUM(D18:D19) | E20: =SUM(E18:E19)

Sheet By Board
K1: Score | N1: Net
A2: Board | B2: Round | C2: Table | D2: NS | E2: EW | F2: Vul | G2: Contract | H2: By | I2: Made | J2: Down | K2: NS | L2: EW | M2: IMP | N2: NS | O2: EW
A3: 1 | B3: 1 | C3: 1 | D3: 1 | E3: 4 | F3: None | M3: =IF(AND(ISNUMBER(N3),ISNUMBER(N4)),VLOOKUP(ABS(N3-N4),'IMP Table'!$A$2:$C$26,3)*SIGN(N3-N4),0) | N3: =IF(ISNUMBER(K3),K3,IF(ISNUMBER(L3),-L3,"")) | O3: =IF(ISNUMBER(L3),L3,IF(ISNUMBER(K3),-K3,""))
B4: 2 | C4: 2 | D4: 3 | E4: 2 | F4: None | M4: =IF(AND(ISNUMBER(N4),ISNUMBER(N3)),VLOOKUP(ABS(N4-N3),'IMP Table'!$A$2:$C$26,3)*SIGN(N4-N3),0) | N4: =IF(ISNUMBER(K4),K4,IF(ISNUMBER(L4),-L4,"")) | O4: =IF(ISNUMBER(L4),L4,IF(ISNUMBER(K4),-K4,""))
A5: 2 | B5: 1 | C5: 1 | D5: 1 | E5: 4 | F5: NS | M5: =IF(AND(ISNUMBER(N5),ISNUMBER(N6)),VLOOKUP(ABS(N5-N6),'IMP Table'!$A$2:$C$26,3)*SIGN(N5-N6),0) | N5: =IF(ISNUMBER(K5),K5,IF(ISNUMBER(L5),-L5,"")) | O5: =IF(ISNUMBER(L5),L5,IF(ISNUMBER(K5),-K5,""))
B6: 2 | C6: 2 | D6: 3 | E6: 2 | F6: NS | M6: =IF(AND(ISNUMBER(N6),ISNUMBER(N5)),VLOOKUP(ABS(N6-N5),'IMP Table'!$A$2:$C$26,3)*SIGN(N6-N5),0) | N6: =IF(ISNUMBER(K6),K6,IF(ISNUMBER(L6),-L6,"")) | O6: =IF(ISNUMBER(L6),L6,IF(ISNUMBER(K6),-K6,""))
A7: 3 | B7: 1 | C7: 1 | D7: 1 | E7: 4 | F7: EW | M7: =IF(AND(ISNUMBER(N7),ISNUMBER(N8)),VLOOKUP(ABS(N7-N8),'IMP Table'!$A$2:$C$26,3)*SIGN(N7-N8),0) | N7: =IF(ISNUMBER(K7),K7,IF(ISNUMBER(L7),-L7,"")) | O7: =IF(ISNUMBER(L7),L7,IF(ISNUMBER(K7),-K7,""))
B8: 2 | C8: 2 | D8: 3 | E8: 2 | F8: EW | M8: =IF(AND(ISNUMBER(N8),ISNUMBER(N7)),VLOOKUP(ABS(N8-N7),'IMP Table'!$A$2:$C$26,3)*SIGN(N8-N7),0) | N8: =IF(ISNUMBER(K8),K8,IF(ISNUMBER(L8),-L8,"")) | O8: =IF(ISNUMBER(L8),L8,IF(ISNUMBER(K8),-K8,""))
A9: 4 | B9: 1 | C9: 1 | D9: 1 | E9: 4 | F9: Both | M9: =IF(AND(ISNUMBER(N9),ISNUMBER(N10)),VLOOKUP(ABS(N9-N10),'IMP Table'!$A$2:$C$26,3)*SIGN(N9-N10),0) | N9: =IF(ISNUMBER(K9),K9,IF(ISNUMBER(L9),-L9,"")) | O9: =IF(ISNUMBER(L9),L9,IF(ISNUMBER(K9),-K9,""))
B10: 2 | C10: 2 | D10: 3 | E10: 2 | F10: Both | M10: =IF(AND(ISNUMBER(N10),ISNUMBER(N9)),VLOOKUP(ABS(N10-N9),'IMP Table'!$A$2:$C$26,3)*SIGN(N10-N9),0) | N10: =IF(ISNUMBER(K10),K10,IF(ISNUMBER(L10),-L10,"")) | O10: =IF(ISNUMBER(L10),L10,IF(ISNUMBER(K10),-K10,""))
A11: 5 | B11: 2 | C11: 1 | D11: 1 | E11: 4 | F11: NS | M11: =IF(AND(ISNUMBER(N11),ISNUMBER(N12)),VLOOKUP(ABS(N11-N12),'IMP Table'!$A$2:$C$26,3)*SIGN(N11-N12),0) | N11: =IF(ISNUMBER(K11),K11,IF(ISNUMBER(L11),-L11,"")) | O11: =IF(ISNUMBER(L11),L11,IF(ISNUMBER(K11),-K11,""))
B12: 1 | C12: 2 | D12: 3 | E12: 2 | F12: NS | M12: =IF(AND(ISNUMBER(N12),ISNUMBER(N11)),VLOOKUP(ABS(N12-N11),'IMP Table'!$A$2:$C$26,3)*SIGN(N12-N11),0) | N12: =IF(ISNUMBER(K12),K12,IF(ISNUMBER(L12),-L12,"")) | O12: =IF(ISNUMBER(L12),L12,IF(ISNUMBER(K12),-K12,""))
A13: 6 | B13: 2 | C13: 1 | D13: 1 | E13: 4 | F13: EW | M13: =IF(AND(ISNUMBER(N13),ISNUMBER(N14)),VLOOKUP(ABS(N13-N14),'IMP Table'!$A$2:$C$26,3)*SIGN(N13-N14),0) | N13: =IF(ISNUMBER(K13),K13,IF(ISNUMBER(L13),-L13,"")) | O13: =IF(ISNUMBER(L13),L13,IF(ISNUMBER(K13),-K13,""))
B14: 1 | C14: 2 | D14: 3 | E14: 2 | F14: EW | M14: =IF(AND(ISNUMBER(N14),ISNUMBER(N13)),VLOOKUP(ABS(N14-N13),'IMP Table'!$A$2:$C$26,3)*SIGN(N14-N13),0) | N14: =IF(ISNUMBER(K14),K14,IF(ISNUMBER(L14),-L14,"")) | O14: =IF(ISNUMBER(L14),L14,IF(ISNUMBER(K14),-K14,""))
A15: 7 | B15: 2 | C15: 1 | D15: 1 | E15: 4 | F15: Both | M15: =IF(AND(ISNUMBER(N15),ISNUMBER(N16)),VLOOKUP(ABS(N15-N16),'IMP Table'!$A$2:$C$26,3)*SIGN(N15-N16),0) | N15: =IF(ISNUMBER(K15),K15,IF(ISNUMBER(L15),-L15,"")) | O15: =IF(ISNUMBER(L15),L15,IF(ISNUMBER(K15),-K15,""))
B16: 1 | C16: 2 | D16: 3 | E16: 2 | F16: Both | M16: =IF(AND(ISNUMBER(N16),ISNUMBER(N15)),VLOOKUP(ABS(N16-N15),'IMP Table'!$A$2:$C$26,3)*SIGN(N16-N15),0) | N16: =IF(ISNUMBER(K16),K16,IF(ISNUMBER(L16),-L16,"")) | O16: =IF(ISNUMBER(L16),L16,IF(ISNUMBER(K16),-K16,""))
A17: 8 | B17: 2 | C17: 1 | D17: 1 | E17: 4 | F17: None | M17: =IF(AND(ISNUMBER(N17),ISNUMBER(N18)),VLOOKUP(ABS(N17-N18),'IMP Table'!$A$2:$C$26,3)*SIGN(N17-N18),0) | N17: =IF(ISNUMBER(K17),K17,IF(ISNUMBER(L17),-L17,"")) | O17: =IF(ISNUMBER(L17),L17,IF(ISNUMBER(K17),-K17,""))
B18: 1 | C18: 2 | D18: 3 | E18: 2 | F18: None | M18: =IF(AND(ISNUMBER(N18),ISNUMBER(N17)),VLOOKUP(ABS(N18-N17),'IMP Table'!$A$2:$C$26,3)*SIGN(N18-N17),0) | N18: =IF(ISNUMBER(K18),K18,IF(ISNUMBER(L18),-L18,"")) | O18: =IF(ISNUMBER(L18),L18,IF(ISNUMBER(K18),-K18,""))
A19: 9 | B19: 3 | C19: 1 | D19: 1 | E19: 3 | F19: EW | M19: =IF(AND(ISNUMBER(N19),ISNUMBER(N20)),VLOOKUP(ABS(N19-N20),'IMP Table'!$A$2:$C$26,3)*SIGN(N19-N20),0) | N19: =IF(ISNUMBER(K19),K19,IF(ISNUMBER(L19),-L19,"")) | O19: =IF(ISNUMBER(L19),L19,IF(ISNUMBER(K19),-K19,""))
B20: 4 | C20: 2 | D20: 4 | E20: 2 | F20: EW | M20: =IF(AND(ISNUMBER(N20),ISNUMBER(N19)),VLOOKUP(ABS(N20-N19),'IMP Table'!$A$2:$C$26,3)*SIGN(N20-N19),0) | N20: =IF(ISNUMBER(K20),K20,IF(ISNUMBER(L20),-L20,"")) | O20: =IF(ISNUMBER(L20),L20,IF(ISNUMBER(K20),-K20,""))
A21: 10 | B21: 3 | C21: 1 | D21: 1 | E21: 3 | F21: Both | M21: =IF(AND(ISNUMBER(N21),ISNUMBER(N22)),VLOOKUP(ABS(N21-N22),'IMP Table'!$A$2:$C$26,3)*SIGN(N21-N22),0) | N21: =IF(ISNUMBER(K21),K21,IF(ISNUMBER(L21),-L21,"")) | O21: =IF(ISNUMBER(L21),L21,IF(ISNUMBER(K21),-K21,""))
B22: 4 | C22: 2 | D22: 4 | E22: 2 | F22: Both | M22: =IF(AND(ISNUMBER(N22),ISNUMBER(N21)),VLOOKUP(ABS(N22-N21),'IMP Table'!$A$2:$C$26,3)*SIGN(N22-N21),0) | N22: =IF(ISNUMBER(K22),K22,IF(ISNUMBER(L22),-L22,"")) | O22: =IF(ISNUMBER(L22),L22,IF(ISNUMBER(K22),-K22,""))
A23: 11 | B23: 3 | C23: 1 | D23: 1 | E23: 3 | F23: None | M23: =IF(AND(ISNUMBER(N23),ISNUMBER(N24)),VLOOKUP(ABS(N23-N24),'IMP Table'!$A$2:$C$26,3)*SIGN(N23-N24),0) | N23: =IF(ISNUMBER(K23),K23,IF(ISNUMBER(L23),-L23,"")) | O23: =IF(ISNUMBER(L23),L23,IF(ISNUMBER(K23),-K23,""))
B24: 4 | C24: 2 | D24: 4 | E24: 2 | F24: None | M24: =IF(AND(ISNUMBER(N24),ISNUMBER(N23)),VLOOKUP(ABS(N24-N23),'IMP Table'!$A$2:$C$26,3)*SIGN(N24-N23),0) | N24: =IF(ISNUMBER(K24),K24,IF(ISNUMBER(L24),-L24,"")) | O24: =IF(ISNUMBER(L24),L24,IF(ISNUMBER(K24),-K24,""))
A25: 12 | B25: 3 | C25: 1 | D25: 1 | E25: 3 | F25: NS | M25: =IF(AND(ISNUMBER(N25),ISNUMBER(N26)),VLOOKUP(ABS(N25-N26),'IMP Table'!$A$2:$C$26,3)*SIGN(N25-N26),0) | N25: =IF(ISNUMBER(K25),K25,IF(ISNUMBER(L25),-L25,"")) | O25: =IF(ISNUMBER(L25),L25,IF(ISNUMBER(K25),-K25,""))
B26: 4 | C26: 2 | D26: 4 | E26: 2 | F26: NS | M26: =IF(AND(ISNUMBER(N26),ISNUMBER(N25)),VLOOKUP(ABS(N26-N25),'IMP Table'!$A$2:$C$26,3)*SIGN(N26-N25),0) | N26: =IF(ISNUMBER(K26),K26,IF(ISNUMBER(L26),-L26,"")) | O26: =IF(ISNUMBER(L26),L26,IF(ISNUMBER(K26),-K26,""))
A27: 13 | B27: 4 | C27: 1 | D27: 1 | E27: 3 | F27: Both | M27: =IF(AND(ISNUMBER(N27),ISNUMBER(N28)),VLOOKUP(ABS(N27-N28),'IMP Table'!$A$2:$C$26,3)*SIGN(N27-N28),0) | N27: =IF(ISNUMBER(K27),K27,IF(ISNUMBER(L27),-L27,"")) | O27: =IF(ISNUMBER(L27),L27,IF(ISNUMBER(K27),-K27,""))
B28: 3 | C28: 2 | D28: 4 | E28: 2 | F28: Both | M28: =IF(AND(ISNUMBER(N28),ISNUMBER(N27)),VLOOKUP(ABS(N28-N27),'IMP Table'!$A$2:$C$26,3)*SIGN(N28-N27),0) | N28: =IF(ISNUMBER(K28),K28,IF(ISNUMBER(L28),-L28,"")) | O28: =IF(ISNUMBER(L28),L28,IF(ISNUMBER(K28),-K28,""))
A29: 14 | B29: 4 | C29: 1 | D29: 1 | E29: 3 | F29: None | M29: =IF(AND(ISNUMBER(N29),ISNUMBER(N30)),VLOOKUP(ABS(N29-N30),'IMP Table'!$A$2:$C$26,3)*SIGN(N29-N30),0) | N29: =IF(ISNUMBER(K29),K29,IF(ISNUMBER(L29),-L29,"")) | O29: =IF(ISNUMBER(L29),L29,IF(ISNUMBER(K29),-K29,""))
B30: 3 | C30: 2 | D30: 4 | E30: 2 | F30: None | M30: =IF(AND(ISNUMBER(N30),ISNUMBER(N29)),VLOOKUP(ABS(N30-N29),'IMP Table'!$A$2:$C$26,3)*SIGN(N30-N29),0) | N30: =IF(ISNUMBER(K30),K30,IF(ISNUMBER(L30),-L30,"")) | O30: =IF(ISNUMBER(L30),L30,IF(ISNUMBER(K30),-K30,""))
A31: 15 | B31: 4 | C31: 1 | D31: 1 | E31: 3 | F31: NS | M31: =IF(AND(ISNUMBER(N31),ISNUMBER(N32)),VLOOKUP(ABS(N31-N32),'IMP Table'!$A$2:$C$26,3)*SIGN(N31-N32),0) | N31: =IF(ISNUMBER(K31),K31,IF(ISNUMBER(L31),-L31,"")) | O31: =IF(ISNUMBER(L31),L31,IF(ISNUMBER(K31),-K31,""))
B32: 3 | C32: 2 | D32: 4 | E32: 2 | F32: NS | M32: =IF(AND(ISNUMBER(N32),ISNUMBER(N31)),VLOOKUP(ABS(N32-N31),'IMP Table'!$A$2:$C$26,3)*SIGN(N32-N31),0) | N32: =IF(ISNUMBER(K32),K32,IF(ISNUMBER(L32),-L32,"")) | O32: =IF(ISNUMBER(L32),L32,IF(ISNUMBER(K32),-K32,""))
A33: 16 | B33: 4 | C33: 1 | D33: 1 | E33: 3 | F33: EW | M33: =IF(AND(ISNUMBER(N33),ISNUMBER(N34)),VLOOKUP(ABS(N33-N34),'IMP Table'!$A$2:$C$26,3)*SIGN(N33-N34),0) | N33: =IF(ISNUMBER(K33),K33,IF(ISNUMBER(L33),-L33,"")) | O33: =IF(ISNUMBER(L33),L33,IF(ISNUMBER(K33),-K33,""))
B34: 3 | C34: 2 | D34: 4 | E34: 2 | F34: EW | M34: =IF(AND(ISNUMBER(N34),ISNUMBER(N33)),VLOOKUP(ABS(N34-N33),'IMP Table'!$A$2:$C$26,3)*SIGN(N34-N33),0) | N34: =IF(ISNUMBER(K34),K34,IF(ISNUMBER(L34),-L34,"")) | O34: =IF(ISNUMBER(L34),L34,IF(ISNUMBER(K34),-K34,""))

Sheet IMP Table
A1: From | B1: To | C1: IMP
A2: 0 | B2: 10 | C2: 0
A3: 20 | B3: 40 | C3: 1
A4: 50 | B4: 80 | C4: 2
A5: 90 | B5: 120 | C5: 3
A6: 130 | B6: 160 | C6: 4
A7: 170 | B7: 210 | C7: 5
A8: 220 | B8: 260 | C8: 6
A9: 270 | B9: 310 | C9: 7
A10: 320 | B10: 360 | C10: 8
A11: 370 | B11: 420 | C11: 9
A12: 430 | B12: 490 | C12: 10
A13: 500 | B13: 590 | C13: 11
... A26: 4000 | B26: 10000 | C26: 24

Sheet VP Table
B1: 20 Victory Point Scales
A2: IMP | B2: 8 | C2: 9 | D2: 10 | E2: 11 | F2: 12 | G2: 13 | H2: 14 | I2: 15 | J2: 16
A3: 0 | B3: 10 | C3: 10 | D3: 10 | E3: 10 | F3: 10 | G3: 10 | H3: 10 | I3: 10 | J3: 10
A4: 1 | B4: 10.437924 | C4: 10.413278 | D4: 10.392391 | E4: 10.374394 | F4: 10.358676 | G4: 10.344791 | H4: 10.33241 | I4: 10.321278 | J4: 10.311198
A5: 2 | B5: 10.861197 | C5: 10.813509 | D5: 10.773021 | E5: 10.738081 | F5: 10.707524 | G5: 10.680501 | H5: 10.656379 | I5: 10.634671 | J5: 10.614999
A6: 3 | B6: 11.270311 | C6: 11.201103 | D6: 11.14224 | E6: 11.091365 | F6: 11.046813 | G6: 11.007368 | H6: 10.972121 | I6: 10.940372 | J6: 10.911576
A7: 4 | B7: 11.665737 | C7: 11.576461 | D7: 11.500392 | E7: 11.434545 | F7: 11.376805 | G7: 11.325626 | H7: 11.279845 | I7: 11.23857 | J7: 11.201103
A8: 5 | B8: 12.047935 | C8: 11.939968 | D8: 11.847807 | E8: 11.76791 | F8: 11.697756 | G8: 11.635501 | H8: 11.579755 | I8: 11.529449 | J8: 11.483747
A9: 6 | B9: 12.417346 | C9: 12.291998 | D9: 12.184809 | E9: 12.09174 | F9: 12.009913 | G9: 11.937214 | H9: 11.872049 | I9: 11.813189 | J9: 11.759672
A10: 7 | B10: 12.774399 | C10: 12.632914 | D10: 12.511708 | E10: 12.406308 | F10: 12.313516 | G10: 12.23098 | H10: 12.15692 | I10: 12.089965 | J10: 12.029037
A11: 8 | B11: 13.119507 | C11: 12.963067 | D11: 12.828809 | E11: 12.711879 | F11: 12.608801 | G11: 12.517008 | H11: 12.434558 | I11: 12.359949 | J11: 12.291998
A12: 9 | B12: 13.45307 | C12: 13.282797 | D12: 13.136404 | E12: 13.00871 | F12: 12.895994 | G12: 12.795502 | H12: 12.705145 | I12: 12.623305 | J12: 12.548708
A13: 10 | B13: 13.775473 | C13: 13.592432 | D13: 13.434778 | E13: 13.297052 | F13: 13.175318 | G13: 13.066661 | H13: 12.968861 | I13: 12.880198 | J13: 12.799315
A14: 11 | B14: 14.087091 | C14: 13.892291 | D14: 13.724209 | E14: 13.577146 | F14: 13.446989 | G14: 13.330677 | H14: 13.22588 | I14: 13.130786 | J14: 13.043964
... A63: 60 | B63: 20 | C63: 20 | D63: 20 | E63: 20 | F63: 20 | G63: 20 | H63: 20 | I63: 20 | J63: 20

Sheet Scoring Table
C1: Not Vulnerable | F1: Vulnerable | K1: Not Vulnerable | N1: Vulnerable
A2: Contract | B2: Made | D2: X | E2: XX | G2: X | H2: XX | J2: Down by | L2: X | M2: XX | O2: X | P2: XX
A3: 1 D/C | B3: 1 | C3: 70 | D3: 140 | E3: 230 | F3: 70 | G3: 140 | H3: 230 | J3: -1 | K3: -50 | L3: -100 | M3: =L3*2 | N3: -100 | O3: -200 | P3: =O3*2
B4: 2 | C4: 90 | D4: 240 | E4: 430 | F4: 90 | G4: 340 | H4: 630 | J4: -2 | K4: =K3-50 | L4: =L3-200 | M4: =L4*2 | N4: =N3-100 | O4: =O3-300 | P4: =O4*2
B5: 3 | C5: 110 | D5: 340 | E5: 630 | F5: 110 | G5: 540 | H5: 1030 | J5: -3 | K5: =K4-50 | L5: =L4-200 | M5: =L5*2 | N5: =N4-100 | O5: =O4-300 | P5: =O5*2
B6: 4 | C6: 130 | D6: 440 | E6: 830 | F6: 130 | G6: 740 | H6: 1430 | J6: -4 | K6: =K5-50 | L6: =L5-300 | M6: =L6*2 | N6: =N5-100 | O6: =O5-300 | P6: =O6*2
B7: 5 | C7: 150 | D7: 540 | E7: 1030 | F7: 150 | G7: 940 | H7: 1830 | J7: -5 | K7: =K6-50 | L7: =L6-300 | M7: =L7*2 | N7: =N6-100 | O7: =O6-300 | P7: =O7*2
B8: 6 | C8: 170 | D8: 640 | E8: 1230 | F8: 170 | G8: 1140 | H8: 2230 | J8: -6 | K8: =K7-50 | L8: =L7-300 | M8: =L8*2 | N8: =N7-100 | O8: =O7-300 | P8: =O8*2
B9: 7 | C9: 190 | D9: 740 | E9: 1430 | F9: 190 | G9: 1340 | H9: 2630 | J9: -7 | K9: =K8-50 | L9: =L8-300 | M9: =L9*2 | N9: =N8-100 | O9: =O8-300 | P9: =O9*2
A10: 1 H/S | B10: 1 | C10: 80 | D10: 160 | E10: 520 | F10: 80 | G10: 160 | H10: 720 | J10: -8 | K10: =K9-50 | L10: =L9-300 | M10: =L10*2 | N10: =N9-100 | O10: =O9-300 | P10: =O10*2
B11: 2 | C11: 110 | D11: 260 | E11: 720 | F11: 110 | G11: 360 | H11: 1120 | J11: -9 | K11: =K10-50 | L11: =L10-300 | M11: =L11*2 | N11: =N10-100 | O11: =O10-300 | P11: =O11*2
B12: 3 | C12: 140 | D12: 360 | E12: 920 | F12: 140 | G12: 560 | H12: 1520 | J12: -10 | K12: =K11-50 | L12: =L11-300 | M12: =L12*2 | N12: =N11-100 | O12: =O11-300 | P12: =O12*2
B13: 4 | C13: 170 | D13: 460 | E13: 1120 | F13: 170 | G13: 760 | H13: 1920 | J13: -11 | K13: =K12-50 | L13: =L12-300 | M13: =L13*2 | N13: =N12-100 | O13: =O12-300 | P13: =O13*2
B14: 5 | C14: 200 | D14: 560 | E14: 1320 | F14: 200 | G14: 960 | H14: 2320 | J14: -12 | K14: =K13-50 | L14: =L13-300 | M14: =L14*2 | N14: =N13-100 | O14: =O13-300 | P14: =O14*2
B15: 6 | C15: 230 | D15: 660 | E15: 1520 | F15: 230 | G15: 1160 | H15: 2720 | J15: -13 | K15: =K14-50 | L15: =L14-300 | M15: =L15*2 | N15: =N14-100 | O15: =O14-300 | P15: =O15*2
B16: 7 | C16: 260 | D16: 760 | E16: 1720 | F16: 260 | G16: 1360 | H16: 3120
A17: 1 NT | B17: 1 | C17: 90 | D17: 180 | E17: 560 | F17: 90 | G17: 180 | H17: 760
B18: 2 | C18: 120 | D18: 280 | E18: 760 | F18: 120 | G18: 380 | H18: 1160
B19: 3 | C19: 150 | D19: 380 | E19: 960 | F19: 150 | G19: 580 | H19: 1560
B20: 4 | C20: 180 | D20: 480 | E20: 1160 | F20: 180 | G20: 780 | H20: 1960
B21: 5 | C21: 210 | D21: 580 | E21: 1360 | F21: 210 | G21: 980 | H21: 2360
B22: 6 | C22: 240 | D22: 680 | E22: 1560 | F22: 240 | G22: 1180 | H22: 2760
B23: 7 | C23: 270 | D23: 780 | E23: 1760 | F23: 270 | G23: 1380 | H23: 3160
A24: 2 D/C | B24: 2 | C24: 90 | D24: 180 | E24: 560 | F24: 90 | G24: 180 | H24: 760
B25: 3 | C25: 110 | D25: 280 | E25: 760 | F25: 110 | G25: 380 | H25: 1160
B26: 4 | C26: 130 | D26: 380 | E26: 960 | F26: 130 | G26: 580 | H26: 1560
B27: 5 | C27: 150 | D27: 480 | E27: 1160 | F27: 150 | G27: 780 | H27: 1960
B28: 6 | C28: 170 | D28: 580 | E28: 1360 | F28: 170 | G28: 980 | H28: 2360
B29: 7 | C29: 190 | D29: 680 | E29: 1560 | F29: 190 | G29: 1180 | H29: 2760
A30: 2 H/S | B30: 2 | C30: 110 | D30: 470 | E30: 640 | F30: 110 | G30: 670 | H30: 840
B31: 3 | C31: 140 | D31: 570 | E31: 840 | F31: 140 | G31: 870 | H31: 1240
B32: 4 | C32: 170 | D32: 670 | E32: 1040 | F32: 170 | G32: 1070 | H32: 1640
B33: 5 | C33: 200 | D33: 770 | E33: 1240 | F33: 200 | G33: 1270 | H33: 2040
B34: 6 | C34: 230 | D34: 870 | E34: 1440 | F34: 230 | G34: 1470 | H34: 2440
B35: 7 | C35: 260 | D35: 970 | E35: 1640 | F35: 260 | G35: 1670 | H35: 2840
A36: 2 NT | B36: 2 | C36: 120 | D36: 490 | E36: 680 | F36: 120 | G36: 690 | H36: 880
B37: 3 | C37: 150 | D37: 590 | E37: 880 | F37: 150 | G37: 890 | H37: 1280
B38: 4 | C38: 180 | D38: 690 | E38: 1080 | F38: 180 | G38: 1090 | H38: 1680
B39: 5 | C39: 210 | D39: 790 | E39: 1280 | F39: 210 | G39: 1290 | H39: 2080
B40: 6 | C40: 240 | D40: 890 | E40: 1480 | F40: 240 | G40: 1490 | H40: 2480
...
