Workbook

Sheet Roster
A1: For public domain. No rights reserved. Generated on Mar 07, 2026.
A2: Team Match
A3: Pairs | C3: 4
A4: Rounds | C4: 4
A5: Boards per Round | C5: 4
A7: Pairs | D7: IMP
A8: 1 | B8: Name 18 | C8: Name 18 | D8: =SUMIF('By Board'!D3:D19,"="&A8,'By Board'!L3:L19)+SUMIF('By Board'!E3:E19,"="&A8,'By Board'!M3:M19)
A9: 2 | B9: Name 29 | C9: Name 90 | D9: =SUMIF('By Board'!D3:D19,"="&A9,'By Board'!L3:L19)+SUMIF('By Board'!E3:E19,"="&A9,'By Board'!M3:M19)
A10: 3 | B10: Name 73 | C10: Name 43 | D10: =SUMIF('By Board'!D3:D19,"="&A10,'By Board'!L3:L19)+SUMIF('By Board'!E3:E19,"="&A10,'By Board'!M3:M19)
A11: 4 | B11: Name 13 | C11: Name 37 | D11: =SUMIF('By Board'!D3:D19,"="&A11,'By Board'!L3:L19)+SUMIF('By Board'!E3:E19,"="&A11,'By Board'!M3:M19)
C12: Sum | D12: =SUM(D3:D7)

Sheet By Board
J1: Score | L1: IMP | N1: Net
A2: Board | B2: Round | C2: Table | D2: NS | E2: EW | F2: Vul | G2: Contract | H2: By | I2: Result | J2: NS | K2: EW | L2: NS | M2: EW | N2: NS | O2: EW
A3: 1 | B3: 1 | C3: 1 | D3: 1 | E3: 3 | F3: None | L3: =IF(AND(ISNUMBER(N3),ISNUMBER(N4)),VLOOKUP(ABS(N3-N4),'IMP Table'!$A$2:$C$26,3)*SIGN(N3-N4),0) | M3: =IF(AND(ISNUMBER(O3),ISNUMBER(O4)),VLOOKUP(ABS(O3-O4),'IMP Table'!$A$2:$C$26,3)*SIGN(O3-O4),0) | N3: =IF(ISNUMBER(J3),J3,IF(ISNUMBER(K3),-K3,"")) | O3: =IF(ISNUMBER(K3),K3,IF(ISNUMBER(J3),-J3,""))
B4: 2 | C4: 2 | D4: 4 | E4: 2 | F4: None | L4: =IF(AND(ISNUMBER(N4),ISNUMBER(N3)),VLOOKUP(ABS(N4-N3),'IMP Table'!$A$2:$C$26,3)*SIGN(N4-N3),0) | M4: =IF(AND(ISNUMBER(O4),ISNUMBER(O3)),VLOOKUP(ABS(O4-O3),'IMP Table'!$A$2:$C$26,3)*SIGN(O4-O3),0) | N4: =IF(ISNUMBER(J4),J4,IF(ISNUMBER(K4),-K4,"")) | O4: =IF(ISNUMBER(K4),K4,IF(ISNUMBER(J4),-J4,""))
A5: 2 | B5: 1 | C5: 1 | D5: 1 | E5: 3 | F5: NS | L5: =IF(AND(ISNUMBER(N5),ISNUMBER(N6)),VLOOKUP(ABS(N5-N6),'IMP Table'!$A$2:$C$26,3)*SIGN(N5-N6),0) | M5: =IF(AND(ISNUMBER(O5),ISNUMBER(O6)),VLOOKUP(ABS(O5-O6),'IMP Table'!$A$2:$C$26,3)*SIGN(O5-O6),0) | N5: =IF(ISNUMBER(J5),J5,IF(ISNUMBER(K5),-K5,"")) | O5: =IF(ISNUMBER(K5),K5,IF(ISNUMBER(J5),-J5,""))
B6: 2 | C6: 2 | D6: 4 | E6: 2 | F6: NS | L6: =IF(AND(ISNUMBER(N6),ISNUMBER(N5)),VLOOKUP(ABS(N6-N5),'IMP Table'!$A$2:$C$26,3)*SIGN(N6-N5),0) | M6: =IF(AND(ISNUMBER(O6),ISNUMBER(O5)),VLOOKUP(ABS(O6-O5),'IMP Table'!$A$2:$C$26,3)*SIGN(O6-O5),0) | N6: =IF(ISNUMBER(J6),J6,IF(ISNUMBER(K6),-K6,"")) | O6: =IF(ISNUMBER(K6),K6,IF(ISNUMBER(J6),-J6,""))
A7: 3 | B7: 1 | C7: 1 | D7: 1 | E7: 3 | F7: EW | L7: =IF(AND(ISNUMBER(N7),ISNUMBER(N8)),VLOOKUP(ABS(N7-N8),'IMP Table'!$A$2:$C$26,3)*SIGN(N7-N8),0) | M7: =IF(AND(ISNUMBER(O7),ISNUMBER(O8)),VLOOKUP(ABS(O7-O8),'IMP Table'!$A$2:$C$26,3)*SIGN(O7-O8),0) | N7: =IF(ISNUMBER(J7),J7,IF(ISNUMBER(K7),-K7,"")) | O7: =IF(ISNUMBER(K7),K7,IF(ISNUMBER(J7),-J7,""))
B8: 2 | C8: 2 | D8: 4 | E8: 2 | F8: EW | L8: =IF(AND(ISNUMBER(N8),ISNUMBER(N7)),VLOOKUP(ABS(N8-N7),'IMP Table'!$A$2:$C$26,3)*SIGN(N8-N7),0) | M8: =IF(AND(ISNUMBER(O8),ISNUMBER(O7)),VLOOKUP(ABS(O8-O7),'IMP Table'!$A$2:$C$26,3)*SIGN(O8-O7),0) | N8: =IF(ISNUMBER(J8),J8,IF(ISNUMBER(K8),-K8,"")) | O8: =IF(ISNUMBER(K8),K8,IF(ISNUMBER(J8),-J8,""))
A9: 4 | B9: 1 | C9: 1 | D9: 1 | E9: 3 | F9: Both | L9: =IF(AND(ISNUMBER(N9),ISNUMBER(N10)),VLOOKUP(ABS(N9-N10),'IMP Table'!$A$2:$C$26,3)*SIGN(N9-N10),0) | M9: =IF(AND(ISNUMBER(O9),ISNUMBER(O10)),VLOOKUP(ABS(O9-O10),'IMP Table'!$A$2:$C$26,3)*SIGN(O9-O10),0) | N9: =IF(ISNUMBER(J9),J9,IF(ISNUMBER(K9),-K9,"")) | O9: =IF(ISNUMBER(K9),K9,IF(ISNUMBER(J9),-J9,""))
B10: 2 | C10: 2 | D10: 4 | E10: 2 | F10: Both | L10: =IF(AND(ISNUMBER(N10),ISNUMBER(N9)),VLOOKUP(ABS(N10-N9),'IMP Table'!$A$2:$C$26,3)*SIGN(N10-N9),0) | M10: =IF(AND(ISNUMBER(O10),ISNUMBER(O9)),VLOOKUP(ABS(O10-O9),'IMP Table'!$A$2:$C$26,3)*SIGN(O10-O9),0) | N10: =IF(ISNUMBER(J10),J10,IF(ISNUMBER(K10),-K10,"")) | O10: =IF(ISNUMBER(K10),K10,IF(ISNUMBER(J10),-J10,""))
A11: 5 | B11: 1 | C11: 2 | D11: 4 | E11: 2 | F11: NS | L11: =IF(AND(ISNUMBER(N11),ISNUMBER(N12)),VLOOKUP(ABS(N11-N12),'IMP Table'!$A$2:$C$26,3)*SIGN(N11-N12),0) | M11: =IF(AND(ISNUMBER(O11),ISNUMBER(O12)),VLOOKUP(ABS(O11-O12),'IMP Table'!$A$2:$C$26,3)*SIGN(O11-O12),0) | N11: =IF(ISNUMBER(J11),J11,IF(ISNUMBER(K11),-K11,"")) | O11: =IF(ISNUMBER(K11),K11,IF(ISNUMBER(J11),-J11,""))
B12: 2 | C12: 1 | D12: 1 | E12: 3 | F12: NS | L12: =IF(AND(ISNUMBER(N12),ISNUMBER(N11)),VLOOKUP(ABS(N12-N11),'IMP Table'!$A$2:$C$26,3)*SIGN(N12-N11),0) | M12: =IF(AND(ISNUMBER(O12),ISNUMBER(O11)),VLOOKUP(ABS(O12-O11),'IMP Table'!$A$2:$C$26,3)*SIGN(O12-O11),0) | N12: =IF(ISNUMBER(J12),J12,IF(ISNUMBER(K12),-K12,"")) | O12: =IF(ISNUMBER(K12),K12,IF(ISNUMBER(J12),-J12,""))
A13: 6 | B13: 1 | C13: 2 | D13: 4 | E13: 2 | F13: EW | L13: =IF(AND(ISNUMBER(N13),ISNUMBER(N14)),VLOOKUP(ABS(N13-N14),'IMP Table'!$A$2:$C$26,3)*SIGN(N13-N14),0) | M13: =IF(AND(ISNUMBER(O13),ISNUMBER(O14)),VLOOKUP(ABS(O13-O14),'IMP Table'!$A$2:$C$26,3)*SIGN(O13-O14),0) | N13: =IF(ISNUMBER(J13),J13,IF(ISNUMBER(K13),-K13,"")) | O13: =IF(ISNUMBER(K13),K13,IF(ISNUMBER(J13),-J13,""))
B14: 2 | C14: 1 | D14: 1 | E14: 3 | F14: EW | L14: =IF(AND(ISNUMBER(N14),ISNUMBER(N13)),VLOOKUP(ABS(N14-N13),'IMP Table'!$A$2:$C$26,3)*SIGN(N14-N13),0) | M14: =IF(AND(ISNUMBER(O14),ISNUMBER(O13)),VLOOKUP(ABS(O14-O13),'IMP Table'!$A$2:$C$26,3)*SIGN(O14-O13),0) | N14: =IF(ISNUMBER(J14),J14,IF(ISNUMBER(K14),-K14,"")) | O14: =IF(ISNUMBER(K14),K14,IF(ISNUMBER(J14),-J14,""))
A15: 7 | B15: 1 | C15: 2 | D15: 4 | E15: 2 | F15: Both | L15: =IF(AND(ISNUMBER(N15),ISNUMBER(N16)),VLOOKUP(ABS(N15-N16),'IMP Table'!$A$2:$C$26,3)*SIGN(N15-N16),0) | M15: =IF(AND(ISNUMBER(O15),ISNUMBER(O16)),VLOOKUP(ABS(O15-O16),'IMP Table'!$A$2:$C$26,3)*SIGN(O15-O16),0) | N15: =IF(ISNUMBER(J15),J15,IF(ISNUMBER(K15),-K15,"")) | O15: =IF(ISNUMBER(K15),K15,IF(ISNUMBER(J15),-J15,""))
B16: 2 | C16: 1 | D16: 1 | E16: 3 | F16: Both | L16: =IF(AND(ISNUMBER(N16),ISNUMBER(N15)),VLOOKUP(ABS(N16-N15),'IMP Table'!$A$2:$C$26,3)*SIGN(N16-N15),0) | M16: =IF(AND(ISNUMBER(O16),ISNUMBER(O15)),VLOOKUP(ABS(O16-O15),'IMP Table'!$A$2:$C$26,3)*SIGN(O16-O15),0) | N16: =IF(ISNUMBER(J16),J16,IF(ISNUMBER(K16),-K16,"")) | O16: =IF(ISNUMBER(K16),K16,IF(ISNUMBER(J16),-J16,""))
A17: 8 | B17: 1 | C17: 2 | D17: 4 | E17: 2 | F17: None | L17: =IF(AND(ISNUMBER(N17),ISNUMBER(N18)),VLOOKUP(ABS(N17-N18),'IMP Table'!$A$2:$C$26,3)*SIGN(N17-N18),0) | M17: =IF(AND(ISNUMBER(O17),ISNUMBER(O18)),VLOOKUP(ABS(O17-O18),'IMP Table'!$A$2:$C$26,3)*SIGN(O17-O18),0) | N17: =IF(ISNUMBER(J17),J17,IF(ISNUMBER(K17),-K17,"")) | O17: =IF(ISNUMBER(K17),K17,IF(ISNUMBER(J17),-J17,""))
B18: 2 | C18: 1 | D18: 1 | E18: 3 | F18: None | L18: =IF(AND(ISNUMBER(N18),ISNUMBER(N17)),VLOOKUP(ABS(N18-N17),'IMP Table'!$A$2:$C$26,3)*SIGN(N18-N17),0) | M18: =IF(AND(ISNUMBER(O18),ISNUMBER(O17)),VLOOKUP(ABS(O18-O17),'IMP Table'!$A$2:$C$26,3)*SIGN(O18-O17),0) | N18: =IF(ISNUMBER(J18),J18,IF(ISNUMBER(K18),-K18,"")) | O18: =IF(ISNUMBER(K18),K18,IF(ISNUMBER(J18),-J18,""))
A19: 9 | B19: 3 | C19: 1 | D19: 1 | E19: 4 | F19: EW | L19: =IF(AND(ISNUMBER(N19),ISNUMBER(N20)),VLOOKUP(ABS(N19-N20),'IMP Table'!$A$2:$C$26,3)*SIGN(N19-N20),0) | M19: =IF(AND(ISNUMBER(O19),ISNUMBER(O20)),VLOOKUP(ABS(O19-O20),'IMP Table'!$A$2:$C$26,3)*SIGN(O19-O20),0) | N19: =IF(ISNUMBER(J19),J19,IF(ISNUMBER(K19),-K19,"")) | O19: =IF(ISNUMBER(K19),K19,IF(ISNUMBER(J19),-J19,""))
B20: 4 | C20: 2 | D20: 3 | E20: 2 | F20: EW | L20: =IF(AND(ISNUMBER(N20),ISNUMBER(N19)),VLOOKUP(ABS(N20-N19),'IMP Table'!$A$2:$C$26,3)*SIGN(N20-N19),0) | M20: =IF(AND(ISNUMBER(O20),ISNUMBER(O19)),VLOOKUP(ABS(O20-O19),'IMP Table'!$A$2:$C$26,3)*SIGN(O20-O19),0) | N20: =IF(ISNUMBER(J20),J20,IF(ISNUMBER(K20),-K20,"")) | O20: =IF(ISNUMBER(K20),K20,IF(ISNUMBER(J20),-J20,""))
A21: 10 | B21: 3 | C21: 1 | D21: 1 | E21: 4 | F21: Both | L21: =IF(AND(ISNUMBER(N21),ISNUMBER(N22)),VLOOKUP(ABS(N21-N22),'IMP Table'!$A$2:$C$26,3)*SIGN(N21-N22),0) | M21: =IF(AND(ISNUMBER(O21),ISNUMBER(O22)),VLOOKUP(ABS(O21-O22),'IMP Table'!$A$2:$C$26,3)*SIGN(O21-O22),0) | N21: =IF(ISNUMBER(J21),J21,IF(ISNUMBER(K21),-K21,"")) | O21: =IF(ISNUMBER(K21),K21,IF(ISNUMBER(J21),-J21,""))
B22: 4 | C22: 2 | D22: 3 | E22: 2 | F22: Both | L22: =IF(AND(ISNUMBER(N22),ISNUMBER(N21)),VLOOKUP(ABS(N22-N21),'IMP Table'!$A$2:$C$26,3)*SIGN(N22-N21),0) | M22: =IF(AND(ISNUMBER(O22),ISNUMBER(O21)),VLOOKUP(ABS(O22-O21),'IMP Table'!$A$2:$C$26,3)*SIGN(O22-O21),0) | N22: =IF(ISNUMBER(J22),J22,IF(ISNUMBER(K22),-K22,"")) | O22: =IF(ISNUMBER(K22),K22,IF(ISNUMBER(J22),-J22,""))
A23: 11 | B23: 3 | C23: 1 | D23: 1 | E23: 4 | F23: None | L23: =IF(AND(ISNUMBER(N23),ISNUMBER(N24)),VLOOKUP(ABS(N23-N24),'IMP Table'!$A$2:$C$26,3)*SIGN(N23-N24),0) | M23: =IF(AND(ISNUMBER(O23),ISNUMBER(O24)),VLOOKUP(ABS(O23-O24),'IMP Table'!$A$2:$C$26,3)*SIGN(O23-O24),0) | N23: =IF(ISNUMBER(J23),J23,IF(ISNUMBER(K23),-K23,"")) | O23: =IF(ISNUMBER(K23),K23,IF(ISNUMBER(J23),-J23,""))
B24: 4 | C24: 2 | D24: 3 | E24: 2 | F24: None | L24: =IF(AND(ISNUMBER(N24),ISNUMBER(N23)),VLOOKUP(ABS(N24-N23),'IMP Table'!$A$2:$C$26,3)*SIGN(N24-N23),0) | M24: =IF(AND(ISNUMBER(O24),ISNUMBER(O23)),VLOOKUP(ABS(O24-O23),'IMP Table'!$A$2:$C$26,3)*SIGN(O24-O23),0) | N24: =IF(ISNUMBER(J24),J24,IF(ISNUMBER(K24),-K24,"")) | O24: =IF(ISNUMBER(K24),K24,IF(ISNUMBER(J24),-J24,""))
A25: 12 | B25: 3 | C25: 1 | D25: 1 | E25: 4 | F25: NS | L25: =IF(AND(ISNUMBER(N25),ISNUMBER(N26)),VLOOKUP(ABS(N25-N26),'IMP Table'!$A$2:$C$26,3)*SIGN(N25-N26),0) | M25: =IF(AND(ISNUMBER(O25),ISNUMBER(O26)),VLOOKUP(ABS(O25-O26),'IMP Table'!$A$2:$C$26,3)*SIGN(O25-O26),0) | N25: =IF(ISNUMBER(J25),J25,IF(ISNUMBER(K25),-K25,"")) | O25: =IF(ISNUMBER(K25),K25,IF(ISNUMBER(J25),-J25,""))
B26: 4 | C26: 2 | D26: 3 | E26: 2 | F26: NS | L26: =IF(AND(ISNUMBER(N26),ISNUMBER(N25)),VLOOKUP(ABS(N26-N25),'IMP Table'!$A$2:$C$26,3)*SIGN(N26-N25),0) | M26: =IF(AND(ISNUMBER(O26),ISNUMBER(O25)),VLOOKUP(ABS(O26-O25),'IMP Table'!$A$2:$C$26,3)*SIGN(O26-O25),0) | N26: =IF(ISNUMBER(J26),J26,IF(ISNUMBER(K26),-K26,"")) | O26: =IF(ISNUMBER(K26),K26,IF(ISNUMBER(J26),-J26,""))
A27: 13 | B27: 3 | C27: 2 | D27: 3 | E27: 2 | F27: Both | L27: =IF(AND(ISNUMBER(N27),ISNUMBER(N28)),VLOOKUP(ABS(N27-N28),'IMP Table'!$A$2:$C$26,3)*SIGN(N27-N28),0) | M27: =IF(AND(ISNUMBER(O27),ISNUMBER(O28)),VLOOKUP(ABS(O27-O28),'IMP Table'!$A$2:$C$26,3)*SIGN(O27-O28),0) | N27: =IF(ISNUMBER(J27),J27,IF(ISNUMBER(K27),-K27,"")) | O27: =IF(ISNUMBER(K27),K27,IF(ISNUMBER(J27),-J27,""))
B28: 4 | C28: 1 | D28: 1 | E28: 4 | F28: Both | L28: =IF(AND(ISNUMBER(N28),ISNUMBER(N27)),VLOOKUP(ABS(N28-N27),'IMP Table'!$A$2:$C$26,3)*SIGN(N28-N27),0) | M28: =IF(AND(ISNUMBER(O28),ISNUMBER(O27)),VLOOKUP(ABS(O28-O27),'IMP Table'!$A$2:$C$26,3)*SIGN(O28-O27),0) | N28: =IF(ISNUMBER(J28),J28,IF(ISNUMBER(K28),-K28,"")) | O28: =IF(ISNUMBER(K28),K28,IF(ISNUMBER(J28),-J28,""))
A29: 14 | B29: 3 | C29: 2 | D29: 3 | E29: 2 | F29: None | L29: =IF(AND(ISNUMBER(N29),ISNUMBER(N30)),VLOOKUP(ABS(N29-N30),'IMP Table'!$A$2:$C$26,3)*SIGN(N29-N30),0) | M29: =IF(AND(ISNUMBER(O29),ISNUMBER(O30)),VLOOKUP(ABS(O29-O30),'IMP Table'!$A$2:$C$26,3)*SIGN(O29-O30),0) | N29: =IF(ISNUMBER(J29),J29,IF(ISNUMBER(K29),-K29,"")) | O29: =IF(ISNUMBER(K29),K29,IF(ISNUMBER(J29),-J29,""))
B30: 4 | C30: 1 | D30: 1 | E30: 4 | F30: None | L30: =IF(AND(ISNUMBER(N30),ISNUMBER(N29)),VLOOKUP(ABS(N30-N29),'IMP Table'!$A$2:$C$26,3)*SIGN(N30-N29),0) | M30: =IF(AND(ISNUMBER(O30),ISNUMBER(O29)),VLOOKUP(ABS(O30-O29),'IMP Table'!$A$2:$C$26,3)*SIGN(O30-O29),0) | N30: =IF(ISNUMBER(J30),J30,IF(ISNUMBER(K30),-K30,"")) | O30: =IF(ISNUMBER(K30),K30,IF(ISNUMBER(J30),-J30,""))
A31: 15 | B31: 3 | C31: 2 | D31: 3 | E31: 2 | F31: NS | L31: =IF(AND(ISNUMBER(N31),ISNUMBER(N32)),VLOOKUP(ABS(N31-N32),'IMP Table'!$A$2:$C$26,3)*SIGN(N31-N32),0) | M31: =IF(AND(ISNUMBER(O31),ISNUMBER(O32)),VLOOKUP(ABS(O31-O32),'IMP Table'!$A$2:$C$26,3)*SIGN(O31-O32),0) | N31: =IF(ISNUMBER(J31),J31,IF(ISNUMBER(K31),-K31,"")) | O31: =IF(ISNUMBER(K31),K31,IF(ISNUMBER(J31),-J31,""))
B32: 4 | C32: 1 | D32: 1 | E32: 4 | F32: NS | L32: =IF(AND(ISNUMBER(N32),ISNUMBER(N31)),VLOOKUP(ABS(N32-N31),'IMP Table'!$A$2:$C$26,3)*SIGN(N32-N31),0) | M32: =IF(AND(ISNUMBER(O32),ISNUMBER(O31)),VLOOKUP(ABS(O32-O31),'IMP Table'!$A$2:$C$26,3)*SIGN(O32-O31),0) | N32: =IF(ISNUMBER(J32),J32,IF(ISNUMBER(K32),-K32,"")) | O32: =IF(ISNUMBER(K32),K32,IF(ISNUMBER(J32),-J32,""))
A33: 16 | B33: 3 | C33: 2 | D33: 3 | E33: 2 | F33: EW | L33: =IF(AND(ISNUMBER(N33),ISNUMBER(N34)),VLOOKUP(ABS(N33-N34),'IMP Table'!$A$2:$C$26,3)*SIGN(N33-N34),0) | M33: =IF(AND(ISNUMBER(O33),ISNUMBER(O34)),VLOOKUP(ABS(O33-O34),'IMP Table'!$A$2:$C$26,3)*SIGN(O33-O34),0) | N33: =IF(ISNUMBER(J33),J33,IF(ISNUMBER(K33),-K33,"")) | O33: =IF(ISNUMBER(K33),K33,IF(ISNUMBER(J33),-J33,""))
B34: 4 | C34: 1 | D34: 1 | E34: 4 | F34: EW | L34: =IF(AND(ISNUMBER(N34),ISNUMBER(N33)),VLOOKUP(ABS(N34-N33),'IMP Table'!$A$2:$C$26,3)*SIGN(N34-N33),0) | M34: =IF(AND(ISNUMBER(O34),ISNUMBER(O33)),VLOOKUP(ABS(O34-O33),'IMP Table'!$A$2:$C$26,3)*SIGN(O34-O33),0) | N34: =IF(ISNUMBER(J34),J34,IF(ISNUMBER(K34),-K34,"")) | O34: =IF(ISNUMBER(K34),K34,IF(ISNUMBER(J34),-J34,""))

Sheet IMP Table
A1: From | B1: To | C1: IMP
A2: 0 | B2: 10 | C2: 0
A3: 20 | B3: 40 | C3: 1
A4: 50 | B4: 80 | C4: 2
A5: 90 | B5: 120 | C5: 3
A6: 130 | B6: 160 | C6: 4
A7: 170 | B7: 210 | C7: 5
A8: 220 | B8: 260 | C8: 6
A9: 270 | B9: 310 | C9: 7
A10: 320 | B10: 360 | C10: 8
A11: 370 | B11: 420 | C11: 9
A12: 430 | B12: 490 | C12: 10
A13: 500 | B13: 590 | C13: 11
... A26: 4000 | B26: 10000 | C26: 24

Sheet Scoring Table
C1: Not Vulnerable | F1: Vulnerable | K1: Not Vulnerable | N1: Vulnerable
A2: Contract | B2: Made | D2: X | E2: XX | G2: X | H2: XX | J2: Down by | L2: X | M2: XX | O2: X | P2: XX
A3: 1 D/C | B3: 1 | C3: 70 | D3: 140 | E3: 230 | F3: 70 | G3: 140 | H3: 230 | J3: -1 | K3: -50 | L3: -100 | M3: =L3*2 | N3: -100 | O3: -200 | P3: =O3*2
B4: 2 | C4: 90 | D4: 240 | E4: 430 | F4: 90 | G4: 340 | H4: 630 | J4: -2 | K4: =K3-50 | L4: =L3-200 | M4: =L4*2 | N4: =K3-100 | O4: =L3-300 | P4: =L4*2
B5: 3 | C5: 110 | D5: 340 | E5: 630 | F5: 110 | G5: 540 | H5: 1030 | J5: -3 | K5: =K4-50 | L5: =L4-200 | M5: =L5*2 | N5: =K4-100 | O5: =L4-300 | P5: =L5*2
B6: 4 | C6: 130 | D6: 440 | E6: 830 | F6: 130 | G6: 740 | H6: 1430 | J6: -4 | K6: =K5-50 | L6: =L5-300 | M6: =L6*2 | N6: =K5-100 | O6: =L5-300 | P6: =L6*2
B7: 5 | C7: 150 | D7: 540 | E7: 1030 | F7: 150 | G7: 940 | H7: 1830 | J7: -5 | K7: =K6-50 | L7: =L6-300 | M7: =L7*2 | N7: =K6-100 | O7: =L6-300 | P7: =L7*2
B8: 6 | C8: 170 | D8: 640 | E8: 1230 | F8: 170 | G8: 1140 | H8: 2230 | J8: -6 | K8: =K7-50 | L8: =L7-300 | M8: =L8*2 | N8: =K7-100 | O8: =L7-300 | P8: =L8*2
B9: 7 | C9: 190 | D9: 740 | E9: 1430 | F9: 190 | G9: 1340 | H9: 2630 | J9: -7 | K9: =K8-50 | L9: =L8-300 | M9: =L9*2 | N9: =K8-100 | O9: =L8-300 | P9: =L9*2
A10: 1 H/S | B10: 1 | C10: 80 | D10: 160 | E10: 520 | F10: 80 | G10: 160 | H10: 720 | J10: -8 | K10: =K9-50 | L10: =L9-300 | M10: =L10*2 | N10: =K9-100 | O10: =L9-300 | P10: =L10*2
B11: 2 | C11: 110 | D11: 260 | E11: 720 | F11: 110 | G11: 360 | H11: 1120 | J11: -9 | K11: =K10-50 | L11: =L10-300 | M11: =L11*2 | N11: =K10-100 | O11: =L10-300 | P11: =L11*2
B12: 3 | C12: 140 | D12: 360 | E12: 920 | F12: 140 | G12: 560 | H12: 1520 | J12: -10 | K12: =K11-50 | L12: =L11-300 | M12: =L12*2 | N12: =K11-100 | O12: =L11-300 | P12: =L12*2
B13: 4 | C13: 170 | D13: 460 | E13: 1120 | F13: 170 | G13: 760 | H13: 1920 | J13: -11 | K13: =K12-50 | L13: =L12-300 | M13: =L13*2 | N13: =K12-100 | O13: =L12-300 | P13: =L13*2
B14: 5 | C14: 200 | D14: 560 | E14: 1320 | F14: 200 | G14: 960 | H14: 2320 | J14: -12 | K14: =K13-50 | L14: =L13-300 | M14: =L14*2 | N14: =K13-100 | O14: =L13-300 | P14: =L14*2
B15: 6 | C15: 230 | D15: 660 | E15: 1520 | F15: 230 | G15: 1160 | H15: 2720 | J15: -13 | K15: =K14-50 | L15: =L14-300 | M15: =L15*2 | N15: =K14-100 | O15: =L14-300 | P15: =L15*2
B16: 7 | C16: 260 | D16: 760 | E16: 1720 | F16: 260 | G16: 1360 | H16: 3120
A17: 1 NT | B17: 1 | C17: 90 | D17: 180 | E17: 560 | F17: 90 | G17: 180 | H17: 760
B18: 2 | C18: 120 | D18: 280 | E18: 760 | F18: 120 | G18: 380 | H18: 1160
B19: 3 | C19: 150 | D19: 380 | E19: 960 | F19: 150 | G19: 580 | H19: 1560
B20: 4 | C20: 180 | D20: 480 | E20: 1160 | F20: 180 | G20: 780 | H20: 1960
B21: 5 | C21: 210 | D21: 580 | E21: 1360 | F21: 210 | G21: 980 | H21: 2360
B22: 6 | C22: 240 | D22: 680 | E22: 1560 | F22: 240 | G22: 1180 | H22: 2760
B23: 7 | C23: 270 | D23: 780 | E23: 1760 | F23: 270 | G23: 1380 | H23: 3160
A24: 2 D/C | B24: 2 | C24: 90 | D24: 180 | E24: 560 | F24: 90 | G24: 180 | H24: 760
B25: 3 | C25: 110 | D25: 280 | E25: 760 | F25: 110 | G25: 380 | H25: 1160
B26: 4 | C26: 130 | D26: 380 | E26: 960 | F26: 130 | G26: 580 | H26: 1560
B27: 5 | C27: 150 | D27: 480 | E27: 1160 | F27: 150 | G27: 780 | H27: 1960
B28: 6 | C28: 170 | D28: 580 | E28: 1360 | F28: 170 | G28: 980 | H28: 2360
B29: 7 | C29: 190 | D29: 680 | E29: 1560 | F29: 190 | G29: 1180 | H29: 2760
A30: 2 H/S | B30: 2 | C30: 110 | D30: 470 | E30: 640 | F30: 110 | G30: 670 | H30: 840
B31: 3 | C31: 140 | D31: 570 | E31: 840 | F31: 140 | G31: 870 | H31: 1240
B32: 4 | C32: 170 | D32: 670 | E32: 1040 | F32: 170 | G32: 1070 | H32: 1640
B33: 5 | C33: 200 | D33: 770 | E33: 1240 | F33: 200 | G33: 1270 | H33: 2040
B34: 6 | C34: 230 | D34: 870 | E34: 1440 | F34: 230 | G34: 1470 | H34: 2440
B35: 7 | C35: 260 | D35: 970 | E35: 1640 | F35: 260 | G35: 1670 | H35: 2840
A36: 2 NT | B36: 2 | C36: 120 | D36: 490 | E36: 680 | F36: 120 | G36: 690 | H36: 880
B37: 3 | C37: 150 | D37: 590 | E37: 880 | F37: 150 | G37: 890 | H37: 1280
B38: 4 | C38: 180 | D38: 690 | E38: 1080 | F38: 180 | G38: 1090 | H38: 1680
B39: 5 | C39: 210 | D39: 790 | E39: 1280 | F39: 210 | G39: 1290 | H39: 2080
B40: 6 | C40: 240 | D40: 890 | E40: 1480 | F40: 240 | G40: 1490 | H40: 2480
...
